File: examples/171124 - Er(COT)I(THF)2 - ACvsF.dat
[Header]
; MPMS3 Data File (default extension .dat)
; Copyright (c) 2007, Quantum Design, Inc. All rights reserved.
TITLE,
FILEOPENTIME,3720609901.29649,11/23/2017,1:47 pm
BYAPP,SQUID AC,0.9.1.0
INFO,MPMS3 Measurement Release 1.1.16 Build 347, MultiVu Release 2.3.3.2,APPNAME
INFO,0,MOMENT_UNITS
INFO,Er(COT)I(THF)2,SAMPLE_MATERIAL
INFO,pink cyrstalline powder in 28.8 mg eicosane,SAMPLE_COMMENT
INFO,26.3,SAMPLE_MASS
INFO,28.8,SAMPLE_VOLUME
INFO,542.53,SAMPLE_MOLECULAR_WEIGHT
INFO,,SAMPLE_SIZE
INFO,,SAMPLE_SHAPE
INFO,Straw,SAMPLE_HOLDER
INFO,Standard,SAMPLE_HOLDER_DETAIL
INFO,65.79,SAMPLE_OFFSET
DATATYPE,COMMENT,1
DATATYPE,TIME,2
STARTUPAXIS,X,2
STARTUPAXIS,Y1,5
FIELDGROUP, VSM,2,3,4,5,6,8,9,10,11,14,15
FIELDGROUP, DC, 2,3,4,14,56,57,58,59,60,61,62,63,64,65,66,67,68,69
FIELDGROUP, AC, 2,3,4,11,16,17,18,19,20,21,22,23,24,25,26,27,28,29,30
STARTUPGROUP, All
[Data]
Comment,Time Stamp (sec),Temperature (K),Magnetic Field (Oe),Moment (emu),M. Std. Err. (emu),Transport Action,Averaging Time (sec),Frequency (Hz),Peak Amplitude (mm),Center Position (mm),Lockin Signal' (V),Lockin Signal (V),Range,M. Quad. Signal (emu),AC Moment (emu),AC M. Std Err. (emu),AC Phase (deg),AC Phase Std. Err. (deg),AC Susceptibility (emu/Oe),AC Suscept. Std Err. (emu/Oe),AC X' (emu/Oe),AC X' Std Err. (emu/Oe),AC X'' (emu/Oe),AC X'' Std Err. (emu/Oe),AC Drive (Oe),AC Frequency (Hz),AC Averaging Time (sec),AC Cycles,AC Range,AC Measure Type,AC Signal' (V),AC Signal'' (V),AC Trim Coil Ratio,AC Trim Coil Phase,Min. Temperature (K),Max. Temperature (K),Min. Field (Oe),Max. Field (Oe),Mass (grams),Motor Lag (deg),Pressure (Torr),Measure Count,Measurement Number,SQUID Status (code),Motor Status (code),Measure Status (code),Motor Current (amps),Motor Temp. (C),Temp. Status (code),Field Status (code),Chamber Status (code),Chamber Temp (K),Redirection State,Evercool Status,Average Temp (K),Rotation Angle (deg),Rotator state,DC Moment Fixed Ctr (emu),DC Moment Err Fixed Ctr (emu),DC Moment Free Ctr (emu),DC Moment Err Free Ctr (emu),DC Fixed Fit,DC Free Fit,DC Calculated Center (mm),DC Calculated Center Err (mm),DC Scan Length (mm),DC Scan Time (s),DC Number of Points,DC Squid Drift,DC Min V (V),DC Max V (V),DC Scans per Measure,Map 01,Map 02,Map 03,Map 04,Map 05,Map 06,Map 07,Map 08,Map 09,Map 10,Map 11,Map 12,Map 13,Map 14,Map 15,Map 16
,3720610041.02044,11.1026692390442,-0.232215464115143,,,5,,,,21.5700007975101,,,,,5.675461762531E-5,6.04127466048367E-8,44.6569755380522,0.00903515641152056,2.83685173858973E-5,3.01970152226843E-8,2.01793055729591E-5,2.5939880972859E-8,1.99391174645994E-5,1.54590524765567E-8,2.00061980163702,999.040954589844,2,1998,1,5,0.108696954465075,0.168410700927026,0.0269327480345964,352.687438964844,11.0985317230225,11.1037120819092,-0.232215464115143,-0.232215464115143,,,0.286798715591431,0,1,,,,,,1,1,3,11.1035394668579,0,0,11.1009126186371,,,,,,,,,,,,,,,,,,,,,,,,,,,,,,,,,
,3720610316.92931,11.0998382568359,-0.232215464115143,,,5,,,,21.5700007975101,,,,,9.02742306814027E-5,2.58955798024487E-8,12.9829998764394,0.000241744654981038,4.51482090623398E-5,1.29509721864881E-8,4.39940748610522E-5,6.58237772927566E-9,1.01430842773232E-5,1.11534740778076E-8,1.99950856426561,188.890228271484,2,377,1,5,0.300786950714284,0.100176562220249,0.0260232780128717,3.392822265625,11.098916053772,11.1015272140503,-0.232215464115143,-0.232215464115143,,,0.284721463918686,0,1,,,,,,1,1,3,11.0999965667725,0,0,11.099947301965,,,,,,,,,,,,,,,,,,,,,,,,,,,,,,,,,
,3720610594.3709,11.0998935699463,-0.232215464115143,,,5,,,,21.5700007975101,,,,,9.33854610377461E-5,1.26867106957437E-8,2.74056268391526,0.000117624152480007,4.66989170517037E-5,6.34419580795378E-9,4.66455063571014E-5,3.12581229014763E-9,2.23284358868216E-6,5.52069904780366E-9,1.99973504598302,35.5890121459961,2,71,1,5,0.320559238203193,0.0702715848398344,0.0210405625402927,19.0458068847656,11.0989351272583,11.1013374328613,-0.232215464115143,-0.232215464115143,,,0.284106582403183,0,1,,,,,,1,1,3,11.0999555587769,0,0,11.0999604777286,,,,,,,,,,,,,,,,,,,,,,,,,,,,,,,,,
,3720610893.53353,11.1000928878784,-0.232215464115143,,,5,,,,21.5700007975101,,,,,9.45199194270705E-5,1.77646500129142E-7,1.00147535380481,0.00129300519640774,4.72596320769624E-5,8.88226342844178E-8,4.72524129521513E-5,6.4479069807519E-8,8.26011046667422E-7,6.10893601045265E-8,2.00001386538822,6.72193384170532,2,13,1,5,0.331714437507061,0.0289980227482311,0.012982465326786,11.9632263183594,11.0992317199707,11.1014366149902,-0.232215464115143,-0.232215464115143,,,0.283608347177506,0,1,,,,,,1,1,3,11.1001453399658,0,0,11.1000215499128,,,,,,,,,,,,,,,,,,,,,,,,,,,,,,,,,
,3720611374.97424,11.0999803543091,-0.232215464115143,,,5,,,,21.5700007975101,,,,,9.46304621745602E-5,1.30609940890518E-7,0.193275822747516,0.000658014079583265,4.7315973857989E-5,6.53059956250602E-8,4.73157046504783E-5,5.74088702908277E-8,1.59610646900099E-7,3.11302855192705E-8,1.99996860380762,1.30083453655243,2,2,1,5,0.333605241283713,0.0062071098858529,0.0122663425281644,2.73287963867187,11.0992527008057,11.101450920105,-0.232215464115143,-0.232215464115143,,,0.283132314682007,0,1,,,,,,1,1,3,11.1000566482544,0,0,11.1000182098813,,,,,,,,,,,,,,,,,,,,,,,,,,,,,,,,,
,3720611716.84931,10.9997882843018,-0.232215464115143,,,5,,,,21.5700007975101,,,,,8.51926685408153E-5,2.01227600467252E-8,21.7090134254322,0.000198957026682957,4.25961749119639E-5,1.00613423824273E-8,3.95750153808779E-5,5.74685483230413E-9,1.57560234429219E-5,8.25858765606145E-9,2.00000748228892,303.751953125,2,607,1,5,0.265911679955296,0.13729239374027,0.0262283142656088,0.335357666015625,10.9989557266235,11.0013551712036,-0.232215464115143,-0.232215464115143,,,0.281915217638016,0,1,,,,,,1,1,3,10.9997711181641,0,0,11.0000043919212,,,,,,,,,,,,,,,,,,,,,,,,,,,,,,,,,
,3720611992.12457,10.9998788833618,-0.232215464115143,,,5,,,,21.5700007975101,,,,,9.3710100978168E-5,9.67153351218556E-9,4.57474295757271,8.26235291644417E-5,4.68594267921814E-5,4.83621842097869E-9,4.67101389741857E-5,2.87922617955667E-9,3.73748529148507E-6,3.88575156467434E-9,1.99981321567945,57.4448547363281,2,114,1,5,0.320364157008198,0.0756999020803119,0.023620568215847,14.2135314941406,10.9990711212158,11.0013723373413,-0.232215464115143,-0.232215464115143,,,0.281565308570862,0,1,,,,,,1,1,3,10.9999113082886,0,0,11.0000006274173,,,,,,,,,,,,,,,,,,,,,,,,,,,,,,,,,
,3720612262.89618,10.9999327659607,-0.232215464115143,,,5,,,,21.5700007975101,,,,,9.49438295172008E-5,2.79980422144601E-8,1.33357096921919,0.000156154516636974,4.74697051279978E-5,1.39983695079507E-8,4.74568477049801E-5,1.19009891500751E-8,1.10476732635671E-6,7.37026499733345E-9,2.00009309645369,10.8218364715576,2,21,1,5,0.331543422546172,0.0422682123354388,0.0141223818063736,17.1456604003906,10.9988718032837,11.001467704773,-0.232215464115143,-0.232215464115143,,,0.281447947025299,0,1,,,,,,1,1,3,10.9998741149902,0,0,11.0000173418145,,,,,,,,,,,,,,,,,,,,,,,,,,,,,,,,,
,3720612698.46214,11.0000100135803,-0.232215464115143,,,5,,,,21.5700007975101,,,,,9.58500014873241E-5,1.8013437420952E-7,0.419471469174341,0.00144104137130667,4.79246238872846E-5,9.0066478864941E-8,4.79233395284802E-5,5.78096094508539E-8,3.50860621466156E-7,6.9065329002826E-8,2.0000157270458,2.03994512557983,2,4,1,5,0.337783972722067,0.0102616500189762,0.012301579117775,3.96044921875,10.9992790222168,11.0015621185303,-0.232215464115143,-0.232215464115143,,,0.281280368566513,0,1,,,,,,1,1,3,11.0000486373901,0,0,11.0000277774435,,,,,,,,,,,,,,,,,,,,,,,,,,,,,,,,,
,3720613128.14671,10.8998460769653,-0.232215464115143,,,5,,,,21.5700007975101,,,,,7.40504882447769E-5,1.33427366039345E-8,33.5165544508136,0.000296180574518655,3.70227741164515E-5,6.67092324563595E-9,3.08668610829609E-5,5.39116484625554E-9,2.0443157538966E-5,3.92893860344808E-9,2.00013343170499,489.505035400391,2,979,1,5,0.197801546740774,0.169269534457694,0.0263376943767071,357.377471923828,10.8989391326904,10.9014091491699,-0.232215464115143,-0.232215464115143,,,0.280188769102097,0,1,,,,,,1,1,3,10.8999881744385,0,0,10.8999727444771,,,,,,,,,,,,,,,,,,,,,,,,,,,,,,,,,
,3720613407.91377,10.8998875617981,-0.232215464115143,,,5,,,,21.5700007975101,,,,,9.39404084541264E-5,1.71075195065051E-8,7.98924656784462,0.000141716779044446,4.69590281079861E-5,8.55172446643334E-9,4.65032518439064E-5,5.34810158404449E-9,6.52670581448588E-6,6.67306532236388E-9,2.00047599447976,92.4775085449219,2,184,1,5,0.318588255121065,0.0857344802516735,0.0251245927065611,9.23187255859375,10.8989877700806,10.9014043807983,-0.232215464115143,-0.232215464115143,,,0.279857903718948,0,1,,,,,,1,1,3,10.8999357223511,0,0,10.899986546214,,,,,,,,,,,,,,,,,,,,,,,,,,,,,,,,,
,3720613679.00113,10.8999285697937,-0.232215464115143,,,5,,,,21.5700007975101,,,,,9.51160994032185E-5,1.39027561337213E-8,1.89211644774918,7.0333373892028E-5,4.75606529642589E-5,6.95175857579657E-9,4.75347213948987E-5,6.12944961911932E-9,1.57034145841904E-6,3.27975527483974E-9,1.99989052872543,17.4386157989502,2,34,1,5,0.329517745086534,0.0578891776070785,0.0163540299981833,20.8293762207031,10.8987483978271,10.9015579223633,-0.232215464115143,-0.232215464115143,,,0.279761165380478,0,1,,,,,,1,1,3,10.8999853134155,0,0,10.8999899563036,,,,,,,,,,,,,,,,,,,,,,,,,,,,,,,,,
,3720614055.21873,10.8999590873718,-0.232215464115143,,,5,,,,21.5700007975101,,,,,9.63408317521972E-5,2.27386677868022E-7,0.679912737111534,0.00185612653151279,4.81714440412185E-5,1.13695765641843E-7,4.81680523550317E-5,7.02082637266148E-8,5.71623424270673E-7,8.94288925872333E-8,1.99995731225665,3.30276823043823,2,6,1,5,0.339219169838936,0.0163245839346577,0.0124331135302782,6.1134033203125,10.8993053436279,10.901330947876,-0.232215464115143,-0.232215464115143,,,0.279718369245529,0,1,,,,,,1,1,3,10.8999509811401,0,0,10.8999878369845,,,,,,,,,,,,,,,,,,,,,,,,,,,,,,,,,
,3720614536.64758,10.7997641563416,-0.232215464115143,,,5,,,,21.5700007975101,,,,,5.68606348756733E-5,2.28434367179428E-8,46.0839104600539,0.00295509779666925,2.84396717852273E-5,1.14254764148412E-8,1.97258741705582E-5,9.57099268365795E-9,2.04866985983287E-5,6.24000082976427E-9,1.99934216207126,787.550415039063,2,1575,1,5,0.111417162393038,0.166524854231299,0.0265771485865116,354.282836914063,10.7992124557495,10.8014011383057,-0.232215464115143,-0.232215464115143,,,0.27873033285141,0,1,,,,,,1,1,3,10.7998285293579,0,0,10.7999794106734,,,,,,,,,,,,,,,,,,,,,,,,,,,,,,,,,
,3720614814.52261,10.799946308136,-0.232215464115143,,,5,,,,21.5700007975101,,,,,9.22220236109634E-5,1.8715527355501E-8,13.9372645223273,0.000162448106781335,4.61250439374365E-5,9.36061135707018E-9,4.47671242443534E-5,5.55974759863735E-9,1.11096473895925E-5,7.53062093173979E-9,1.99939156125363,148.866241455078,2,297,1,5,0.304901183555571,0.109188105307853,0.0258024632930756,5.12326049804687,10.7990627288818,10.8014678955078,-0.232215464115143,-0.232215464115143,,,0.278303146362305,0,1,,,,,,1,1,3,10.7999401092529,0,0,10.7999962364755,,,,,,,,,,,,,,,,,,,,,,,,,,,,,,,,,
,3720615089.0186,10.7998223304749,-0.232215464115143,,,5,,,,21.5700007975101,,,,,9.59787984776737E-5,1.05421364607579E-8,2.965189942437,7.34948444515228E-5,4.79847869406602E-5,5.27056162394559E-9,4.7920542372548E-5,3.94499673613319E-9,2.48221603841999E-6,3.49511381555829E-9,2.000192240019,28.1268005371094,2,56,1,5,0.329431024383547,0.0727643474000661,0.0194897446781397,20.6346435546875,10.7990007400513,10.8014335632324,-0.232215464115143,-0.232215464115143,,,0.278186351060867,0,1,,,,,,1,1,3,10.7998142242432,0,0,10.8000396176388,,,,,,,,,,,,,,,,,,,,,,,,,,,,,,,,,
,3720615411.54848,10.7999520301819,-0.232215464115143,,,5,,,,21.5700007975101,,,,,9.67450018970312E-5,1.34908242567999E-7,1.03553336651476,0.000683399422508193,4.8373027070501E-5,6.74548549466284E-8,4.83651267560567E-5,5.88504475416158E-8,8.74220700961486E-7,3.29663810574075E-8,1.99997824729949,5.29819059371948,2,10,1,5,0.339972498937378,0.0253137235839025,0.0126921273767948,9.6492919921875,10.7992744445801,10.8013315200806,-0.232215464115143,-0.232215464115143,,,0.278075963258743,0,1,,,,,,1,1,3,10.800048828125,0,0,10.7999809941938,,,,,,,,,,,,,,,,,,,,,,,,,,,,,,,,,
,3720615910.1245,10.7999339103699,-0.232215464115143,,,5,,,,21.5700007975101,,,,,9.75917440750873E-5,1.81540464381814E-7,0.310358466173278,0.00067261277605082,4.87964831170768E-5,9.07713689229462E-8,4.87957672384542E-5,8.4635629178928E-8,2.64318379535654E-7,3.28062751563263E-8,1.99997495395184,1.00057637691498,2,2,1,5,0.344058720036179,0.00600704379613311,0.0122133195400238,2.18807983398438,10.7991924285889,10.8014440536499,-0.232215464115143,-0.232215464115143,,,0.278201639652252,0,1,,,,,,1,1,3,10.7999210357666,0,0,10.7999974576438,,,,,,,,,,,,,,,,,,,,,,,,,,,,,,,,,
,3720616217.69662,10.6999297142029,-0.232215464115143,,,5,,,,21.5700007975101,,,,,8.63468495357682E-5,1.51232581652746E-8,23.1748686205566,0.000146662579707372,4.31844874291704E-5,7.56356665747095E-9,3.96998466578807E-5,5.62203892903043E-9,1.69947677201228E-5,5.05966588447029E-9,1.99948765577897,239.353561401367,2,478,1,5,0.266388087387284,0.14493548981758,0.0261182691901922,1.82904052734375,10.6989698410034,10.7013454437256,-0.232215464115143,-0.232215464115143,,,0.276911318302155,0,1,,,,,,1,1,3,10.6999197006226,0,0,10.6999592136692,,,,,,,,,,,,,,,,,,,,,,,,,,,,,,,,,
,3720616495.34562,10.6998615264893,-0.232215464115143,,,5,,,,21.5700007975101,,,,,9.63465062795139E-5,1.03833991656771E-8,4.96866877418471,7.76101838325792E-5,4.81683100442796E-5,5.19116685845197E-9,4.79873035919867E-5,3.63072806266787E-9,4.1719044203269E-6,3.71025970617235E-9,2.00020524263661,45.2112274169922,2,90,1,5,0.32800212263066,0.083666040829913,0.0224773790687323,16.7923889160156,10.6991176605225,10.7014074325562,-0.232215464115143,-0.232215464115143,,,0.276809334754944,0,1,,,,,,1,1,3,10.6999731063843,0,0,10.6999859558909,,,,,,,,,,,,,,,,,,,,,,,,,,,,,,,,,
,3720616769.86752,10.6999449729919,-0.232215464115143,,,5,,,,21.5700007975101,,,,,9.7453877908172E-5,8.60116098490156E-8,1.44753961631966,0.000599318556440623,4.87280080742859E-5,4.30067485170204E-8,4.87124576868391E-5,3.15924057133564E-8,1.23094963161871E-6,2.91804783930786E-8,1.99995611886296,8.52446269989014,2,17,1,5,0.34109198175787,0.0379563832528207,0.0134058408439159,14.58056640625,10.6992483139038,10.7012643814087,-0.232215464115143,-0.232215464115143,,,0.276773542165756,0,1,,,,,,1,1,3,10.6999673843384,0,0,10.7001085119732,,,,,,,,,,,,,,,,,,,,,,,,,,,,,,,,,
,3720617241.18082,10.6999897956848,-0.232215464115143,,,5,,,,21.5700007975101,,,,,9.85307754876048E-5,1.41847259818122E-7,0.28507067365792,0.000988314652159434,4.92647051821083E-5,7.09226472769293E-8,4.92640954138465E-5,5.15699905553606E-8,2.4511167961714E-7,4.86883761373055E-8,2.00002770996768,1.61127662658691,2,3,1,5,0.347310552218832,0.00816224665433842,0.0122436238452792,3.22891235351562,10.6990261077881,10.7013959884644,-0.232215464115143,-0.232215464115143,,,0.276658922433853,0,1,,,,,,1,1,3,10.6999626159668,0,0,10.699976404508,,,,,,,,,,,,,,,,,,,,,,,,,,,,,,,,,
,3720617647.9489,10.5999450683594,-0.232215464115143,,,5,,,,21.5700007975101,,,,,7.36605970491007E-5,1.36679726739668E-8,35.3729714937848,0.000331776587301514,3.6837672739543E-5,6.83535464749197E-9,3.00374741967429E-5,5.61229618660132E-9,2.13252028535645E-5,3.90182068666031E-9,1.99959963730365,385.993103027344,2,771,1,5,0.193801786410585,0.171569440839186,0.0262805335223675,358.864715576172,10.5990581512451,10.6014738082886,-0.232215464115143,-0.232215464115143,,,0.275452017784119,0,1,,,,,,1,1,3,10.6000299453735,0,0,10.6000103699534,,,,,,,,,,,,,,,,,,,,,,,,,,,,,,,,,
,3720617924.29081,10.5998945236206,-0.232215464115143,,,5,,,,21.5700007975101,,,,,9.61252444305028E-5,1.26706751329014E-8,8.59980210859464,0.000108163971184522,4.80665233535431E-5,6.33585179199295E-9,4.7526106505369E-5,3.54137566116955E-9,7.18747992950411E-6,5.25372975671343E-9,1.99983767753441,72.6609039306641,2,145,1,5,0.323683727138204,0.0960268551418277,0.0244797542691231,11.6899108886719,10.5991115570068,10.6013975143433,-0.232215464115143,-0.232215464115143,,,0.275273829698563,0,1,,,,,,1,1,3,10.5999412536621,0,0,10.5999910705968,,,,,,,,,,,,,,,,,,,,,,,,,,,,,,,,,
,3720618194.76732,10.5998630523682,-0.232215464115143,,,5,,,,21.5700007975101,,,,,9.77709806413641E-5,2.33665505890952E-8,2.02579217985478,0.000202965636461448,4.89002535269575E-5,1.16868035930676E-8,4.88696916243226E-5,6.12775856159889E-9,1.7285935162251E-6,9.95147995193119E-9,1.9993961910129,13.746657371521,2,27,1,5,0.339754050326229,0.0541243085311958,0.0151071259751916,19.3669738769531,10.5989971160889,10.6013278961182,-0.232215464115143,-0.232215464115143,,,0.275212824344635,0,1,,,,,,1,1,3,10.5999240875244,0,0,10.5999819855941,,,,,,,,,,,,,,,,,,,,,,,,,,,,,,,,,
,3720618605.4254,10.6000175476074,-0.232215464115143,,,5,,,,21.5700007975101,,,,,9.89518331034923E-5,1.14010302761726E-7,0.688971542713367,0.000460990261719312,4.94751948224327E-5,5.70043198189309E-8,4.94716178994612E-5,5.22608658562641E-8,5.94916067510132E-7,2.2766079547707E-8,2.00002917540057,2.59945297241211,2,5,1,5,0.348559575596517,0.0142797060585647,0.0123628471046686,4.87371826171875,10.5992441177368,10.601354598999,-0.232215464115143,-0.232215464115143,,,0.275234073400497,0,1,,,,,,1,1,3,10.6000900268555,0,0,10.5999865196121,,,,,,,,,,,,,,,,,,,,,,,,,,,,,,,,,
,3720619063.01456,10.4999618530273,-0.232215464115143,,,5,,,,21.5700007975101,,,,,5.57611445910864E-5,1.03547895691265E-8,47.7694800859187,0.00103587334560044,2.78784470697616E-5,5.17700013223111E-9,1.87375252570066E-5,3.36482733071473E-9,2.06425036820764E-5,3.93437001355949E-9,2.00015246371337,621.025451660156,2,1242,1,5,0.109391801996032,0.162886052123658,0.0264472644776106,355.842681884766,10.4990348815918,10.5012578964233,-0.232215464115143,-0.232215464115143,,,0.274176508188248,0,1,,,,,,1,1,3,10.500036239624,0,0,10.4999432434907,,,,,,,,,,,,,,,,,,,,,,,,,,,,,,,,,
,3720619337.62984,10.5000014305115,-0.232215464115143,,,5,,,,21.5700007975101,,,,,9.41865729104915E-5,1.59893349657957E-8,14.9203865176741,0.000116955992416062,4.71014284913926E-5,7.99604969417522E-9,4.55133815628014E-5,6.27009163273548E-9,1.21275168376969E-5,4.96213277017254E-9,1.99965427646644,117.093826293945,2,234,1,5,0.308269534602791,0.119905847461384,0.0255516692996025,7.0885009765625,10.4991064071655,10.5014209747314,-0.232215464115143,-0.232215464115143,,,0.273869246244431,0,1,,,,,,1,1,3,10.4999122619629,0,0,10.500000326257,,,,,,,,,,,,,,,,,,,,,,,,,,,,,,,,,
,3720619611.40895,10.4999599456787,-0.232215464115143,,,5,,,,21.5700007975101,,,,,9.85239673027428E-5,1.63157704798286E-8,3.18752643654436,9.80001844439891E-5,4.92603383153792E-5,8.15761276890906E-9,4.91841273074566E-5,6.63967409244521E-9,2.73907866800539E-6,4.73934320698343E-9,2.00006680165214,22.1141872406006,2,44,1,5,0.338698164415047,0.0727670545678635,0.0178622789680958,21.285888671875,10.4990139007568,10.5012626647949,-0.232215464115143,-0.232215464115143,,,0.273699998855591,0,1,,,,,,1,1,3,10.499942779541,0,0,10.5000124955789,,,,,,,,,,,,,,,,,,,,,,,,,,,,,,,,,
,3720619960.11788,10.4999651908875,-0.232215464115143,,,5,,,,21.5700007975101,,,,,9.9634814613869E-5,1.40771547972066E-7,1.14111922875116,0.00097022036727641,4.98163284507059E-5,7.03842496969386E-8,4.98064487418337E-5,5.11732354832315E-8,9.92090739649687E-7,4.83243476477308E-8,2.00004331335778,4.2035231590271,2,8,1,5,0.350420480678997,0.0229219818896736,0.0124931493774056,7.71920776367187,10.4992389678955,10.5013484954834,-0.232215464115143,-0.232215464115143,,,0.273750782012939,0,1,,,,,,1,1,3,10.4999961853027,0,0,10.4999805934845,,,,,,,,,,,,,,,,,,,,,,,,,,,,,,,,,
,3720620534.0266,10.000093460083,-0.232215464115143,,,5,,,,21.5700007975101,,,,,2.79085369633088E-5,8.71347739079842E-8,60.0786618555779,0.350505129219064,1.3954338604366E-5,4.3567605887956E-8,6.96057139260823E-6,4.02183876119798E-8,1.20943793463618E-5,1.67516441193338E-8,1.9999899496904,999.040954589844,2,1998,1,5,0.0294888105733421,0.0940489306441938,0.0269240457564592,352.658538818359,9.99921798706055,10.0013046264648,-0.232215464115143,-0.232215464115143,,,0.267711371183395,0,1,,,,,,1,1,3,10.0002326965332,0,0,10.0000698740889,,,,,,,,,,,,,,,,,,,,,,,,,,,,,,,,,
,3720620804.07693,9.99998092651367,-0.232215464115143,,,5,,,,21.5700007975101,,,,,8.0720673567204E-5,2.81294976215225E-8,33.1337810189831,0.000394164421205578,4.03496562167314E-5,1.40610268524685E-8,3.37886647163656E-5,7.83914207015091E-9,2.20549516774226E-5,1.16730599137429E-8,2.00052940063792,188.890228271484,2,377,1,5,0.221629032422545,0.176751388864961,0.0260454881936312,3.41976928710937,9.99895668029785,10.0013389587402,-0.232215464115143,-0.232215464115143,,,0.266095757484436,0,1,,,,,,1,1,3,10.0001201629639,0,0,9.99997587461729,,,,,,,,,,,,,,,,,,,,,,,,,,,,,,,,,
,3720621080.54034,9.99996089935303,-0.232215464115143,,,5,,,,21.5700007975101,,,,,0.000102042782723564,1.20176777387282E-8,7.9384202807248,9.04547971120522E-5,5.10295027652743E-5,6.00979415724018E-9,5.05404909023812E-5,3.87769566714823E-9,7.04761887572402E-6,4.59141613506966E-9,1.99968208965196,35.5890121459961,2,71,1,5,0.341879272225141,0.108205704553059,0.0210351068526506,19.0704650878906,9.99905776977539,10.0013608932495,-0.232215464115143,-0.232215464115143,,,0.26544451713562,0,1,,,,,,1,1,3,9.99996757507324,0,0,9.99998554023537,,,,,,,,,,,,,,,,,,,,,,,,,,,,,,,,,
,3720621379.22798,9.99998044967651,-0.232215464115143,,,5,,,,21.5700007975101,,,,,0.00010407950526153,3.20698607855113E-7,1.98460938597981,0.00143002849095134,5.20398030786809E-5,1.60349459371958E-7,5.20085878124218E-5,1.42385226183653E-7,1.8021926160935E-6,7.3745484509285E-8,1.99999806117961,6.72193384170532,2,13,1,5,0.364661795353769,0.0381937369584263,0.0129402903839946,12.0147399902344,9.99925994873047,10.0013437271118,-0.232215464115143,-0.232215464115143,,,0.264947354793549,0,1,,,,,,1,1,3,9.99996852874756,0,0,10.0000050028817,,,,,,,,,,,,,,,,,,,,,,,,,,,,,,,,,
,3720621865.90251,10.0000433921814,-0.232215464115143,,,5,,,,21.5700007975101,,,,,0.000105349311122253,1.86823273980694E-7,0.622003856215838,0.00173924452742343,5.26745109819786E-5,9.34113805980696E-8,5.2671407086123E-5,1.81374989537034E-8,5.71824062538524E-7,9.16336027718098E-8,2.00000548952977,1.30083453655243,2,2,1,5,0.371330800343293,0.00968907639250513,0.0122610768303275,2.69061279296875,9.99930000305176,10.0013618469238,-0.232215464115143,-0.232215464115143,,,0.264775693416595,0,1,,,,,,1,1,3,10.0000085830688,0,0,10.0000082386865,,,,,,,,,,,,,,,,,,,,,,,,,,,,,,,,,
,3720622516.06013,9.49986982345581,-0.232215464115143,,,5,,,,21.5700007975101,,,,,5.14210906384493E-5,1.44740828775315E-8,49.6160450974974,0.00165879256366908,2.57156960448408E-5,7.23849127245308E-9,1.66613695673233E-5,5.48197691988806E-9,1.95881542574004E-5,4.72691071961319E-9,1.99959940997847,303.751953125,2,607,1,5,0.103040702825553,0.148357448977625,0.0262637790292501,0.3251953125,9.49914646148682,9.50138187408447,-0.232215464115143,-0.232215464115143,,,0.256132632493973,0,1,,,,,,1,1,3,9.49994087219238,0,0,9.50000501933851,,,,,,,,,,,,,,,,,,,,,,,,,,,,,,,,,
,3720622793.23133,9.49992275238037,-0.232215464115143,,,5,,,,21.5700007975101,,,,,0.000100266761431797,1.73635477489806E-8,18.8583335036874,0.000134242790768376,5.0132490218776E-5,8.68161966397144E-9,4.74414115857686E-5,7.82788883366674E-9,1.62042908603055E-5,3.75428773505857E-9,2.00003552574862,57.4448547363281,2,114,1,5,0.312197162371788,0.163067268284813,0.0236416086554527,14.263427734375,9.49919891357422,9.50117111206055,-0.232215464115143,-0.232215464115143,,,0.255272060632706,0,1,,,,,,1,1,3,9.49991321563721,0,0,9.50001417963128,,,,,,,,,,,,,,,,,,,,,,,,,,,,,,,,,
,3720623063.86031,9.49987125396729,-0.232215464115143,,,5,,,,21.5700007975101,,,,,0.000108492438448494,2.27351357573931E-8,4.08391829013644,0.000113194438017446,5.42484261774715E-5,1.13680303568368E-8,5.41106791952518E-5,9.64528718429255E-9,3.86343626336931E-6,6.01668923299886E-9,1.99991863530872,10.8218364715576,2,21,1,5,0.376100914370032,0.0664242058739082,0.0141397397965193,17.1861267089844,9.4990873336792,9.50123977661133,-0.232215464115143,-0.232215464115143,,,0.254886865615845,0,1,,,,,,1,1,3,9.49982833862305,0,0,9.49997801529734,,,,,,,,,,,,,,,,,,,,,,,,,,,,,,,,,
,3720623506.37952,9.50001335144043,-0.232215464115143,,,5,,,,21.5700007975101,,,,,0.000109569028057675,1.52396108289543E-7,1.19172997463385,0.000935442026593829,5.47855675124462E-5,7.61995194019244E-8,5.47737171680256E-5,5.63981832292325E-8,1.13943637731461E-6,5.12407229215803E-8,1.99996154156445,2.03994512557983,2,4,1,5,0.385937865052706,0.016933792172289,0.0123127093538642,3.93429565429687,9.49936485290527,9.50129985809326,-0.232215464115143,-0.232215464115143,,,0.254541277885437,0,1,,,,,,1,1,3,9.49988651275635,0,0,9.50000012887491,,,,,,,,,,,,,,,,,,,,,,,,,,,,,,,,,
,3720624257.86879,9.00006437301636,-0.232215464115143,,,5,,,,21.5700007975101,,,,,3.13851408129902E-5,1.84103396572905E-8,53.316639101699,0.0068856161316046,1.56976049853282E-5,9.20812308308182E-9,9.37762803948964E-6,7.40794840912257E-9,1.25886812108488E-5,5.46917096834269E-9,1.99935855452627,489.505035400391,2,979,1,5,0.0545642575699861,0.0959052437839382,0.0263940617442131,357.337860107422,8.99932765960693,9.00137424468994,-0.232215464115143,-0.232215464115143,,,0.245723962783813,0,1,,,,,,1,1,3,9.00017261505127,0,0,9.00000073359563,,,,,,,,,,,,,,,,,,,,,,,,,,,,,,,,,
,3720624540.28663,8.99996042251587,-0.232215464115143,,,5,,,,21.5700007975101,,,,,8.37277387376178E-5,1.73537287675488E-8,34.1546555549207,0.000284511192842555,4.18710613185409E-5,8.67835501455988E-9,3.46493564467311E-5,5.22748383671499E-9,2.35076131023205E-5,6.92728363037202E-9,1.99965647158178,92.4775085449219,2,184,1,5,0.221154476392016,0.193801755719072,0.0251245573163033,9.2822265625,8.99914455413818,9.0014533996582,-0.232215464115143,-0.232215464115143,,,0.244465187191963,0,1,,,,,,1,1,3,8.99995994567871,0,0,8.99997836787526,,,,,,,,,,,,,,,,,,,,,,,,,,,,,,,,,
,3720624810.97236,8.9999361038208,-0.232215464115143,,,5,,,,21.5700007975101,,,,,0.000112399690688313,1.44592780988313E-8,8.98924270207085,8.95903794346638E-5,5.61986214677621E-5,7.2294816079758E-9,5.55083727908509E-5,5.31683076421267E-9,8.78097972829556E-6,4.89864419454833E-9,2.00004355538845,17.4386157989502,2,34,1,5,0.377958598088786,0.115996182414341,0.0163790918886662,20.8922119140625,8.99906635284424,9.00123310089111,-0.232215464115143,-0.232215464115143,,,0.243973776698112,0,1,,,,,,1,1,3,8.99992752075195,0,0,8.99997731801626,,,,,,,,,,,,,,,,,,,,,,,,,,,,,,,,,
,3720625187.33816,9.0000376701355,-0.232215464115143,,,5,,,,21.5700007975101,,,,,0.000114995989360286,1.95527175977686E-7,2.12300207089254,0.00145776985647851,5.74992880373409E-5,9.77657870784096E-8,5.745982065227E-5,5.01412088984547E-8,2.13005525986263E-6,8.39285904401024E-8,1.99995501310566,3.30276823043823,2,6,1,5,0.404285406286423,0.0296769104101733,0.0123958727344871,6.122802734375,8.99928283691406,9.00143051147461,-0.232215464115143,-0.232215464115143,,,0.243638157844543,0,1,,,,,,1,1,3,9.00008583068848,0,0,9.00001041816943,,,,,,,,,,,,,,,,,,,,,,,,,,,,,,,,,
,3720625981.05012,8.50011301040649,-0.232215464115143,,,5,,,,21.5700007975101,,,,,2.18515329043362E-5,2.93615371423358E-8,51.2218404290666,0.0158882265198287,1.09220244737524E-5,1.46757405377242E-8,6.84053701850577E-6,1.04190686256798E-8,8.51455647134361E-6,1.03353940081633E-8,2.00068521699886,787.550415039063,2,1575,1,5,0.0368972300957936,0.067580082361623,0.0265893042087555,354.226348876953,8.49917507171631,8.50127601623535,-0.232215464115143,-0.232215464115143,,,0.235071048140526,0,1,,,,,,1,1,3,8.50038814544678,0,0,8.49999161770469,,,,,,,,,,,,,,,,,,,,,,,,,,,,,,,,,
,3720626252.04626,8.49984884262085,-0.232215464115143,,,5,,,,21.5700007975101,,,,,6.18653093451883E-5,1.89173445983474E-8,44.0306452465907,0.000799714617380863,3.09386190767227E-5,9.46049611108732E-9,2.22438817883689E-5,5.53507239693799E-9,2.15036711600513E-5,7.67228520250345E-9,1.99961443630604,148.866241455078,2,297,1,5,0.140232832270443,0.165936985115106,0.0258843805640936,5.15042114257812,8.4990291595459,8.50138187408447,-0.232215464115143,-0.232215464115143,,,0.233624696731567,0,1,,,,,,1,1,3,8.499831199646,0,0,8.50000313000801,,,,,,,,,,,,,,,,,,,,,,,,,,,,,,,,,
,3720626526.8682,8.49995279312134,-0.232215464115143,,,5,,,,21.5700007975101,,,,,0.000112039679768605,1.2299103720199E-8,17.324863740235,8.64634924959734E-5,5.60282754150267E-5,6.15047786656012E-9,5.34863657094351E-5,4.7633257641941E-9,1.66846135459785E-5,3.89090036510968E-9,1.99969888308495,28.1268005371094,2,56,1,5,0.351475431528057,0.177663221273553,0.0194968953728676,20.7061157226562,8.49913501739502,8.50124073028564,-0.232215464115143,-0.232215464115143,,,0.233029156923294,0,1,,,,,,1,1,3,8.49998188018799,0,0,8.50001114293149,,,,,,,,,,,,,,,,,,,,,,,,,,,,,,,,,
,3720626849.3013,8.50001239776611,-0.232215464115143,,,5,,,,21.5700007975101,,,,,0.000120911276339958,1.37762263820446E-7,3.79339443035665,0.000458888909440937,6.0454124055125E-5,6.88794067784051E-8,6.03216752542941E-5,6.33832545522496E-8,3.99957620104066E-6,2.69617455019094E-8,2.00005009136689,5.29819059371948,2,10,1,5,0.422881007890546,0.0520448916306657,0.0126751596108079,9.69174194335938,8.49936580657959,8.50141716003418,-0.232215464115143,-0.232215464115143,,,0.232555493712425,0,1,,,,,,1,1,3,8.50005149841309,0,0,8.50000324556904,,,,,,,,,,,,,,,,,,,,,,,,,,,,,,,,,
,3720627352.28315,8.50009536743164,-0.232215464115143,,,5,,,,21.5700007975101,,,,,0.000122486923232596,1.39583279338114E-7,1.1045370106871,0.000656540851653347,6.12436063622057E-5,6.97918046181631E-8,6.12322266156043E-5,5.70571765308742E-8,1.18056933048439E-6,4.01917230059189E-8,1.99999527310959,1.00057637691498,2,2,1,5,0.431680438575875,0.0135241877384858,0.0122144836932421,2.19747924804687,8.49936008453369,8.50142574310303,-0.232215464115143,-0.232215464115143,,,0.232350051403046,0,1,,,,,,1,1,3,8.50002288818359,0,0,8.50001075655915,,,,,,,,,,,,,,,,,,,,,,,,,,,,,,,,,
,3720627964.96182,8.00001430511475,-0.232215464115143,,,5,,,,21.5700007975101,,,,,4.62808662765644E-5,1.99569509411845E-8,48.3228755399958,0.00191139158748606,2.31418461681551E-5,9.9790847886565E-9,1.53877587712368E-5,6.71329724959386E-9,1.72847309515878E-5,7.38334431391297E-9,1.99987788097262,239.353561401367,2,478,1,5,0.096223356921239,0.131003941252413,0.0261990036815405,1.8184814453125,7.99919033050537,8.00110530853271,-0.232215464115143,-0.232215464115143,,,0.223259598016739,0,1,,,,,,1,1,3,8.00004959106445,0,0,8.00001188328392,,,,,,,,,,,,,,,,,,,,,,,,,,,,,,,,,
,3720628241.87388,7.99998712539673,-0.232215464115143,,,5,,,,21.5700007975101,,,,,0.000103635852979659,1.03130638891274E-8,26.9160567323855,0.000118303669710954,5.18300190106601E-5,5.15773530166766E-9,4.62153094875633E-5,3.92664383941991E-9,2.34626520157915E-5,3.34420418043135E-9,1.99953337771965,45.2112274169922,2,90,1,5,0.293608414024682,0.215345963498494,0.0224812440574169,16.8651123046875,7.99917078018188,8.00105953216553,-0.232215464115143,-0.232215464115143,,,0.222283929586411,0,1,,,,,,1,1,3,7.99999809265137,0,0,7.99998668620461,,,,,,,,,,,,,,,,,,,,,,,,,,,,,,,,,
,3720628517.68433,8.00003528594971,-0.232215464115143,,,5,,,,21.5700007975101,,,,,0.000127042153882808,8.72744418660057E-8,6.76392950900114,0.000519502104077846,6.3523211452329E-5,4.36386872829029E-8,6.30810805252016E-5,2.8491244425367E-8,7.48168918028079E-6,3.30542587100208E-8,1.99993279587488,8.52446269989014,2,17,1,5,0.438154288085795,0.0904683264372917,0.0133875524625182,14.6650695800781,7.99931859970093,8.00135612487793,-0.232215464115143,-0.232215464115143,,,0.221902549266815,0,1,,,,,,1,1,3,8.00002479553223,0,0,7.99999094817598,,,,,,,,,,,,,,,,,,,,,,,,,,,,,,,,,
,3720628977.64168,8.00002098083496,-0.232215464115143,,,5,,,,21.5700007975101,,,,,0.000128930754738789,1.4628386135887E-7,1.52412549395215,0.000388133014656471,6.44666172582793E-5,7.31433374480069E-8,6.44438098746689E-5,6.87815799750195E-8,1.71467476887223E-6,2.48805560462984E-8,1.99996153392446,1.61127662658691,2,3,1,5,0.454130028046763,0.0205056849126908,0.0122619345784187,3.26138305664063,7.99928569793701,8.00146389007568,-0.232215464115143,-0.232215464115143,,,0.221615269780159,0,1,,,,,,1,1,3,8.00001716613769,0,0,8.0000002073205,,,,,,,,,,,,,,,,,,,,,,,,,,,,,,,,,
,3720629679.39792,7.50009226799011,-0.232215464115143,,,5,,,,21.5700007975101,,,,,3.56546308820568E-5,1.43902504292162E-8,49.9770163642088,0.00177017053977672,1.78207162651236E-5,7.19246177954938E-9,1.14604108377393E-5,3.68226248472527E-9,1.36468645348398E-5,6.17838566648793E-9,2.00074061848094,385.993103027344,2,771,1,5,0.0698211805910986,0.104025693086937,0.0263228435069323,358.829071044922,7.49931335449219,7.501145362854,-0.232215464115143,-0.232215464115143,,,0.212526485323906,0,1,,,,,,1,1,3,7.50016832351685,0,0,7.49997536759628,,,,,,,,,,,,,,,,,,,,,,,,,,,,,,,,,
,3720629956.36955,7.50003957748413,-0.232215464115143,,,5,,,,21.5700007975101,,,,,9.03290392123702E-5,9.41175929639351E-9,35.2919033984991,0.000162685187736213,4.51573591696942E-5,4.70513357245748E-9,3.68583053978131E-5,2.82708376085179E-9,2.60893160198253E-5,3.76110081542552E-9,2.00031713265003,72.6609039306641,2,145,1,5,0.231211847131893,0.217257174905028,0.0245217103511095,11.7495727539062,7.4992208480835,7.50116634368897,-0.232215464115143,-0.232215464115143,,,0.211687296628952,0,1,,,,,,1,1,3,7.50012969970703,0,0,7.49998910803544,,,,,,,,,,,,,,,,,,,,,,,,,,,,,,,,,
,3720630226.67742,7.4999270439148,-0.232215464115143,,,5,,,,21.5700007975101,,,,,0.000132060730566897,1.84455956385265E-8,11.1942310050179,8.71743736775351E-5,6.60325183752973E-5,9.2230985525808E-9,6.47762303945134E-5,7.5718355253857E-9,1.28192612447405E-5,5.26619916895716E-9,1.99993478692311,13.746657371521,2,27,1,5,0.441398527265595,0.145296616808426,0.0150870606303215,19.4809265136719,7.4993748664856,7.50120878219604,-0.232215464115143,-0.232215464115143,,,0.211110889911652,0,1,,,,,,1,1,3,7.49992322921753,0,0,7.50000626162479,,,,,,,,,,,,,,,,,,,,,,,,,,,,,,,,,
,3720630631.57446,7.49999737739563,-0.232215464115143,,,5,,,,21.5700007975101,,,,,0.000136843562909092,8.2490814143129E-8,2.4440339511217,0.000381200720221988,6.84232693938724E-5,4.12463040178573E-8,6.83610283056933E-5,3.19768104449681E-8,2.91780800167507E-6,2.60526618390538E-8,1.99995650779801,2.59945297241211,2,5,1,5,0.481202883915289,0.0345022534721579,0.0123102143406868,4.91552734375,7.49930667877197,7.50154209136963,-0.232215464115143,-0.232215464115143,,,0.210659310221672,0,1,,,,,,1,1,3,7.50013780593872,0,0,7.50000795951256,,,,,,,,,,,,,,,,,,,,,,,,,,,,,,,,,
,3720631409.61236,7.00013899803162,-0.232215464115143,,,5,,,,21.5700007975101,,,,,2.81242312957379E-5,1.06464069201086E-8,50.1094847158179,0.00238630010370005,1.40665937749011E-5,5.32489865172452E-9,9.02122486745809E-6,2.97738560677495E-9,1.07928940659511E-5,4.41471636684702E-9,1.99936329617478,621.025451660156,2,1242,1,5,0.0517491861278991,0.0843514125243675,0.0264498945325613,355.802612304687,6.99909591674805,7.00121545791626,-0.232215464115143,-0.232215464115143,,,0.201812997460365,0,1,,,,,,1,1,3,7.00036907196045,0,0,6.99994126119112,,,,,,,,,,,,,,,,,,,,,,,,,,,,,,,,,
,3720631685.7859,6.99990701675415,-0.232215464115143,,,5,,,,21.5700007975101,,,,,7.55010371098303E-5,1.39582178186112E-8,41.8642625427832,0.000440468353597009,3.77545242059004E-5,6.97984945209943E-9,2.81168495216183E-5,4.31076467566581E-9,2.51961677838633E-5,5.48959072108337E-9,1.99978780551102,117.093826293945,2,234,1,5,0.176725429087049,0.197664360517962,0.0255687162280083,7.12881469726563,6.99932241439819,7.00123262405395,-0.232215464115143,-0.232215464115143,,,0.20066624879837,0,1,,,,,,1,1,3,7.00000095367432,0,0,6.99997131448043,,,,,,,,,,,,,,,,,,,,,,,,,,,,,,,,,
,3720631959.76296,6.99996423721314,-0.232215464115143,,,5,,,,21.5700007975101,,,,,0.000134019883505652,2.1586016263978E-8,17.3295403935084,0.000128840279184762,6.70034850428309E-5,1.07919681769964E-8,6.39620194937286E-5,7.55293268983935E-9,1.9958132932936E-5,7.70842298502476E-9,2.00019272758696,22.1141872406006,2,44,1,5,0.422573946558901,0.208554359537313,0.0178327765315771,21.4078979492187,6.99924993515015,7.00111150741577,-0.232215464115143,-0.232215464115143,,,0.200112342834473,0,1,,,,,,1,1,3,6.99990129470825,0,0,7.00000819407011,,,,,,,,,,,,,,,,,,,,,,,,,,,,,,,,,
,3720632307.56716,7.00001645088196,-0.232215464115143,,,5,,,,21.5700007975101,,,,,0.000145915888045853,1.94225813088111E-7,3.90400130702698,0.000621131337184169,7.29561068665324E-5,9.71104611407537E-8,7.27868141530179E-5,8.62613999658597E-8,4.967213965084E-6,4.46028310637319E-8,2.00005036333415,4.2035231590271,2,8,1,5,0.510978468704341,0.0582686377081446,0.0124594112858176,7.82046508789063,6.99934673309326,7.00139284133911,-0.232215464115143,-0.232215464115143,,,0.199500173330307,0,1,,,,,,1,1,3,7.00000667572022,0,0,7.00000993789188,,,,,,,,,,,,,,,,,,,,,,,,,,,,,,,,,
,3720633147.37489,6.50030755996704,-0.232215464115143,,,5,,,,21.5700007975101,,,,,2.19182528105814E-5,6.18952414203171E-8,49.8755368405279,0.0472985785626975,1.09623210282777E-5,3.09566420478874E-8,7.06466958373225E-6,2.64719356467727E-8,8.38229837214761E-6,1.60483740607624E-8,1.99941716302984,999.040954589844,2,1998,1,5,0.0358454825395967,0.0686034964843891,0.0268914103507996,352.625762939453,6.49941539764404,6.50100326538086,-0.232215464115143,-0.232215464115143,,,0.190200448036194,0,1,,,,,,1,1,3,6.50074291229248,0,0,6.50013181141445,,,,,,,,,,,,,,,,,,,,,,,,,,,,,,,,,
,3720633421.11973,6.49999165534973,-0.232215464115143,,,5,,,,21.5700007975101,,,,,6.16029875767693E-5,2.63018196877112E-8,46.4988377693188,0.0012218582215893,3.07934384460042E-5,1.31474705599646E-8,2.11972573471523E-5,6.83554209682202E-9,2.23363410675618E-5,1.1230821268621E-8,2.00052318563869,188.890228271484,2,377,1,5,0.133363608801482,0.170344561879299,0.0260323937982321,3.4195556640625,6.4992823600769,6.50119113922119,-0.232215464115143,-0.232215464115143,,,0.188918277621269,0,1,,,,,,1,1,3,6.50004816055298,0,0,6.4999852051606,,,,,,,,,,,,,,,,,,,,,,,,,,,,,,,,,
,3720633700.28736,6.50000309944153,-0.232215464115143,,,5,,,,21.5700007975101,,,,,0.000130034818179239,1.46789830951664E-8,24.7562306343455,0.00012061241514223,6.5029878145476E-5,7.3408991172072E-9,5.90534789558068E-5,5.547070740229E-9,2.72318136529968E-5,4.80820195623154E-9,1.99961651301794,35.5890121459961,2,71,1,5,0.377129874054247,0.258046495624899,0.0210411846637726,19.1680908203125,6.49912595748901,6.50123357772827,-0.232215464115143,-0.232215464115143,,,0.188094452023506,0,1,,,,,,1,1,3,6.50002479553223,0,0,6.5000072403958,,,,,,,,,,,,,,,,,,,,,,,,,,,,,,,,,
,3720633998.79841,6.49996542930603,-0.232215464115143,,,5,,,,21.5700007975101,,,,,0.000155986566217229,1.7992514085706E-7,6.22177197637443,0.000678313658274268,7.79908371194294E-5,8.99597490641054E-8,7.7531459642438E-5,7.3412945364992E-8,8.4524221559487E-6,5.19932294103138E-8,2.0000627250399,6.72193384170532,2,13,1,5,0.540804389123803,0.0974672535479846,0.0128996120765805,12.0925903320312,6.49942636489868,6.50148582458496,-0.232215464115143,-0.232215464115143,,,0.187493368983269,0,1,,,,,,1,1,3,6.50005674362183,0,0,6.5000563684057,,,,,,,,,,,,,,,,,,,,,,,,,,,,,,,,,
,3720634484.88023,6.49996685981751,-0.232215464115143,,,5,,,,21.5700007975101,,,,,0.000158014721630125,3.06242010236554E-7,1.29001630181352,0.00165582069242194,7.90089894226371E-5,1.53124161457461E-7,7.89889643870288E-5,7.94925234683874E-8,1.77873962430534E-6,1.30873784749576E-7,1.99995877411959,1.30083453655243,2,2,1,5,0.556756313865708,0.0210255893363201,0.012206144630909,2.723388671875,6.49941778182983,6.50124216079712,-0.232215464115143,-0.232215464115143,,,0.186719447374344,0,1,,,,,,1,1,3,6.50002431869507,0,0,6.50000673294067,,,,,,,,,,,,,,,,,,,,,,,,,,,,,,,,,
,3720635151.08031,5.99999904632568,-0.232215464115143,,,5,,,,21.5700007975101,,,,,4.96282929861564E-5,1.60387054625332E-8,49.219062982768,0.00156245962941251,2.48203038977196E-5,8.0213426606701E-9,1.6211845795044E-5,5.21093009535676E-9,1.87942422431145E-5,6.09820839437217E-9,1.99950384131743,303.751953125,2,607,1,5,0.100419287632208,0.142504545139543,0.0262696836143732,0.322357177734375,5.9993724822998,6.00119972229004,-0.232215464115143,-0.232215464115143,,,0.176425814628601,0,1,,,,,,1,1,3,6.00012254714966,0,0,5.99999856948852,,,,,,,,,,,,,,,,,,,,,,,,,,,,,,,,,
,3720635427.29196,5.99998641014099,-0.232215464115143,,,5,,,,21.5700007975101,,,,,0.000119629914665536,8.24251601261283E-9,32.4725128312845,0.000103022318730434,5.98212835045242E-5,4.12169388032792E-9,5.04681728102205E-5,2.79213011122945E-9,3.21177442129173E-5,3.03189212952875E-9,1.99978849762541,57.4448547363281,2,114,1,5,0.316219350322464,0.276776329489546,0.0236152745783329,14.3240356445313,5.99927663803101,6.00138711929321,-0.232215464115143,-0.232215464115143,,,0.175469219684601,0,1,,,,,,1,1,3,5.99993324279785,0,0,5.99997809058742,,,,,,,,,,,,,,,,,,,,,,,,,,,,,,,,,
,3720635697.77853,5.99997282028198,-0.232215464115143,,,5,,,,21.5700007975101,,,,,0.000165818171547389,2.33968383271148E-8,9.70602144207561,8.45830906856363E-5,8.29081482377321E-5,1.16982868778306E-8,8.17213808094472E-5,9.654657309424E-9,1.39777309606056E-5,6.60586921711362E-9,2.00002261625624,10.8218364715576,2,21,1,5,0.562115266135359,0.157349882906691,0.014105168171227,17.3369750976562,5.99907207489014,6.00120687484741,-0.232215464115143,-0.232215464115143,,,0.1748978048563,0,1,,,,,,1,1,3,5.99995803833008,0,0,6.00000469308151,,,,,,,,,,,,,,,,,,,,,,,,,,,,,,,,,
,3720636141.64027,6.00007724761963,-0.232215464115143,,,5,,,,21.5700007975101,,,,,0.000170542534002802,1.86585545203734E-7,2.04915613752263,0.000888940704114656,8.52694623845051E-5,9.32907982238656E-8,8.52149340699615E-5,5.43097016818097E-8,3.04897143224425E-6,7.58526818014949E-8,2.00004232739003,2.03994512557983,2,4,1,5,0.600244735408098,0.0353439339089291,0.0122402096167207,3.98623657226562,5.99922227859497,6.00141286849976,-0.232215464115143,-0.232215464115143,,,0.174032866954803,0,1,,,,,,1,1,3,6.00006818771362,0,0,5.99999409836608,,,,,,,,,,,,,,,,,,,,,,,,,,,,,,,,,
,3720636882.63026,5.50017738342285,-0.232215464115143,,,5,,,,21.5700007975101,,,,,4.01787813085415E-5,1.11040838772315E-8,50.3582868990054,0.00175089392870776,2.00967931339668E-5,5.55408773873131E-9,1.28214481113792E-5,3.51847666139612E-9,1.5475514938013E-5,4.29746583380675E-9,1.99926331732166,489.505035400391,2,979,1,5,0.0760711609251005,0.119021402996362,0.0263860505074263,357.347503662109,5.49928903579712,5.50126886367798,-0.232215464115143,-0.232215464115143,,,0.163453683257103,0,1,,,,,,1,1,3,5.50037813186646,0,0,5.50001181874956,,,,,,,,,,,,,,,,,,,,,,,,,,,,,,,,,
,3720637159.38653,5.49991059303284,-0.232215464115143,,,5,,,,21.5700007975101,,,,,0.000105369463789284,1.44804698530458E-8,39.36040692089,0.000276079740476349,5.26859781157473E-5,7.24040618930143E-9,4.0735323415805E-5,4.37971666048017E-9,3.3413256594094E-5,5.76554973614719E-9,1.9999526924943,92.4775085449219,2,184,1,5,0.255030518057652,0.26815107835464,0.0251488108187914,9.32623291015625,5.49930763244629,5.50105714797974,-0.232215464115143,-0.232215464115143,,,0.162390634417534,0,1,,,,,,1,1,3,5.49991893768311,0,0,5.49998848612716,,,,,,,,,,,,,,,,,,,,,,,,,,,,,,,,,
,3720637428.89614,5.50008869171143,-0.232215464115143,,,5,,,,21.5700007975101,,,,,0.000173183180065357,1.32089303380963E-8,14.8196222434342,5.67800355177396E-5,8.65987243900415E-5,6.60500931674991E-9,8.37180913191647E-5,4.79744771891307E-9,2.21499492518236E-5,4.53989465281397E-9,1.99983523181402,17.4386157989502,2,34,1,5,0.561181280576718,0.236961429263272,0.0163163989782333,21.034912109375,5.49939155578613,5.50124406814575,-0.232215464115143,-0.232215464115143,,,0.161700412631035,0,1,,,,,,1,1,3,5.50012302398682,0,0,5.50002820868241,,,,,,,,,,,,,,,,,,,,,,,,,,,,,,,,,
,3720637804.93432,5.49998092651367,-0.232215464115143,,,5,,,,21.5700007975101,,,,,0.000185009515477341,3.01368874692848E-7,3.23137330280294,0.00139290183171945,9.25047329480682E-5,1.50684396964091E-7,9.2357654905842E-5,7.76397107261881E-8,5.21432623517323E-6,1.29142800057865E-7,2.0000005359856,3.30276823043823,2,6,1,5,0.64938297141177,0.0603187484928915,0.0123468413949013,6.20196533203125,5.4992733001709,5.50151586532593,-0.232215464115143,-0.232215464115143,,,0.160889148712158,0,1,,,,,,1,1,3,5.5001015663147,0,0,5.50001161545515,,,,,,,,,,,,,,,,,,,,,,,,,,,,,,,,,
,3720638608.94745,5.00037050247192,-0.232215464115143,,,5,,,,21.5700007975101,,,,,3.29471170780227E-5,2.71719331715869E-8,50.2375261073995,0.00922060417063433,1.64694862223639E-5,1.35826080911629E-8,1.05339883274733E-5,1.03448233244192E-8,1.26601369007327E-5,8.80181077646397E-9,2.00049452868079,787.550415039063,2,1575,1,5,0.0573416992937248,0.100939347247201,0.0265861544758081,354.235504150391,4.99844837188721,5.00157833099365,-0.232215464115143,-0.232215464115143,,,0.150899589061737,0,1,,,,,,1,1,3,5.00071859359741,0,0,5.0000033629568,,,,,,,,,,,,,,,,,,,,,,,,,,,,,,,,,
,3720638887.40956,4.99991393089294,-0.232215464115143,,,5,,,,21.5700007975101,,,,,8.99872611280332E-5,2.07895814005022E-8,44.780411999939,0.000877541614399045,4.49774022749937E-5,1.03910415102946E-8,3.19254815106991E-5,8.26973245783886E-9,3.16817036429012E-5,6.29168250505634E-9,2.00072161966686,148.866241455078,2,297,1,5,0.200787678040943,0.244026551340725,0.0258535277098417,5.1875,4.99927425384521,5.00130653381348,-0.232215464115143,-0.232215464115143,,,0.149807810783386,0,1,,,,,,1,1,3,4.99984455108643,0,0,4.99998996315933,,,,,,,,,,,,,,,,,,,,,,,,,,,,,,,,,
,3720639161.64447,4.99998831748962,-0.232215464115143,,,5,,,,21.5700007975101,,,,,0.000176634151705761,1.71189610945332E-8,21.5009065180046,8.860789601661E-5,8.83171877515134E-5,8.55949139221546E-9,8.21713509052719E-5,6.49034307588505E-9,3.23696577482485E-5,5.58035300413168E-9,1.99999746598288,28.1268005371094,2,56,1,5,0.532240956694506,0.319705139115522,0.0194355901330709,20.8418884277344,4.99938488006592,5.00115585327148,-0.232215464115143,-0.232215464115143,,,0.149139329791069,0,1,,,,,,1,1,3,4.99989891052246,0,0,4.99999203180012,,,,,,,,,,,,,,,,,,,,,,,,,,,,,,,,,
,3720639484.81205,5.00009250640869,-0.232215464115143,,,5,,,,21.5700007975101,,,,,0.000202335764115629,1.71369639709584E-7,5.04135520241686,0.00028244381660087,0.000101165256682072,8.56825962751049E-8,0.000100773902016919,8.14965908280638E-8,8.8898724306966E-6,2.64539786770489E-8,2.00005190271499,5.29819059371948,2,10,1,5,0.705594093592513,0.102486277597957,0.0125875165686011,9.79998779296875,4.99927139282227,5.00119972229004,-0.232215464115143,-0.232215464115143,,,0.148368686437607,0,1,,,,,,1,1,3,4.99999332427978,0,0,5.00001165943761,,,,,,,,,,,,,,,,,,,,,,,,,,,,,,,,,
,3720639983.6028,5.00001096725464,-0.232215464115143,,,5,,,,21.5700007975101,,,,,0.000204345302316803,3.08875851065617E-7,1.06570747443071,0.00145398229962425,0.000102170624864069,1.54434862710325E-7,0.000102152951700718,4.20193847958077E-8,1.90027470255245E-6,1.48608539868134E-7,2.00003966491024,1.00057637691498,2,2,1,5,0.720188890139579,0.0220746581798145,0.0121345678344369,2.22039794921875,4.99930810928345,5.00127553939819,-0.232215464115143,-0.232215464115143,,,0.147570848464966,0,1,,,,,,1,1,3,5.00003433227539,0,0,5.00001140527947,,,,,,,,,,,,,,,,,,,,,,,,,,,,,,,,,