File: examples/190412 - K(18-c-6)_Er(BAT)2 - 1 - 3 - MvsH.dat
[Header]
; MPMS3 Data File (default extension .dat)
; Copyright (c) 2007, Quantum Design, Inc. All rights reserved.
TITLE,
FILEOPENTIME,3765254776.59291,04/24/2019,9:07 am
BYAPP,SQUID AC,0.9.1.0
INFO,MPMS3 Measurement Release 1.1.16 Build 399, MultiVu Release 2.3.4.15,APPNAME
INFO,0,MOMENT_UNITS
INFO,K(18-c-6)_Er(hdcCOT)2,SAMPLE_MATERIAL
INFO,yellow crystalline powder,SAMPLE_COMMENT
INFO,7.2,SAMPLE_MASS
INFO,22.7,SAMPLE_VOLUME
INFO,839.24,SAMPLE_MOLECULAR_WEIGHT
INFO,-125.81E-6,SAMPLE_SIZE
INFO,,SAMPLE_SHAPE
INFO,Standard,SAMPLE_HOLDER
INFO,Standard,SAMPLE_HOLDER_DETAIL
INFO,66.57,SAMPLE_OFFSET
DATATYPE,COMMENT,1
DATATYPE,TIME,2
STARTUPAXIS,X,2
STARTUPAXIS,Y1,5
FIELDGROUP, VSM,2,3,4,5,6,8,9,10,11,14,15
FIELDGROUP, DC, 2,3,4,14,56,57,58,59,60,61,62,63,64,65,66,67,68,69
FIELDGROUP, AC, 2,3,4,11,16,17,18,19,20,21,22,23,24,25,26,27,28,29,30
STARTUPGROUP, All
[Data]
Comment,Time Stamp (sec),Temperature (K),Magnetic Field (Oe),Moment (emu),M. Std. Err. (emu),Transport Action,Averaging Time (sec),Frequency (Hz),Peak Amplitude (mm),Center Position (mm),Lockin Signal' (V),Lockin Signal (V),Range,M. Quad. Signal (emu),AC Moment (emu),AC M. Std Err. (emu),AC Phase (deg),AC Phase Std. Err. (deg),AC Susceptibility (emu/Oe),AC Suscept. Std Err. (emu/Oe),AC X' (emu/Oe),AC X' Std Err. (emu/Oe),AC X'' (emu/Oe),AC X'' Std Err. (emu/Oe),AC Drive (Oe),AC Frequency (Hz),AC Averaging Time (sec),AC Cycles,AC Range,AC Measure Type,AC Signal' (V),AC Signal'' (V),AC Trim Coil Ratio,AC Trim Coil Phase,Min. Temperature (K),Max. Temperature (K),Min. Field (Oe),Max. Field (Oe),Mass (grams),Motor Lag (deg),Pressure (Torr),Measure Count,Measurement Number,SQUID Status (code),Motor Status (code),Measure Status (code),Motor Current (amps),Motor Temp. (C),Temp. Status (code),Field Status (code),Chamber Status (code),Chamber Temp (K),Redirection State,Evercool Status,Average Temp (K),Rotation Angle (deg),Rotator state,DC Moment Fixed Ctr (emu),DC Moment Err Fixed Ctr (emu),DC Moment Free Ctr (emu),DC Moment Err Free Ctr (emu),DC Fixed Fit,DC Free Fit,DC Calculated Center (mm),DC Calculated Center Err (mm),DC Scan Length (mm),DC Scan Time (s),DC Number of Points,DC Squid Drift,DC Min V (V),DC Max V (V),DC Scans per Measure,Map 01,Map 02,Map 03,Map 04,Map 05,Map 06,Map 07,Map 08,Map 09,Map 10,Map 11,Map 12,Map 13,Map 14,Map 15,Map 16
,3765255498.28532,2.00137138366699,70000.375,,,6,,,,31.3976535797119,,,1000,,,,,,,,,,,,,,,,,,,,,,1.99721479415894,2.00166344642639,70000.375,70000.375,,,2.56195211410522,,1,0,0,0,0.013885498046875,32.7468223571777,1,1,1,2.00107932090759,0,1816138976,2.00002929568291,,,0.232584971691443,0.011874447674655,0.238160139178214,0.0118796593848452,0.786354959011078,0.985134780406952,30.5782814025879,,35,4,200,0.000235555053222924,-4.56324911117554,4.8023509979248,1,,,,,,,,,,,,,,,,
,3765255788.48797,2.00148725509644,61000.3125,,,6,,,,31.3976535797119,,,1000,,,,,,,,,,,,,,,,,,,,,,1.99803733825684,2.00173687934875,61000.3125,61000.3125,,,2.56786942481995,,1,0,0,0,0.013885498046875,33.2355842590332,1,1,1,2.00123763084412,0,1816139136,2.00023137331009,,,0.231927101554737,0.0118472872633757,0.237622363325958,0.0118528260972909,0.783946692943573,0.985193371772766,30.5688552856445,0,35,4,200,0.000173824315425009,-0.953308463096619,0.229510277509689,1,,,,,,,,,,,,,,,,
,3765256065.93083,2.0015424489975,52000.44921875,,,6,,,,31.3976535797119,,,1000,,,,,,,,,,,,,,,,,,,,,,1.9972710609436,2.0016565322876,52000.44921875,52000.44921875,,,2.57313847541809,,1,0,0,0,0.013885498046875,33.2355842590332,1,1,1,2.0014283657074,0,1816139296,2.00011143684387,,,0.230893028547552,0.0117989902384348,0.236654289120026,0.0118045374762372,0.782260835170746,0.98518830537796,30.5622673034668,0,35,4,200,0.000138874820549972,-0.949324667453766,0.229560106992722,1,,,,,,,,,,,,,,,,
,3765256342.37793,2.00130224227905,43000.171875,,,6,,,,31.3976535797119,,,1000,,,,,,,,,,,,,,,,,,,,,,1.99732339382172,2.00140762329102,43000.171875,43000.171875,,,2.57721090316772,,1,0,0,0,0.013885498046875,34.2131004333496,1,1,1,2.00119686126709,0,1816139008,2.00012449026108,,,0.229681110396369,0.0117401549039653,0.235473235664462,0.0117456212473388,0.78111058473587,0.985213935375214,30.5577526092529,5.10428142547607,35,4,200,9.7216761787422E-5,-0.944072425365448,0.227674603462219,1,,,,,,,,,,,,,,,,
,3765256617.77527,2.00106394290924,34000.23046875,,,6,,,,31.3976535797119,,,1000,,,,,,,,,,,,,,,,,,,,,,1.99737155437469,2.00146269798279,34000.23046875,34000.23046875,,,2.58127808570862,,1,0,0,0,0.013885498046875,34.2131004333496,1,1,1,2.00066518783569,0,1816139072,2.00018647909164,,,0.228227084962399,0.0116678866896699,0.234025949579559,0.0116734311760619,0.780346393585205,0.985207080841064,30.5547332763672,0,35,4,200,6.54476971249096E-5,-0.939395129680634,0.226166918873787,1,,,,,,,,,,,,,,,,
,3765256893.49638,2.0012549161911,25000.23046875,,,6,,,,31.3976535797119,,,1000,,,,,,,,,,,,,,,,,,,,,,1.99762845039368,2.00149655342102,25000.23046875,25000.23046875,,,2.58538842201233,,1,0,0,0,0.013885498046875,33.7243423461914,1,1,1,2.00101327896118,0,1816139168,2.00011199712753,,,0.226200024631132,0.0115657397928331,0.231977652789716,0.0115712644490376,0.779791295528412,0.985187888145447,30.5525436401367,0,35,4,200,2.77525741694262E-5,-0.931326568126679,0.224061414599419,1,,,,,,,,,,,,,,,,
,3765257173.87891,2.00129652023315,16000.353515625,,,6,,,,31.3976535797119,,,1000,,,,,,,,,,,,,,,,,,,,,,1.99766182899475,2.00148677825928,16000.353515625,16000.353515625,,,2.58655095100403,,1,0,0,0,0.014801025390625,33.7243423461914,1,1,1,2.00110626220703,0,1816138976,2.00009713172913,,,0.222712497002833,0.011388381972125,0.228425347235104,0.01139407874002,0.779426693916321,0.985146403312683,30.5511474609375,0,35,4,200,-3.34213691530749E-5,-0.916463911533356,0.221425101161003,1,,,,,,,,,,,,,,,,
,3765257450.67127,2.00142359733582,7000.48974609375,,,6,,,,31.3976535797119,,,1000,,,,,,,,,,,,,,,,,,,,,,1.99825239181519,2.00154995918274,7000.48974609375,7000.48974609375,,,2.58623552322388,,1,0,0,0,0.0147247314453125,33.7243423461914,1,1,1,2.00129723548889,0,1816138976,2.0000936627388,,,0.215208052991357,0.0110047879382287,0.220725477591041,0.0110100100243783,0.779368281364441,0.985071301460266,30.5509719848633,0,35,4,200,-8.24682647362351E-5,-0.886643171310425,0.213844835758209,1,,,,,,,,,,,,,,,,
,3765257724.58334,2.00120222568512,-2000.36511230469,,,6,,,,31.3976535797119,,,1000,,,,,,,,,,,,,,,,,,,,,,1.99818456172943,2.00145292282104,-2000.36511230469,-2000.36511230469,,,2.58768129348755,,1,0,0,0,0.013885498046875,33.7243423461914,1,1,1,2.00109696388245,0,1816138912,2.00011577606201,,,0.0450607825387358,0.00230236202662873,0.0461802456039945,0.00230353622586514,0.782857894897461,0.984553754329681,30.56494140625,0.128284126520157,35,4,200,-6.42849481664598E-5,-0.186537638306618,0.043935239315033,1,,,,,,,,,,,,,,,,
,3765258020.14818,2.00094985961914,-11000.376953125,,,6,,,,31.3976535797119,,,10,,,,,,,,,,,,,,,,,,,,,,1.99765861034393,2.00143933296204,-11000.376953125,-11000.376953125,,,2.59327149391174,,1,0,0,0,0.0147247314453125,33.7243423461914,1,1,1,2.00071620941162,0,1816139200,2.00004101426978,,,-0.00264214970587457,0.000142353706292914,-0.00274034609753912,0.000142452615556901,0.621769547462463,0.718118488788605,30.3806533813477,0,35,4,200,-0.0501111038029194,-0.554851055145264,1.23221945762634,1,,,,,,,,,,,,,,,,
,3765258329.69466,2.00129640102386,-20000.33984375,,,6,,,,31.3976535797119,,,1000,,,,,,,,,,,,,,,,,,,,,,1.99720621109009,2.00168442726135,-20000.33984375,-20000.33984375,,,2.59047484397888,,1,0,0,0,0.0147247314453125,33.2355842590332,1,1,1,2.00086331367493,0,1816139136,2.00014443397522,,,-0.167069587692378,0.00854046187379112,-0.171295584680813,0.00854451754485306,0.780756115913391,0.984169125556946,30.556734085083,0.195910722017288,35,4,200,-0.000608840316999704,-0.170253127813339,0.681604325771332,1,,,,,,,,,,,,,,,,
,3765258614.46231,2.00152933597565,-29000.15625,,,6,,,,31.3976535797119,,,1000,,,,,,,,,,,,,,,,,,,,,,1.99799621105194,2.00165915489197,-29000.15625,-29000.15625,,,2.58518648147583,,1,0,0,0,0.013885498046875,33.2355842590332,1,1,1,2.00139951705933,0,1816138976,2.00022130012512,,,-0.215757585037231,0.0110285150889846,-0.221194377716998,0.0110333906624129,0.781086206436157,0.985138714313507,30.5575675964355,INF,35,4,200,-0.000385311723221093,-0.216892778873444,0.884741544723511,1,,,,,,,,,,,,,,,,
,3765258898.77021,2.00101673603058,-38000.328125,,,6,,,,31.3976535797119,,,1000,,,,,,,,,,,,,,,,,,,,,,1.99801969528198,2.00137758255005,-38000.328125,-38000.328125,,,2.58352565765381,,1,0,0,0,0.013885498046875,33.2355842590332,1,1,1,2.00107073783874,0,1816139232,2.00014365911484,,,-0.225433182772356,0.0115218067316334,-0.231099050341933,0.011527440864432,0.781569361686707,0.985159873962402,30.5595874786377,0,35,4,200,-0.000292174430796877,-0.225491508841515,0.924787700176239,1,,,,,,,,,,,,,,,,
,3765259182.61271,2.00134479999542,-47000.4609375,,,6,,,,31.3976535797119,,,1000,,,,,,,,,,,,,,,,,,,,,,1.99724674224854,2.0015709400177,-47000.4609375,-47000.4609375,,,2.58474206924438,,1,0,0,0,0.013885498046875,33.2355842590332,1,1,1,2.00111865997314,0,1816139200,2.00008300542831,,,-0.228991014498024,0.0117014492252407,-0.23469785744892,0.0117069548505352,0.782390415668488,0.985161364078522,30.5628147125244,,35,4,200,-0.000254789454629645,-0.228455856442451,0.940227389335632,1,,,,,,,,,,,,,,,,
,3765259467.93488,2.00128388404846,-56000.37109375,,,6,,,,31.3976535797119,,,1000,,,,,,,,,,,,,,,,,,,,,,1.99756932258606,2.00201678276062,-56000.37109375,-56000.37109375,,,2.58243560791016,,1,0,0,0,0.013885498046875,33.7243423461914,1,1,1,2.00115871429443,0,1816139008,2.00012682676315,,,-0.230924070949227,0.0117970457854031,-0.236611047217539,0.011802384432978,0.783574283123016,0.98516458272934,30.5674018859863,,35,4,200,-0.000237490385188721,-0.230049580335617,0.947736084461212,1,,,,,,,,,,,,,,,,
,3765259753.6407,2.00141000747681,-65000.49609375,,,6,,,,31.3976535797119,,,1000,,,,,,,,,,,,,,,,,,,,,,1.99763607978821,2.00144100189209,-65000.49609375,-65000.49609375,,,2.58494091033936,,1,0,0,0,0.013885498046875,33.7243423461914,1,1,1,2.00147795677185,0,1816139072,2.00017037391663,,,-0.232284054989375,0.0118623351814101,-0.237918378713552,0.0118675962555121,0.785135269165039,0.985167920589447,30.5734767913818,INF,35,4,200,-0.000259074324276298,-0.231598138809204,0.952733874320984,1,,,,,,,,,,,,,,,,
,3765260037.42687,2.00085151195526,-66000.375,,,6,,,,31.3976535797119,,,1000,,,,,,,,,,,,,,,,,,,,,,1.99735522270203,2.0015594959259,-66000.375,-66000.375,,,2.58470964431763,,1,0,0,0,0.013885498046875,33.7243423461914,1,1,1,2.00044798851013,0,1816139168,2.00010614395142,,,-0.232555510369258,0.0118762560467593,-0.238202443605897,0.0118817550172835,0.785113155841827,0.985222697257996,30.5734367370605,0,35,4,200,-0.000185474214958958,-0.231418415904045,0.953212738037109,1,,,,,,,,,,,,,,,,
,3765260315.29051,2.00136208534241,-57000.25390625,,,6,,,,31.3976535797119,,,1000,,,,,,,,,,,,,,,,,,,,,,1.99798583984375,2.00171732902527,-57000.25390625,-57000.25390625,,,2.58403515815735,,1,0,0,0,0.013885498046875,33.7243423461914,1,1,1,2.00100684165955,0,1816139200,2.00025457143784,,,-0.231546665631917,0.0118302260643781,-0.237274140930786,0.0118354498708574,0.783063888549805,0.985232830047607,30.565357208252,0.134890139102936,35,4,200,-0.000149133309605531,-0.230677410960197,0.950200617313385,1,,,,,,,,,,,,,,,,
,3765260590.80181,2.00109302997589,-48000.40625,,,6,,,,31.3976535797119,,,1000,,,,,,,,,,,,,,,,,,,,,,1.99724090099335,2.00164699554443,-48000.40625,-48000.40625,,,2.58317399024963,,1,0,0,0,0.013885498046875,33.7243423461914,1,1,1,2.00053906440735,0,1816139168,2.00011779069901,,,-0.230415755585336,0.0117763282067039,-0.23620086012686,0.0117819136009564,0.781620144844055,0.985225439071655,30.5597763061523,0,35,4,200,-0.000110874556412455,-0.229407206177711,0.945940613746643,1,,,,,,,,,,,,,,,,
,3765260867.50677,2.00128269195557,-39000.3046875,,,6,,,,31.3976535797119,,,1000,,,,,,,,,,,,,,,,,,,,,,1.99719059467316,2.00172901153564,-39000.3046875,-39000.3046875,,,2.58247756958008,,1,0,0,0,0.013885498046875,33.7243423461914,1,1,1,2.00083637237549,0,1816139264,2.00015776157379,,,-0.229124774645141,0.0117129538718304,-0.23492572080011,0.01171831083967,0.780652165412903,0.985214829444885,30.5558986663818,0.0885959714651108,35,4,200,-7.30318279238418E-5,-0.228181034326553,0.940732896327972,1,,,,,,,,,,,,,,,,
,3765261145.56512,2.00140035152435,-30000.171875,,,6,,,,31.3976535797119,,,1000,,,,,,,,,,,,,,,,,,,,,,1.99754524230957,2.00157618522644,-30000.171875,-30000.171875,,,2.58304476737976,,1,0,0,0,0.013885498046875,33.7243423461914,1,1,1,2.00128865242004,0,1816139008,2.00012702941895,,,-0.227465071781062,0.011630031024247,-0.233265917643837,0.0116355193970904,0.779935896396637,0.985202968120575,30.5531883239746,,35,4,200,-4.19119569414761E-5,-0.227347686886787,0.934396326541901,1,,,,,,,,,,,,,,,,
,3765261422.09813,2.00150573253632,-21000.369140625,,,6,,,,31.3976535797119,,,1000,,,,,,,,,,,,,,,,,,,,,,1.99729013442993,2.00157046318054,-21000.369140625,-21000.369140625,,,2.58437633514404,,1,0,0,0,0.0144195556640625,34.7018585205078,1,1,1,2.00134062767029,0,1816138976,2.00007026195526,,,-0.2249633906283,0.0115033796488837,-0.230722661371244,0.0115086653023772,0.779464542865753,0.985176801681519,30.5513134002686,3.5496774216881E-5,35,4,200,4.76009745398187E-6,-0.225132212042809,0.924016118049622,1,,,,,,,,,,,,,,,,
,3765261701.13033,2.00127792358398,-12000.5166015625,,,6,,,,31.3976535797119,,,1000,,,,,,,,,,,,,,,,,,,,,,1.9975711107254,2.00138020515442,-12000.5166015625,-12000.5166015625,,,2.58348178863525,,1,0,0,0,0.014801025390625,35.6793746948242,1,1,1,2.0011944770813,0,1816138944,2.00013006925583,,,-0.220184285575587,0.0112597594552983,-0.225837367221486,0.0112649919577908,0.779175639152527,0.985130906105042,30.5502471923828,0,35,4,200,6.69915534672327E-5,-0.220358729362488,0.904884040355682,1,,,,,,,,,,,,,,,,
,3765261975.23768,2.00140964984894,-3000.23608398438,,,6,,,,31.3976535797119,,,1000,,,,,,,,,,,,,,,,,,,,,,1.99812543392181,2.00164318084717,-3000.23608398438,-3000.23608398438,,,2.58350586891174,,1,0,0,0,0.013885498046875,33.7243423461914,1,1,1,2.00120043754578,0,1816139168,2.00016722679138,,,-0.207245156451192,0.0105973487078777,-0.212556208239246,0.0106025314117624,0.77947062253952,0.984987854957581,30.5513744354248,0,35,4,200,8.93626493052579E-5,-0.207174077630043,0.852942585945129,1,,,,,,,,,,,,,,,,
,3765262247.2665,2.00104689598083,6000.42333984375,,,6,,,,31.3976535797119,,,1000,,,,,,,,,,,,,,,,,,,,,,1.99822652339935,2.00129508972168,6000.42333984375,6000.42333984375,,,2.58502984046936,,1,0,0,0,0.013885498046875,33.7243423461914,1,1,1,2.0008590221405,0,1816139040,2.00007556676865,,,-0.033267471438169,0.00169907206562646,-0.0340785633406882,0.00169990056786577,0.784713804721832,0.98404198884964,30.5723552703857,0,35,4,200,0.000119523188914172,-0.0339299291372299,0.135939955711365,1,,,,,,,,,,,,,,,,
,3765262559.56138,2.00154042243958,15000.3486328125,,,6,,,,31.3976535797119,,,100,,,,,,,,,,,,,,,,,,,,,,1.99839675426483,2.00147819519043,15000.3486328125,15000.3486328125,,,2.58673453330994,,1,0,0,0,0.013885498046875,33.7243423461914,1,1,1,2.00161194801331,0,1816139040,2.00022790431976,,,0.0724652421159365,0.00370574330756484,0.0743117393125993,0.00370760269686152,0.7791468501091,0.973826766014099,30.5540199279785,5.10210227966309,35,4,200,0.00704386411234736,-2.92666268348694,0.753829002380371,1,,,,,,,,,,,,,,,,
,3765262854.51173,2.0012503862381,24000.41015625,,,6,,,,31.3976535797119,,,1000,,,,,,,,,,,,,,,,,,,,,,1.99811458587646,2.00171232223511,24000.41015625,24000.41015625,,,2.58621048927307,,1,0,0,0,0.0147247314453125,33.7243423461914,1,1,1,2.00078845024109,0,1816138976,2.00017683506012,,,0.199695505806989,0.0102085634370692,0.204757170145884,0.0102135086643571,0.780633151531219,0.985007762908936,30.5559597015381,3.47708919434808E-5,35,4,200,0.000405980390496552,-0.820043325424194,0.199299350380898,1,,,,,,,,,,,,,,,,
,3765263138.31432,2.00157463550568,33000.28515625,,,6,,,,31.3976535797119,,,1000,,,,,,,,,,,,,,,,,,,,,,1.99798035621643,2.00195693969727,33000.28515625,33000.28515625,,,2.58372616767883,,1,0,0,0,0.013885498046875,33.2355842590332,1,1,1,2.00119233131409,0,1816139264,2.00018970966339,,,0.221459584846944,0.0113203363213399,0.227048852121947,0.0113254205798062,0.780948221683502,0.985135436058044,30.5571956634521,5.10443258285522,35,4,200,0.00025141699006781,-0.910691499710083,0.220725700259209,1,,,,,,,,,,,,,,,,
,3765263424.26347,2.00103008747101,42000.2265625,,,6,,,,31.3976535797119,,,1000,,,,,,,,,,,,,,,,,,,,,,1.99713706970215,2.00145292282104,42000.2265625,42000.2265625,,,2.58263254165649,,1,0,0,0,0.013885498046875,33.7243423461914,1,1,1,2.00062799453735,0,1816139200,2.0001721739769,,,0.227341745322373,0.0116193339845564,0.233055077005839,0.0116250096726724,0.781576633453369,0.985161542892456,30.5596103668213,0,35,4,200,0.000192437102668919,-0.935113906860352,0.226253747940063,1,,,,,,,,,,,,,,,,
,3765263712.58044,2.00130152702332,51000.3203125,,,6,,,,31.3976535797119,,,1000,,,,,,,,,,,,,,,,,,,,,,1.99700939655304,2.00160074234009,51000.3203125,51000.3203125,,,2.58263182640076,,1,0,0,0,0.013885498046875,33.2355842590332,1,1,1,2.00100827217102,0,1816139008,2.00006692409515,,,0.229943689242429,0.011749879057675,0.235668721447066,0.0117553820186629,0.782483816146851,0.98515647649765,30.5632095336914,0,35,4,200,0.000226209667744115,-0.944866418838501,0.228274986147881,1,,,,,,,,,,,,,,,,
,3765263999.55329,2.00153422355652,60000.25,,,6,,,,31.3976535797119,,,1000,,,,,,,,,,,,,,,,,,,,,,1.99779713153839,2.00171661376953,60000.25,60000.25,,,2.5812394618988,,1,0,0,0,0.013885498046875,33.2355842590332,1,1,1,2.00143456459045,0,1816139424,2.000244140625,,,0.231557745475681,0.0118290795800857,0.237254856657861,0.0118345014580742,0.783700883388519,0.985156118869782,30.5680103302002,0,35,4,200,0.000253270496614277,-0.951327085494995,0.229605168104172,1,,,,,,,,,,,,,,,,
,3765264288.52607,2.00085270404816,69000.390625,,,6,,,,31.3976535797119,,,1000,,,,,,,,,,,,,,,,,,,,,,1.9976521730423,2.00180792808533,69000.390625,69000.390625,,,2.58254361152649,,1,0,0,0,0.013885498046875,33.7243423461914,1,1,1,2.00033593177795,0,1816139168,2.00011684894562,,,0.232794155586025,0.0118877222381806,0.238424539107797,0.0118928464174338,0.785383701324463,0.985165596008301,30.5745830535889,0,35,4,200,0.000262927816947922,-0.955598950386047,0.231187656521797,1,,,,,,,,,,,,,,,,
,3765265846.14756,4.0027117729187,63000.2265625,,,6,,,,31.3976535797119,,,1000,,,,,,,,,,,,,,,,,,,,,,3.99682140350342,4.00287342071533,63000.2265625,63000.2265625,,,3.54042553901672,,1,0,0,0,0.013885498046875,33.7243423461914,1,1,1,4.00255012512207,0,1816138944,4.00062365531921,,,0.230660623496789,0.0117846252403588,0.236365791610764,0.011790138291713,0.783186197280884,0.985228955745697,30.5658645629883,0,35,4,200,0.000174763234099373,-0.947299301624298,0.228296399116516,1,,,,,,,,,,,,,,,,
,3765266123.70805,4.00270223617554,54000.27734375,,,6,,,,31.3976535797119,,,1000,,,,,,,,,,,,,,,,,,,,,,3.99704313278198,4.00283670425415,54000.27734375,54000.27734375,,,3.55093955993652,,1,0,0,0,0.013885498046875,33.7243423461914,1,1,1,4.00256776809692,0,1816139072,4.00047900676727,,,0.228986786117309,0.0117032770389369,0.234733795632577,0.0117087315053279,0.781626403331757,0.985239803791046,30.5598011016846,0,35,4,200,0.00012219614291098,-0.941678702831268,0.226729273796082,1,,,,,,,,,,,,,,,,
,3765266406.55598,4.00250101089478,45000.4140625,,,6,,,,31.3976535797119,,,1000,,,,,,,,,,,,,,,,,,,,,,3.99683690071106,4.0027027130127,45000.4140625,45000.4140625,,,3.55490493774414,,1,0,0,0,0.013885498046875,34.2131004333496,1,1,1,4.00229930877686,0,1816138912,4.00047106742859,,,0.226824742926697,0.0115954443259009,0.232573324160808,0.0116009690947785,0.78062641620636,0.985228538513184,30.5558986663818,0,35,4,200,0.000107095889688935,-0.933210611343384,0.224592611193657,1,,,,,,,,,,,,,,,,
,3765266685.09066,4.00237846374512,36000.25390625,,,6,,,,31.3976535797119,,,1000,,,,,,,,,,,,,,,,,,,,,,3.99674463272095,4.00280904769897,36000.25390625,36000.25390625,,,3.56096124649048,,1,0,0,0,0.013885498046875,33.7243423461914,1,1,1,4.00194787979126,0,1816138976,4.00039813518524,,,0.223686143135221,0.0114368129872689,0.229394205893011,0.0114423953305452,0.779939293861389,0.985219120979309,30.5531597137451,0.132411867380142,35,4,200,5.91415628150571E-5,-0.920024931430817,0.22212316095829,1,,,,,,,,,,,,,,,,
,3765266964.49607,4.00245809555054,27000.451171875,,,6,,,,31.3976535797119,,,1000,,,,,,,,,,,,,,,,,,,,,,3.99677586555481,4.00278520584106,27000.451171875,27000.451171875,,,3.56302809715271,,1,0,0,0,0.013885498046875,33.7243423461914,1,1,1,4.0022554397583,0,1816139168,4.00048038959503,,,0.218418306306129,0.0111686135878114,0.224018383004254,0.0111742475292884,0.779498755931854,0.985199213027954,30.5513172149658,INF,35,4,200,1.59065602929331E-5,-0.899299800395966,0.216668576002121,1,,,,,,,,,,,,,,,,
,3765267243.27405,4.00220704078674,18000.4140625,,,6,,,,31.3976535797119,,,1000,,,,,,,,,,,,,,,,,,,,,,3.99724316596985,4.00228691101074,18000.4140625,18000.4140625,,,3.56499814987183,,1,0,0,0,0.0147247314453125,33.7243423461914,1,1,1,4.00212717056274,0,1816138944,4.00049376487732,,,0.208403445694966,0.0106573537101276,0.213757037668354,0.0106624068095436,0.779157817363739,0.985154449939728,30.5501136779785,0,35,4,200,-4.45925907115452E-5,-0.857909202575684,0.207103058695793,1,,,,,,,,,,,,,,,,
,3765267518.77909,4.00230646133423,9000.3662109375,,,6,,,,31.3976535797119,,,1000,,,,,,,,,,,,,,,,,,,,,,3.99728941917419,4.00248336791992,9000.3662109375,9000.3662109375,,,3.56620740890503,,1,0,0,0,0.014801025390625,33.2355842590332,1,1,1,4.00212955474854,0,1816139136,4.00047628879547,,,0.192738056747694,0.0098564469794619,0.197692796730843,0.00986111470332593,0.779073178768158,0.985085427761078,30.5497531890869,5.10150337219238,35,4,200,-9.97510651359335E-5,-0.794435918331146,0.190480828285217,1,,,,,,,,,,,,,,,,
,3765267794.22368,4.00218772888184,0.207771733403206,,,6,,,,31.3976535797119,,,1000,,,,,,,,,,,,,,,,,,,,,,3.99707365036011,4.00241041183472,0.207771733403206,0.207771733403206,,,3.56866836547852,,1,0,0,0,0.013885498046875,33.7243423461914,1,1,1,4.00196504592895,0,2084574336,4.00033464431763,,,0.0724246483023025,0.00371007583244851,0.0742744444342534,0.00371194377481381,0.771835625171661,0.936587989330292,30.5530586242676,3.56280033884104E-5,35,4,200,-0.00131612492259592,-0.318586021661758,0.0681808590888977,1,,,,,,,,,,,,,,,,
,3765268080.31064,4.00227451324463,-9000.29296875,,,6,,,,31.3976535797119,,,100,,,,,,,,,,,,,,,,,,,,,,3.99731516838074,4.00240659713745,-9000.29296875,-9000.29296875,,,3.57311987876892,,1,0,0,0,0.0146484375,33.2355842590332,1,1,1,4.00214242935181,0,2084574336,4.00047087669373,,,0.0175433967946518,0.000895950010823676,0.0179657817991672,0.000896385110803905,0.784938275814056,0.972733736038208,30.5776042938232,5.10901737213135,35,4,200,-0.00291217374615371,-0.741207659244537,0.162973895668983,1,,,,,,,,,,,,,,,,
,3765268386.50348,4.00241470336914,-18000.365234375,,,6,,,,31.3976535797119,,,1000,,,,,,,,,,,,,,,,,,,,,,3.99648761749268,4.00260257720947,-18000.365234375,-18000.365234375,,,3.58020520210266,,1,0,0,0,0.013885498046875,33.2355842590332,1,1,1,4.00222682952881,0,2084574656,4.0001494884491,,,-0.134835826640402,0.00689320255366029,-0.138255665367426,0.00689657198899398,0.780440926551819,0.982946574687958,30.5557708740234,1,35,4,200,-0.000734191155061126,-4.77595901489258,4.84018278121948,1,,,,,,,,,,,,,,,,
,3765268675.97128,4.00230646133423,-27000.169921875,,,6,,,,31.3976535797119,,,1000,,,,,,,,,,,,,,,,,,,,,,3.9970018863678,4.00260925292969,-27000.169921875,-27000.169921875,,,3.57452249526978,,1,0,0,0,0.0147247314453125,33.2355842590332,1,1,1,4.00200366973877,0,2084574368,4.00033099651337,,,-0.206390968741926,0.0105506510898787,-0.21161940435982,0.0105557831361782,0.780708909034729,0.985113143920898,30.5561923980713,INF,35,4,200,-0.000381276535335928,-0.207852214574814,0.846299827098846,1,,,,,,,,,,,,,,,,
,3765268962.59109,4.00239896774292,-36000.2890625,,,6,,,,31.3976535797119,,,1000,,,,,,,,,,,,,,,,,,,,,,3.9965717792511,4.00258731842041,-36000.2890625,-36000.2890625,,,3.5772910118103,,1,0,0,0,0.0147247314453125,33.2355842590332,1,1,1,4.00221061706543,0,2084574624,4.00036191940308,,,-0.220663369886666,0.0112789977401214,-0.226223743844616,0.0112842601102543,0.781194508075714,0.985157132148743,30.5580711364746,0,35,4,200,-0.000291339529212564,-0.221057340502739,0.905710637569427,1,,,,,,,,,,,,,,,,
,3765269246.68843,4.00255727767944,-45000.1796875,,,6,,,,31.3976535797119,,,1000,,,,,,,,,,,,,,,,,,,,,,3.99681901931763,4.00294017791748,-45000.1796875,-45000.1796875,,,3.57698512077332,,1,0,0,0,0.013885498046875,33.7243423461914,1,1,1,4.00217437744141,0,2084574432,4.00059332847595,,,-0.225850987961194,0.0115421531574814,-0.231496993314083,0.011547293547011,0.781951904296875,0.985167920589447,30.5610675811768,,35,4,200,-0.00026010739384219,-0.226366683840752,0.92682558298111,1,,,,,,,,,,,,,,,,
,3765269532.21515,4.00258612632751,-54000.37890625,,,6,,,,31.3976535797119,,,1000,,,,,,,,,,,,,,,,,,,,,,3.99698257446289,4.00275039672852,-54000.37890625,-54000.37890625,,,3.57650446891785,,1,0,0,0,0.013885498046875,33.7243423461914,1,1,1,4.00242185592651,0,2084574336,4.00043015480041,,,-0.228629457040294,0.0116812856053615,-0.234287557275194,0.011686486345129,0.783023178577423,0.985161900520325,30.5653381347656,,35,4,200,-0.000242847570916638,-0.228999421000481,0.937660038471222,1,,,,,,,,,,,,,,,,
,3765269816.38589,4.00255870819092,-63000.45703125,,,6,,,,31.3976535797119,,,1000,,,,,,,,,,,,,,,,,,,,,,3.99672436714172,4.00286817550659,-63000.45703125,-63000.45703125,,,3.57666420936584,,1,0,0,0,0.013885498046875,34.2131004333496,1,1,1,4.00224924087524,0,2084574496,4.00039525032043,,,-0.230512711507455,0.0117735707700507,-0.236136077211438,0.0117786931430864,0.784497618675232,0.985175788402557,30.5710735321045,3.73845672607422,35,4,200,-0.000260996050201356,-0.230267941951752,0.945369243621826,1,,,,,,,,,,,,,,,,
,3765270102.40518,4.0024311542511,-68000.3515625,,,6,,,,31.3976535797119,,,1000,,,,,,,,,,,,,,,,,,,,,,3.9966516494751,4.00279712677002,-68000.3515625,-68000.3515625,,,3.57524609565735,,1,0,0,0,0.0139617919921875,33.7243423461914,1,1,1,4.00206518173218,0,2084574496,4.00051519870758,,,-0.231436051611676,0.0118181804984286,-0.237035090306163,0.0118235251556722,0.785454273223877,0.985235631465912,30.5747146606445,0.195728287100792,35,4,200,-0.000185320095624775,-0.230308577418327,0.948724687099457,1,,,,,,,,,,,,,,,,
,3765270381.99184,4.00259017944336,-59000.3984375,,,6,,,,31.3976535797119,,,1000,,,,,,,,,,,,,,,,,,,,,,3.99645566940308,4.00305891036987,-59000.3984375,-59000.3984375,,,3.57735633850098,,1,0,0,0,0.013885498046875,33.2355842590332,1,1,1,4.00212144851685,0,2084574624,4.00037474632263,,,-0.229955945258926,0.0117482819369445,-0.235628345738985,0.0117533534791093,0.783314108848572,0.985236346721649,30.5662822723389,0,35,4,200,-0.000159314353368245,-0.229249849915504,0.943742036819458,1,,,,,,,,,,,,,,,,
,3765270662.45171,4.00263977050781,-50000.171875,,,6,,,,31.3976535797119,,,1000,,,,,,,,,,,,,,,,,,,,,,3.99669289588928,4.00280094146729,-50000.171875,-50000.171875,,,3.57777309417725,,1,0,0,0,0.013885498046875,33.7243423461914,1,1,1,4.00247859954834,0,2084574592,4.00046231746674,,,-0.228098675500715,0.0116574267751116,-0.233814419034881,0.0116628742856916,0.781799018383026,0.985235631465912,30.560396194458,0,35,4,200,-0.000116920040454715,-0.228025406599045,0.936966240406036,1,,,,,,,,,,,,,,,,
,3765270938.21486,4.00244498252869,-41000.328125,,,6,,,,31.3976535797119,,,1000,,,,,,,,,,,,,,,,,,,,,,3.99689173698425,4.00273084640503,-41000.328125,-41000.328125,,,3.57921886444092,,1,0,0,0,0.013885498046875,33.7243423461914,1,1,1,4.00215911865234,0,2084574560,4.00032875537872,,,-0.225593201106875,0.0115319946384644,-0.231299666351111,0.0115374362893591,0.780811548233032,0.985233724117279,30.5565071105957,5.52779388427734,35,4,200,-6.99388765497133E-5,-0.225246742367744,0.926195323467255,1,,,,,,,,,,,,,,,,
,3765271218.50753,4.00254774093628,-32000.4765625,,,6,,,,31.3976535797119,,,1000,,,,,,,,,,,,,,,,,,,,,,3.99719595909119,4.00248908996582,-32000.4765625,-32000.4765625,,,3.5801157951355,,1,0,0,0,0.013885498046875,33.7243423461914,1,1,1,4.00260639190674,0,2084574592,4.00047686100006,,,-0.221699985816744,0.0113346998921961,-0.227354451261274,0.0113406501895926,0.780153453350067,0.98520827293396,30.553918838501,0,35,4,200,-4.53275206382386E-5,-0.221172079443932,0.91106241941452,1,,,,,,,,,,,,,,,,
,3765271497.52202,4.00236749649048,-23000.4765625,,,6,,,,31.3976535797119,,,1000,,,,,,,,,,,,,,,,,,,,,,3.99678063392639,4.00239276885986,-23000.4765625,-23000.4765625,,,3.58055830001831,,1,0,0,0,0.013885498046875,33.7243423461914,1,1,1,4.00235271453857,0,2084574496,4.0003502368927,,,-0.21475798072936,0.0109809767563469,-0.22025515491831,0.0109865374859161,0.779683530330658,0.98518180847168,30.5520858764648,,35,4,200,7.58298392611323E-6,-0.214058354496956,0.882473468780518,1,,,,,,,,,,,,,,,,
,3765271775.94239,4.002281665802,-14000.3681640625,,,6,,,,31.3976535797119,,,1000,,,,,,,,,,,,,,,,,,,,,,3.9971706867218,4.00257349014282,-14000.3681640625,-14000.3681640625,,,3.58113765716553,,1,0,0,0,0.0147247314453125,33.7243423461914,1,1,1,4.00198984146118,0,2084574432,4.00040457248688,,,-0.201735040121957,0.0103158399337473,-0.206912087430946,0.0103209816014573,0.77936977148056,0.985125482082367,30.5509433746338,5.10210657119751,35,4,200,8.35375321912579E-5,-0.201030611991882,0.829694032669067,1,,,,,,,,,,,,,,,,
,3765272050.41588,4.00241374969482,-5000.25927734375,,,6,,,,31.3976535797119,,,1000,,,,,,,,,,,,,,,,,,,,,,3.99729204177856,4.00262594223022,-5000.25927734375,-5000.25927734375,,,3.58075284957886,,1,0,0,0,0.013885498046875,33.2355842590332,1,1,1,4.00220155715942,0,2084574400,4.00040588378906,,,-0.185583422067283,0.00948976383157092,-0.190344257414231,0.00949457131388305,0.779438674449921,0.985044181346893,30.5512046813965,0,35,4,200,0.000102781232271809,-0.185302034020424,0.762947499752045,1,,,,,,,,,,,,,,,,
,3765272318.92842,4.00210928916931,4000.16821289063,,,6,,,,31.3976535797119,,,1000,,,,,,,,,,,,,,,,,,,,,,3.99753069877625,4.00231552124023,4000.16821289063,4000.16821289063,,,3.58213925361633,,1,0,0,0,0.013885498046875,33.2355842590332,1,1,1,4.00190305709839,0,2084574400,4.00033807754517,,,-0.0356076468662426,0.00181938947682476,-0.0364925204603992,0.00182029612558056,0.782780826091766,0.9846311211586,30.5645008087158,0.000173963533597998,35,4,200,6.72746173222549E-5,-0.0357314348220825,0.145766094326973,1,,,,,,,,,,,,,,,,
,3765272630.16021,4.00226521492004,13000.36328125,,,6,,,,31.3976535797119,,,100,,,,,,,,,,,,,,,,,,,,,,3.99706268310547,4.00229597091675,13000.36328125,13000.36328125,,,3.58760547637939,,1,0,0,0,0.013885498046875,33.2355842590332,1,1,1,4.00225448608398,0,2084574400,4.00034501552582,,,0.0346337059719657,0.00177209845702019,0.0355227165919575,0.00177300341857441,0.776748955249786,0.961843132972717,30.5509033203125,0.00018144007481169,35,4,200,0.00562836229801178,-1.41383266448975,0.372510135173798,1,,,,,,,,,,,,,,,,
,3765272924.38292,4.00238609313965,22000.314453125,,,6,,,,31.3976535797119,,,1000,,,,,,,,,,,,,,,,,,,,,,3.99702191352844,4.00246667861938,22000.314453125,22000.314453125,,,3.58592772483826,,1,0,0,0,0.013885498046875,32.7468223571777,1,1,1,4.00230550765991,0,2084574592,4.00035378932953,,,0.181870183504391,0.00929739217055416,0.186475030096583,0.0093016047991729,0.780599057674408,0.984784483909607,30.5558242797852,0.000177367881406099,35,4,200,0.000474499043775722,-0.745742976665497,0.18184432387352,1,,,,,,,,,,,,,,,,
,3765273208.32102,4.00251007080078,31000.19140625,,,6,,,,31.3976535797119,,,1000,,,,,,,,,,,,,,,,,,,,,,3.99681615829468,4.00272655487061,31000.19140625,31000.19140625,,,3.58277344703674,,1,0,0,0,0.0147247314453125,33.2355842590332,1,1,1,4.00229358673096,0,2084574592,4.00035724639893,,,0.214863247399578,0.0109833716245485,0.220300345632889,0.0109887909758007,0.78085869550705,0.985142230987549,30.5567893981934,0,35,4,200,0.000278766674455255,-0.882930994033814,0.213805690407753,1,,,,,,,,,,,,,,,,
,3765273493.52932,4.00251173973084,40000.49609375,,,6,,,,31.3976535797119,,,1000,,,,,,,,,,,,,,,,,,,,,,3.99678373336792,4.00276708602905,40000.49609375,40000.49609375,,,3.58414793014526,,1,0,0,0,0.013885498046875,33.2355842590332,1,1,1,4.00225639343262,0,2084574464,4.00026805400848,,,0.22347231309162,0.0114219546146044,0.229088132621528,0.0114271336453322,0.781430065631866,0.985176801681519,30.5589847564697,5.10452318191528,35,4,200,0.000185589349712245,-0.918649315834045,0.222561791539192,1,,,,,,,,,,,,,,,,
,3765273781.34193,4.00254511833191,49000.2265625,,,6,,,,31.3976535797119,,,1000,,,,,,,,,,,,,,,,,,,,,,3.99695730209351,4.0027961730957,49000.2265625,49000.2265625,,,3.58215761184692,,1,0,0,0,0.013885498046875,32.7468223571777,1,1,1,4.00229406356812,0,2084574464,4.00043964385986,,,0.227252935064288,0.0116129536153652,0.232914183688401,0.0116179775280775,0.782267928123474,0.98516833782196,30.5622596740723,5.52831411361694,35,4,200,0.000224027782678604,-0.934406936168671,0.225430175662041,1,,,,,,,,,,,,,,,,
,3765274069.00413,4.00277304649353,58000.38671875,,,6,,,,31.3976535797119,,,1000,,,,,,,,,,,,,,,,,,,,,,3.99681448936462,4.00297927856445,58000.38671875,58000.38671875,,,3.58264303207397,,1,0,0,0,0.013885498046875,33.2355842590332,1,1,1,4.00256681442261,0,2084574432,4.00046653747559,,,0.229516190683134,0.0117254426586038,0.235183200942731,0.0117311638199528,0.783454537391663,0.985162854194641,30.5669612884521,0,35,4,200,0.000241447152802721,-0.942673742771149,0.228230059146881,1,,,,,,,,,,,,,,,,
,3765274357.98377,4.00248432159424,67000.4375,,,6,,,,31.3976535797119,,,1000,,,,,,,,,,,,,,,,,,,,,,3.99651646614075,4.00290966033936,67000.4375,67000.4375,,,3.57963991165161,,1,0,0,0,0.013885498046875,33.2355842590332,1,1,1,4.00205898284912,0,2084574432,4.00047209262848,,,0.231189604861264,0.0118066584943741,0.23680007868631,0.0118118153228656,0.785054683685303,0.985166013240814,30.5731544494629,0,35,4,200,0.000268027710262686,-0.94893342256546,0.228880167007446,1,,,,,,,,,,,,,,,,
,3765276587.64307,6.00325345993042,65000.265625,,,6,,,,31.3976535797119,,,1000,,,,,,,,,,,,,,,,,,,,,,5.99715232849121,6.00360631942749,65000.265625,65000.265625,,,4.14266538619995,,1,0,0,0,0.0147247314453125,33.7243423461914,1,1,1,6.0037088394165,0,2084574624,6.0004382610321,,,0.228363547980748,0.0116660812044726,0.233988559582304,0.0116715652589109,0.783634483814239,0.985219419002533,30.5676612854004,,35,4,200,0.000185909942956641,-0.938041687011719,0.226210549473763,1,,,,,,,,,,,,,,,,
,3765276864.52228,6.00328660011292,56000.3359375,,,6,,,,31.3976535797119,,,1000,,,,,,,,,,,,,,,,,,,,,,5.99710035324097,6.00347137451172,56000.3359375,56000.3359375,,,4.15949726104736,,1,0,0,0,0.013885498046875,33.2355842590332,1,1,1,6.00364208221436,0,2084574336,6.00039920806885,,,0.225844705304788,0.0115415692844566,0.231493319516079,0.0115471013760391,0.782051622867584,0.985224306583405,30.5614109039307,3.35593322233763E-5,35,4,200,0.000138371149660088,-0.928376197814941,0.223439902067184,1,,,,,,,,,,,,,,,,
,3765277141.86799,6.00330686569214,47000.30078125,,,6,,,,31.3976535797119,,,1000,,,,,,,,,,,,,,,,,,,,,,5.99721479415894,6.00328350067139,47000.30078125,47000.30078125,,,4.16965579986572,,1,0,0,0,0.013885498046875,34.7018585205078,1,1,1,6.00372076034546,0,2084574464,6.00019459724426,,,0.222331116659803,0.0113648283374525,0.227944781922164,0.0113700891161032,0.780968189239502,0.985227882862091,30.5572185516357,0.195911407470703,35,4,200,0.00010642348206602,-0.914999604225159,0.220501869916916,1,,,,,,,,,,,,,,,,
,3765277419.88229,6.00316095352173,38000.328125,,,6,,,,31.3976535797119,,,1000,,,,,,,,,,,,,,,,,,,,,,5.99726009368897,6.00329446792602,38000.328125,38000.328125,,,4.1774640083313,,1,0,0,0,0.013885498046875,33.7243423461914,1,1,1,6.0036883354187,0,2084574656,6.00037698745727,,,0.216865365289997,0.0110871353279639,0.222382796923085,0.0110926593506898,0.780305981636047,0.98522275686264,30.5545463562012,0,35,4,200,6.97747600497678E-5,-0.892216801643372,0.215083345770836,1,,,,,,,,,,,,,,,,
,3765277700.42365,6.00298523902893,29000.412109375,,,6,,,,31.3976535797119,,,1000,,,,,,,,,,,,,,,,,,,,,,5.99740695953369,6.00339937210083,29000.412109375,29000.412109375,,,4.18395471572876,,1,0,0,0,0.0147247314453125,33.2355842590332,1,1,1,6.00358629226685,0,2084574496,6.00045747756958,,,0.207397066450816,0.010604204267312,0.212692828226143,0.0106093182911009,0.779843807220459,0.985190808773041,30.5528526306152,0,35,4,200,1.96934470295673E-5,-0.853567063808441,0.205581173300743,1,,,,,,,,,,,,,,,,
,3765277977.5932,6.00302171707153,20000.47265625,,,6,,,,31.3976535797119,,,1000,,,,,,,,,,,,,,,,,,,,,,5.99748086929321,6.0030026435852,20000.47265625,20000.47265625,,,4.18705749511719,,1,0,0,0,0.013885498046875,33.7243423461914,1,1,1,6.00332641601562,0,2084574304,6.00020213127136,,,0.189881480697095,0.00970934700015923,0.194739571851639,0.00971379953995818,0.779525876045227,0.985140144824982,30.5516300201416,,35,4,200,-5.42512134416029E-5,-0.782241880893707,0.187812119722366,1,,,,,,,,,,,,,,,,
,3765278253.80218,6.00292110443115,11000.42578125,,,6,,,,31.3976535797119,,,1000,,,,,,,,,,,,,,,,,,,,,,5.99749279022217,6.00320625305176,11000.42578125,11000.42578125,,,4.19098949432373,,1,0,0,0,0.013885498046875,33.7243423461914,1,1,1,6.00329685211182,0,2084574368,6.0003424167633,,,0.164638575092857,0.00841887569606754,0.168861400654693,0.00842297884762917,0.779375791549683,0.985074281692505,30.5509071350098,0,35,4,200,-0.000120388482173439,-0.67853319644928,0.162856072187424,1,,,,,,,,,,,,,,,,
,3765278527.81083,6.00295281410217,2000.34057617187,,,6,,,,31.3976535797119,,,1000,,,,,,,,,,,,,,,,,,,,,,5.99759674072266,6.00326728820801,2000.34057617187,2000.34057617187,,,4.19299697875977,,1,0,0,0,0.0147247314453125,33.2355842590332,1,1,1,6.00344705581665,0,2084574528,6.00039591789246,,,0.143112234674852,0.00731770940183808,0.146771607930027,0.00732113032336242,0.77961540222168,0.984959363937378,30.5519580841064,3.57490062015131E-5,35,4,200,-0.000123798192362301,-0.590687811374664,0.141890674829483,1,,,,,,,,,,,,,,,,
,3765278811.04516,6.00295352935791,-7000.35546875,,,6,,,,31.3976535797119,,,100,,,,,,,,,,,,,,,,,,,,,,5.99756288528442,6.00300407409668,-7000.35546875,-7000.35546875,,,4.19851064682007,,1,0,0,0,0.0147247314453125,33.7243423461914,1,1,1,6.00342750549316,0,2084574400,6.00025129318237,,,0.0188354613567319,0.000962265416521938,0.0192998091222204,0.000962751065767652,0.783424735069275,0.981510162353516,30.5679740905762,0.195816814899445,35,4,200,-0.00208704522810876,-0.782167196273804,0.181601792573929,1,,,,,,,,,,,,,,,,
,3765279113.86768,6.00294971466065,-16000.4775390625,,,6,,,,31.3976535797119,,,100,,,,,,,,,,,,,,,,,,,,,,5.99755477905273,6.00297355651855,-16000.4775390625,-16000.4775390625,,,4.19966602325439,,1,0,0,0,0.013885498046875,33.2355842590332,1,1,1,6.00344610214233,0,2084574336,6.00038113594055,,,-0.0909529320579801,0.00464984349749466,-0.0932558080919731,0.00465217759775719,0.780380070209503,0.979260087013245,30.5565185546875,,35,4,200,-0.00672933785244823,-0.942078471183777,3.66786432266235,1,,,,,,,,,,,,,,,,
,3765279418.05534,6.00294375419617,-25000.341796875,,,6,,,,31.3976535797119,,,1000,,,,,,,,,,,,,,,,,,,,,,5.99745035171509,6.00327110290527,-25000.341796875,-25000.341796875,,,4.20079183578491,,1,0,0,0,0.013885498046875,33.7243423461914,1,1,1,6.00358104705811,0,2084574336,6.00026288032532,,,-0.189233623432793,0.00967337903401363,-0.194024256858615,0.00967813178629436,0.7807976603508,0.985062897205353,30.5566005706787,0,35,4,200,-0.000402495294110849,-0.190653055906296,0.775196135044098,1,,,,,,,,,,,,,,,,
,3765279703.78676,6.00285696983337,-34000.328125,,,6,,,,31.3976535797119,,,1000,,,,,,,,,,,,,,,,,,,,,,5.99726247787476,6.00334453582764,-34000.328125,-34000.328125,,,4.2008056640625,,1,0,0,0,0.013885498046875,32.7468223571777,1,1,1,6.00356340408325,0,2084574592,6.00033884048462,,,-0.211027566425905,0.0107860982315936,-0.216341323943358,0.0107913078995909,0.781345248222351,0.985196888446808,30.5586833953857,,35,4,200,-0.000318271951982751,-0.211603045463562,0.86653208732605,1,,,,,,,,,,,,,,,,
,3765279987.64479,6.0031201839447,-43000.47265625,,,6,,,,31.3976535797119,,,1000,,,,,,,,,,,,,,,,,,,,,,5.99733448028564,6.00337076187134,-43000.47265625,-43000.47265625,,,4.19682645797729,,1,0,0,0,0.013885498046875,32.7468223571777,1,1,1,6.00352001190186,0,2084574496,6.00029306411743,,,-0.219610902816798,0.011223051354234,-0.225105039637895,0.0112284494371671,0.782029509544373,0.985200703144073,30.5613136291504,3.36120028805453E-5,35,4,200,-0.000253506732406095,-0.219800606369972,0.901470839977264,1,,,,,,,,,,,,,,,,
,3765280273.46105,6.00300455093384,-52000.33984375,,,6,,,,31.3976535797119,,,1000,,,,,,,,,,,,,,,,,,,,,,5.9971752166748,6.00335168838501,-52000.33984375,-52000.33984375,,,4.19591045379639,,1,0,0,0,0.013885498046875,33.2355842590332,1,1,1,6.00359058380127,0,2084574432,6.00012340545654,,,-0.224274130645626,0.0114589338992421,-0.22983076268671,0.0114641704829244,0.782957196235657,0.985209465026855,30.5650119781494,0,35,4,200,-0.000241927627939731,-0.223847672343254,0.920155704021454,1,,,,,,,,,,,,,,,,
,3765280559.82407,6.00322937965393,-61000.38671875,,,6,,,,31.3976535797119,,,1000,,,,,,,,,,,,,,,,,,,,,,5.99720048904419,6.00351190567017,-61000.38671875,-61000.38671875,,,4.19477987289429,,1,0,0,0,0.013885498046875,33.2355842590332,1,1,1,6.00375509262085,0,2084574304,6.00033745765686,,,-0.227286988446665,0.0116091829108256,-0.23285087108879,0.0116148139711696,0.78435605764389,0.985212087631226,30.5703392028809,5.10721397399902,35,4,200,-0.000243871239945292,-0.226726368069649,0.93191647529602,1,,,,,,,,,,,,,,,,
,3765280845.2474,6.00319266319275,-70000.296875,,,6,,,,31.3976535797119,,,1000,,,,,,,,,,,,,,,,,,,,,,5.99700021743774,6.00350093841553,-70000.296875,-70000.296875,,,4.19141292572022,,1,0,0,0,0.013885498046875,32.7468223571777,1,1,1,6.00388765335083,0,2084574592,6.00043611526489,,,-0.229499570942762,0.0117176487538164,-0.235019860049431,0.0117230079721392,0.786080121994019,0.985214114189148,30.5771789550781,0,35,4,200,-0.000267002324108034,-0.228848844766617,0.940479159355164,1,,,,,,,,,,,,,,,,
,3765281124.73978,6.00332117080689,-61000.32421875,,,6,,,,31.3976535797119,,,1000,,,,,,,,,,,,,,,,,,,,,,5.9968318939209,6.00338935852051,-61000.32421875,-61000.32421875,,,4.19554328918457,,1,0,0,0,0.013885498046875,33.2355842590332,1,1,1,6.00369215011597,0,2084574336,6.00021758079529,,,-0.227380375610221,0.0116151396908964,-0.232962578321462,0.0116203770726007,0.783905923366547,0.985282897949219,30.5685119628906,5.10658979415894,35,4,200,-0.000160697018145584,-0.226800560951233,0.933408856391907,1,,,,,,,,,,,,,,,,
,3765281402.06744,6.0032217502594,-52000.49609375,,,6,,,,31.3976535797119,,,1000,,,,,,,,,,,,,,,,,,,,,,5.99715375900269,6.00334405899048,-52000.49609375,-52000.49609375,,,4.19713449478149,,1,0,0,0,0.013885498046875,32.7468223571777,1,1,1,6.00368690490723,0,2084574336,6.0002498626709,,,-0.224485878051906,0.0114714894432928,-0.230080024159958,0.0114765926438834,0.782293796539307,0.985278606414795,30.5622100830078,0.132768794894218,35,4,200,-0.000123675257782452,-0.22429932653904,0.92167603969574,1,,,,,,,,,,,,,,,,
,3765281679.75716,6.00300002098083,-43000.4140625,,,6,,,,31.3976535797119,,,1000,,,,,,,,,,,,,,,,,,,,,,5.99729347229004,6.00342702865601,-43000.4140625,-43000.4140625,,,4.19914627075195,,1,0,0,0,0.013885498046875,33.2355842590332,1,1,1,6.00371360778809,0,2084574528,6.00048742294311,,,-0.22024241656824,0.0112573692691392,-0.225801140499066,0.0112631601619128,0.781237483024597,0.985273540019989,30.5581607818604,0,35,4,200,-7.58244641474448E-5,-0.219532996416092,0.904360353946686,1,,,,,,,,,,,,,,,,
,3765281959.26558,6.00294375419617,-34000.37890625,,,6,,,,31.3976535797119,,,1000,,,,,,,,,,,,,,,,,,,,,,5.99740362167358,6.00333309173584,-34000.37890625,-34000.37890625,,,4.20184850692749,,1,0,0,0,0.013885498046875,33.7243423461914,1,1,1,6.00368499755859,0,2084573920,6.00042986869812,,,-0.213353000158616,0.0109069626615725,-0.218769255757578,0.0109124055287605,0.780545115470886,0.985247552394867,30.5555038452148,,35,4,200,-4.37238886661362E-5,-0.21316397190094,0.876524388790131,1,,,,,,,,,,,,,,,,
,3765282238.33294,6.00305986404419,-25000.416015625,,,6,,,,31.3976535797119,,,1000,,,,,,,,,,,,,,,,,,,,,,5.99737787246704,6.00327396392822,-25000.416015625,-25000.416015625,,,4.20209407806396,,1,0,0,0,0.013885498046875,33.7243423461914,1,1,1,6.00348424911499,0,2084574304,6.00028781890869,,,-0.20091255050123,0.0102720758037337,-0.206033677296637,0.0102771484945454,0.780085563659668,0.985216319561005,30.5537357330322,3.50551672454458E-5,35,4,200,1.39221201607143E-5,-0.200264155864716,0.825527548789978,1,,,,,,,,,,,,,,,,
,3765282515.84411,6.00295495986938,-16000.5263671875,,,6,,,,31.3976535797119,,,1000,,,,,,,,,,,,,,,,,,,,,,5.99750852584839,6.00316905975342,-16000.5263671875,-16000.5263671875,,,4.20188903808594,,1,0,0,0,0.013885498046875,33.2355842590332,1,1,1,6.00352382659912,0,2084574528,6.00033149719238,,,-0.178795635545097,0.00914184771525642,-0.183368077954797,0.00914657582937326,0.77982747554779,0.985156416893005,30.5525455474854,0,35,4,200,0.000110975939605851,-0.177911981940269,0.735906958580017,1,,,,,,,,,,,,,,,,
,3765282792.54745,6.00280809402466,-7000.4287109375,,,6,,,,31.3976535797119,,,1000,,,,,,,,,,,,,,,,,,,,,,5.99745655059814,6.00311708450317,-7000.4287109375,-7000.4287109375,,,4.20274639129639,,1,0,0,0,0.013885498046875,33.7243423461914,1,1,1,6.00345945358276,0,2084574272,6.0003511428833,,,-0.155146926559661,0.00793296070348374,-0.159117030504632,0.00793691464530685,0.77967768907547,0.985119640827179,30.5521583557129,5.10250377655029,35,4,200,0.000136480288347229,-0.154485926032066,0.638528227806091,1,,,,,,,,,,,,,,,,
,3765283062.48541,6.00296473503113,2000.31616210938,,,6,,,,31.3976535797119,,,1000,,,,,,,,,,,,,,,,,,,,,,5.99768114089966,6.00308084487915,2000.31616210938,2000.31616210938,,,4.20221757888794,,1,0,0,0,0.013885498046875,33.7243423461914,1,1,1,6.00337839126587,0,2084574208,6.00029773712158,,,-0.0308054180137798,0.00157432010363434,-0.0315759024458685,0.00157504499894458,0.781939446926117,0.984787344932556,30.5611534118652,0,35,4,200,7.43099735700525E-5,-0.0306475553661585,0.125994965434074,1,,,,,,,,,,,,,,,,
,3765283361.72204,6.00302171707153,11000.4501953125,,,6,,,,31.3976535797119,,,10,,,,,,,,,,,,,,,,,,,,,,5.99756669998169,6.00312614440918,11000.4501953125,11000.4501953125,,,4.20603084564209,,1,0,0,0,0.0139617919921875,33.2355842590332,1,1,1,6.00335550308228,0,2084574208,6.00026702880859,,,0.0108732021791842,0.000557635773258773,0.0111578882266325,0.000557903464961704,0.767137050628662,0.929239153861999,30.5419940948486,0,35,4,200,0.0419217646121979,-4.52133941650391,1.3102217912674,1,,,,,,,,,,,,,,,,
,3765283666.4223,6.00299978256226,20000.291015625,,,6,,,,31.3976535797119,,,1000,,,,,,,,,,,,,,,,,,,,,,5.99731826782227,6.00313663482666,20000.291015625,20000.291015625,,,4.20394659042358,,1,0,0,0,0.0139617919921875,33.2355842590332,1,1,1,6.00353384017944,0,2084574368,6.00023674964905,,,0.154239945200448,0.00788474175420402,0.158148906469665,0.00788871008340274,0.780688941478729,0.984389424324036,30.5563259124756,0,35,4,200,0.000505529751535505,-0.631117224693298,0.155055359005928,1,,,,,,,,,,,,,,,,
,3765283950.6218,6.00313401222229,29000.314453125,,,6,,,,31.3976535797119,,,1000,,,,,,,,,,,,,,,,,,,,,,5.99739646911621,6.00315141677856,29000.314453125,29000.314453125,,,4.20342445373535,,1,0,0,0,0.013885498046875,32.7468223571777,1,1,1,6.00349426269531,0,2084574240,6.00027985572815,,,0.20195036007209,0.010322959102129,0.207057718983957,0.0103282428013658,0.781000554561615,0.985131323337555,30.5572052001953,0,35,4,200,0.000293625227641314,-0.829637765884399,0.200914189219475,1,,,,,,,,,,,,,,,,
,3765284235.94269,6.00315475463867,38000.4609375,,,6,,,,31.3976535797119,,,1000,,,,,,,,,,,,,,,,,,,,,,5.99726629257202,6.0034761428833,38000.4609375,38000.4609375,,,4.20341110229492,,1,0,0,0,0.013885498046875,33.7243423461914,1,1,1,6.00350666046143,0,2084574272,6.00038318634033,,,0.215596402598656,0.0110193199333008,0.221017370494875,0.0110245563427358,0.781463623046875,0.985164523124695,30.5591144561768,3.41025333909783E-5,35,4,200,0.000225052674068138,-0.885882973670959,0.214271903038025,1,,,,,,,,,,,,,,,,
,3765284522.37492,6.00319933891296,47000.26171875,,,6,,,,31.3976535797119,,,1000,,,,,,,,,,,,,,,,,,,,,,5.99734354019165,6.00330495834351,47000.26171875,47000.26171875,,,4.20053672790527,,1,0,0,0,0.013885498046875,33.2355842590332,1,1,1,6.00374460220337,0,2084574400,6.00033354759216,,,0.221962035165034,0.0113427118249348,0.227500467305799,0.0113479448134264,0.782218873500824,0.985140204429626,30.5620441436768,0,35,4,200,0.0001995749771595,-0.912838757038116,0.220694869756699,1,,,,,,,,,,,,,,,,
,3765284809.44558,6.00334906578064,56000.421875,,,6,,,,31.3976535797119,,,1000,,,,,,,,,,,,,,,,,,,,,,5.9972038269043,6.00348567962647,56000.421875,56000.421875,,,4.19777584075928,,1,0,0,0,0.013885498046875,33.2355842590332,1,1,1,6.00378704071045,0,2084574496,6.00034275054932,,,0.22573095759594,0.0115324332922585,0.231306560615863,0.0115377918678455,0.783313453197479,0.985168099403381,30.5663166046143,0,35,4,200,0.000229824698180892,-0.927187025547028,0.223867952823639,1,,,,,,,,,,,,,,,,
,3765285099.52109,6.00320935249329,65000.296875,,,6,,,,31.3976535797119,,,1000,,,,,,,,,,,,,,,,,,,,,,5.9971661567688,6.00345373153687,65000.296875,65000.296875,,,4.19568872451782,,1,0,0,0,0.013885498046875,33.2355842590332,1,1,1,6.00374221801758,0,2084574336,6.00039277076721,,,0.228322953750673,0.011660950285689,0.233886576304348,0.0116664860385663,0.784792959690094,0.985178053379059,30.5721035003662,1,35,4,200,0.000255934661254287,-0.937640190124512,0.226072445511818,1,,,,,,,,,,,,,,,,
,3765285260.62957,6.00337672233582,70000.2578125,,,6,,,,31.3976535797119,,,1000,,,,,,,,,,,,,,,,,,,,,,5.99713277816772,6.00347805023193,70000.2578125,70000.2578125,,,4.19330835342407,,1,0,0,0,0.013885498046875,33.2355842590332,1,1,1,6.00371408462524,0,2084574496,6.0004602432251,,,0.229484219053829,0.011717675963208,0.235015994067625,0.0117228213548937,0.785771727561951,0.985179305076599,30.5759105682373,0,35,4,200,0.000260446104221046,-0.942423760890961,0.226824209094048,1,,,,,,,,,,,,,,,,