File: examples/190412 - K(18-c-6)_Er(BAT)2 - 1 - 3 - DC Relaxation.dat
[Header]
; MPMS3 Data File (default extension .dat)
; Copyright (c) 2007, Quantum Design, Inc. All rights reserved.
TITLE,
FILEOPENTIME,3765697694.43407,04/29/2019,12:09 pm
BYAPP,SQUID AC,0.9.1.0
INFO,MPMS3 Measurement Release 1.1.16 Build 399, MultiVu Release 2.3.4.15,APPNAME
INFO,0,MOMENT_UNITS
INFO,K(18-c-6)_Er(hdcCOT)2,SAMPLE_MATERIAL
INFO,yellow crystalline powder,SAMPLE_COMMENT
INFO,7.2,SAMPLE_MASS
INFO,22.7,SAMPLE_VOLUME
INFO,839.24,SAMPLE_MOLECULAR_WEIGHT
INFO,-125.81E-6,SAMPLE_SIZE
INFO,,SAMPLE_SHAPE
INFO,Standard,SAMPLE_HOLDER
INFO,Standard,SAMPLE_HOLDER_DETAIL
INFO,66.35,SAMPLE_OFFSET
DATATYPE,COMMENT,1
DATATYPE,TIME,2
STARTUPAXIS,X,2
STARTUPAXIS,Y1,5
FIELDGROUP, VSM,2,3,4,5,6,8,9,10,11,14,15
FIELDGROUP, DC, 2,3,4,14,56,57,58,59,60,61,62,63,64,65,66,67,68,69
FIELDGROUP, AC, 2,3,4,11,16,17,18,19,20,21,22,23,24,25,26,27,28,29,30
STARTUPGROUP, All
[Data]
Comment,Time Stamp (sec),Temperature (K),Magnetic Field (Oe),Moment (emu),M. Std. Err. (emu),Transport Action,Averaging Time (sec),Frequency (Hz),Peak Amplitude (mm),Center Position (mm),Lockin Signal' (V),Lockin Signal (V),Range,M. Quad. Signal (emu),AC Moment (emu),AC M. Std Err. (emu),AC Phase (deg),AC Phase Std. Err. (deg),AC Susceptibility (emu/Oe),AC Suscept. Std Err. (emu/Oe),AC X' (emu/Oe),AC X' Std Err. (emu/Oe),AC X'' (emu/Oe),AC X'' Std Err. (emu/Oe),AC Drive (Oe),AC Frequency (Hz),AC Averaging Time (sec),AC Cycles,AC Range,AC Measure Type,AC Signal' (V),AC Signal'' (V),AC Trim Coil Ratio,AC Trim Coil Phase,Min. Temperature (K),Max. Temperature (K),Min. Field (Oe),Max. Field (Oe),Mass (grams),Motor Lag (deg),Pressure (Torr),Measure Count,Measurement Number,SQUID Status (code),Motor Status (code),Measure Status (code),Motor Current (amps),Motor Temp. (C),Temp. Status (code),Field Status (code),Chamber Status (code),Chamber Temp (K),Redirection State,Evercool Status,Average Temp (K),Rotation Angle (deg),Rotator state,DC Moment Fixed Ctr (emu),DC Moment Err Fixed Ctr (emu),DC Moment Free Ctr (emu),DC Moment Err Free Ctr (emu),DC Fixed Fit,DC Free Fit,DC Calculated Center (mm),DC Calculated Center Err (mm),DC Scan Length (mm),DC Scan Time (s),DC Number of Points,DC Squid Drift,DC Min V (V),DC Max V (V),DC Scans per Measure,Map 01,Map 02,Map 03,Map 04,Map 05,Map 06,Map 07,Map 08,Map 09,Map 10,Map 11,Map 12,Map 13,Map 14,Map 15,Map 16
,3765699270.59636,2.00029414892197,-0.415543466806412,,,6,,,,31.494945526123,,,100,,,,,,,,,,,,,,,,,,,,,,1.99174475669861,2.0144989490509,-0.415543466806412,-0.415543466806412,,,2.31730604171753,,1,0,0,0,0.013885498046875,33.2355842590332,5,1,1,1.99960219860077,0,2084573184,2.00025304367668,,,0.0982308664812178,0.00503380187923301,0.100873848658031,0.00503622739496547,0.770389020442963,0.955024421215057,30.6309776306152,0,35,4,200,-0.012488279491663,-4.65302562713623,4.84174013137817,1,,,,,,,,,,,,,,,,
,3765699479.93404,1.99995625019073,-0.415543466806412,,,6,,,,31.494945526123,,,100,,,,,,,,,,,,,,,,,,,,,,1.99271023273468,2.00033926963806,-0.415543466806412,-0.415543466806412,,,2.3568389415741,,1,0,0,0,0.013885498046875,33.2355842590332,6,1,1,2.00201416015625,0,2084573184,1.99770022630692,,,0.0286690323062343,0.00146643165751218,0.0294038884910748,0.00146707641091473,0.778126060962677,0.972776472568512,30.6509647369385,5.10073137283325,35,4,200,-0.0011319505283609,-1.19161140918732,0.281809478998184,1,,,,,,,,,,,,,,,,
,3765699685.40443,2.00153267383575,-0.415543466806412,,,6,,,,31.494945526123,,,100,,,,,,,,,,,,,,,,,,,,,,1.99793565273285,2.00221729278564,-0.415543466806412,-0.415543466806412,,,2.37079501152039,,1,0,0,0,0.013885498046875,33.2355842590332,1,1,1,2.00176286697388,0,2084573184,2.00011830329895,,,0.0182087354226511,0.000930949618974158,0.0186671177375119,0.000931355049883807,0.780133783817291,0.973636925220489,30.6583938598633,0,35,4,200,-0.000606011948548257,-0.751347482204437,0.176047623157501,1,,,,,,,,,,,,,,,,
,3765699890.68422,2.00107234716415,-0.415543466806412,,,6,,,,31.494945526123,,,100,,,,,,,,,,,,,,,,,,,,,,1.98411393165588,2.00263094902039,-0.415543466806412,-0.415543466806412,,,2.37363409996033,,1,0,0,0,0.013885498046875,33.2355842590332,5,1,1,2.00215601921082,0,2084573184,1.99855828285217,,,0.0139318988002851,0.000712157311809703,0.0142807352532568,0.000712503277428823,0.780939221382141,0.973776876926422,30.661470413208,0,35,4,200,-0.000411157117923722,-0.579915046691895,0.134136065840721,1,,,,,,,,,,,,,,,,
,3765700095.34571,2.00379931926727,-0.415543466806412,,,6,,,,31.494945526123,,,100,,,,,,,,,,,,,,,,,,,,,,1.9966721534729,2.00855278968811,-0.415543466806412,-0.415543466806412,,,2.38494467735291,,1,0,0,0,0.013885498046875,32.7468223571777,6,1,1,2.00504970550537,0,2084573184,2.00454802513123,,,0.0115143892065689,0.000588522135907393,0.0118006592637413,0.000588765563070826,0.781377553939819,0.973794102668762,30.6632385253906,5.53743982315063,35,4,200,-0.000308237242279574,-0.47630113363266,0.117359824478626,1,,,,,,,,,,,,,,,,
,3765700300.13415,2.00663006305695,-0.415543466806412,,,6,,,,31.494945526123,,,100,,,,,,,,,,,,,,,,,,,,,,1.99233305454254,2.00857663154602,-0.415543466806412,-0.415543466806412,,,2.39244103431702,,1,0,0,0,0,33.2355842590332,6,1,1,2.0114152431488,0,2084573184,2.00063029527664,,,0.00989754057868624,0.000505845978917499,0.0101436321033298,0.000506091783304558,0.781687617301941,0.973823547363281,30.6643543243408,0,35,4,200,-0.000246952171437442,-0.409042447805405,0.0933399423956871,1,,,,,,,,,,,,,,,,
,3765700504.4613,2.00137531757355,-0.415543466806412,,,6,,,,31.494945526123,,,100,,,,,,,,,,,,,,,,,,,,,,1.99837553501129,2.00235509872437,-0.415543466806412,-0.415543466806412,,,2.3949830532074,,1,0,0,0,0.013885498046875,33.2355842590332,6,1,1,2.00175738334656,0,2084573184,2.00018054246902,,,0.00871924205929997,0.000445602998005423,0.00893587624954193,0.000445833621210502,0.781904280185699,0.973827481269836,30.6652221679687,5.53761863708496,35,4,200,-0.000201248403755017,-0.357778191566467,0.0860736519098282,1,,,,,,,,,,,,,,,,
,3765700709.11823,2.0010050535202,-0.415543466806412,,,6,,,,31.494945526123,,,100,,,,,,,,,,,,,,,,,,,,,,1.99783194065094,2.00395011901855,-0.415543466806412,-0.415543466806412,,,2.38354063034058,,1,0,0,0,0.013885498046875,32.2580642700195,1,1,1,2.00056576728821,0,2084573184,2.00030199289322,,,0.00780757205987346,0.000399005648530939,0.0080009865061071,0.000399189754240446,0.781969368457794,0.973824620246887,30.6656284332275,,35,4,200,-0.00016807863721624,-0.318978250026703,0.0795594528317452,1,,,,,,,,,,,,,,,,
,3765700913.7955,2.00118732452393,-0.415543466806412,,,6,,,,31.494945526123,,,100,,,,,,,,,,,,,,,,,,,,,,1.9979510307312,2.00247025489807,-0.415543466806412,-0.415543466806412,,,2.39205241203308,,1,0,0,0,0.013885498046875,32.7468223571777,1,1,1,2.00211119651794,0,2084573184,2.00016454458237,,,0.00707579474323978,0.000361597590551582,0.00725081611814505,0.000361761624568383,0.782095849514008,0.973831057548523,30.6660251617432,0,35,4,200,-0.000141196156619117,-0.291121006011963,0.0710769891738892,1,,,,,,,,,,,,,,,,
,3765701118.39015,1.99892842769623,-0.415543466806412,,,6,,,,31.494945526123,,,100,,,,,,,,,,,,,,,,,,,,,,1.99398362636566,2.00372529029846,-0.415543466806412,-0.415543466806412,,,2.39835858345032,,1,0,0,0,0.013885498046875,32.7468223571777,5,1,1,1.99928212165833,0,2084573184,1.99862736463547,,,0.00647276660524706,0.000330770868939242,0.00663249186670622,0.000330911893927006,0.782227396965027,0.973833024501801,30.6664142608643,6.32246155873872E-5,35,4,200,-0.000119217547762673,-0.273427098989487,0.0588097237050533,1,,,,,,,,,,,,,,,,
,3765701322.99679,1.9992448091507,-0.415543466806412,,,6,,,,31.494945526123,,,100,,,,,,,,,,,,,,,,,,,,,,1.99277544021606,2.00002527236938,-0.415543466806412,-0.415543466806412,,,2.40321111679077,,1,0,0,0,0.013885498046875,32.7468223571777,6,1,1,1.99920332431793,0,2084573184,1.99595638513565,,,0.0059642680234581,0.000304773394913975,0.0061116185051858,0.000304924118316941,0.782402753829956,0.973842680454254,30.6670341491699,0.000323525397107005,35,4,200,-0.000101413912489079,-0.243852734565735,0.0631692633032799,1,,,,,,,,,,,,,,,,
,3765701527.27042,1.99999231100082,-0.415543466806412,,,6,,,,31.494945526123,,,100,,,,,,,,,,,,,,,,,,,,,,1.99071848392487,2.00611972808838,-0.415543466806412,-0.415543466806412,,,2.40350365638733,,1,0,0,0,0,32.7468223571777,1,1,1,2.00107622146606,0,2084573184,1.9991506934166,,,0.00553010942743038,0.000282587150935173,0.00566652391168931,0.000282717237552121,0.782415270805359,0.973842918872833,30.6671581268311,5.10447692871094,35,4,200,-0.00010614980419632,-0.234964832663536,0.0504575222730637,1,,,,,,,,,,,,,,,,
,3765701731.50183,2.00423872470856,-0.415543466806412,,,6,,,,31.494945526123,,,100,,,,,,,,,,,,,,,,,,,,,,1.98267602920532,2.01276803016663,-0.415543466806412,-0.415543466806412,,,2.40104222297668,,1,0,0,0,0.013885498046875,32.7468223571777,6,1,1,1.99783205986023,0,2084573184,2.0003075838089,,,0.00515171579339216,0.000263241651763945,0.00527868336236268,0.000263366967245129,0.782576620578766,0.973833858966827,30.6678943634033,0,35,4,200,-7.45662473491393E-5,-0.21445620059967,0.0522159487009048,1,,,,,,,,,,,,,,,,
,3765701936.1852,1.99912065267563,-0.415543466806412,,,6,,,,31.494945526123,,,100,,,,,,,,,,,,,,,,,,,,,,1.99453914165497,2.00207090377808,-0.415543466806412,-0.415543466806412,,,2.40275597572327,,1,0,0,0,0.013885498046875,33.2355842590332,6,1,1,2.00108170509338,0,2084573184,1.99840116500854,,,0.00481907098331174,0.000246238123960875,0.00493773340459399,0.000246356066943339,0.782685577869415,0.973844289779663,30.668285369873,5.10520887374878,35,4,200,-6.50316869723611E-5,-0.203615501523018,0.0465419664978981,1,,,,,,,,,,,,,,,,
,3765702141.17718,2.00084143877029,-0.415543466806412,,,6,,,,31.494945526123,,,100,,,,,,,,,,,,,,,,,,,,,,1.9979385137558,2.00235509872437,-0.415543466806412,-0.415543466806412,,,2.40651726722717,,1,0,0,0,0.013885498046875,32.7468223571777,1,1,1,2.00182890892029,0,2084573184,2.00004365444183,,,0.00452358448670774,0.000231133617090265,0.00463503086950495,0.000231253515023672,0.782802402973175,0.973837673664093,30.6687526702881,5.5379376411438,35,4,200,-5.45968578080647E-5,-0.191691115498543,0.0438109152019024,1,,,,,,,,,,,,,,,,
,3765702345.99303,2.00038176774979,-0.415543466806412,,,6,,,,31.494945526123,,,100,,,,,,,,,,,,,,,,,,,,,,1.99835097789764,2.00222730636597,-0.415543466806412,-0.415543466806412,,,2.40730309486389,,1,0,0,0,0.013885498046875,32.2580642700195,1,1,1,2.00134778022766,0,2084573184,1.9999484539032,,,0.00426025746221372,0.000217673597938344,0.00436484841260395,0.000217773454267595,0.782908618450165,0.97383326292038,30.6691360473633,0,35,4,200,-4.64974727947265E-5,-0.178917855024338,0.0434952825307846,1,,,,,,,,,,,,,,,,
,3765702550.80799,2.0014261007309,-0.415543466806412,,,6,,,,31.494945526123,,,100,,,,,,,,,,,,,,,,,,,,,,1.99833762645721,2.00230431556702,-0.415543466806412,-0.415543466806412,,,2.40751266479492,,1,0,0,0,0.013885498046875,32.7468223571777,1,1,1,2.00185823440552,0,2084573184,2.00020517110825,,,0.00402298134645225,0.000205547167720092,0.00412169010538707,0.000205641715838857,0.782973229885101,0.973819732666016,30.6695919036865,0.0501995533704758,35,4,200,-4.17742521676701E-5,-0.165672540664673,0.0349342152476311,1,,,,,,,,,,,,,,,,
,3765702755.08473,2.00121593475342,-0.415543466806412,,,6,,,,31.494945526123,,,100,,,,,,,,,,,,,,,,,,,,,,1.99837720394135,2.00205230712891,-0.415543466806412,-0.415543466806412,,,2.40743184089661,,1,0,0,0,0.013885498046875,33.2355842590332,1,1,1,2.00126242637634,0,2084573184,2.00011185407639,,,0.00380848154167406,0.000194582694933324,0.0039019439522594,0.00019467797487521,0.783085346221924,0.973824918270111,30.6699905395508,5.53804922103882,35,4,200,-3.48076464433689E-5,-0.162061259150505,0.0379357933998108,1,,,,,,,,,,,,,,,,
,3765702959.66583,2.00186157226562,-0.415543466806412,,,6,,,,31.494945526123,,,100,,,,,,,,,,,,,,,,,,,,,,1.99827182292938,2.00239014625549,-0.415543466806412,-0.415543466806412,,,2.40726137161255,,1,0,0,0,0.013885498046875,32.2580642700195,1,1,1,2.00201749801636,0,2084573184,2.00024803876877,,,0.0036127103509672,0.000184576312269608,0.003701324746832,0.000184668592250335,0.783182919025421,0.973829507827759,30.670373916626,0.0531599931418896,35,4,200,-2.92849726974964E-5,-0.147390380501747,0.0327338092029095,1,,,,,,,,,,,,,,,,
,3765703164.1701,1.99612998962402,-0.415543466806412,,,6,,,,31.494945526123,,,100,,,,,,,,,,,,,,,,,,,,,,1.99418485164642,2.00873613357544,-0.415543466806412,-0.415543466806412,,,2.40308976173401,,1,0,0,0,0.013885498046875,32.7468223571777,6,1,1,1.99457085132599,0,2084573184,1.99938080310822,,,0.00343388211057025,0.000175436029441095,0.00351798751901961,0.000175521404416657,0.783277332782745,0.973826825618744,30.6706523895264,5.53810930252075,35,4,200,-2.65377457253635E-5,-0.142790555953979,0.0283963587135077,1,,,,,,,,,,,,,,,,
,3765703369.18142,2.00132524967194,-0.415543466806412,,,6,,,,31.494945526123,,,100,,,,,,,,,,,,,,,,,,,,,,1.9974091053009,2.00213742256165,-0.415543466806412,-0.415543466806412,,,2.40695714950562,,1,0,0,0,0.013885498046875,32.2580642700195,5,1,1,2.00077748298645,0,2084573184,2.00011023283005,,,0.00326897964446382,0.000167007298564885,0.00334884443471157,0.000167082405235895,0.783379375934601,0.973822176456451,30.6710681915283,5.10637760162354,35,4,200,-2.20835227082716E-5,-0.137610152363777,0.0355913825333118,1,,,,,,,,,,,,,,,,
,3765703573.35406,2.00105631351471,-0.415543466806412,,,6,,,,31.494945526123,,,100,,,,,,,,,,,,,,,,,,,,,,1.99839460849762,2.00196170806885,-0.415543466806412,-0.415543466806412,,,2.40767598152161,,1,0,0,0,0.013885498046875,32.7468223571777,5,1,1,2.00118017196655,0,2084573184,2.00015975236893,,,0.0031174170649679,0.000159258765950709,0.0031935406576399,0.000159333956343241,0.783529818058014,0.973813712596893,30.6715908050537,0.000316724297590554,35,4,200,-1.75264249264728E-5,-0.131935328245163,0.0337465442717075,1,,,,,,,,,,,,,,,,
,3765703778.2033,2.00063675642014,-0.415543466806412,,,6,,,,31.494945526123,,,100,,,,,,,,,,,,,,,,,,,,,,1.99794614315033,2.00207734107971,-0.415543466806412,-0.415543466806412,,,2.40767931938171,,1,0,0,0,0.013885498046875,32.7468223571777,1,1,1,2.0015025138855,0,2084573184,2.00004448890686,,,0.00297658749430631,0.000152059819264326,0.00304921122897576,0.000152133136398653,0.783658385276794,0.973781883716583,30.6721076965332,6.2037244788371E-5,35,4,200,-1.51129770529224E-5,-0.125766932964325,0.0329242348670959,1,,,,,,,,,,,,,,,,
,3765703983.0338,2.00161957740784,-0.415543466806412,,,6,,,,31.494945526123,,,100,,,,,,,,,,,,,,,,,,,,,,1.99831008911133,2.00228476524353,-0.415543466806412,-0.415543466806412,,,2.40756869316101,,1,0,0,0,0.013885498046875,32.7468223571777,1,1,1,2.00168895721436,0,2084573184,2.00010405778885,,,0.00284562314035092,0.000145364505413777,0.00291500230329294,0.000145437058047724,0.783809185028076,0.973796129226685,30.6725826263428,6.19747879682109E-5,35,4,200,-1.32837303681299E-5,-0.119249403476715,0.0225513838231564,1,,,,,,,,,,,,,,,,
,3765704187.95475,2.00182318687439,-0.415543466806412,,,6,,,,31.494945526123,,,100,,,,,,,,,,,,,,,,,,,,,,1.99820804595947,2.00161409378052,-0.415543466806412,-0.415543466806412,,,2.40729212760925,,1,0,0,0,0,33.2355842590332,1,1,1,2.00214195251465,0,2084573184,2.00014477968216,,,0.00272356589674417,0.000139127021936129,0.00278975397500203,0.000139188086903011,0.783884346485138,0.973798751831055,30.6729488372803,0,35,4,200,-9.81170887826011E-6,-0.112119846045971,0.0235691051930189,1,,,,,,,,,,,,,,,,
,3765704392.08706,2.00218915939331,-0.415543466806412,,,6,,,,31.494945526123,,,100,,,,,,,,,,,,,,,,,,,,,,1.9977924823761,2.00219774246216,-0.415543466806412,-0.415543466806412,,,2.40797233581543,,1,0,0,0,0.001983642578125,32.2580642700195,1,1,1,2.00261282920837,0,2084573184,2.00008704662323,,,0.00261009152649173,0.000133326674210483,0.00267345753051052,0.000133385702831633,0.784007668495178,0.973800122737885,30.6734657287598,0.000313446071231738,35,4,200,-7.4278932515881E-6,-0.104616798460484,0.0254095699638128,1,,,,,,,,,,,,,,,,
,3765704606.27313,2.00078618526459,-0.415543466806412,,,6,,,,31.494945526123,,,10,,,,,,,,,,,,,,,,,,,,,,1.99808979034424,2.00219488143921,-0.415543466806412,-0.415543466806412,,,2.40670967102051,,1,0,0,0,0,32.7468223571777,1,1,1,2.00138425827026,0,2084573184,2.00005050897598,,,0.00249776246989457,0.000127585893283432,0.00255839047456041,0.00012764475257801,0.784109055995941,0.973803818225861,30.6739501953125,6.13118609180674E-5,35,4,200,-5.30817014805507E-5,-1.07813835144043,0.271115690469742,1,,,,,,,,,,,,,,,,
,3765704810.58451,2.00068259239197,-0.415543466806412,,,6,,,,31.494945526123,,,10,,,,,,,,,,,,,,,,,,,,,,1.99822926521301,2.00153422355652,-0.415543466806412,-0.415543466806412,,,2.40710592269897,,1,0,0,0,0.013885498046875,32.7468223571777,1,1,1,2.00170993804932,0,2084573184,1.99990420341492,,,0.00239799525571109,0.000122485469402859,0.0024561228893179,0.00012254232975685,0.784262835979462,0.973798811435699,30.6744422912598,,35,4,200,-2.29939105338417E-5,-0.99642676115036,0.197955101728439,1,,,,,,,,,,,,,,,,
,3765705015.38519,2.00193774700165,-0.415543466806412,,,6,,,,31.494945526123,,,10,,,,,,,,,,,,,,,,,,,,,,1.99779748916626,2.00238490104675,-0.415543466806412,-0.415543466806412,,,2.40723299980164,,1,0,0,0,0.013885498046875,32.2580642700195,1,1,1,2.00150084495544,0,2084573184,2.00036560297012,,,0.00230381730620137,0.000117672200131639,0.00235958170562975,0.000117725671860735,0.784370005130768,0.973798215389252,30.6748809814453,5.53849077224731,35,4,200,-8.98468169907574E-6,-0.909588992595673,0.237744137644768,1,,,,,,,,,,,,,,,,
,3765705220.28543,2.00150048732758,-0.415543466806412,,,6,,,,31.494945526123,,,10,,,,,,,,,,,,,,,,,,,,,,1.99805808067322,2.0020546913147,-0.415543466806412,-0.415543466806412,,,2.40684580802917,,1,0,0,0,0.013885498046875,32.2580642700195,1,1,1,2.00180649757385,0,2084573184,2.00006650686264,,,0.00221499382947768,0.000113132560225211,0.00226851592851195,0.000113182208226837,0.784479200839996,0.97378134727478,30.6753883361816,5.10747051239014,35,4,200,1.15294815259404E-5,-0.928107857704163,0.174836203455925,1,,,,,,,,,,,,,,,,
,3765705424.71648,2.00055819749832,-0.415543466806412,,,6,,,,31.494945526123,,,10,,,,,,,,,,,,,,,,,,,,,,1.99844038486481,2.00219821929932,-0.415543466806412,-0.415543466806412,,,2.40650606155396,,1,0,0,0,0.013885498046875,32.2580642700195,1,1,1,2.00129294395447,0,2084573184,2.00008420944214,,,0.00213124927976697,0.000108850825541606,0.00218271241769339,0.000108901256332736,0.784658789634705,0.973778188228607,30.675968170166,0,35,4,200,2.15389445656911E-5,-0.835721611976623,0.225460305809975,1,,,,,,,,,,,,,,,,
,3765705629.93122,2.00119602680206,-0.415543466806412,,,6,,,,31.494945526123,,,10,,,,,,,,,,,,,,,,,,,,,,1.9984118938446,2.00175786018372,-0.415543466806412,-0.415543466806412,,,2.40708017349243,,1,0,0,0,0.013885498046875,32.2580642700195,1,1,1,2.00189900398254,0,2084573184,1.99997656345367,,,0.00205115148322006,0.000104758258903235,0.00210062839512071,0.000104805855480085,0.78472900390625,0.973777890205383,30.6763725280762,0.000309855851810426,35,4,200,2.7698699341272E-5,-0.84968364238739,0.171632900834084,1,,,,,,,,,,,,,,,,
,3765705834.94965,2.00138175487518,-0.415543466806412,,,6,,,,31.494945526123,,,10,,,,,,,,,,,,,,,,,,,,,,1.99792337417603,2.00225758552551,-0.415543466806412,-0.415543466806412,,,2.40645265579224,,1,0,0,0,0.013885498046875,32.7468223571777,1,1,1,2.00100064277649,0,2084573184,2.00007389783859,,,0.00197624593364116,0.000100928694154037,0.00202386310656873,0.000100975852760957,0.784901320934296,0.973772287368774,30.6770286560059,0,35,4,200,3.92830261262134E-5,-0.861623704433441,0.228880167007446,1,,,,,,,,,,,,,,,,
,3765706039.42899,2.00069463253021,-0.415543466806412,,,6,,,,31.494945526123,,,10,,,,,,,,,,,,,,,,,,,,,,1.99822425842285,2.00196504592896,-0.415543466806412,-0.415543466806412,,,2.40559363365173,,1,0,0,0,0.013885498046875,32.7468223571777,1,1,1,2.00119066238403,0,2084573184,2.00001105070114,,,0.00190468823659127,9.72720999298831E-5,0.00195058005924097,9.73196157100023E-5,0.784997642040253,0.973767697811127,30.6775646209717,0,35,4,200,6.01091887801886E-5,-0.763511598110199,0.184651464223862,1,,,,,,,,,,,,,,,,
,3765706244.36613,2.00128364562988,-0.415543466806412,,,6,,,,31.494945526123,,,10,,,,,,,,,,,,,,,,,,,,,,1.99837303161621,2.00182437896729,-0.415543466806412,-0.415543466806412,,,2.40704607963562,,1,0,0,0,0.013885498046875,32.2580642700195,1,1,1,2.00194263458252,0,2084573184,2.0001052737236,,,0.00183670375032587,9.37971935223308E-5,0.00188083297171164,9.38397340494602E-5,0.785135805606842,0.973761558532715,30.6780891418457,5.53878021240234,35,4,200,7.44616554584354E-5,-0.770894229412079,0.143332660198212,1,,,,,,,,,,,,,,,,
,3765706449.40228,2.00168430805206,-0.415543466806412,,,6,,,,31.494945526123,,,10,,,,,,,,,,,,,,,,,,,,,,1.99751615524292,2.00209212303162,-0.415543466806412,-0.415543466806412,,,2.40623116493225,,1,0,0,0,0.013885498046875,32.2580642700195,1,1,1,2.00170063972473,0,2084573184,2.00019980669022,,,0.00177195122346662,9.04864712995319E-5,0.00181442058022944,9.05262551850424E-5,0.785327851772308,0.973751068115234,30.6786518096924,0,35,4,200,7.98703404143453E-5,-0.77529501914978,0.213770285248756,1,,,,,,,,,,,,,,,,
,3765716965.34499,4.002596616745,-0.0366655997931957,,,6,,,,31.494945526123,,,100,,,,,,,,,,,,,,,,,,,,,,3.99699187278748,4.00272703170776,-0.0366655997931957,-0.0366655997931957,,,3.24176359176636,,1,0,0,0,0,33.2355842590332,1,1,1,4.00260877609253,0,2084573184,4.00018603801727,,,0.0215110060400537,0.00110017605881139,0.0220604142821484,0.00110069327481587,0.778594195842743,0.972389042377472,30.6528778076172,,35,4,200,-0.00115065684076399,-0.895358145236969,0.210177734494209,1,,,,,,,,,,,,,,,,
,3765717169.56028,4.00242376327515,-0.0366655997931957,,,6,,,,31.494945526123,,,100,,,,,,,,,,,,,,,,,,,,,,3.99726033210754,4.00283622741699,-0.0366655997931957,-0.0366655997931957,,,3.26190280914307,,1,0,0,0,0.013885498046875,33.2355842590332,1,1,1,4.00259256362915,0,2084573184,4.00033133029938,,,0.0125075885626155,0.00063942841047434,0.0128220351623386,0.000639729515085334,0.780414462089539,0.973521590232849,30.6595764160156,,35,4,200,-0.000631736766081303,-0.520606160163879,0.122808367013931,1,,,,,,,,,,,,,,,,
,3765717374.14915,4.00239586830139,-0.0366655997931957,,,6,,,,31.494945526123,,,100,,,,,,,,,,,,,,,,,,,,,,3.99772238731384,4.00269508361816,-0.0366655997931957,-0.0366655997931957,,,3.27608251571655,,1,0,0,0,0,33.2355842590332,1,1,1,4.00273990631103,0,2084573184,4.00017712116241,,,0.00896611607121228,0.000458304584148812,0.00919011848432792,0.000458519935945909,0.781097531318665,0.973708271980286,30.6621570587158,5.5373420715332,35,4,200,-0.000447595142759383,-0.377081394195557,0.0897467955946922,1,,,,,,,,,,,,,,,,
,3765717578.63944,4.00229287147522,-0.0366655997931957,,,6,,,,31.494945526123,,,100,,,,,,,,,,,,,,,,,,,,,,3.99703407287598,4.00268936157227,-0.0366655997931957,-0.0366655997931957,,,3.28696656227112,,1,0,0,0,0.013885498046875,32.7468223571777,1,1,1,4.00220584869385,0,2084573184,4.00005581378937,,,0.00698135616500356,0.000356824264936605,0.00715508354504833,0.000356986096178691,0.781451106071472,0.97375500202179,30.6634635925293,0,35,4,200,-0.000349479611031711,-0.290220379829407,0.0669909790158272,1,,,,,,,,,,,,,,,,
,3765717783.0037,4.00272083282471,-0.0366655997931957,,,6,,,,31.494945526123,,,100,,,,,,,,,,,,,,,,,,,,,,3.9969494342804,4.00288009643555,-0.0366655997931957,-0.0366655997931957,,,3.29389357566833,,1,0,0,0,0,33.2355842590332,1,1,1,4.00257730484009,0,2084573184,4.00025236606598,,,0.00567515298147194,0.000290049629059655,0.00581610143848935,0.000290180549528308,0.781649589538574,0.973772466182709,30.6643371582031,0,35,4,200,-0.000281334650935605,-0.234941139817238,0.0573682673275471,1,,,,,,,,,,,,,,,,
,3765717987.28327,4.0028133392334,-0.0366655997931957,,,6,,,,31.494945526123,,,100,,,,,,,,,,,,,,,,,,,,,,3.99705028533936,4.00295543670654,-0.0366655997931957,-0.0366655997931957,,,3.29971241950989,,1,0,0,0,0.013885498046875,32.2580642700195,1,1,1,4.00279664993286,0,2084573184,4.00023226737976,,,0.00473816907959669,0.000242151102210632,0.0048555677967643,0.000242256975496603,0.781839072704315,0.97377872467041,30.6650161743164,3.75154495239258,35,4,200,-0.000235448824241757,-0.193700298666954,0.0435378924012184,1,,,,,,,,,,,,,,,,
,3765718192.08785,4.00278353691101,-0.0366655997931957,,,6,,,,31.494945526123,,,100,,,,,,,,,,,,,,,,,,,,,,3.99684119224548,4.00282096862793,-0.0366655997931957,-0.0366655997931957,,,3.3056263923645,,1,0,0,0,0.013885498046875,32.7468223571777,1,1,1,4.00274705886841,0,2084573184,4.00017547607422,,,0.00402695099552939,0.000205796365767201,0.00412660896684568,0.000205887350603449,0.78198629617691,0.973780572414398,30.6655883789063,0,35,4,200,-0.000200616879737936,-0.173040688037872,0.0374325513839722,1,,,,,,,,,,,,,,,,
,3765718396.85074,4.00200629234314,-0.0366655997931957,,,6,,,,31.494945526123,,,100,,,,,,,,,,,,,,,,,,,,,,3.9970703125,4.00296783447266,-0.0366655997931957,-0.0366655997931957,,,3.31065249443054,,1,0,0,0,0.013885498046875,32.7468223571777,1,1,1,4.00279855728149,0,2084573184,4.00004389286041,,,0.00346852551489566,0.00017725398519076,0.0035544459902824,0.000177340638518649,0.782089233398438,0.973779141902924,30.6660671234131,,35,4,200,-0.000172585976542905,-0.141511678695679,0.0321856439113617,1,,,,,,,,,,,,,,,,
,3765718601.97969,4.00251364707947,-0.0366655997931957,,,6,,,,31.494945526123,,,100,,,,,,,,,,,,,,,,,,,,,,3.99695229530334,4.00270128250122,-0.0366655997931957,-0.0366655997931957,,,3.31189727783203,,1,0,0,0,0.0017547607421875,32.7468223571777,1,1,1,4.00297784805298,0,2084573184,3.99980823198954,,,0.00301750187129532,0.000154200403354007,0.00309216207413623,0.000154276055207127,0.782221078872681,0.973780691623688,30.6666049957275,0,35,4,200,-0.000149331928696483,-0.129198342561722,0.0312167797237635,1,,,,,,,,,,,,,,,,
,3765718806.95268,4.00249052047729,-0.0366655997931957,,,6,,,,31.494945526123,,,100,,,,,,,,,,,,,,,,,,,,,,3.99721097946167,4.00274753570557,-0.0366655997931957,-0.0366655997931957,,,3.31687712669373,,1,0,0,0,0.0156402587890625,32.7468223571777,1,1,1,4.0027871131897,0,2084573184,4.00010178089142,,,0.00264671645154506,0.000135247577763565,0.00271199787443293,0.00013530876084889,0.782382190227509,0.973764061927795,30.667200088501,,35,4,200,-0.000130561034893617,-0.115831092000008,0.026192270219326,1,,,,,,,,,,,,,,,,
,3765719021.13657,4.00270962715149,-0.0366655997931957,,,6,,,,31.494945526123,,,10,,,,,,,,,,,,,,,,,,,,,,3.99700951576233,4.00292921066284,-0.0366655997931957,-0.0366655997931957,,,3.31764340400696,,1,0,0,0,0.013885498046875,32.7468223571777,1,1,1,4.00266742706299,0,2084573184,4.00017726421356,,,0.00232259208001777,0.000118680827701356,0.00237982803075364,0.00011873588606873,0.782526254653931,0.973762691020966,30.6677989959717,0.195862144231796,35,4,200,-0.00114731234498322,-1.01798605918884,0.24147617816925,1,,,,,,,,,,,,,,,,
,3765719225.37986,4.00278449058533,-0.0366655997931957,,,6,,,,31.494945526123,,,10,,,,,,,,,,,,,,,,,,,,,,3.99683523178101,4.00293159484863,-0.0366655997931957,-0.0366655997931957,,,3.31996035575867,,1,0,0,0,0,32.7468223571777,1,1,1,4.00269079208374,0,2084573184,4.00017187595367,,,0.00206159667289313,0.000105340374862457,0.00211237127911595,0.00010539186014465,0.782693862915039,0.973740041255951,30.6684398651123,0.195861205458641,35,4,200,-0.00102955114562064,-0.85703581571579,0.175560846924782,1,,,,,,,,,,,,,,,,
,3765719429.76641,4.00280857086182,-0.0366655997931957,,,6,,,,31.494945526123,,,10,,,,,,,,,,,,,,,,,,,,,,3.99700808525085,4.00308418273926,-0.0366655997931957,-0.0366655997931957,,,3.321702003479,,1,0,0,0,0.013885498046875,32.7468223571777,1,1,1,4.0026593208313,0,2084573184,4.00017197132111,,,0.00183717031252482,9.38698095950733E-5,0.0018822618618431,9.39110683767678E-5,0.782840609550476,0.973737895488739,30.669059753418,0,35,4,200,-0.000910652335733175,-0.787307620048523,0.132844477891922,1,,,,,,,,,,,,,,,,
,3765719634.43154,4.00243020057678,-0.0366655997931957,,,6,,,,31.494945526123,,,10,,,,,,,,,,,,,,,,,,,,,,3.99691963195801,4.00267505645752,-0.0366655997931957,-0.0366655997931957,,,3.32250356674194,,1,0,0,0,0.013885498046875,32.7468223571777,1,1,1,4.00273704528809,0,2084573184,4.00018303394318,,,0.00164205406294194,8.38972704011316E-5,0.00168232283572003,8.39356153973231E-5,0.783003926277161,0.973722040653229,30.6697673797607,5.53802919387817,35,4,200,-0.000816664251033217,-0.70439338684082,0.118099391460419,1,,,,,,,,,,,,,,,,
,3765719839.39666,4.0019850730896,-0.0366655997931957,,,6,,,,31.494945526123,,,10,,,,,,,,,,,,,,,,,,,,,,3.9973771572113,4.00293684005737,-0.0366655997931957,-0.0366655997931957,,,3.3234167098999,,1,0,0,0,0,32.7468223571777,1,1,1,4.00284385681152,0,2084573184,4.00016112327576,,,0.00147095830900973,7.51518072097652E-5,0.00150697196632708,7.51869142354769E-5,0.783218741416931,0.973701477050781,30.6704425811768,0,35,4,200,-0.000737427035346627,-0.611444532871246,0.125349283218384,1,,,,,,,,,,,,,,,,
,3765720044.00643,4.0027334690094,-0.0366655997931957,,,6,,,,31.494945526123,,,10,,,,,,,,,,,,,,,,,,,,,,3.99706149101257,4.00293254852295,-0.0366655997931957,-0.0366655997931957,,,3.32471442222595,,1,0,0,0,0,32.2580642700195,1,1,1,4.00253438949585,0,2084573184,4.00025007724762,,,0.00132074417985796,6.74739458809042E-5,0.00135302841826099,6.75063019306403E-5,0.7834392786026,0.973684072494507,30.6714267730713,0,35,4,200,-0.000667902291752398,-0.507785320281982,0.153800994157791,1,,,,,,,,,,,,,,,,
,3765720248.30272,4.00271987915039,-0.0366655997931957,,,6,,,,31.494945526123,,,10,,,,,,,,,,,,,,,,,,,,,,3.99700093269348,4.00273704528809,-0.0366655997931957,-0.0366655997931957,,,3.32485485076904,,1,0,0,0,0.013885498046875,32.2580642700195,1,1,1,4.00281047821045,0,2084573184,4.00018737316132,,,0.00118747061583701,6.06623224024478E-5,0.00121639201363274,6.06892089040723E-5,0.783655405044556,0.973645389080048,30.6724052429199,0,35,4,200,-0.000598224287386984,-0.503547251224518,0.0913791656494141,1,,,,,,,,,,,,,,,,
,3765733896.31129,10.0027856826782,0.0855530723929405,,,6,,,,31.494945526123,,,10,,,,,,,,,,,,,,,,,,,,,,9.99723625183105,10.0036306381226,0.0855530723929405,0.0855530723929405,,,4.43996667861938,,1,0,0,0,0.013885498046875,32.7468223571777,1,1,1,10.0024394989014,0,2084573184,10.0002207756042,,,0.00141290796739057,7.23461306078017E-5,0.00144938541880616,7.2378821248662E-5,0.773708522319794,0.950133740901947,30.6477279663086,,35,4,200,-0.0109259206801653,-0.618221759796143,0.132847890257835,1,,,,,,,,,,,,,,,,
,3765734110.00241,10.0026135444641,0.0855530723929405,,,6,,,,31.494945526123,,,1,,,,,,,,,,,,,,,,,,,,,,9.99717140197754,10.0036945343018,0.0855530723929405,0.0855530723929405,,,4.46766662597656,,1,0,0,0,0.013885498046875,32.7468223571777,1,1,1,10.0025844573975,0,2084573184,10.0000920295715,,,-3.85556884339084E-5,1.98805347852255E-6,-3.97270894813295E-5,1.98925726322538E-6,0.746246695518494,0.911244869232178,30.5783023834229,0,35,4,200,-0.0643533915281296,-0.35770046710968,0.227729573845863,1,,,,,,,,,,,,,,,,
,3765734314.6452,10.0028305053711,0.0855530723929405,,,6,,,,31.494945526123,,,1,,,,,,,,,,,,,,,,,,,,,,9.99703407287598,10.0033264160156,0.0855530723929405,0.0855530723929405,,,4.48707723617554,,1,0,0,0,0.013885498046875,33.2355842590332,1,1,1,10.0024433135986,0,2084573184,9.99989070892334,,,-0.000172012147233483,8.80488238663647E-6,-0.000176571027938605,8.80936628223134E-6,0.775035381317139,0.974772572517395,30.6375389099121,0,35,4,200,-0.0481139458715916,-0.883168816566467,0.265221744775772,1,,,,,,,,,,,,,,,,
,3765734519.09862,10.0030117034912,0.0855530723929405,,,6,,,,31.494945526123,,,1,,,,,,,,,,,,,,,,,,,,,,9.99709320068359,10.003532409668,0.0855530723929405,0.0855530723929405,,,4.50015163421631,,1,0,0,0,0.013885498046875,33.2355842590332,1,1,1,10.0026264190674,0,2084573184,10.0000569343567,,,-0.000198412512411493,1.01540208394414E-5,-0.000203626135636092,1.01591178697013E-5,0.775962769985199,0.975002706050873,30.6410827636719,0,35,4,200,-0.038230687379837,-0.741067469120026,1.18969428539276,1,,,,,,,,,,,,,,,,
,3765734724.2903,10.0028767585754,0.0855530723929405,,,6,,,,31.494945526123,,,1,,,,,,,,,,,,,,,,,,,,,,9.99721622467041,10.0035886764526,0.0855530723929405,0.0855530723929405,,,4.5116753578186,,1,0,0,0,0.013885498046875,33.2355842590332,1,1,1,10.0028963088989,0,2084573184,10.0000632286072,,,-0.000204670081332663,1.04734184197162E-5,-0.000210029698382071,1.04786009971113E-5,0.776305973529816,0.975013017654419,30.6424770355225,0,35,4,200,-0.0314431898295879,-0.417803287506103,0.79412168264389,1,,,,,,,,,,,,,,,,
,3765734928.84943,10.0026502609253,0.0855530723929405,,,6,,,,31.494945526123,,,1,,,,,,,,,,,,,,,,,,,,,,9.99700164794922,10.0035963058472,0.0855530723929405,0.0855530723929405,,,4.51984786987305,,1,0,0,0,0.013885498046875,33.2355842590332,1,1,1,10.0023384094238,0,2084573184,10.0001236915588,,,-0.000206144751615329,1.05484671229968E-5,-0.000211531862645846,1.05535721012619E-5,0.776472151279449,0.974909663200378,30.6431522369385,5.53562545776367,35,4,200,-0.0263753049075603,-0.744446516036987,1.26811361312866,1,,,,,,,,,,,,,,,,
,3765743078.93414,8.00366735458374,-0.293324798345566,,,6,,,,31.494945526123,,,100,,,,,,,,,,,,,,,,,,,,,,7.99697542190552,8.00360488891602,-0.293324798345566,-0.293324798345566,,,4.19907236099243,,1,0,0,0,0.013885498046875,32.7468223571777,1,1,1,8.00372982025146,0,2084573184,8.00005660057068,,,0.0194675482000533,0.000996450701372444,0.0199757333825736,0.000996929298705692,0.775229573249817,0.964452981948852,30.6438217163086,0,35,4,200,-0.00218375795520842,-0.82498162984848,0.186090350151062,1,,,,,,,,,,,,,,,,
,3765743283.84381,8.00375413894653,-0.293324798345566,,,6,,,,31.494945526123,,,100,,,,,,,,,,,,,,,,,,,,,,7.9966139793396,8.00384712219238,-0.293324798345566,-0.293324798345566,,,4.21769332885742,,1,0,0,0,0,33.2355842590332,1,1,1,8.00381374359131,0,2084573184,8.00012969970703,,,0.00482184975639514,0.00024663377752487,0.00494536589728423,0.000246753459494501,0.778224587440491,0.971393406391144,30.6517524719238,0,35,4,200,-0.00080295791849494,-0.201020747423172,0.0489702932536602,1,,,,,,,,,,,,,,,,
,3765743497.64502,8.00374221801758,-0.293324798345566,,,6,,,,31.494945526123,,,10,,,,,,,,,,,,,,,,,,,,,,7.99688482284546,8.00379180908203,-0.293324798345566,-0.293324798345566,,,4.2309513092041,,1,0,0,0,0.0006103515625,33.2355842590332,1,1,1,8.00369262695313,0,2084573184,8.00012927055359,,,0.00182371669096055,9.32649731495271E-5,0.00187013871471046,9.33093329426386E-5,0.778990507125854,0.972484409809113,30.6541538238525,0,35,4,200,-0.00534052168950439,-0.75454044342041,0.180609822273254,1,,,,,,,,,,,,,,,,
,3765743702.10287,8.00370311737061,-0.293324798345566,,,6,,,,31.494945526123,,,10,,,,,,,,,,,,,,,,,,,,,,7.99665355682373,8.00373268127441,-0.293324798345566,-0.293324798345566,,,4.23608255386353,,1,0,0,0,0.013885498046875,34.7018585205078,1,1,1,8.0036735534668,0,2084573184,8.00012354850769,,,0.000772527883741036,3.95020885854993E-5,0.000792088377127206,3.95207070839972E-5,0.779540300369263,0.972509920597076,30.6564788818359,6.40413345536217E-5,35,4,200,-0.00410743057727814,-0.307896494865417,0.0993746444582939,1,,,,,,,,,,,,,,,,
,3765743916.07429,8.0034556388855,-0.293324798345566,,,6,,,,31.494945526123,,,1,,,,,,,,,,,,,,,,,,,,,,7.99671363830566,8.00345611572266,-0.293324798345566,-0.293324798345566,,,4.24218320846558,,1,0,0,0,0.013885498046875,32.7468223571777,1,1,1,8.00380039215088,0,2084573184,8.00011110305786,,,0.000284158378470263,1.45258043017982E-5,0.00029125955769902,1.4532549901886E-5,0.78080016374588,0.971656560897827,30.6618576049805,0,35,4,200,-0.0329750888049602,-1.37811732292175,0.225167497992516,1,,,,,,,,,,,,,,,,
,3765744120.39171,8.00383901596069,-0.293324798345566,,,6,,,,31.494945526123,,,1,,,,,,,,,,,,,,,,,,,,,,7.99689292907715,8.00384140014648,-0.293324798345566,-0.293324798345566,,,4.24933815002441,,1,0,0,0,0.013885498046875,32.7468223571777,1,1,1,8.0038366317749,0,2084573184,8.00011515617371,,,6.21287063213201E-5,3.17194891491488E-6,6.35795391233909E-5,3.17334718049673E-6,0.786334633827209,0.962038278579712,30.6892395019531,0,35,4,200,-0.0276182889938354,-0.127636194229126,0.344987392425537,1,,,,,,,,,,,,,,,,
,3765744325.18458,8.00384283065796,-0.293324798345566,,,6,,,,31.494945526123,,,1,,,,,,,,,,,,,,,,,,,,,,7.9968318939209,8.00394916534424,-0.293324798345566,-0.293324798345566,,,4.25274991989136,,1,0,0,0,0,33.2355842590332,1,1,1,8.00373649597168,0,2084573184,8.00023941993713,,,-5.35480611607338E-5,2.74542038325997E-6,-5.50500520531233E-5,2.74694516040511E-6,0.768337607383728,0.969261944293976,30.6137542724609,3.75140357017517,35,4,200,-0.0235388316214085,0.253319561481476,0.662688434123993,1,,,,,,,,,,,,,,,,
,3765744529.93342,8.00391387939453,-0.293324798345566,,,6,,,,31.494945526123,,,1,,,,,,,,,,,,,,,,,,,,,,7.99665832519531,8.00410747528076,-0.293324798345566,-0.293324798345566,,,4.25417518615723,,1,0,0,0,0.013885498046875,32.7468223571777,1,1,1,8.0037202835083,0,2084573184,8.00012102127075,,,-0.000118588791474336,6.07105137606787E-6,-0.000121744621089617,6.07410561729176E-6,0.774493932723999,0.974114656448364,30.635778427124,0.196244552731514,35,4,200,-0.0203144010156393,0.0645502954721451,0.778394639492035,1,,,,,,,,,,,,,,,,
,3765744735.0813,8.00399208068848,-0.293324798345566,,,6,,,,31.494945526123,,,1,,,,,,,,,,,,,,,,,,,,,,7.99668312072754,8.00421333312988,-0.293324798345566,-0.293324798345566,,,4.2577109336853,,1,0,0,0,0.013885498046875,32.7468223571777,1,1,1,8.00377082824707,0,2084573184,8.00021719932556,,,-0.000158126475451454,8.09279366044928E-6,-0.000162283668247797,8.09670128702857E-6,0.775723099708557,0.974053800106049,30.6407375335693,0,35,4,200,-0.0175112262368202,-0.610300362110138,0.284294188022614,1,,,,,,,,,,,,,,,,
,3765744939.43352,8.0037727355957,-0.293324798345566,,,6,,,,31.494945526123,,,1,,,,,,,,,,,,,,,,,,,,,,7.99653005599976,8.00378131866455,-0.293324798345566,-0.293324798345566,,,4.25926971435547,,1,0,0,0,0,32.7468223571777,1,1,1,8.00376415252686,0,2084573184,8.00012726783752,,,-0.000183651883010008,9.39799018239998E-6,-0.000188462555859421,9.40269877836132E-6,0.776252567768097,0.974574089050293,30.6425609588623,0,35,4,200,-0.0156011069193482,-0.751015663146973,0.258654564619064,1,,,,,,,,,,,,,,,,
,3765745143.66841,8.00321292877197,-0.293324798345566,,,6,,,,31.494945526123,,,1,,,,,,,,,,,,,,,,,,,,,,7.99667835235596,8.00362777709961,-0.293324798345566,-0.293324798345566,,,4.26109838485718,,1,0,0,0,0,32.7468223571777,1,1,1,8.00352191925049,0,2084573184,7.99996376037598,,,-0.000200927204291316,1.02813119641538E-5,-0.000206175046687672,1.0286404111415E-5,0.776542723178863,0.974557995796204,30.6436805725098,0,35,4,200,-0.0138169033452868,-0.494875371456146,0.590172588825226,1,,,,,,,,,,,,,,,,
,3765745348.16724,8.00356912612915,-0.293324798345566,,,6,,,,31.494945526123,,,1,,,,,,,,,,,,,,,,,,,,,,7.99649667739868,8.00377082824707,-0.293324798345566,-0.293324798345566,,,4.26116275787354,,1,0,0,0,0.0153350830078125,32.7468223571777,1,1,1,8.00336742401123,0,2084573184,8.00003261566162,,,-0.000213176461915693,1.09079296412369E-5,-0.000218741015829771,1.09133219891483E-5,0.77660721540451,0.974613010883331,30.6438770294189,0,35,4,200,-0.0123580666258931,0.0930318012833595,1.22979819774628,1,,,,,,,,,,,,,,,,
,3765745552.77241,8.00396013259888,-0.293324798345566,,,6,,,,31.494945526123,,,1,,,,,,,,,,,,,,,,,,,,,,7.99715280532837,8.00393390655518,-0.293324798345566,-0.293324798345566,,,4.26370668411255,,1,0,0,0,0,32.7468223571777,1,1,1,8.00398635864258,0,2084573184,8.00026874542236,,,-0.000222012926197767,1.13596845754195E-5,-0.000227801203596258,1.13653526286992E-5,0.7767573595047,0.974622488021851,30.6443901062012,0,35,4,200,-0.0111366882920265,-0.128929406404495,1.04521012306213,1,,,,,,,,,,,,,,,,
,3765745757.00456,8.00377798080444,-0.293324798345566,,,6,,,,31.494945526123,,,1,,,,,,,,,,,,,,,,,,,,,,7.99689531326294,8.00378894805908,-0.293324798345566,-0.293324798345566,,,4.26458835601807,,1,0,0,0,0,32.2580642700195,1,1,1,8.0037670135498,0,2084573184,8.00027480125427,,,-0.000228534890010455,1.16933355342076E-5,-0.000234493696793441,1.16992597538559E-5,0.776778697967529,0.974600315093994,30.6446132659912,6.7492168454919E-5,35,4,200,-0.00996050145477057,-0.103877887129784,1.09592723846436,1,,,,,,,,,,,,,,,,
,3765745961.63326,8.00394010543823,-0.293324798345566,,,6,,,,31.494945526123,,,1,,,,,,,,,,,,,,,,,,,,,,7.9966983795166,8.00388526916504,-0.293324798345566,-0.293324798345566,,,4.26552772521973,,1,0,0,0,0,32.7468223571777,1,1,1,8.00399494171143,0,2084573184,8.00008792877197,,,-0.000233558404734773,1.19501075612277E-5,-0.0002396449193737,1.19562634918171E-5,0.776871681213379,0.974586963653564,30.6448593139648,6.751628825441E-5,35,4,200,-0.00900003593415022,0.133715718984604,1.35226535797119,1,,,,,,,,,,,,,,,,
,3765746165.95615,8.00378179550171,-0.293324798345566,,,6,,,,31.494945526123,,,1,,,,,,,,,,,,,,,,,,,,,,7.99670934677124,8.00400447845459,-0.293324798345566,-0.293324798345566,,,4.26543951034546,,1,0,0,0,0,32.7468223571777,1,1,1,8.00355911254883,0,2084573184,8.00001106262207,,,-0.000237313341712963,1.21421531539916E-5,-0.000243487317206841,1.21479590012784E-5,0.77689927816391,0.974616825580597,30.6449184417725,0,35,4,200,-0.0081832567229867,-0.524311125278473,0.707917332649231,1,,,,,,,,,,,,,,,,
,3765746370.97232,8.00380945205688,-0.293324798345566,,,6,,,,31.494945526123,,,1,,,,,,,,,,,,,,,,,,,,,,7.9968433380127,8.00392818450928,-0.293324798345566,-0.293324798345566,,,4.26664352416992,,1,0,0,0,0,32.7468223571777,1,1,1,8.00369071960449,0,2084573184,8.00024580955505,,,-0.000240275114867938,1.22935471890109E-5,-0.000246522393906495,1.22993869359176E-5,0.776949107646942,0.974602162837982,30.6450843811035,6.71885718475096E-5,35,4,200,-0.00748079270124435,0.0546840503811836,1.29796409606934,1,,,,,,,,,,,,,,,,
,3765752194.64499,6.00265622138977,-0.219993591308594,,,6,,,,31.494945526123,,,100,,,,,,,,,,,,,,,,,,,,,,5.99723768234253,6.00379705429077,-0.219993591308594,-0.219993591308594,,,3.78250503540039,,1,0,0,0,0.013885498046875,33.7243423461914,1,1,1,6.00378465652466,0,2084573184,6.00031394958496,,,0.0738749574016775,0.00378623613072506,0.0758519766666965,0.00378817583076134,0.769795775413513,0.948512852191925,30.6336307525635,0,35,4,200,-0.0109811872243881,-4.42120981216431,4.7760534286499,1,,,,,,,,,,,,,,,,
,3765752404.01237,6.00379395484924,-0.219993591308594,,,6,,,,31.494945526123,,,100,,,,,,,,,,,,,,,,,,,,,,5.9970235824585,6.00374174118042,-0.219993591308594,-0.219993591308594,,,3.81801605224609,,1,0,0,0,0.000762939453125,33.2355842590332,1,1,1,6.00384616851807,0,2084573184,6.00015416145325,,,0.0147374553151233,0.000753713534944682,0.0151130827550802,0.000754068088625903,0.778768718242645,0.971985936164856,30.6536560058594,0,35,4,200,-0.00108339369762689,-0.61230593919754,0.144208028912544,1,,,,,,,,,,,,,,,,
,3765752608.31681,6.00378656387329,-0.219993591308594,,,6,,,,31.494945526123,,,100,,,,,,,,,,,,,,,,,,,,,,5.99685287475586,6.00394535064697,-0.219993591308594,-0.219993591308594,,,3.83116817474365,,1,0,0,0,0.013885498046875,32.7468223571777,1,1,1,6.00366067886353,0,2084573184,6.00006165504456,,,0.00751437781144615,0.000384188117426786,0.00770388104434557,0.000384371566483183,0.780088543891907,0.973315298557282,30.6582355499268,0,35,4,200,-0.000635829346720129,-0.310338348150253,0.0735842511057854,1,,,,,,,,,,,,,,,,
,3765752812.61483,6.00378799438477,-0.219993591308594,,,6,,,,31.494945526123,,,100,,,,,,,,,,,,,,,,,,,,,,5.9969654083252,6.00375175476074,-0.219993591308594,-0.219993591308594,,,3.84055614471436,,1,0,0,0,0.013885498046875,33.2355842590332,1,1,1,6.00411558151245,0,2084573184,6.00023832321167,,,0.00463469606199647,0.000236943743078276,0.00475126084825685,0.000237053638756012,0.780356287956238,0.973651468753815,30.6591339111328,0.195974454283714,35,4,200,-0.000466817611595616,-0.19942831993103,0.0410132370889187,1,,,,,,,,,,,,,,,,
,3765753016.94156,6.00362062454224,-0.219993591308594,,,6,,,,31.494945526123,,,100,,,,,,,,,,,,,,,,,,,,,,5.99684429168701,6.00366878509522,-0.219993591308594,-0.219993591308594,,,3.85052132606506,,1,0,0,0,0,33.2355842590332,1,1,1,6.00366878509522,0,2084573184,6.00006132125854,,,0.00304995442775261,0.000155923174420316,0.00312677398634969,0.000156002798100933,0.78042197227478,0.973805844783783,30.6592636108398,0,35,4,200,-0.000368685345165431,-0.126314267516136,0.0274485368281603,1,,,,,,,,,,,,,,,,
,3765753230.92738,6.0037956237793,-0.219993591308594,,,6,,,,31.494945526123,,,10,,,,,,,,,,,,,,,,,,,,,,5.99695491790771,6.00368022918701,-0.219993591308594,-0.219993591308594,,,3.85620188713074,,1,0,0,0,0.013885498046875,33.2355842590332,1,1,1,6.00391101837158,0,2084573184,6.0001540184021,,,0.00202238696007161,0.000103389603921034,0.00207316176737348,0.000103435026122119,0.780469477176666,0.973939776420593,30.6592788696289,6.37228149571456E-5,35,4,200,-0.00301247253082693,-0.831164360046387,0.191820546984673,1,,,,,,,,,,,,,,,,
,3765753435.72529,6.00379800796509,-0.219993591308594,,,6,,,,31.494945526123,,,10,,,,,,,,,,,,,,,,,,,,,,5.99673223495483,6.00366592407227,-0.219993591308594,-0.219993591308594,,,3.86110424995422,,1,0,0,0,0,32.7468223571777,1,1,1,6.00393009185791,0,2084573184,6.00011739730835,,,0.00137362684784456,7.02213342137987E-5,0.00140819074989817,7.02578699629696E-5,0.780593812465668,0.974035918712616,30.6596527099609,0.167050704360008,35,4,200,-0.0025432794354856,-0.604796290397644,0.179325506091118,1,,,,,,,,,,,,,,,,
,3765753640.15297,6.0037796497345,-0.219993591308594,,,6,,,,31.494945526123,,,10,,,,,,,,,,,,,,,,,,,,,,5.99688386917114,6.00376224517822,-0.219993591308594,-0.219993591308594,,,3.86409878730774,,1,0,0,0,0,32.7468223571777,1,1,1,6.00379705429077,0,2084573184,6.00016894340515,,,0.000924121377130438,4.72404188908241E-5,0.000947286028386631,4.72621401199304E-5,0.780749201774597,0.974143266677856,30.6604900360107,0,35,4,200,-0.0022005895152688,-0.385631322860718,0.0866284444928169,1,,,,,,,,,,,,,,,,
,3765753844.31915,6.00388765335083,-0.219993591308594,,,6,,,,31.494945526123,,,10,,,,,,,,,,,,,,,,,,,,,,5.99671745300293,6.00408172607422,-0.219993591308594,-0.219993591308594,,,3.8674635887146,,1,0,0,0,0,32.7468223571777,1,1,1,6.00369358062744,0,2084573184,6.0002676486969,,,0.000603245797122477,3.08339422323628E-5,0.000618302721788328,3.08483754413439E-5,0.781248807907105,0.974236607551575,30.6623115539551,0,35,4,200,-0.00190798717085272,-0.249646008014679,0.0614212937653065,1,,,,,,,,,,,,,,,,
,3765754048.64023,6.00390839576721,-0.219993591308594,,,6,,,,31.494945526123,,,10,,,,,,,,,,,,,,,,,,,,,,5.99704647064209,6.00305604934692,-0.219993591308594,-0.219993591308594,,,3.86918783187866,,1,0,0,0,0.0148773193359375,33.2355842590332,1,1,1,6.00399827957153,0,2084573184,5.99987904230754,,,0.000368854449321157,1.88491716644569E-5,0.000377996015990077,1.88589547656042E-5,0.782227396965027,0.974293887615204,30.6658573150635,0.0538204908370972,35,4,200,-0.00167147384490818,-0.201545387506485,-0.00845829769968986,1,,,,,,,,,,,,,,,,
,3765754262.49983,6.00406551361084,-0.219993591308594,,,6,,,,31.494945526123,,,1,,,,,,,,,,,,,,,,,,,,,,5.9969596862793,6.00409698486328,-0.219993591308594,-0.219993591308594,,,3.87259268760681,,1,0,0,0,0.013885498046875,32.7468223571777,1,1,1,6.0040340423584,0,2084573184,6.00018057823181,,,0.000188268999645075,9.61596855458722E-6,0.000192825986749945,9.62053468809971E-6,0.784485578536987,0.973995804786682,30.6747951507568,,35,4,200,-0.0147216478362679,-1.37358295917511,0.598836183547974,1,,,,,,,,,,,,,,,,
,3765754466.96533,6.00385594367981,-0.219993591308594,,,6,,,,31.494945526123,,,1,,,,,,,,,,,,,,,,,,,,,,5.99689149856567,6.00406455993652,-0.219993591308594,-0.219993591308594,,,3.87362551689148,,1,0,0,0,0.013885498046875,32.7468223571777,1,1,1,6.0036473274231,0,2084573184,6.00016169548035,,,5.98173720686665E-5,3.04887620180651E-6,6.11216149548129E-5,3.05010019993312E-6,0.793898403644562,0.967293083667755,30.7143211364746,0.0688564777374268,35,4,200,-0.0130876256152987,-0.522652864456177,-0.150659516453743,1,,,,,,,,,,,,,,,,
,3765754671.57769,6.00381231307983,-0.219993591308594,,,6,,,,31.494945526123,,,1,,,,,,,,,,,,,,,,,,,,,,5.99680805206299,6.00391244888306,-0.219993591308594,-0.219993591308594,,,3.87515091896057,,1,0,0,0,0,32.7468223571777,1,1,1,6.00371217727661,0,2084573184,6.00019030570984,,,-3.71479723517515E-5,1.91218278050284E-6,-3.83149408004649E-5,1.91332938133299E-6,0.752667427062988,0.950412690639496,30.5662307739258,3.75142383575439,35,4,200,-0.0116919530555606,0.370622515678406,0.628386199474335,1,,,,,,,,,,,,,,,,
,3765754875.95007,6.00402355194092,-0.219993591308594,,,6,,,,31.494945526123,,,1,,,,,,,,,,,,,,,,,,,,,,5.99704647064209,6.00370979309082,-0.219993591308594,-0.219993591308594,,,3.8754096031189,,1,0,0,0,0.013885498046875,32.7468223571777,1,1,1,6.00433731079102,0,2084573184,6.00032196044922,,,-0.000110418248574301,5.6571955062385E-6,-0.00011343208154609,5.66011173848388E-6,0.771224796772003,0.969502627849579,30.6259574890137,,35,4,200,-0.0105865597724915,0.1946731954813,0.809668362140655,1,,,,,,,,,,,,,,,,
,3765755080.73619,6.00392293930054,-0.219993591308594,,,6,,,,31.494945526123,,,1,,,,,,,,,,,,,,,,,,,,,,5.99671077728271,6.00390434265137,-0.219993591308594,-0.219993591308594,,,3.87681818008423,,1,0,0,0,0.013885498046875,32.7468223571777,1,1,1,6.00394153594971,0,2084573184,6.00010504722595,,,-0.000165980536890583,8.4978331779295E-6,-0.000170399047464018,8.50215713831126E-6,0.774194955825806,0.971612691879272,30.6363353729248,0.113817520439625,35,4,200,-0.00949347019195557,0.264736205339432,1.15026068687439,1,,,,,,,,,,,,,,,,
,3765755285.10303,6.00382256507874,-0.219993591308594,,,6,,,,31.494945526123,,,1,,,,,,,,,,,,,,,,,,,,,,5.99685335159302,6.0036997795105,-0.219993591308594,-0.219993591308594,,,3.87734150886536,,1,0,0,0,0.013885498046875,32.7468223571777,1,1,1,6.00394535064697,0,2084573184,6.00019822120666,,,-0.000207881688690915,1.06400871080583E-5,-0.000213356605065052,1.06453351364388E-5,0.775381147861481,0.972339272499084,30.6405849456787,7.62046620366164E-5,35,4,200,-0.00862240232527256,-0.533949851989746,0.554687082767487,1,,,,,,,,,,,,,,,,
,3765755489.60615,6.00382876396179,-0.219993591308594,,,6,,,,31.494945526123,,,1,,,,,,,,,,,,,,,,,,,,,,5.99673175811768,6.00375461578369,-0.219993591308594,-0.219993591308594,,,3.87677121162415,,1,0,0,0,0.013885498046875,32.7468223571777,1,1,1,6.00390291213989,0,2084573184,6.00002174377441,,,-0.00023952373306186,1.22578055582591E-5,-0.000245791151094339,1.22635313204609E-5,0.776012122631073,0.972665071487427,30.6429786682129,0,35,4,200,-0.00781278870999813,-0.0614324547350407,1.17988359928131,1,,,,,,,,,,,,,,,,
,3765755694.61213,6.00367999076843,-0.219993591308594,,,6,,,,31.494945526123,,,1,,,,,,,,,,,,,,,,,,,,,,5.99686908721924,6.00382232666016,-0.219993591308594,-0.219993591308594,,,3.87898707389832,,1,0,0,0,0.013885498046875,33.7243423461914,1,1,1,6.00353765487671,0,2084573184,6.00027794837952,,,-0.000263301833092585,1.34735226752621E-5,-0.000270175196526023,1.34800780628768E-5,0.776374280452728,0.972878634929657,30.6441192626953,0,35,4,200,-0.00716851931065321,-0.515225946903229,0.840917706489563,1,,,,,,,,,,,,,,,,
,3765755772.41831,6.00384926795959,-0.219993591308594,,,6,,,,31.494945526123,,,1,,,,,,,,,,,,,,,,,,,,,,5.99693536758423,6.00395107269287,-0.219993591308594,-0.219993591308594,,,3.87952876091003,,1,0,0,0,0.0159454345703125,33.2355842590332,1,1,1,6.00374746322632,0,2084573184,6.00025196075439,,,-0.000270666954801281,1.3849978881581E-5,-0.000277726440466358,1.38568093663059E-5,0.776504993438721,0.972952902317047,30.6445617675781,5.53575325012207,35,4,200,-0.00688199838623405,0.0236478187143803,1.41424000263214,1,,,,,,,,,,,,,,,,