File: examples/190424 - K(18-c-6)_Er(BAT)2 - 1 - 3 - ACvsF.dat
[Header]
; MPMS3 Data File (default extension .dat)
; Copyright (c) 2007, Quantum Design, Inc. All rights reserved.
TITLE,
FILEOPENTIME,3765464791.22163,04/26/2019,7:27 pm
BYAPP,SQUID AC,0.9.1.0
INFO,MPMS3 Measurement Release 1.1.16 Build 399, MultiVu Release 2.3.4.15,APPNAME
INFO,0,MOMENT_UNITS
INFO,K(18-c-6)_Er(hdcCOT)2,SAMPLE_MATERIAL
INFO,yellow crystalline powder,SAMPLE_COMMENT
INFO,7.2,SAMPLE_MASS
INFO,22.7,SAMPLE_VOLUME
INFO,839.24,SAMPLE_MOLECULAR_WEIGHT
INFO,-125.81E-6,SAMPLE_SIZE
INFO,,SAMPLE_SHAPE
INFO,Standard,SAMPLE_HOLDER
INFO,Standard,SAMPLE_HOLDER_DETAIL
INFO,66.54,SAMPLE_OFFSET
DATATYPE,COMMENT,1
DATATYPE,TIME,2
STARTUPAXIS,X,2
STARTUPAXIS,Y1,5
FIELDGROUP, VSM,2,3,4,5,6,8,9,10,11,14,15
FIELDGROUP, DC, 2,3,4,14,56,57,58,59,60,61,62,63,64,65,66,67,68,69
FIELDGROUP, AC, 2,3,4,11,16,17,18,19,20,21,22,23,24,25,26,27,28,29,30
STARTUPGROUP, All
[Data]
Comment,Time Stamp (sec),Temperature (K),Magnetic Field (Oe),Moment (emu),M. Std. Err. (emu),Transport Action,Averaging Time (sec),Frequency (Hz),Peak Amplitude (mm),Center Position (mm),Lockin Signal' (V),Lockin Signal (V),Range,M. Quad. Signal (emu),AC Moment (emu),AC M. Std Err. (emu),AC Phase (deg),AC Phase Std. Err. (deg),AC Susceptibility (emu/Oe),AC Suscept. Std Err. (emu/Oe),AC X' (emu/Oe),AC X' Std Err. (emu/Oe),AC X'' (emu/Oe),AC X'' Std Err. (emu/Oe),AC Drive (Oe),AC Frequency (Hz),AC Averaging Time (sec),AC Cycles,AC Range,AC Measure Type,AC Signal' (V),AC Signal'' (V),AC Trim Coil Ratio,AC Trim Coil Phase,Min. Temperature (K),Max. Temperature (K),Min. Field (Oe),Max. Field (Oe),Mass (grams),Motor Lag (deg),Pressure (Torr),Measure Count,Measurement Number,SQUID Status (code),Motor Status (code),Measure Status (code),Motor Current (amps),Motor Temp. (C),Temp. Status (code),Field Status (code),Chamber Status (code),Chamber Temp (K),Redirection State,Evercool Status,Average Temp (K),Rotation Angle (deg),Rotator state,DC Moment Fixed Ctr (emu),DC Moment Err Fixed Ctr (emu),DC Moment Free Ctr (emu),DC Moment Err Free Ctr (emu),DC Fixed Fit,DC Free Fit,DC Calculated Center (mm),DC Calculated Center Err (mm),DC Scan Length (mm),DC Scan Time (s),DC Number of Points,DC Squid Drift,DC Min V (V),DC Max V (V),DC Scans per Measure,Map 01,Map 02,Map 03,Map 04,Map 05,Map 06,Map 07,Map 08,Map 09,Map 10,Map 11,Map 12,Map 13,Map 14,Map 15,Map 16
,3765465082.44612,13.9997162818909,0,,,5,,,,31.5000005066395,,,,,1.00625768661988E-6,5.94588389322348E-8,4.25560912067859,0.0398799891500161,5.03079267288015E-7,2.97264900646909E-8,5.01692240155803E-7,2.24400846369753E-8,3.73315596044178E-8,1.9496328194087E-8,2.00019709030028,999.040954589844,2,1998,1,5,0.0034196809121297,0.0010280553897312,0.0268615055829287,352.335357666016,13.9983358383179,14.0020980834961,0,0,,,5.89779090881348,,1,,,,,,1,1,1,13.9993572235107,0,0,14.0000639955203,,,,,,,,,,,,,,,,,,,,,,,,,,,,,,,,,
,3765465211.23148,13.9999976158142,0,,,5,,,,31.5000005066395,,,,,1.07049041839327E-6,1.50055071689775E-8,5.18449294799157,0.010138617735249,5.35118146480674E-7,7.50097249381994E-9,5.32928920226803E-7,5.1966227295068E-9,4.83549033584551E-8,5.40922365596179E-9,2.0004748959339,491.971038818359,2,983,1,5,0.00368245725879431,0.000798348743258279,0.0262756533920765,357.197967529297,13.9988965988159,14.0017166137695,0,0,,,5.8458662033081,,1,,,,,,1,1,1,13.9997100830078,0,0,14.0000494321187,,,,,,,,,,,,,,,,,,,,,,,,,,,,,,,,,
,3765465335.86893,13.999888420105,0,,,5,,,,31.5000005066395,,,,,1.11879183295982E-6,3.31953130965195E-8,9.7457611660271,0.0268922624958186,5.59520866320062E-7,1.66013638948304E-8,5.51446188558461E-7,6.16095211559434E-9,9.47137844872568E-8,1.54158344632372E-8,1.99955336843477,242.323211669922,2,484,1,5,0.00379449323407562,0.00102507092134798,0.0260520596057177,1.74972534179687,13.9994373321533,14.000862121582,0,0,,,5.79302358627319,,1,,,,,,1,1,1,13.9997482299805,0,0,13.9999775133635,,,,,,,,,,,,,,,,,,,,,,,,,,,,,,,,,
,3765465462.35836,13.9998803138733,0,,,5,,,,31.5000005066395,,,,,1.21440118036529E-6,1.81949861852099E-8,16.1996025485391,0.0123956308353642,6.07400083941508E-7,9.10048204406948E-9,5.83283640785571E-7,4.96409165408774E-9,1.69455175087926E-7,7.62735652006955E-9,1.99934312238626,119.384170532227,2,238,1,5,0.00394108542905903,0.0016305214928346,0.0254904702305794,7.11361694335938,13.9995203018188,14.0006713867188,0,0,,,5.74001264572144,,1,,,,,,1,1,1,13.999852180481,0,0,14.0000100589934,,,,,,,,,,,,,,,,,,,,,,,,,,,,,,,,,
,3765465590.40337,13.9999151229858,0,,,5,,,,31.5000005066395,,,,,1.37084956111603E-6,1.14365492409356E-8,27.0612784067541,0.00958583089752546,6.8552748803935E-7,5.7191314753708E-9,6.10476259017028E-7,4.33686715943168E-9,3.11876055563931E-7,3.7282768236841E-9,1.99970035488546,58.8290672302246,2,117,1,5,0.0039103968191326,0.00281040019988321,0.0235915277153254,14.4718322753906,13.999436378479,14.0005311965942,0,0,,,5.68820762634277,,1,,,,,,1,1,1,13.9997663497925,0,0,13.9999877384731,,,,,,,,,,,,,,,,,,,,,,,,,,,,,,,,,
,3765465718.56959,13.9999718666077,0,,,5,,,,31.5000005066395,,,,,1.79082111363102E-6,9.17213857736819E-9,37.6334702330602,0.0135822424551943,8.95268987345604E-7,4.58534420520902E-9,7.08993128611795E-7,3.48192518259238E-9,5.46658305785325E-7,2.98355132402192E-9,2.00031626130673,28.9266147613525,2,57,1,5,0.00428000362041131,0.00461566278147849,0.0194613058120012,21.4202270507813,13.9997339248657,14.000524520874,0,0,,,5.62350845336914,,1,,,,,,1,1,1,13.9999208450317,0,0,14.0000448908125,,,,,,,,,,,,,,,,,,,,,,,,,,,,,,,,,
,3765465844.87181,14.00004529953,0,,,5,,,,31.5000005066395,,,,,2.69230927905589E-6,1.82774753917104E-8,43.3810326760219,0.0272875453101095,1.34614210157124E-6,9.13865257851855E-9,9.78378887679831E-7,7.6722757223493E-9,9.24593591674203E-7,4.96499307060073E-9,2.00001862798392,14.2605514526367,2,28,1,5,0.00601629234738531,0.0073174448661985,0.0149303749203682,20.8445434570313,13.9996356964111,14.0004739761353,0,0,,,5.59572982788086,,1,,,,,,1,1,1,14.0000696182251,0,0,14.0000128064837,,,,,,,,,,,,,,,,,,,,,,,,,,,,,,,,,
,3765466007.18588,13.9999203681946,0,,,5,,,,31.5000005066395,,,,,1.43999792740112E-5,2.47031343785872E-7,43.1644143742385,0.0448138505534483,2.05715830755443E-6,3.52905078143131E-8,1.50047820585224E-6,2.60830575413487E-8,1.40729011085229E-6,2.37717069451646E-8,6.99993735101995,7.01553535461426,2,14,1,5,0.0343924557535397,0.0372866268064295,0.0125724030658603,13.3533020019531,13.9997797012329,14.000506401062,0,0,,,5.55075740814209,,1,,,,,,1,1,1,13.9998350143433,0,0,14.0000207062924,,,,,,,,,,,,,,,,,,,,,,,,,,,,,,,,,
,3765466209.39317,13.9998955726624,0,,,5,,,,31.5000005066395,,,,,2.03202009366649E-5,3.07404459606899E-7,39.5134036956057,0.0293076722506872,2.90288111214177E-6,4.3914851155378E-8,2.23950240931522E-6,3.91790822290428E-8,1.84698340812817E-6,1.98371789246582E-8,7.00001142026535,3.46004295349121,2,6,1,5,0.0534965763217755,0.0476323414437034,0.0118871992453933,6.91925048828125,13.9996128082275,14.0004596710205,0,0,,,5.50383138656616,,1,,,,,,1,1,1,13.9999742507935,0,0,13.9999718385584,,,,,,,,,,,,,,,,,,,,,,,,,,,,,,,,,
,3765466427.20931,13.9997730255127,0,,,5,,,,31.5000005066395,,,,,2.76809554904806E-5,2.13799772346058E-7,32.0820367849859,0.00717674045310516,3.95442370476673E-6,3.05428361434175E-8,3.3505376594424E-6,1.66877055755606E-8,2.10032479142615E-6,2.55809562430151E-8,6.99999735918877,1.70109140872955,2,3,1,5,0.0816692068043637,0.0534380128419568,0.0117192501202226,3.62405395507812,13.9997634887695,14.0003747940063,0,0,,,5.45716381072998,,1,,,,,,1,1,1,13.9998178482056,0,0,14.0000041060978,,,,,,,,,,,,,,,,,,,,,,,,,,,,,,,,,
,3765466692.05516,13.9999742507935,0,,,5,,,,31.5000005066395,,,,,3.4916423584286E-5,0,24.5121077151787,0,4.98804959827745E-6,0,4.53849473371609E-6,0,2.06946958105384E-6,0,7.00001531587494,0.840704679489136,2.37895666432513,1,1,5,0.111487072099162,0.0522350955146768,0.0116833234205842,1.98684692382813,13.99964427948,14.0003118515015,0,0,,,5.40740346908569,,1,,,,,,1,1,1,13.9999513626099,0,0,13.9999904844496,,,,,,,,,,,,,,,,,,,,,,,,,,,,,,,,,
,3765467108.9133,13.9999885559082,0,,,5,,,,31.5000005066395,,,,,4.02308188341359E-5,1.85685620309455E-7,15.8105760532376,0.00334827141322323,5.74729264510242E-6,2.65266686294812E-8,5.5298594476168E-6,1.84887034345103E-8,1.56589502778816E-6,1.90218819754784E-8,6.99996003656065,0.410403162240982,4.87325679724084,2,1,5,0.136266758809501,0.0394357373886677,0.0116071188822389,1.07199096679688,13.9996843338013,14.0003452301025,0,0,,,5.3476448059082,,1,,,,,,1,1,1,13.9999294281006,0,0,14.0000106216108,,,,,,,,,,,,,,,,,,,,,,,,,,,,,,,,,
,3765467767.67933,14.0000734329224,0,,,5,,,,31.5000005066395,,,,,4.38185267996027E-5,2.30630991544329E-7,9.71163102903898,0.00349554438278467,6.25981699232382E-6,3.2947428981998E-8,6.17010909164745E-6,2.47635656205897E-8,1.05596523359227E-6,2.17324387558908E-8,6.99996930474736,0.200194045901299,9.99030710926367,2,1,5,0.15220274297089,0.0265999498073797,0.0115764103829861,0.75897216796875,13.9997282028198,14.000376701355,0,0,,,5.29346609115601,,1,,,,,,1,1,1,14.0001211166382,0,0,13.9999996388077,,,,,,,,,,,,,,,,,,,,,,,,,,,,,,,,,
,3765468946.55415,14.0001521110535,0,,,5,,,,31.5000005066395,,,,,4.48259718729588E-5,1.16153969022974E-7,5.05818132508508,0.00169846547331421,6.40368809371891E-6,1.65933666888172E-8,6.37875009398331E-6,1.25463158962206E-8,5.64595820162678E-7,1.08595476656162E-8,7.00002423867687,0.100097022950649,19.9806142185273,2,1,5,0.157411964738205,0.0143221126159764,0.0115809217095375,0.346099853515625,13.999605178833,14.0002593994141,0,0,,,5.23937129974365,,1,,,,,,1,1,1,14.000114440918,0,0,13.9999910844393,,,,,,,,,,,,,,,,,,,,,,,,,,,,,,,,,
,3765477640.96535,11.999972820282,0,,,5,,,,31.5000005066395,,,,,1.14846835873088E-6,1.0201614999131E-8,2.06824968684042,0.00729367449191432,5.74020471766691E-7,5.09890917765856E-9,5.73646524041325E-7,2.8977273515398E-9,2.07163573670699E-8,4.19547982931021E-9,2.0007445992234,624.001586914062,2,1248,1,5,0.00398190465032528,0.000733473650546059,0.0263328179717064,355.425079345703,11.9995985031128,12.0004367828369,0,0,,,4.94884252548218,,1,,,,,,1,1,1,12.0000791549683,0,0,11.9999591676812,,,,,,,,,,,,,,,,,,,,,,,,,,,,,,,,,
,3765477757.81225,11.999924659729,0,,,5,,,,31.5000005066395,,,,,1.17059811571712E-6,2.26279528795534E-8,3.26926833474783,0.0181385050541402,5.85141485371223E-7,1.13109305243847E-8,5.84189196012493E-7,3.7230935293556E-9,3.33697642292942E-8,1.06806237598339E-8,2.00053857910018,307.095123291016,2,614,1,5,0.00406462798417897,0.000635264323896767,0.0261191688477993,0.129608154296875,11.9996023178101,12.0004281997681,0,0,,,4.94959449768066,,1,,,,,,1,1,1,11.9998435974121,0,0,11.9999796390533,,,,,,,,,,,,,,,,,,,,,,,,,,,,,,,,,
,3765477872.80346,11.999945640564,0,,,5,,,,31.5000005066395,,,,,1.18833207745113E-6,1.50402312605084E-8,3.26373791977271,0.0106403236137151,5.93960136795904E-7,7.517509614059E-9,5.92996762272488E-7,4.03208334974696E-9,3.38154408067593E-8,6.34470288178752E-9,2.00069331901893,151.170669555664,2,302,1,5,0.00412223319532038,0.000652839554385756,0.0257411729544401,5.08416748046875,11.9996118545532,12.0003566741943,0,0,,,4.94980573654175,,1,,,,,,1,1,1,11.9999151229858,0,0,11.999995432402,,,,,,,,,,,,,,,,,,,,,,,,,,,,,,,,,
,3765477988.21032,12.0000171661377,0,,,5,,,,31.5000005066395,,,,,1.20666776260678E-6,1.70896645095146E-8,4.61854382539981,0.00775106858820622,6.03312090213299E-7,8.54452363424842E-9,6.01353057307394E-7,7.25217405266641E-9,4.85796116142348E-8,4.51828016462701E-9,2.00007223820123,74.4331207275391,2,148,1,5,0.00413857154656934,0.000914154836533716,0.0244678501039743,11.7928466796875,11.9996566772461,12.0003356933594,0,0,,,4.95054006576538,,1,,,,,,1,1,1,11.9999475479126,0,0,12.0000227627001,,,,,,,,,,,,,,,,,,,,,,,,,,,,,,,,,
,3765478103.10244,11.9999485015869,0,,,5,,,,31.5000005066395,,,,,1.24017234413174E-6,1.40449034737875E-8,7.73536009138771,0.00830208469019446,6.20003535068836E-7,7.02151587612229E-9,6.14361702183316E-7,4.85983305703758E-9,8.34510778137212E-8,5.06790961406792E-9,2.00026656943828,36.6577529907227,2,73,1,5,0.00415986476476075,0.00129932105752091,0.0210506543517113,19.568359375,11.9996509552002,12.000452041626,0,0,,,4.9509015083313,,1,,,,,,1,1,1,12.0000114440918,0,0,12.0000572957491,,,,,,,,,,,,,,,,,,,,,,,,,,,,,,,,,
,3765478218.12622,12.0001091957092,0,,,5,,,,31.5000005066395,,,,,1.31557760473791E-6,1.52636818927668E-8,13.1133033835768,0.00687289182875415,6.57830141298493E-7,7.63232057165825E-9,6.40676112148458E-7,6.83415998497138E-9,1.49246822824243E-7,3.39802510414118E-9,1.99987431731402,18.0577392578125,2,36,1,5,0.00431033399501866,0.00168285793582125,0.0162766650319099,22.1171569824219,11.9997138977051,12.0004405975342,0,0,,,4.95086574554443,,1,,,,,,1,1,1,11.9999656677246,0,0,12.0000224113464,,,,,,,,,,,,,,,,,,,,,,,,,,,,,,,,,
,3765478343.48026,12.0000262260437,0,,,5,,,,31.5000005066395,,,,,4.8132066790939E-6,1.89680955806212E-7,23.7862099963963,0.0333262713382175,6.87606293807104E-7,2.7097489828185E-8,6.29198792193977E-7,2.01669085922944E-8,2.77328857468498E-7,1.80988881652611E-8,6.99994564105045,8.89725303649902,2,17,1,5,0.0148434086194397,0.00818228703242787,0.0130946738645434,16.1132507324219,11.9996814727783,12.0015630722046,0,0,,,4.95238971710205,,1,,,,,,1,1,1,12.000129699707,0,0,12.0000488313578,,,,,,,,,,,,,,,,,,,,,,,,,,,,,,,,,
,3765478531.83684,12.0000510215759,0,,,5,,,,31.5000005066395,,,,,6.27277810920905E-6,3.24429386670623E-7,34.9614111927501,0.0756194976209724,8.96104821669617E-7,4.63467274986265E-8,7.3439209958817E-7,4.25072428398848E-8,5.13490112350778E-7,1.84703398989569E-8,7.00004950037168,4.372145652771,2,8,1,5,0.0175019414132874,0.0135074691620337,0.0119994934648275,8.69729614257812,11.9996404647827,12.0003900527954,0,0,,,4.95190572738647,,1,,,,,,1,1,1,12.0001106262207,0,0,11.9999950470463,,,,,,,,,,,,,,,,,,,,,,,,,,,,,,,,,
,3765478730.16954,12.0001320838928,0,,,5,,,,31.5000005066395,,,,,8.9073069014966E-6,3.02208063612408E-7,40.7403389591456,0.0694931022778284,1.27247019598099E-6,4.3172505245924E-8,9.6411890662224E-7,3.94450623351005E-8,8.3045477514037E-7,1.75485687903424E-8,7.000012204317,2.14912533760071,2,4,1,5,0.0232913480064096,0.0210651212723678,0.0117581794038415,4.44244384765625,11.999662399292,12.0004301071167,0,0,,,4.9524073600769,,1,,,,,,1,1,1,12.0001630783081,0,0,12.0000137384387,,,,,,,,,,,,,,,,,,,,,,,,,,,,,,,,,
,3765478957.32087,11.9999418258667,0,,,5,,,,31.5000005066395,,,,,1.36521124814771E-5,2.51982954180269E-7,41.4762105958369,0.034354020559955,1.95029067139919E-6,3.59973597900078E-8,1.46121779772172E-6,2.92091449471247E-8,1.29169510743363E-6,2.10389106968285E-8,7.00003988209755,1.06037449836731,2,2,1,5,0.035659104726823,0.0323365423704351,0.0116738602519035,2.45065307617187,11.9996671676636,12.0003089904785,0,0,,,4.95182180404663,,1,,,,,,1,1,1,11.9999408721924,0,0,12.0000064611435,,,,,,,,,,,,,,,,,,,,,,,,,,,,,,,,,
,3765479314.74311,11.999990940094,0,,,5,,,,31.5000005066395,,,,,1.96529228329768E-5,2.44192840119341E-7,40.3461360287489,0.019452844314795,2.80754755420008E-6,3.48845317745737E-8,2.13976470609605E-6,2.61143681229882E-8,1.81761664595165E-6,2.31294257314855E-8,7.00003203991189,0.520422518253326,3.84303124836435,2,1,5,0.0525032661566174,0.045228857289848,0.0116122849285603,1.33779907226562,11.9996576309204,12.0005149841309,0,0,,,4.95080137252808,,1,,,,,,1,1,1,12.0000791549683,0,0,12.0000280900435,,,,,,,,,,,,,,,,,,,,,,,,,,,,,,,,,
,3765479841.25854,12.0000729560852,0,,,5,,,,31.5000005066395,,,,,2.81301500102679E-5,1.54945540856352E-7,36.1946937344262,0.00622668133654831,4.01858912836578E-6,2.21350567183898E-8,3.24306172849547E-6,1.50635798549836E-8,2.37310117942485E-6,1.62187945877264E-8,7.00000649773007,0.260255664587021,7.68475108187805,2,1,5,0.0798038149548687,0.0589073992176834,0.0116010690107942,0.60650634765625,11.9997034072876,12.0005292892456,0,0,,,4.94999980926514,,1,,,,,,1,1,1,12.0001487731934,0,0,11.9999972369831,,,,,,,,,,,,,,,,,,,,,,,,,,,,,,,,,
,3765480771.84918,11.9999113082886,0,,,5,,,,31.5000005066395,,,,,3.66423731528622E-5,1.69099232869369E-7,28.3766849002431,0.0037849543740484,5.23459883514655E-6,2.41569137378056E-8,4.60562013619973E-6,2.1203175748622E-8,2.48782799364208E-6,1.15750515985385E-8,7.00003463624282,0.13012783229351,15.3695021637561,2,1,5,0.113509901557806,0.0617221151102228,0.0115982480347157,0.243133544921875,11.9995422363281,12.0004224777222,0,0,,,4.94904613494873,,1,,,,,,1,1,1,11.9999370574951,0,0,11.9999956183963,,,,,,,,,,,,,,,,,,,,,,,,,,,,,,,,,
,3765485462.50291,15.9998354911804,0,,,5,,,,31.5000005066395,,,,,1.06437691020337E-6,2.30355161268123E-8,15.1303552597696,0.0156991534659428,5.32334692145298E-7,1.15209229627423E-8,5.1388103338781E-7,9.60442784477538E-9,1.3894786067337E-7,6.36291063020259E-9,1.99945058232811,789.141418457031,2,1578,1,5,0.00340275806185426,0.00160394548652427,0.026463944464922,353.825347900391,15.9996995925903,16.0004138946533,0,0,,,5.39125108718872,,1,,,,,,1,1,1,15.9998321533203,0,0,16.0000152343359,,,,,,,,,,,,,,,,,,,,,,,,,,,,,,,,,
,3765485578.98176,16.0000548362732,0,,,5,,,,31.5000005066395,,,,,1.16384675494759E-6,1.30148513686967E-8,25.7540737436891,0.0100642968921992,5.81816460476329E-7,6.50623007261948E-9,5.2402308841236E-7,3.49724099988031E-9,2.52804660740215E-7,5.48637723334937E-9,2.00036752826614,389.068725585937,2,778,1,5,0.00347446819188139,0.00216284529619416,0.0261870883405209,358.626556396484,15.9997358322144,16.000509262085,0,0,,,5.40049934387207,,1,,,,,,1,1,1,15.9999170303345,0,0,16.0000544096294,,,,,,,,,,,,,,,,,,,,,,,,,,,,,,,,,
,3765485690.89374,15.9999394416809,0,,,5,,,,31.5000005066395,,,,,1.50484111275237E-6,2.86245119829583E-8,36.1853379187079,0.0219582721400604,7.52155706587782E-7,1.43072181201201E-8,6.07073462399599E-7,6.41785729152175E-9,4.44072086718732E-7,1.2787008959188E-8,2.00070424191715,191.482849121094,2,382,1,5,0.00395253319665143,0.00350948519849039,0.0259175263345242,3.32968139648438,15.9997081756592,16.0005741119385,0,0,,,5.40312480926514,,1,,,,,,1,1,1,15.9998159408569,0,0,16.0000037896006,,,,,,,,,,,,,,,,,,,,,,,,,,,,,,,,,
,3765485807.00556,15.9999470710754,0,,,5,,,,31.5000005066395,,,,,2.27053326192362E-6,1.65841600800901E-8,42.7882552618477,0.0251397564135642,1.1355646128781E-6,8.29425652425851E-9,8.33355807608814E-7,6.43091983552057E-9,7.71378692955441E-7,5.23812574871136E-9,1.99947518280702,94.2627868652344,2,188,1,5,0.0051481261370678,0.0060901095004094,0.0250594113022089,9.31192016601562,15.9995594024658,16.0004539489746,0,0,,,5.40792894363403,,1,,,,,,1,1,1,15.9999313354492,0,0,16.00002293709,,,,,,,,,,,,,,,,,,,,,,,,,,,,,,,,,
,3765485922.47549,16.0000638961792,0,,,5,,,,31.5000005066395,,,,,3.29289808274605E-6,1.19991352876457E-8,43.4890071605902,0.0130219326613717,1.64608142045778E-6,5.99822805389759E-9,1.19424264863074E-6,3.6101508749159E-9,1.13285856971105E-6,4.79015140125111E-9,2.00044666188522,46.4145660400391,2,92,1,5,0.00699894295054273,0.00921198630353118,0.0224394537508488,17.1334838867187,15.9995718002319,16.0004329681396,0,0,,,5.40789127349854,,1,,,,,,1,1,1,15.9999961853027,0,0,16.0000165136237,,,,,,,,,,,,,,,,,,,,,,,,,,,,,,,,,
,3765486037.60401,15.9998183250427,0,,,5,,,,31.5000005066395,,,,,4.82407691525955E-6,2.41367409580501E-8,39.733606224994,0.0159119863716511,2.41174901064088E-6,1.20669222626896E-8,1.85469470483112E-6,9.50460713332992E-9,1.54163576833138E-6,7.4345851353555E-9,2.00024003077237,22.8596096038818,2,45,1,5,0.0111793790305104,0.0127559604877397,0.0178426969796419,22.2962036132813,15.9995927810669,16.0002365112305,0,0,,,5.40861034393311,,1,,,,,,1,1,1,15.9996328353882,0,0,15.9999483059614,,,,,,,,,,,,,,,,,,,,,,,,,,,,,,,,,
,3765486154.716,16.0000782012939,0,,,5,,,,31.5000005066395,,,,,6.58507731165359E-6,3.04948865198563E-8,33.1434673719954,0.00703614598902699,3.29237755111984E-6,1.52466971988686E-8,2.75672147256017E-6,1.25722897678063E-8,1.80006573820056E-6,8.62550320087469E-9,2.00009786526876,11.2610988616943,2,22,1,5,0.0179489586958523,0.0146673039614825,0.0138768199831247,18.6799011230469,15.9997119903564,16.000280380249,0,0,,,5.4054651260376,,1,,,,,,1,1,1,16.0000400543213,0,0,16.0000133514404,,,,,,,,,,,,,,,,,,,,,,,,,,,,,,,,,
,3765486329.17595,15.9998369216919,0,,,5,,,,31.5000005066395,,,,,3.00381446159224E-5,1.82955146162658E-7,24.933329433126,0.00487575408519615,4.29119532657635E-6,2.61366431989987E-8,3.89125137687905E-6,2.43902234497013E-8,1.80901079398869E-6,9.39367434955083E-9,6.99994811000314,5.53858041763306,2,11,1,5,0.0932032327358898,0.0501620327707702,0.0122178578749299,10.8295288085938,15.9996604919434,16.0005931854248,0,0,,,5.40765428543091,,1,,,,,,1,1,1,15.9998788833618,0,0,15.9999937935481,,,,,,,,,,,,,,,,,,,,,,,,,,,,,,,,,
,3765486524.32473,15.9999980926514,0,,,5,,,,31.5000005066395,,,,,3.47424516691086E-5,1.82217569776708E-7,17.0362856346189,0.00261379261756334,4.9631839861484E-6,2.60309586935331E-8,4.74539651522943E-6,2.44153186805315E-8,1.45410013190573E-6,9.02790253782783E-9,7.00003299617146,2.72965812683105,2,5,1,5,0.115966872811766,0.0394128187132788,0.0118155442178249,5.5291748046875,15.9996194839478,16.0007152557373,0,0,,,5.40829515457153,,1,,,,,,1,1,1,16.0002593994141,0,0,16.0000167615486,,,,,,,,,,,,,,,,,,,,,,,,,,,,,,,,,
,3765486740.48565,16.0001010894775,0,,,5,,,,31.5000005066395,,,,,3.82895061101192E-5,1.4454811107291E-7,10.8356939712588,0.00203211609640865,5.46989811046804E-6,2.06496118637706E-8,5.3723716093254E-6,1.77055535531972E-8,1.02830376359141E-6,1.0626374899242E-8,7.00004009889005,1.34084260463715,2,2,1,5,0.132186102037794,0.0274528718882793,0.011748731136322,2.99057006835937,15.999623298645,16.0003662109375,0,0,,,5.41263866424561,,1,,,,,,1,1,1,16.0001430511475,0,0,16.0000374317169,,,,,,,,,,,,,,,,,,,,,,,,,,,,,,,,,
,3765487030.88007,15.9998087882996,0,,,5,,,,31.5000005066395,,,,,3.91036566358882E-5,0,6.12148975893085,0,5.58622054560569E-6,0,5.5543680168475E-6,0,5.9569784082936E-7,0,7.00002019552351,0.660553634166718,3.02776322247168,1,1,5,0.136967925644748,0.0158574853064283,0.0116505157202482,1.66018676757813,15.9996738433838,16.0005130767822,0,0,,,5.41442823410034,,1,,,,,,1,1,1,15.9997472763062,0,0,16.0000350108513,,,,,,,,,,,,,,,,,,,,,,,,,,,,,,,,,
,3765487465.00755,16.0000305175781,0,,,5,,,,31.5000005066395,,,,,4.00935984223002E-5,2.08755179461744E-7,2.73271900920136,0.00478194254778413,5.72763089870813E-6,2.98220330227434E-8,5.7211175041217E-6,1.17262978291371E-8,2.7307547650506E-7,2.74198394020091E-8,7.00003179872211,0.330276817083359,6.05552644494336,2,1,5,0.141179269783781,0.00743282510645654,0.0116287609562278,0.89886474609375,15.9994239807129,16.000452041626,0,0,,,5.4176664352417,,1,,,,,,1,1,1,16.0000476837158,0,0,16.000026457491,,,,,,,,,,,,,,,,,,,,,,,,,,,,,,,,,
,3765488187.75276,15.9999580383301,0,,,5,,,,31.5000005066395,,,,,4.03337108648426E-5,1.45835746218166E-7,1.02005784993213,0.00256091657499439,5.76197561019431E-6,2.08337391919974E-8,5.76106247666767E-6,1.47073624850271E-8,1.02577153430063E-7,1.47559539662533E-8,6.9999794503612,0.160146817564964,12.4885403931845,2,1,5,0.142190762379307,0.00297164994861361,0.0115676587447524,0.435638427734375,15.9995975494385,16.0003395080566,0,0,,,5.42092609405518,,1,,,,,,1,1,1,16.0000915527344,0,0,15.999989565681,,,,,,,,,,,,,,,,,,,,,,,,,,,,,,,,,
,3765493442.5541,18.0000257492065,0,,,5,,,,31.5000005066395,,,,,1.20718631171087E-6,6.16692993589806E-8,28.967660085978,0.0989743234488223,6.03639367843851E-7,3.08370104260628E-8,5.28119985884167E-7,2.77318632898664E-8,2.92352128298446E-7,1.34857321080194E-8,1.99984688875219,999.040954589844,2,1998,1,5,0.0032135117205453,0.00283267230622705,0.0268111657351255,352.169586181641,17.9990711212158,18.0005512237549,0,0,,,5.57924509048462,,1,,,,,,1,1,1,17.9998626708984,0,0,18.0000855372502,,,,,,,,,,,,,,,,,,,,,,,,,,,,,,,,,
,3765493562.16336,17.9998912811279,0,,,5,,,,31.5000005066395,,,,,1.77101179817723E-6,1.61421642677441E-8,41.3098980881806,0.0179589611830003,8.85817139733216E-7,8.07391898544871E-9,6.65381636825871E-7,4.038600666123E-9,5.84755745948734E-7,6.99127116075324E-9,1.99929728014815,491.971038818359,2,983,1,5,0.00414410925347493,0.00465677351536668,0.0262953788042068,357.134002685547,17.9996585845947,18.0003490447998,0,0,,,5.58326864242554,,1,,,,,,1,1,1,17.9999904632568,0,0,17.9999855944985,,,,,,,,,,,,,,,,,,,,,,,,,,,,,,,,,
,3765493679.34399,17.9999361038208,0,,,5,,,,31.5000005066395,,,,,2.65532765445749E-6,1.46011414548958E-8,43.9046027948079,0.0142115926826071,1.32815476178644E-6,7.30327028315434E-9,9.56929403879797E-7,4.43919954853822E-9,9.21021816921979E-7,5.79924686464228E-9,1.99926072687939,242.323211669922,2,484,1,5,0.00608756242835799,0.00706857746216318,0.0260581709444523,1.73007202148438,17.9997463226318,18.000337600708,0,0,,,5.58806800842285,,1,,,,,,1,1,1,17.9997882843018,0,0,18.0000086952658,,,,,,,,,,,,,,,,,,,,,,,,,,,,,,,,,
,3765493795.25312,17.999927520752,0,,,5,,,,31.5000005066395,,,,,3.89269545595475E-6,1.47049996284919E-8,41.8497766015787,0.0120246708882821,1.94655517315501E-6,7.3532834566589E-9,1.44998244301191E-6,6.1817149986348E-9,1.29870241283126E-6,3.98210713939579E-9,1.9997868591854,119.384170532227,2,238,1,5,0.0091265872804823,0.0101790447292167,0.0255004465579987,7.08468627929688,17.9996681213379,18.0003528594971,0,0,,,5.59197616577148,,1,,,,,,1,1,1,17.9997863769531,0,0,17.9999750036942,,,,,,,,,,,,,,,,,,,,,,,,,,,,,,,,,
,3765493913.01804,18.0000114440918,0,,,5,,,,31.5000005066395,,,,,5.57314880020332E-6,8.86933490031507E-9,35.7882257051797,0.00275937910718928,2.78731579129969E-6,4.43584733016132E-9,2.2610260029214E-6,2.72175572609985E-9,1.62999715783246E-6,3.50268287230546E-9,1.99946802497202,58.8290672302246,2,117,1,5,0.013980676839355,0.0137046975959266,0.0235984772443771,14.4484252929687,17.9997253417969,18.000467300415,0,0,,,5.58925676345825,,1,,,,,,1,1,1,17.9999828338623,0,0,18.000045625787,,,,,,,,,,,,,,,,,,,,,,,,,,,,,,,,,
,3765494028.17189,17.9998741149902,0,,,5,,,,31.5000005066395,,,,,7.1594429839073E-6,1.17806216594948E-8,27.811241915467,0.00202966280228374,3.57972630974961E-6,5.89031875726796E-9,3.16623015197481E-6,4.28964288256631E-9,1.67015780016116E-6,4.03668415934055E-9,1.99999730828809,28.9266147613525,2,57,1,5,0.0200082808708912,0.0152628068952116,0.0194885153323412,21.3901977539062,17.9997138977051,18.000373840332,0,0,,,5.58667898178101,,1,,,,,,1,1,1,17.9999332427979,0,0,17.999960246839,,,,,,,,,,,,,,,,,,,,,,,,,,,,,,,,,
,3765494144.92438,17.9999513626099,0,,,5,,,,31.5000005066395,,,,,8.71575355344615E-6,2.31598502414881E-8,19.5031426729387,0.00194739675556417,4.35814721519294E-6,1.15806437407031E-8,4.10809058851143E-6,1.0714370156567E-8,1.45500476489863E-6,4.39472201591323E-9,1.99987589291664,14.2605514526367,2,28,1,5,0.0273984758448468,0.0137769374492948,0.0149273397400975,20.8102416992187,17.9997730255127,18.0003967285156,0,0,,,5.58542919158936,,1,,,,,,1,1,1,17.999942779541,0,0,17.9999704862896,,,,,,,,,,,,,,,,,,,,,,,,,,,,,,,,,
,3765494296.05395,17.999960899353,0,,,5,,,,31.4900018274784,,,,,3.34489216044441E-5,2.39739632170408E-7,11.9032464096796,0.00399512066156335,4.77846099519029E-6,3.4248831543058E-8,4.67571118142834E-6,2.95844654454643E-8,9.85603586854771E-7,1.72551982420051E-8,6.9999360961849,7.01553535461426,2,14,1,5,0.113235544500362,0.0325781390898331,0.0125794541090727,13.3558654785156,17.9996910095215,18.0004081726074,0,0,,,5.58468246459961,,1,,,,,,1,1,1,18.0000915527344,0,0,17.9999743870326,,,,,,,,,,,,,,,,,,,,,,,,,,,,,,,,,
,3765494487.97322,17.9999732971191,0,,,5,,,,31.5000005066395,,,,,3.49528133081272E-5,2.95508660332448E-7,6.52078595245549,0.00631023758256792,4.99324427505208E-6,4.22153980403693E-8,4.96094159000552E-6,2.8046473893545E-8,5.67051083143259E-7,3.15521018926713E-8,7.00002070452735,3.46004295349121,2,6,1,5,0.121795373460257,0.0186122483519087,0.0118985408917069,6.923095703125,17.99951171875,18.0005493164062,0,0,,,5.57956552505493,,1,,,,,,1,1,1,18.0001411437988,0,0,18.0000063478947,,,,,,,,,,,,,,,,,,,,,,,,,,,,,,,,,
,3765494690.89389,17.9998903274536,0,,,5,,,,31.5000005066395,,,,,3.5193475729237E-5,2.64825086585002E-7,3.79546935422419,0.005082378607758,5.02761554476144E-6,3.7831975795771E-8,5.01658850454809E-6,2.79177136282058E-8,3.32803007742965E-7,2.55315424208036E-8,7.00003319981519,1.70109140872955,2,3,1,5,0.123630965352616,0.0106227855970361,0.0117588052526116,3.66354370117188,17.99951171875,18.0005855560303,0,0,,,5.57603597640991,,1,,,,,,1,1,1,17.9998950958252,0,0,17.99996378724,,,,,,,,,,,,,,,,,,,,,,,,,,,,,,,,,
,3765494935.04057,17.9999294281006,0,,,5,,,,31.5000005066395,,,,,3.5406034060821E-5,0,1.20997527816941,0,5.05802064956081E-6,0,5.05689282332953E-6,0,1.06807606198291E-7,0,6.99997815625671,0.840704679489136,2.37895666432513,1,1,5,0.124781942525799,0.00392655497427749,0.0116656944155693,2.04489135742187,17.9996929168701,18.0006713867187,0,0,,,5.57474184036255,,1,,,,,,1,1,1,18.0000305175781,0,0,17.9999949486701,,,,,,,,,,,,,,,,,,,,,,,,,,,,,,,,,
,3765495346.85455,18.0000667572021,0,,,5,,,,31.5000005066395,,,,,3.59409577808884E-5,1.63939555652667E-7,0.205337604104802,0.00157362469444096,5.13442534699191E-6,2.34199493249242E-8,5.13439237439912E-6,2.19826244642875E-8,1.84008028397076E-8,8.07825773568341E-9,6.99999617327088,0.410403162240982,4.87325679724084,2,1,5,0.126726340946967,0.00118387001316836,0.0116067035123706,1.10113525390625,17.9994525909424,18.0004558563232,0,0,,,5.58733701705933,,1,,,,,,1,1,1,17.9999618530273,0,0,17.9999746271082,,,,,,,,,,,,,,,,,,,,,,,,,,,,,,,,,
,3765495943.47263,18.0001230239868,0,,,5,,,,31.5000005066395,,,,,3.59256769120939E-5,1.69102383161817E-7,0.686099364129669,0.00428744645491166,5.1322131761457E-6,2.41573591251821E-8,5.13184521812767E-6,9.96546250567286E-9,6.14552079460676E-8,2.20060799996512E-8,7.0000359842952,0.200194045901299,9.99030710926367,2,1,5,0.126663262473358,0.00196264470344997,0.0115650072693825,0.80950927734375,17.9996585845947,18.0005168914795,0,0,,,5.60368585586548,,1,,,,,,1,1,1,17.9999732971191,0,0,17.9999916655544,,,,,,,,,,,,,,,,,,,,,,,,,,,,,,,,,
,3765497151.88017,18.0000076293945,0,,,5,,,,31.5000005066395,,,,,3.56230675038862E-5,1.440184095238E-7,0.00999216118136828,0.00145840745772992,5.08902065880419E-6,2.05741030368815E-8,5.08902058141545E-6,1.91887962908334E-8,8.8750541230901E-10,7.42184698583283E-9,6.99998484821574,0.100097022950649,19.9806142185273,2,1,5,0.125611106170343,0.00033004042387818,0.0115874633193016,0.396697998046875,17.999547958374,18.0003967285156,0,0,,,5.61164379119873,,1,,,,,,1,1,1,18.0000038146973,0,0,17.9999997694414,,,,,,,,,,,,,,,,,,,,,,,,,,,,,,,,,
,3765501638.24469,19.999852180481,0,,,5,,,,31.5000005066395,,,,,2.69293504431447E-6,1.80148956273622E-8,43.3890988466705,0.0189996245782935,1.34696936288363E-6,9.01080497163656E-9,9.78849887805868E-7,4.80966929492179E-9,9.25299606446245E-7,7.61982201303657E-9,1.99925485947903,624.001586914062,2,1248,1,5,0.00588447044713105,0.00744998480667547,0.0263750553131104,355.590881347656,19.9997653961182,20.0002117156982,0,0,,,5.74514102935791,,1,,,,,,1,1,1,19.9998207092285,0,0,19.999949822059,,,,,,,,,,,,,,,,,,,,,,,,,,,,,,,,,
,3765501753.16542,19.9999628067017,0,,,5,,,,31.5000005066395,,,,,3.87578274215722E-6,2.1221670968168E-8,40.6888339473118,0.0113177471481721,1.93740848632655E-6,1.06081914707309E-8,1.46906208205472E-6,6.70622315234156E-9,1.26309470823022E-6,8.21950712090979E-9,2.00049848522443,307.095123291016,2,614,1,5,0.00941532936129751,0.00984298612618562,0.0261456910520792,0.238006591796875,19.999683380127,20.0005130767822,0,0,,,5.74931192398071,,1,,,,,,1,1,1,19.999942779541,0,0,19.9999994754791,,,,,,,,,,,,,,,,,,,,,,,,,,,,,,,,,
,3765501868.93981,19.9999952316284,0,,,5,,,,31.5000005066395,,,,,5.60951427844269E-6,1.4745274230485E-8,33.9697643027121,0.0029411816035817,2.80572002780242E-6,7.37516818218994E-9,2.32687494573131E-6,3.66710105885978E-9,1.5677110260949E-6,6.39886517592739E-9,1.99931362461576,151.170669555664,2,302,1,5,0.0151604328926337,0.0125820894355247,0.0257791317999363,5.13912963867188,19.9996948242187,20.0003280639648,0,0,,,5.7514967918396,,1,,,,,,1,1,1,19.9999961853027,0,0,19.9999951582689,,,,,,,,,,,,,,,,,,,,,,,,,,,,,,,,,
,3765501987.16917,19.9998073577881,0,,,5,,,,31.5000005066395,,,,,7.05860823790809E-6,1.07197836402763E-8,25.2336902339387,0.00146398019814202,3.52988959034636E-6,5.36078096519929E-9,3.19305529629641E-6,3.54815995741005E-9,1.5048316832221E-6,4.01852379282181E-9,1.99966827778754,74.4331207275391,2,148,1,5,0.0207780070651442,0.0135262315231334,0.0244655385613441,11.8045959472656,19.9996204376221,20.000467300415,0,0,,,5.74281930923462,,1,,,,,,1,1,1,19.9997100830078,0,0,19.9999963358829,,,,,,,,,,,,,,,,,,,,,,,,,,,,,,,,,
,3765502102.88657,19.9998893737793,0,,,5,,,,31.5000005066395,,,,,8.05128620306514E-6,1.02897759723364E-8,16.8825632634064,0.0010176945425649,4.02503596733238E-6,5.1441120511502E-9,3.8515650022316E-6,3.72302944216674E-9,1.16891469830096E-6,3.54978035483159E-9,2.00030167889436,36.6577529907227,2,73,1,5,0.025322529968357,0.0126196151102758,0.0210889875888824,19.5662536621094,19.9998111724854,20.0004901885986,0,0,,,5.73571062088013,,1,,,,,,1,1,1,19.9999618530273,0,0,20.0000482358431,,,,,,,,,,,,,,,,,,,,,,,,,,,,,,,,,
,3765502218.73348,19.9998836517334,0,,,5,,,,31.5000005066395,,,,,8.72881077055536E-6,8.93807422724543E-9,9.8565713617052,0.000762042962220289,4.36417553590857E-6,4.46880175387255E-9,4.29975751510177E-6,3.03847398675767E-9,7.47069889333481E-7,3.27686816140218E-9,2.00010533461233,18.0577392578125,2,36,1,5,0.0291873471173756,0.00952205270082153,0.016271248459816,22.0918579101562,19.9998321533203,20.0003070831299,0,0,,,5.73241376876831,,1,,,,,,1,1,1,19.9998245239258,0,0,19.9999948648306,,,,,,,,,,,,,,,,,,,,,,,,,,,,,,,,,
,3765502345.22119,19.9999122619629,0,,,5,,,,31.5000005066395,,,,,3.19612725132434E-5,1.56458706101568E-7,5.6792097016213,0.00375049534413425,4.56593993901021E-6,2.23514584627067E-8,4.54352822159066E-6,1.43165139538432E-8,4.51839381039077E-7,1.71646474947641E-8,6.99993274991959,8.89725303649902,2,17,1,5,0.110570578963699,0.0210073760299365,0.013101295568049,16.0896606445313,19.9988021850586,20.0005874633789,0,0,,,5.73268175125122,,1,,,,,,1,1,1,19.9999256134033,0,0,19.9999761743061,,,,,,,,,,,,,,,,,,,,,,,,,,,,,,,,,
,3765502535.30511,20.0001468658447,0,,,5,,,,31.5000005066395,,,,,3.19730111418859E-5,5.80252466861339E-7,2.84966336753615,0.00921168701097179,4.56754110218985E-6,8.28926302960621E-8,4.56189297073645E-6,7.16028367108981E-8,2.2707761611193E-7,4.17638831091183E-8,7.00004891615684,4.372145652771,2,8,1,5,0.112159678728836,0.010893984819401,0.0120296655222774,8.69818115234375,19.9996376037598,20.0006294250488,0,0,,,5.73474836349487,,1,,,,,,1,1,1,20.0000228881836,0,0,20.0000032394651,,,,,,,,,,,,,,,,,,,,,,,,,,,,,,,,,
,3765502732.76263,19.999924659729,0,,,5,,,,31.5000005066395,,,,,3.25302449708356E-5,2.54491385047651E-7,1.04596117166549,0.00543367012626074,4.64718408232553E-6,3.63559608832556E-8,4.64640973878477E-6,2.61571245542537E-8,8.48318003218092E-8,2.52499648870661E-8,6.99999061680313,2.14912533760071,2,4,1,5,0.114587642114152,0.004867111262643,0.0117601715028286,4.498291015625,19.9995231628418,20.000560760498,0,0,,,5.72967576980591,,1,,,,,,1,1,1,19.9997043609619,0,0,20.0000167675872,,,,,,,,,,,,,,,,,,,,,,,,,,,,,,,,,
,3765502966.80535,19.9999599456787,0,,,5,,,,31.5000005066395,,,,,3.20340793225625E-5,3.1683419905695E-7,0.0498689733620705,0.00520338488059867,4.576288798888E-6,4.52619468675582E-8,4.5762870654872E-6,3.84921345939708E-8,3.98309958140062E-9,2.38117493822124E-8,7.00001261510125,1.06037449836731,2,2,1,5,0.112942275263039,0.00152987073447727,0.0117006786167622,2.46795654296875,19.9995021820068,20.0004043579102,0,0,,,5.73797750473022,,1,,,,,,1,1,1,20.0000820159912,0,0,20.0000126013595,,,,,,,,,,,,,,,,,,,,,,,,,,,,,,,,,
,3765503300.25561,19.9999542236328,0,,,5,,,,31.5000005066395,,,,,3.24178726635849E-5,4.15434868199042E-7,0.0178821090751347,0.0109536690245047,4.6311065722209E-6,5.93476064395631E-8,4.63110634666874E-6,3.08032618476771E-8,1.44537612058614E-9,5.07276793244941E-8,7.00002734941134,0.520422518253326,3.84303124836435,2,1,5,0.114305734708953,0.000827740528313625,0.0116432216018438,1.3641357421875,19.9995384216309,20.0004482269287,0,0,,,5.73899698257446,,1,,,,,,1,1,1,20.0001373291016,0,0,19.9999949715354,,,,,,,,,,,,,,,,,,,,,,,,,,,,,,,,,
,3765503829.14149,20.0001201629639,0,,,5,,,,31.5000005066395,,,,,3.2006734709774E-5,3.24936753430945E-7,-0.0934908950441069,0.00870847557987116,4.57237295144611E-6,4.64193562945571E-8,4.57236686442336E-6,2.38592307214792E-8,-7.46084709284398E-9,3.98182589797728E-8,7.00002713025656,0.260255664587021,7.68475108187805,2,1,5,0.112859330410426,0.00028517927753935,0.011583493091166,0.677001953125,19.9995441436768,20.0005531311035,0,0,,,5.74078845977783,,1,,,,,,1,1,1,20.0001926422119,0,0,20.0000191193361,,,,,,,,,,,,,,,,,,,,,,,,,,,,,,,,,
,3765504775.66044,20.0001287460327,0,,,5,,,,31.5000005066395,,,,,3.22331200149738E-5,2.6508853011214E-7,-0.0945334729037621,0.00555719688560105,4.60470475946771E-6,3.7869570668946E-8,4.60469849191988E-6,2.79158345463645E-8,-7.59739266679961E-9,2.55892665825009E-8,7.0000405452053,0.13012783229351,15.3695021637561,2,1,5,0.113658051902091,0.000127624386518555,0.0116037297993898,0.364227294921875,19.9995574951172,20.0004062652588,0,0,,,5.73291730880737,,1,,,,,,1,1,1,20.0001220703125,0,0,20.0000038350423,,,,,,,,,,,,,,,,,,,,,,,,,,,,,,,,,
,3765509799.57737,21.999906539917,0,,,5,,,,31.5000005066395,,,,,3.69036022946804E-6,2.37535810773655E-8,41.077927120888,0.0249930036318656,1.84494417045123E-6,1.18752718463865E-8,1.39074951688687E-6,9.11048660936941E-9,1.2122849390143E-6,7.6171592582852E-9,2.00025577389991,789.141418457031,2,1578,1,5,0.00818824544098811,0.0101516560514982,0.0266298092901707,354.023315429687,21.9997100830078,22.0003223419189,0,0,,,5.77273321151733,,1,,,,,,1,1,1,21.9999160766602,0,0,22.0000204917712,,,,,,,,,,,,,,,,,,,,,,,,,,,,,,,,,
,3765509918.47265,21.99973487854,0,,,5,,,,31.5000005066395,,,,,5.11380332316911E-6,1.163968616006E-8,33.542291923635,0.0026812198153889,2.55660374449134E-6,5.8191649817052E-9,2.13087346626202E-6,3.17910937798324E-9,1.4126574167602E-6,4.87400704217003E-9,2.0002330569169,389.068725585937,2,778,1,5,0.013845004589685,0.011475414483253,0.0262581948190928,358.805358886719,21.9996929168701,22.000373840332,0,0,,,5.77737236022949,,1,,,,,,1,1,1,21.9996929168701,0,0,22.0000216835424,,,,,,,,,,,,,,,,,,,,,,,,,,,,,,,,,
,3765510041.30789,21.9999599456787,0,,,5,,,,31.5000005066395,,,,,6.447789233897E-6,1.82308841839212E-8,24.4935593173092,0.00246455491979151,3.22289710037324E-6,9.11262165095433E-9,2.9328617618253E-6,5.07245283438462E-9,1.33618397147144E-6,7.57034316239264E-9,2.00061901856882,191.482849121094,2,382,1,5,0.0196347694082638,0.0112869615261459,0.0259534381330013,3.422607421875,21.9997138977051,22.0003433227539,0,0,,,5.78127145767212,,1,,,,,,1,1,1,21.9998664855957,0,0,22.0000040473008,,,,,,,,,,,,,,,,,,,,,,,,,,,,,,,,,
,3765510160.47585,21.9999179840088,0,,,5,,,,31.5000005066395,,,,,7.44078836014372E-6,1.31825112430663E-8,15.7757667154447,0.00126190355313128,3.71937597151349E-6,6.58945170706618E-9,3.57927849178213E-6,5.1263353537315E-9,1.01119884085067E-6,4.1402366648345E-9,2.00054751580167,94.2627868652344,2,188,1,5,0.0240966418561475,0.0101144078580395,0.025066776201129,9.36590576171875,21.9997386932373,22.0004615783691,0,0,,,5.77983236312866,,1,,,,,,1,1,1,21.9998836517334,0,0,22.0000058150873,,,,,,,,,,,,,,,,,,,,,,,,,,,,,,,,,
,3765510276.37344,21.9999237060547,0,,,5,,,,31.5000005066395,,,,,8.10920105163134E-6,1.00182670169149E-8,9.09583117067351,0.00084653539792204,4.05455541605815E-6,5.00907777897276E-9,4.00357064545019E-6,3.78581825367581E-9,6.4096935088661E-7,3.28000615028901E-9,2.00002225139523,46.4145660400391,2,92,1,5,0.0270378289522272,0.0089817889937464,0.0224862359464169,17.1675109863281,21.9997730255127,22.0003433227539,0,0,,,5.77895164489746,,1,,,,,,1,1,1,21.999828338623,0,0,22.0000534057617,,,,,,,,,,,,,,,,,,,,,,,,,,,,,,,,,
,3765510392.30815,21.9998140335083,0,,,5,,,,31.5000005066395,,,,,8.23502549023312E-6,2.82489645850323E-8,4.76816999947846,0.00248537403051574,4.11721603992853E-6,1.41234644918598E-8,4.10296714458582E-6,9.79505729022114E-9,3.42240456249745E-7,1.01749251561921E-8,2.00014412903532,22.8596096038818,2,45,1,5,0.0281185503260207,0.00690706709771867,0.0178349856287241,22.3111572265625,21.9997329711914,22.0004367828369,0,0,,,5.78205490112305,,1,,,,,,1,1,1,21.9997806549072,0,0,22.00008837382,,,,,,,,,,,,,,,,,,,,,,,,,,,,,,,,,
,3765510510.22274,22.0000095367432,0,,,5,,,,31.5000005066395,,,,,8.51542676727975E-6,3.64195629500247E-8,2.68010027018759,0.00205127011553002,4.25791286840437E-6,1.82106346498604E-8,4.25325545911495E-6,1.60691786900931E-8,1.99097951853852E-7,8.56788833824034E-9,1.99990629927354,11.2610988616943,2,22,1,5,0.0296224372254212,0.00458057747354175,0.0138999633491039,18.7257690429687,21.9996509552002,22.0004062652588,0,0,,,5.78259563446045,,1,,,,,,1,1,1,22.0001735687256,0,0,21.9999425839155,,,,,,,,,,,,,,,,,,,,,,,,,,,,,,,,,
,3765510685.28112,21.999810218811,0,,,5,,,,31.5000005066395,,,,,2.92232766563969E-5,1.66080499818622E-7,1.31701806415061,0.00195906252525677,4.1747405013693E-6,2.37257100643669E-8,4.17363764598997E-6,2.23048438359918E-8,9.59533936266574E-8,8.08722817227394E-9,7.00002231200043,5.53858041763306,2,11,1,5,0.102631042205067,0.00838790752196537,0.0122275799512863,10.8701171875,21.9995250701904,22.0005378723145,0,0,,,5.77818918228149,,1,,,,,,1,1,1,21.9998912811279,0,0,22.0000348166814,,,,,,,,,,,,,,,,,,,,,,,,,,,,,,,,,
,3765510885.30698,22.0001878738403,0,,,5,,,,31.5000005066395,,,,,2.9452208008781E-5,2.25697089619295E-7,0.609235468424361,0.00257428002729077,4.20747511564534E-6,3.22425703350879E-8,4.20723726049381E-6,3.03790907520717E-8,4.47379334272225E-8,1.08025083610467E-8,6.9999720020361,2.72965812683105,2,5,1,5,0.103744240797034,0.00424601088962815,0.0118432780727744,5.58660888671875,21.9995918273926,22.0003833770752,0,0,,,5.78134870529175,,1,,,,,,1,1,1,22.0002136230469,0,0,22.0000288827079,,,,,,,,,,,,,,,,,,,,,,,,,,,,,,,,,
,3765511097.21045,22.0000667572021,0,,,5,,,,31.5000005066395,,,,,2.93697655791227E-5,1.64253028164231E-7,0.742217734029502,0.00416730509889041,4.19565958402885E-6,2.34645996736486E-8,4.1953075524979E-6,1.56474330258022E-8,5.4349655079518E-8,1.74855734120338E-8,7.0000353915559,1.34084260463715,2,2,1,5,0.103513864178158,0.00296191510570548,0.011705294251442,3.00357055664063,21.9995803833008,22.0003719329834,0,0,,,5.77987098693848,,1,,,,,,1,1,1,22.000093460083,0,0,22.0000187428792,,,,,,,,,,,,,,,,,,,,,,,,,,,,,,,,,
,3765511360.37545,21.9998722076416,0,,,5,,,,31.5000005066395,,,,,2.95848077751958E-5,0,1.13821452983632,0,4.22639334721419E-6,0,4.22555941908832E-6,0,8.39542800001939E-8,0,7.00001285840953,0.660553634166718,3.02776322247168,1,1,5,0.104276819512284,0.00295039911715433,0.0116168390959501,1.7003173828125,21.9994697570801,22.0004100799561,0,0,,,5.78027629852295,,1,,,,,,1,1,1,21.999849319458,0,0,21.9999781433417,,,,,,,,,,,,,,,,,,,,,,,,,,,,,,,,,
,3765511797.36607,22.0000324249268,0,,,5,,,,31.5000005066395,,,,,2.95080780783916E-5,3.11571961532836E-7,-0.969155011632547,0.0101519370904086,4.21542230851186E-6,4.45100963154258E-8,4.21481927428008E-6,1.22294711012206E-8,-7.13002402286053E-8,4.2797064275402E-8,7.00002892208648,0.330276817083359,6.05552644494336,2,1,5,0.10404148784108,-0.00124968824312569,0.0115992249920964,0.92425537109375,21.9993324279785,22.0004024505615,0,0,,,5.77991771697998,,1,,,,,,1,1,1,22.0001125335693,0,0,21.9999790081399,,,,,,,,,,,,,,,,,,,,,,,,,,,,,,,,,
,3765512603.7018,21.9999685287476,0,,,5,,,,31.5000005066395,,,,,2.92903310272797E-5,1.7840457851309E-7,0.411633551959927,0.00480610737443578,4.18430891676494E-6,2.54862216466164E-8,4.18420093059334E-6,1.56560062576358E-8,3.00613263246785E-8,2.01106181377233E-8,7.00004029576411,0.160146817564964,12.4885403931845,2,1,5,0.103275991017417,0.00106137615795938,0.0115764308720827,0.472076416015625,21.9994602203369,22.0004234313965,0,0,,,5.77345037460327,,1,,,,,,1,1,1,21.9999389648438,0,0,22.0000048504385,,,,,,,,,,,,,,,,,,,,,,,,,,,,,,,,,
,3765517998.65931,23.9999485015869,0,,,5,,,,31.5000005066395,,,,,5.20509635856793E-6,1.89818117834654E-8,30.9469161198624,0.00617694044400066,2.60299396944398E-6,9.49253158784462E-9,2.23244244520025E-6,7.65533864358037E-9,1.33857324559773E-6,5.61283762444033E-9,1.99965747891448,789.141418457031,2,1578,1,5,0.0138948109288426,0.0120550411174564,0.0267170965671539,354.147766113281,23.9997730255127,24.0004177093506,0,0,,,5.90837383270264,,1,,,,,,1,1,1,23.9997386932373,0,0,24.0000406411978,,,,,,,,,,,,,,,,,,,,,,,,,,,,,,,,,
,3765518114.87573,24.0000667572021,0,,,5,,,,31.4900018274784,,,,,6.36281238470898E-6,1.37385347636731E-8,22.0356137992537,0.00177303123978461,3.18099587131612E-6,6.86838141985791E-9,2.94862675751459E-6,5.3446475651337E-9,1.19345505914516E-6,4.31386204382566E-9,2.00025798275444,389.068725585937,2,778,1,5,0.0197316466358936,0.0105488628373003,0.0262959767132998,358.915618896484,23.9998188018799,24.0006332397461,0,0,,,5.90795755386353,,1,,,,,,1,1,1,24.0002155303955,0,0,24.0001048552684,,,,,,,,,,,,,,,,,,,,,,,,,,,,,,,,,
,3765518233.69579,23.9999122619629,0,,,5,,,,31.5000005066395,,,,,7.36650940832713E-6,2.13754054495054E-8,13.3998388429071,0.00247251987056753,3.68451191029208E-6,1.06913507606461E-8,3.58420671101427E-6,5.19542538325987E-9,8.53867829236164E-7,9.34411773117969E-9,1.99931757249854,191.482849121094,2,382,1,5,0.0244957006090649,0.00833427392227212,0.0259894207119942,3.48065185546875,23.9997577667236,24.0004329681396,0,0,,,5.90778970718384,,1,,,,,,1,1,1,23.9997882843018,0,0,24.000008081135,,,,,,,,,,,,,,,,,,,,,,,,,,,,,,,,,
,3765518352.72862,23.999979019165,0,,,5,,,,31.4900018274784,,,,,7.67365314587222E-6,1.73023836362942E-8,7.18148354438006,0.00133656686758624,3.83769928693051E-6,8.65315959438728E-9,3.80759312640388E-6,7.11721143235577E-9,4.7976077441664E-7,4.92163310224167E-9,1.99954518896393,94.2627868652344,2,188,1,5,0.0261309612801497,0.00659829882369299,0.0250837486237288,9.39520263671875,23.9997577667236,24.0003318786621,0,0,,,5.91504955291748,,1,,,,,,1,1,1,23.9998378753662,0,0,24.0000448924739,,,,,,,,,,,,,,,,,,,,,,,,,,,,,,,,,
,3765518474.96231,24.0000333786011,0,,,5,,,,31.5000005066395,,,,,7.82198960661885E-6,8.74409530153414E-9,3.60868009822578,0.000830346012089048,3.91180850829453E-6,4.37295728045145E-9,3.90405219176999E-6,2.93627042819801E-9,2.46215940794641E-7,3.24053565774906E-9,1.99958397504204,46.4145660400391,2,92,1,5,0.0267893560743874,0.00612915636931102,0.0224955938756466,17.1862182617187,23.9997425079346,24.0005779266357,0,0,,,5.91442060470581,,1,,,,,,1,1,1,23.9999713897705,0,0,24.0000071207682,,,,,,,,,,,,,,,,,,,,,,,,,,,,,,,,,
,3765518590.79446,23.9999580383301,0,,,5,,,,31.4900018274784,,,,,7.76923504746109E-6,2.75248281012886E-8,1.74135594381019,0.00237394709167082,3.88484933478841E-6,1.37632353103283E-8,3.88305525978561E-6,1.02549723758095E-8,1.18051698239688E-7,9.17944376195263E-9,1.99988065891988,22.8596096038818,2,45,1,5,0.0268352738357757,0.005106052295405,0.0178385023027658,22.3316345214844,23.999719619751,24.000394821167,0,0,,,5.91398906707764,,1,,,,,,1,1,1,23.9997692108154,0,0,24.0000566482544,,,,,,,,,,,,,,,,,,,,,,,,,,,,,,,,,
,3765518708.30722,23.9999675750732,0,,,5,,,,31.4900018274784,,,,,7.84467458507945E-6,5.26562237735353E-8,1.07779440251353,0.00293934170677119,3.92252294334302E-6,2.63293580404654E-8,3.9218289596382E-6,2.37233099628488E-8,7.37824667215219E-8,1.14210183096615E-8,1.99990534112561,11.2610988616943,2,22,1,5,0.027396457922763,0.00345482694762679,0.0138993728905916,18.7265014648438,23.9997138977051,24.0004119873047,0,0,,,5.9133677482605,,1,,,,,,1,1,1,23.9998359680176,0,0,23.9999993153107,,,,,,,,,,,,,,,,,,,,,,,,,,,,,,,,,
,3765518882.41081,23.9999523162842,0,,,5,,,,31.4900018274784,,,,,2.68730432283473E-5,2.88827165506452E-7,0.681909721003621,0.00250504337207833,3.8389772735887E-6,4.12607130108988E-8,3.83870538629151E-6,4.0155594432752E-8,4.56887774747692E-8,9.48549808497617E-9,7.00005269977182,5.53858041763306,2,11,1,5,0.0944568400598178,0.00666632248426754,0.012219631113112,10.8852844238281,23.9996528625488,24.0002975463867,0,0,,,5.92590188980103,,1,,,,,,1,1,1,23.9999885559082,0,0,23.9999602787078,,,,,,,,,,,,,,,,,,,,,,,,,,,,,,,,,
,3765519079.55014,24.0000019073486,0,,,5,,,,31.4900018274784,,,,,2.71160344087022E-5,1.58442312442125E-7,0.106917957617409,0.00263983032622074,3.87373773959574E-6,2.26347243850269E-8,3.87373099499669E-6,2.01939734002338E-8,7.22866309892058E-9,1.02241961198316E-8,6.99996650045082,2.72965812683105,2,5,1,5,0.09554576920336,0.00307148228055356,0.0118362316861749,5.58316040039063,23.9997501373291,24.0004653930664,0,0,,,5.92499494552612,,1,,,,,,1,1,1,24.0001277923584,0,0,24.0000849892111,,,,,,,,,,,,,,,,,,,,,,,,,,,,,,,,,
,3765519316.66688,23.9999799728394,0,,,5,,,,31.4900018274784,,,,,2.69275714722761E-5,2.18315356770253E-7,-0.969360364025977,0.00424010614338593,3.84680364845151E-6,3.11879707310946E-8,3.84625311347533E-6,2.65807880902684E-8,-6.507915811709E-8,1.63141418047E-8,6.9999859449846,1.34084260463715,2,2,1,5,0.0949451083647605,-0.000120372419632328,0.0117026139050722,3.02804565429687,23.9992942810059,24.0005779266357,0,0,,,5.92061710357666,,1,,,,,,1,1,1,24.0000476837158,0,0,24.0000184451832,,,,,,,,,,,,,,,,,,,,,,,,,,,,,,,,,
,3765519606.29971,23.9999933242798,0,,,5,,,,31.4900018274784,,,,,2.71987144396E-5,0,0.782346761427831,0,3.885525442866E-6,0,3.88516322795286E-6,0,5.30533629648782E-8,0,7.00000935254151,0.660553634166718,3.02776322247168,1,1,5,0.0958816160066156,0.00211691046025223,0.0116501683369279,1.70187377929687,23.9996318817139,24.0004119873047,0,0,,,5.92341136932373,,1,,,,,,1,1,1,23.9999771118164,0,0,23.9999882950742,,,,,,,,,,,,,,,,,,,,,,,,,,,,,,,,,
,3765520033.24282,24.0000610351562,0,,,5,,,,31.5000005066395,,,,,2.6682218613395E-5,1.4318523267644E-7,-0.477082874626705,0.0033638226343077,3.81175967187549E-6,2.04551092033316E-8,3.81162753154278E-6,1.5937520618164E-8,-3.17388865826925E-8,1.28221265422636E-8,6.99997400420225,0.330276817083359,6.05552644494336,2,1,5,0.0940841251416928,-0.000322036172935146,0.0115898912772536,0.9808349609375,23.9993877410889,24.0004634857178,0,0,,,5.92095804214478,,1,,,,,,1,1,1,24.0002536773682,0,0,24.0000094591185,,,,,,,,,,,,,,,,,,,,,,,,,,,,,,,,,
,3765520849.56806,24.000018119812,0,,,5,,,,31.5000005066395,,,,,2.70919461336513E-5,1.77720410875423E-7,0.0924862980216955,0.00393056714293849,3.87025655568317E-6,2.53884893272749E-8,3.87025151349334E-6,2.03264239081073E-8,6.24732831679341E-9,1.52122280231752E-8,7.00003882013168,0.160146817564964,12.4885403931845,2,1,5,0.0955286011279262,0.000449601926560075,0.0115973446518183,0.466949462890625,23.9996109008789,24.0005912780762,0,0,,,5.95075607299805,,1,,,,,,1,1,1,24.0000915527344,0,0,23.9999847517488,,,,,,,,,,,,,,,,,,,,,,,,,,,,,,,,,
,3765521662.84613,24.0002355575562,0,,,5,,,,31.5000005066395,,,,,2.73514514172946E-5,3.79164491818373E-7,-0.365881933895939,0.0129762773249667,3.90735627488934E-6,5.41664401540665E-8,3.9072766061018E-6,1.90576595616641E-8,-2.49515996807518E-8,5.07031443896311E-8,6.99998912130665,0.100097022950649,19.9806142185273,2,1,5,0.0964440065419462,-0.000379312863935632,0.0115698352456093,0.394927978515625,23.9994964599609,24.0005226135254,0,0,,,5.96340751647949,,1,,,,,,1,1,1,24.0002861022949,0,0,23.9999799447901,,,,,,,,,,,,,,,,,,,,,,,,,,,,,,,,,