File: examples/190412 - K(18-c-6)_Er(BAT)2 - 1 - 3 - MvsT.dat
[Header]
; MPMS3 Data File (default extension .dat)
; Copyright (c) 2007, Quantum Design, Inc. All rights reserved.
TITLE,
FILEOPENTIME,3764744147.23462,04/18/2019,11:16 am
BYAPP,SQUID AC,0.9.1.0
INFO,MPMS3 Measurement Release 1.1.16 Build 399, MultiVu Release 2.3.4.15,APPNAME
INFO,0,MOMENT_UNITS
INFO,K(18-c-6)_Er(hdcCOT)2,SAMPLE_MATERIAL
INFO,yellow crystalline powder,SAMPLE_COMMENT
INFO,7.2,SAMPLE_MASS
INFO,22.7,SAMPLE_VOLUME
INFO,839.24,SAMPLE_MOLECULAR_WEIGHT
INFO,-125.81E-6,SAMPLE_SIZE
INFO,,SAMPLE_SHAPE
INFO,Straw,SAMPLE_HOLDER
INFO,Standard,SAMPLE_HOLDER_DETAIL
INFO,66.44,SAMPLE_OFFSET
DATATYPE,COMMENT,1
DATATYPE,TIME,2
STARTUPAXIS,X,2
STARTUPAXIS,Y1,5
FIELDGROUP, VSM,2,3,4,5,6,8,9,10,11,14,15
FIELDGROUP, DC, 2,3,4,14,56,57,58,59,60,61,62,63,64,65,66,67,68,69
FIELDGROUP, AC, 2,3,4,11,16,17,18,19,20,21,22,23,24,25,26,27,28,29,30
STARTUPGROUP, All
[Data]
Comment,Time Stamp (sec),Temperature (K),Magnetic Field (Oe),Moment (emu),M. Std. Err. (emu),Transport Action,Averaging Time (sec),Frequency (Hz),Peak Amplitude (mm),Center Position (mm),Lockin Signal' (V),Lockin Signal (V),Range,M. Quad. Signal (emu),AC Moment (emu),AC M. Std Err. (emu),AC Phase (deg),AC Phase Std. Err. (deg),AC Susceptibility (emu/Oe),AC Suscept. Std Err. (emu/Oe),AC X' (emu/Oe),AC X' Std Err. (emu/Oe),AC X'' (emu/Oe),AC X'' Std Err. (emu/Oe),AC Drive (Oe),AC Frequency (Hz),AC Averaging Time (sec),AC Cycles,AC Range,AC Measure Type,AC Signal' (V),AC Signal'' (V),AC Trim Coil Ratio,AC Trim Coil Phase,Min. Temperature (K),Max. Temperature (K),Min. Field (Oe),Max. Field (Oe),Mass (grams),Motor Lag (deg),Pressure (Torr),Measure Count,Measurement Number,SQUID Status (code),Motor Status (code),Measure Status (code),Motor Current (amps),Motor Temp. (C),Temp. Status (code),Field Status (code),Chamber Status (code),Chamber Temp (K),Redirection State,Evercool Status,Average Temp (K),Rotation Angle (deg),Rotator state,DC Moment Fixed Ctr (emu),DC Moment Err Fixed Ctr (emu),DC Moment Free Ctr (emu),DC Moment Err Free Ctr (emu),DC Fixed Fit,DC Free Fit,DC Calculated Center (mm),DC Calculated Center Err (mm),DC Scan Length (mm),DC Scan Time (s),DC Number of Points,DC Squid Drift,DC Min V (V),DC Max V (V),DC Scans per Measure,Map 01,Map 02,Map 03,Map 04,Map 05,Map 06,Map 07,Map 08,Map 09,Map 10,Map 11,Map 12,Map 13,Map 14,Map 15,Map 16
,3764745666.84624,2.00318431854248,999.907531738281,,,6,,,,30.5443703447874,,,10,,,,,,,,,,,,,,,,,,,,,,1.99688267707825,2.00359725952148,999.907531738281,999.907531738281,,,2.84970021247864,,1,0,0,0,0.013885498046875,33.2355842590332,1,1,1,2.00277137756348,0,2085105664,1.99982533454895,,,0.00683780131350763,0.000341281922457368,0.00683888099592707,0.000341284186858621,0.962242901325226,0.966481626033783,30.6102752685547,2.03900435735704E-5,35,4,200,0.00113629444967955,-2.70255732536316,0.631705462932587,1,,,,,,,,,,,,,,,,
,3764745789.16998,5.14313888549805,999.907531738281,,,6,,,,30.5443703447874,,,10,,,,,,,,,,,,,,,,,,,,,,5.00458145141602,5.28169631958008,999.907531738281,999.907531738281,,,4.30793190002441,,1,0,0,0,0.0147247314453125,32.7468223571777,6,1,1,5.28169631958008,0,2085105664,5.14259123802185,,,0.00482705470236762,0.000240931541799713,0.00482786050866279,0.000240932322045322,0.961358785629272,0.965850114822388,30.6129150390625,0,35,4,200,-0.000325350731145591,-1.90029549598694,0.465592414140701,1,,,,,,,,,,,,,,,,
,3764745918.9367,9.15725231170654,999.907531738281,,,6,,,,30.5443703447874,,,10,,,,,,,,,,,,,,,,,,,,,,9.00295829772949,9.31154632568359,999.907531738281,999.907531738281,,,5.169114112854,,1,0,0,0,0.0147247314453125,32.7468223571777,6,1,1,9.31154632568359,0,2085105664,9.15926189422607,,,0.00521364282575109,0.000260279237428034,0.00521467985456355,0.00026028053519465,0.95650190114975,0.961206436157227,30.6189842224121,0.191324889659882,35,4,200,0.00369621999561787,-2.06340050697327,0.531557083129883,1,,,,,,,,,,,,,,,,
,3764746044.78286,13.15771484375,999.907531738281,,,6,,,,30.5443703447874,,,10,,,,,,,,,,,,,,,,,,,,,,13.001296043396,13.3050022125244,999.907531738281,999.907531738281,,,5.66897106170654,,1,0,0,0,0.0147247314453125,33.2355842590332,6,1,1,13.314133644104,0,2085105664,13.1534155845642,,,0.00734875419585614,0.000366820805627749,0.00735044215252738,0.000366821984541381,0.95968359708786,0.965748846530914,30.6250038146973,0.191298380494118,35,4,200,-0.000852976576425135,-2.9151017665863,0.691282153129578,1,,,,,,,,,,,,,,,,
,3764746162.69724,17.1675691604614,999.907531738281,,,6,,,,30.5493727961678,,,10,,,,,,,,,,,,,,,,,,,,,,17.0067462921143,17.3099918365479,999.907531738281,999.907531738281,,,5.95729207992554,,1,0,0,0,0.0147247314453125,33.2355842590332,2,1,1,17.3283920288086,0,2085105664,17.1602645874023,,,0.00565080589259115,0.000282058618243597,0.00565202031793969,0.000282060443237784,0.960324048995972,0.965971827507019,30.6267261505127,2.25760613830062E-5,35,4,200,-0.00049025850603357,-2.19191217422485,0.576676845550537,1,,,,,,,,,,,,,,,,
,3764746285.01328,21.1618909835815,999.907531738281,,,6,,,,30.5493727961678,,,10,,,,,,,,,,,,,,,,,,,,,,21.0065250396729,21.3105697631836,999.907531738281,999.907531738281,,,6.15304803848267,,1,0,0,0,0.0147247314453125,32.7468223571777,2,1,1,21.3172569274902,0,2085105664,21.1603143692017,,,0.0045890054202729,0.000229060797401929,0.00459004612717364,0.000229062405655368,0.960143804550171,0.96609354019165,30.6287937164307,2.29109245992731E-5,35,4,200,-0.000322824227623641,-1.80994391441345,0.435420125722885,1,,,,,,,,,,,,,,,,
,3764746407.75702,25.1649446487427,999.907531738281,,,6,,,,30.5493727961678,,,10,,,,,,,,,,,,,,,,,,,,,,25.0027179718018,25.3032073974609,999.907531738281,999.907531738281,,,6.30723237991333,,1,0,0,0,0.0147247314453125,33.2355842590332,2,1,1,25.3271713256836,0,2085105664,25.164079284668,,,0.00386913736678683,0.000193131647531905,0.00387009026690327,0.000193133286464393,0.959742069244385,0.966149926185608,30.6319847106934,5.53461694717407,35,4,200,-0.000185622178833,-1.56514763832092,0.326663106679916,1,,,,,,,,,,,,,,,,
,3764746532.5375,29.2399044036865,999.907531738281,,,6,,,,30.5543763635176,,,10,,,,,,,,,,,,,,,,,,,,,,29.0826396942139,29.3794269561768,999.907531738281,999.907531738281,,,6.42958641052246,,1,0,0,0,0.013885498046875,33.2355842590332,2,1,1,29.3971691131592,0,2085105664,29.2332948684692,,,0.00334082447052384,0.000166760622776185,0.00334163741293272,0.000166761702814456,0.959704458713532,0.966077625751495,30.6368274688721,5.53505420684814,35,4,200,1.76630655914778E-5,-1.37893557548523,0.253559142351151,1,,,,,,,,,,,,,,,,
,3764746652.82109,33.1630573272705,999.907531738281,,,6,,,,30.5543763635176,,,10,,,,,,,,,,,,,,,,,,,,,,33.006046295166,33.3132667541504,999.907531738281,999.907531738281,,,6.51516008377075,,1,0,0,0,0.0147247314453125,33.2355842590332,2,1,1,33.320068359375,0,2085105664,33.1586921691895,,,0.00295375665828897,0.000147442659487515,0.00295453182729295,0.000147443226821472,0.959218442440033,0.96613621711731,30.6405258178711,2.40630342887016E-5,35,4,200,4.39069735875819E-5,-1.13633608818054,0.30730739235878,1,,,,,,,,,,,,,,,,
,3764746777.06358,37.2375984191895,999.907531738281,,,6,,,,30.559488927054,,,10,,,,,,,,,,,,,,,,,,,,,,37.0831871032715,37.378532409668,999.907531738281,999.907531738281,,,6.59209966659546,,1,0,0,0,0.0147247314453125,33.2355842590332,2,1,1,37.3920097351074,0,2085105664,37.2285228729248,,,0.00263670831543472,0.000131617769796084,0.00263743041843862,0.000131619047164267,0.958993911743164,0.966029345989227,30.6465644836426,2.44731472776039E-5,35,4,200,1.74931119545363E-5,-1.0193235874176,0.268556922674179,1,,,,,,,,,,,,,,,,
,3764746897.32391,41.17991065979,999.907531738281,,,6,,,,30.559488927054,,,10,,,,,,,,,,,,,,,,,,,,,,41.0134773254395,41.3316841125488,999.907531738281,999.907531738281,,,6.65364742279053,,1,0,0,0,0.013885498046875,33.7243423461914,2,1,1,41.3463439941406,0,2085105664,41.1730861663818,,,0.00239053819910504,0.000119333048289978,0.00239126283578986,0.000119333988018557,0.958288073539734,0.966083526611328,30.6515464782715,0,35,4,200,5.49412252439652E-5,-0.930813014507294,0.236787706613541,1,,,,,,,,,,,,,,,,
,3764747018.71103,45.1539344787598,999.907531738281,,,6,,,,30.5644902944103,,,10,,,,,,,,,,,,,,,,,,,,,,45.0168838500977,45.306324005127,999.907531738281,999.907531738281,,,6.70874500274658,,1,0,0,0,0.013885498046875,32.7468223571777,2,1,1,45.3162651062012,0,2085105664,45.1607261657715,,,0.00218352221542209,0.000108999810943053,0.00218419838180365,0.000109000759081123,0.958126664161682,0.966052889823914,30.6574268341064,2.53497146331938E-5,35,4,200,4.18230338254943E-5,-0.852439343929291,0.21386630833149,1,,,,,,,,,,,,,,,,
,3764747140.54621,49.1617374420166,999.907531738281,,,6,,,,30.5694912767552,,,10,,,,,,,,,,,,,,,,,,,,,,49.0046997070313,49.3001594543457,999.907531738281,999.907531738281,,,6.75562381744385,,1,0,0,0,0.013885498046875,33.2355842590332,2,1,1,49.318775177002,0,2085105664,49.150456237793,,,0.00200878438983246,0.000100278346901375,0.00200942885860781,0.0001002792695902,0.957811057567596,0.965975344181061,30.6640567779541,2.57637602771865E-5,35,4,200,-3.65603118552826E-5,-0.79423189163208,0.186614975333214,1,,,,,,,,,,,,,,,,
,3764747264.25644,53.2354164123535,999.907531738281,,,6,,,,30.5745334494007,,,10,,,,,,,,,,,,,,,,,,,,,,53.0809020996094,53.3764724731445,999.907531738281,999.907531738281,,,6.7967963218689,,1,0,0,0,0.013885498046875,32.7468223571777,2,1,1,53.3899307250977,0,2085105664,53.2300662994385,,,0.0018559903907516,9.2652774712907E-5,0.00185661617303555,9.26534937357768E-5,0.957327961921692,0.965894520282745,30.6717510223389,5.53820848464966,35,4,200,4.80809649161529E-5,-0.742772102355957,0.163307502865791,1,,,,,,,,,,,,,,,,
,3764747386.28172,57.245906829834,999.907531738281,,,6,,,,30.5795372639285,,,10,,,,,,,,,,,,,,,,,,,,,,57.0861778259277,57.3851852416992,999.907531738281,999.907531738281,,,6.8328595161438,,1,0,0,0,0.013885498046875,32.7468223571777,2,1,1,57.4056358337402,0,2085105664,57.2347106933594,,,0.00172811202666312,8.62703936603627E-5,0.00172871966623153,8.62710545777019E-5,0.956944465637207,0.965838253498077,30.6788845062256,5.53885221481323,35,4,200,-2.31259364227299E-5,-0.701669692993164,0.142116919159889,1,,,,,,,,,,,,,,,,
,3764747507.23157,61.2285766601562,999.907531738281,,,6,,,,30.5845380838009,,,10,,,,,,,,,,,,,,,,,,,,,,61.0717163085938,61.3693389892578,999.907531738281,999.907531738281,,,6.86558723449707,,1,0,0,0,0.013885498046875,32.7468223571777,2,1,1,61.3854370117187,0,2085105664,61.2203472137451,,,0.00161770260746009,8.07601294787088E-5,0.00161830035124647,8.07607110838356E-5,0.956493258476257,0.965802311897278,30.6864910125732,0.191304162144661,35,4,200,2.68818366748746E-5,-0.666026413440704,0.123960494995117,1,,,,,,,,,,,,,,,,
,3764747629.04126,65.2374153137207,999.907531738281,,,6,,,,30.5895437968926,,,10,,,,,,,,,,,,,,,,,,,,,,65.0801315307617,65.3847961425781,999.907531738281,999.907531738281,,,6.89913558959961,,1,0,0,0,0.0147247314453125,33.2355842590332,2,1,1,65.3946990966797,0,2085105664,65.2330657958984,,,0.00151864914751337,7.58167851484777E-5,0.00151924701830204,7.5817639581457E-5,0.955988109111786,0.965742766857147,30.6942806243897,0,35,4,200,9.45474948821357E-6,-0.637516915798187,0.103846453130245,1,,,,,,,,,,,,,,,,
,3764747749.73854,69.2395553588867,999.907531738281,,,6,,,,30.5945637149388,,,10,,,,,,,,,,,,,,,,,,,,,,69.0813980102539,69.3759994506836,999.907531738281,999.907531738281,,,6.92616081237793,,1,0,0,0,0.013885498046875,32.7468223571777,2,1,1,69.3977127075195,0,2085105664,69.2299957275391,,,0.00143190936785444,7.14883511299953E-5,0.00143250767413575,7.14892565169293E-5,0.955378413200378,0.965616881847382,30.7023811340332,5.54097270965576,35,4,200,7.48567908885889E-5,-0.610906183719635,0.0881070718169212,1,,,,,,,,,,,,,,,,
,3764747869.13316,73.1643981933594,999.907531738281,,,6,,,,30.599569973024,,,10,,,,,,,,,,,,,,,,,,,,,,73.0007781982422,73.3120040893555,999.907531738281,999.907531738281,,,6.95318460464478,,1,0,0,0,0.013885498046875,33.7243423461914,2,1,1,73.3280181884766,0,2085105664,73.1641593933105,,,0.00135738226075279,6.7768926719594E-5,0.00135796979840864,6.77695262010786E-5,0.954931199550629,0.965579867362976,30.7098598480225,2.90054395009065E-5,35,4,200,6.30140566499904E-5,-0.587193250656128,0.0754853487014771,1,,,,,,,,,,,,,,,,
,3764747990.5216,77.1584587097168,999.907531738281,,,6,,,,30.6047756442019,,,10,,,,,,,,,,,,,,,,,,,,,,77.007209777832,77.2958908081055,999.907531738281,999.907531738281,,,6.97570133209229,,1,0,0,0,0.013885498046875,33.2355842590332,2,1,1,77.3097076416016,0,2085105664,77.1525741577148,,,0.00128769509813301,6.42913419133623E-5,0.00128828679694009,6.42920340930392E-5,0.954378426074982,0.965568482875824,30.718240737915,0.000154335881234147,35,4,200,8.98527214303613E-5,-0.562199890613556,0.066330797970295,1,,,,,,,,,,,,,,,,
,3764748112.14452,81.1666412353516,999.907531738281,,,6,,,,30.6097782263276,,,10,,,,,,,,,,,,,,,,,,,,,,81.015022277832,81.3182601928711,999.907531738281,999.907531738281,,,6.99634742736816,,1,0,0,0,0.013885498046875,32.7468223571777,2,1,1,81.3182601928711,0,2085105664,81.1664573669434,,,0.00122467715588299,6.11469070921091E-5,0.00122527236859921,6.11473306544609E-5,0.953701734542847,0.96554446220398,30.7270050048828,0.191333293914795,35,4,200,-2.91272772301454E-5,-0.540469884872437,0.0575118437409401,1,,,,,,,,,,,,,,,,
,3764748235.4139,85.2468185424805,999.907531738281,,,6,,,,30.6197822251831,,,10,,,,,,,,,,,,,,,,,,,,,,85.0853118896484,85.394905090332,999.907531738281,999.907531738281,,,7.01829290390015,,1,0,0,0,0.013885498046875,33.2355842590332,2,1,1,85.4083251953125,0,2085105664,85.2385848999023,,,0.00116505840173976,5.81702021719921E-5,0.00116562792429682,5.81709739890692E-5,0.953704178333282,0.965445816516876,30.7365684509277,5.22669124603271,35,4,200,-5.87453030220786E-7,-0.520882427692413,0.155901208519936,1,,,,,,,,,,,,,,,,
,3764748353.25718,89.1695175170898,999.907531738281,,,6,,,,30.624800730373,,,10,,,,,,,,,,,,,,,,,,,,,,89.0248641967773,89.3232269287109,999.907531738281,999.907531738281,,,7.03705787658691,,1,0,0,0,0.013885498046875,33.2355842590332,2,1,1,89.3232269287109,0,2085105664,89.1730094909668,,,0.00111618796303019,5.57316427800411E-5,0.00111676160359676,5.57323226947477E-5,0.953133165836334,0.965431094169617,30.7447643280029,0,35,4,200,6.96757269906811E-5,-0.397815644741058,0.147075623273849,1,,,,,,,,,,,,,,,,
,3764748478.26871,93.3240470886231,999.907531738281,,,6,,,,30.634958163919,,,10,,,,,,,,,,,,,,,,,,,,,,93.1629867553711,93.475944519043,999.907531738281,999.907531738281,,,7.05472469329834,,1,0,0,0,0.0147247314453125,32.7468223571777,2,1,1,93.485107421875,0,2085105664,93.3218978881836,,,0.00106697068770727,5.32741848477205E-5,0.00106751265744527,5.32746197457171E-5,0.953139901161194,0.965384304523468,30.7546901702881,3.08806156681385E-5,35,4,200,3.567457315512E-5,-0.380378901958466,0.140551552176476,1,,,,,,,,,,,,,,,,
,3764748594.1022,97.1615715026855,999.907531738281,,,6,,,,30.6399622738622,,,10,,,,,,,,,,,,,,,,,,,,,,97.024299621582,97.2839279174805,999.907531738281,999.907531738281,,,7.06987190246582,,1,0,0,0,0.013885498046875,32.7468223571777,2,1,1,97.3161010742188,0,2085105664,97.1539510091146,,,0.00102543740970171,5.12019902742978E-5,0.00102599189990447,5.12025963835802E-5,0.952490210533142,0.96533727645874,30.763126373291,5.54645156860352,35,4,200,4.96582797495648E-5,-0.365871727466583,0.13469609618187,1,,,,,,,,,,,,,,,,
,3764748716.74416,101.247825622559,999.907531738281,,,6,,,,30.6499890740151,,,10,,,,,,,,,,,,,,,,,,,,,,101.095283508301,101.383453369141,999.907531738281,999.907531738281,,,7.08439016342163,,1,0,0,0,0.013885498046875,33.2355842590332,2,1,1,101.400367736816,0,2085105664,101.239008331299,,,0.000983810599803631,4.91236686066218E-5,0.000984343610323793,4.91242227120632E-5,0.952403664588928,0.965264678001404,30.7733287811279,3.17432895826641E-5,35,4,200,5.34224636794534E-5,-0.351318508386612,0.12881201505661,1,,,,,,,,,,,,,,,,
,3764748834.9847,105.161647796631,999.907531738281,,,6,,,,30.6550331229846,,,10,,,,,,,,,,,,,,,,,,,,,,105.011276245117,105.312019348145,999.907531738281,999.907531738281,,,7.09755563735962,,1,0,0,0,0.013885498046875,33.2355842590332,2,1,1,105.312019348145,0,2085105664,105.162544250488,,,0.000948286254145099,4.73515425863497E-5,0.000948832048971332,4.73520523514157E-5,0.951675891876221,0.965244233608246,30.782283782959,0,35,4,200,7.98852197476663E-5,-0.333620876073837,0.129295781254768,1,,,,,,,,,,,,,,,,
,3764748955.06541,109.148616790771,999.907531738281,,,6,,,,30.6650437910859,,,10,,,,,,,,,,,,,,,,,,,,,,109.003532409668,109.287246704102,999.907531738281,999.907531738281,,,7.11152458190918,,1,0,0,0,0.013885498046875,32.7468223571777,2,1,1,109.293701171875,0,2085105664,109.149038696289,,,0.000914050392426195,4.56420060280834E-5,0.000914581118923759,4.56428254939259E-5,0.951683521270752,0.965194046497345,30.7920627593994,0.000169790582731366,35,4,200,9.36183205340058E-5,-0.319200038909912,0.126997739076614,1,,,,,,,,,,,,,,,,
,3764749078.15482,113.23363494873,999.907531738281,,,6,,,,30.6750937639343,,,10,,,,,,,,,,,,,,,,,,,,,,113.075141906738,113.381149291992,999.907531738281,999.907531738281,,,7.12481641769409,,1,0,0,0,0.013885498046875,33.2355842590332,2,1,1,113.392127990723,0,2085105664,113.229655456543,,,0.00088026474622258,4.39552683527813E-5,0.000880779640518129,4.39560873322259E-5,0.951537847518921,0.965095221996307,30.802526473999,5.22557687759399,35,4,200,5.09316159877926E-5,-0.304880708456039,0.124791607260704,1,,,,,,,,,,,,,,,,
,3764749196.33091,117.164810180664,999.907531738281,,,6,,,,30.6801028071409,,,10,,,,,,,,,,,,,,,,,,,,,,117.004806518555,117.318389892578,999.907531738281,999.907531738281,,,7.13612174987793,,1,0,0,0,0.013885498046875,33.2355842590332,2,1,1,117.324813842773,0,2085105664,117.162497711182,,,0.000852318610251641,4.25614570793673E-5,0.000852842064973517,4.25618588751737E-5,0.950740575790405,0.965076565742493,30.8117790222168,3.34682263201103E-5,35,4,200,-1.83603060577298E-5,-0.296331733465195,0.119725875556469,1,,,,,,,,,,,,,,,,
,3764749316.59982,121.156658172607,999.907531738281,,,6,,,,30.6906359482389,,,10,,,,,,,,,,,,,,,,,,,,,,121.013633728027,121.290702819824,999.907531738281,999.907531738281,,,7.14746809005737,,1,0,0,0,0.013885498046875,32.7468223571777,2,1,1,121.308708190918,0,2085105664,121.156867980957,,,0.000824260376167358,4.11603330193452E-5,0.000824768846632959,4.11608864306679E-5,0.950741648674011,0.965041518211365,30.8221683502197,5.55177164077759,35,4,200,8.93097148946254E-6,-0.288585275411606,0.113792806863785,1,,,,,,,,,,,,,,,,
,3764749437.13123,125.158042907715,999.907531738281,,,6,,,,30.7006406610649,,,10,,,,,,,,,,,,,,,,,,,,,,125.003463745117,125.305053710938,999.907531738281,999.907531738281,,,7.1595025062561,,1,0,0,0,0.013885498046875,32.7468223571777,2,1,1,125.312622070312,0,2085105664,125.159840393066,,,0.000798155069519213,3.98569259761233E-5,0.000798646001118612,3.98572592182848E-5,0.95065051317215,0.965006768703461,30.8325443267822,0,35,4,200,3.04596960631898E-6,-0.28166851401329,0.107952870428562,1,,,,,,,,,,,,,,,,
,3764749557.36784,129.171630859375,999.907531738281,,,6,,,,30.7106751535119,,,10,,,,,,,,,,,,,,,,,,,,,,129.006927490234,129.320556640625,999.907531738281,999.907531738281,,,7.17194414138794,,1,0,0,0,0.013885498046875,33.2355842590332,2,1,1,129.336334228516,0,2085105664,129.179026794434,,,0.000773608685549962,3.86314103107909E-5,0.000774090944205535,3.86318924526468E-5,0.950522840023041,0.964945673942566,30.8430194854736,0,35,4,200,-6.66313690089737E-6,-0.276246070861816,0.101403459906578,1,,,,,,,,,,,,,,,,
,3764749677.88718,133.156303405762,999.907531738281,,,6,,,,30.7212493401776,,,10,,,,,,,,,,,,,,,,,,,,,,133.001968383789,133.296829223633,999.907531738281,999.907531738281,,,7.18319272994995,,1,0,0,0,0.013885498046875,33.2355842590332,2,1,1,133.310638427734,0,2085105664,133.156355285645,,,0.000750506182529103,3.74779595479031E-5,0.000750977056912397,3.74784459726579E-5,0.950403094291687,0.964876592159271,30.8539638519287,0,35,4,200,4.3604945858533E-6,-0.272412955760956,0.0939877778291702,1,,,,,,,,,,,,,,,,
,3764749801.0369,137.266944885254,999.907531738281,,,6,,,,30.7367409178836,,,10,,,,,,,,,,,,,,,,,,,,,,137.099472045898,137.422241210938,999.907531738281,999.907531738281,,,7.19445657730103,,1,0,0,0,0.013885498046875,33.2355842590332,2,1,1,137.434417724609,0,2085105664,137.273257446289,,,0.00072770827909715,3.63382991093684E-5,0.000728137336650381,3.63387268644022E-5,0.951073169708252,0.96477746963501,30.8654460906982,0,35,4,200,1.47268547152635E-5,-0.265481024980545,0.0897365882992744,1,,,,,,,,,,,,,,,,
,3764749921.39297,141.243377685547,999.907531738281,,,6,,,,30.7468151095176,,,10,,,,,,,,,,,,,,,,,,,,,,141.078918457031,141.39794921875,999.907531738281,999.907531738281,,,7.20474910736084,,1,0,0,0,0.013885498046875,33.2355842590332,2,1,1,141.407836914062,0,2085105664,141.242486572266,,,0.000706696517467496,3.52893851953193E-5,0.0007071172404069,3.52897591236601E-5,0.950895726680756,0.964726209640503,30.8762836456299,0,35,4,200,-1.96152041098685E-6,-0.261912882328033,0.0830540060997009,1,,,,,,,,,,,,,,,,
,3764750038.46279,145.151527404785,999.907531738281,,,6,,,,30.7568527857429,,,10,,,,,,,,,,,,,,,,,,,,,,145.001266479492,145.289993286133,999.907531738281,999.907531738281,,,7.21549129486084,,1,0,0,0,0.013885498046875,33.2355842590332,2,1,1,145.301788330078,0,2085105664,145.148461914062,,,0.000688966537038675,3.44042972793242E-5,0.000689380107714104,3.44046131415277E-5,0.950736343860626,0.964683592319489,30.8870277404785,,35,4,200,9.52862501435447E-6,-0.259642153978348,0.0767183974385262,1,,,,,,,,,,,,,,,,
,3764750161.50341,149.238212585449,999.907531738281,,,6,,,,30.7718880544333,,,10,,,,,,,,,,,,,,,,,,,,,,149.08186340332,149.37451171875,999.907531738281,999.907531738281,,,7.22780513763428,,1,0,0,0,0.00152587890625,32.7468223571777,2,1,1,149.394561767578,0,2085105664,149.228485107422,,,0.000669192135046643,3.34159753512847E-5,0.000669573059062833,3.34162232245388E-5,0.951263844966888,0.964588820934296,30.8987693786621,0,35,4,200,3.33357529598288E-5,-0.255876868963242,0.0707487091422081,1,,,,,,,,,,,,,,,,
,3764750279.36801,153.156105041504,999.907531738281,,,6,,,,30.7823830625274,,,10,,,,,,,,,,,,,,,,,,,,,,153.01383972168,153.305892944336,999.907531738281,999.907531738281,,,7.23651695251465,,1,0,0,0,0,33.2355842590332,2,1,1,153.305892944336,0,2085105664,153.160090637207,,,0.000653165283469504,3.26159366943206E-5,0.000653546616400944,3.26164466262091E-5,0.951100587844849,0.964543163776398,30.9099903106689,0,35,4,200,1.40491556521738E-5,-0.253792107105255,0.0650479644536972,1,,,,,,,,,,,,,,,,
,3764750402.36359,157.229766845703,999.907531738281,,,6,,,,30.797445307303,,,10,,,,,,,,,,,,,,,,,,,,,,157.068878173828,157.382919311523,999.907531738281,999.907531738281,,,7.24239253997803,,1,0,0,0,0.01708984375,32.7468223571777,2,1,1,157.390655517578,0,2085105664,157.236460876465,,,0.000635293159980427,3.17227423152737E-5,0.000635642223728446,3.17230166798361E-5,0.95158439874649,0.964437186717987,30.9219341278076,,35,4,200,3.00491862503804E-8,-0.250572979450226,0.0595692507922649,1,,,,,,,,,,,,,,,,
,3764750524.94799,161.315521240234,999.907531738281,,,6,,,,30.8125213016275,,,10,,,,,,,,,,,,,,,,,,,,,,161.157287597656,161.440811157227,999.907531738281,999.907531738281,,,7.25268363952637,,1,0,0,0,0,33.2355842590332,2,1,1,161.473754882813,0,2085105664,161.298051452637,,,0.000620110778961563,3.09638860461059E-5,0.000620433775825224,3.0964064406708E-5,0.952077567577362,0.964384734630585,30.9340381622314,0,35,4,200,2.52696445386391E-5,-0.25026860833168,0.0524839162826538,1,,,,,,,,,,,,,,,,
,3764750640.53111,165.156478881836,999.907531738281,,,6,,,,30.8225430918833,,,10,,,,,,,,,,,,,,,,,,,,,,165.004653930664,165.299240112305,999.907531738281,999.907531738281,,,7.26027965545654,,1,0,0,0,0.013885498046875,33.2355842590332,2,1,1,165.308303833008,0,2085105664,165.156243896484,,,0.000605958671016513,3.02576445734027E-5,0.000606278433520204,3.02577096104014E-5,0.951790869235992,0.964290142059326,30.9452800750732,0,35,4,200,1.07364221548778E-5,-0.247386187314987,0.0484131723642349,1,,,,,,,,,,,,,,,,
,3764750763.61071,169.267196655273,999.907531738281,,,6,,,,30.8376862848583,,,10,,,,,,,,,,,,,,,,,,,,,,169.097503662109,169.424041748047,999.907531738281,999.907531738281,,,7.26985311508179,,1,0,0,0,0.013885498046875,33.2355842590332,2,1,1,169.436889648438,0,2085105664,169.266273498535,,,0.000590333711837767,2.94768378455937E-5,0.00059063313882244,2.94769784587146E-5,0.952216446399689,0.964217007160187,30.957691192627,0.000175588633283041,35,4,200,2.14293468161486E-5,-0.246268823742867,0.04192865639925,1,,,,,,,,,,,,,,,,
,3764750884.1922,173.254364013672,999.907531738281,,,6,,,,30.8531213049837,,,10,,,,,,,,,,,,,,,,,,,,,,173.090438842773,173.393325805664,999.907531738281,999.907531738281,,,7.27620887756348,,1,0,0,0,0.015106201171875,32.7468223571777,2,1,1,173.41828918457,0,2085105664,173.246028137207,,,0.0005767774634444,2.87993007708201E-5,0.000577055084618806,2.8799466634092E-5,0.952688872814178,0.964095830917358,30.9698467254639,5.22678470611572,35,4,200,4.96860184284742E-6,-0.244758144021034,0.0368367582559586,1,,,,,,,,,,,,,,,,
,3764751004.23885,177.250801086426,999.907531738281,,,6,,,,30.8682384215312,,,10,,,,,,,,,,,,,,,,,,,,,,177.094390869141,177.387908935547,999.907531738281,999.907531738281,,,7.2828540802002,,1,0,0,0,0,33.2355842590332,2,1,1,177.407211303711,0,2085105664,177.250230407715,,,0.000563989074616147,2.81601920877671E-5,0.000564248107317469,2.81603633011908E-5,0.953105747699738,0.964021563529968,30.9821929931641,0,35,4,200,-1.03052525446401E-5,-0.244306445121765,0.0310579240322113,1,,,,,,,,,,,,,,,,
,3764751124.12559,181.228904724121,999.907531738281,,,6,,,,30.8837542146152,,,10,,,,,,,,,,,,,,,,,,,,,,181.084121704102,181.367111206055,999.907531738281,999.907531738281,,,7.28853225708008,,1,0,0,0,0.0168609619140625,33.2355842590332,2,1,1,181.373687744141,0,2085105664,181.224995422363,,,0.000551881292197705,2.75550672320387E-5,0.000552121686900528,2.75552600868396E-5,0.953555524349213,0.963922619819641,30.9945831298828,5.22594833374023,35,4,200,-1.70309249369893E-5,-0.246310666203499,0.0231407284736633,1,,,,,,,,,,,,,,,,
,3764751244.54044,185.225646972656,999.907531738281,,,6,,,,30.8990146859161,,,10,,,,,,,,,,,,,,,,,,,,,,185.074813842773,185.368408203125,999.907531738281,999.907531738281,,,7.29637336730957,,1,0,0,0,0.013885498046875,33.2355842590332,2,1,1,185.376480102539,0,2085105664,185.221168518066,,,0.00053992886813179,2.69578306333229E-5,0.000540151869509001,2.69579336697655E-5,0.953925132751465,0.963860392570496,31.0072898864746,INF,35,4,200,-5.28798154846299E-5,-0.249523535370827,0.0141958044841886,1,,,,,,,,,,,,,,,,
,3764751364.96662,189.246520996094,999.907531738281,,,6,,,,30.9145971434401,,,10,,,,,,,,,,,,,,,,,,,,,,189.1005859375,189.373016357422,999.907531738281,999.907531738281,,,7.30299520492554,,1,0,0,0,0.0160980224609375,32.7468223571777,2,1,1,189.392456054687,0,2085105664,189.239483642578,,,0.000528375543293701,2.63805358020777E-5,0.000528584722960939,2.63807092610736E-5,0.954297542572022,0.963784515857697,31.0202293395996,0,35,4,200,-7.61098917223535E-8,-0.251592308282852,0.00640134047716856,1,,,,,,,,,,,,,,,,
,3764751486.08999,193.24796295166,999.907531738281,,,6,,,,30.9303161953468,,,10,,,,,,,,,,,,,,,,,,,,,,193.075012207031,193.401489257813,999.907531738281,999.907531738281,,,7.30837154388428,,1,0,0,0,0.013885498046875,33.7243423461914,2,1,1,193.420913696289,0,2085105664,193.239602661133,,,0.000517182217075209,2.58212683072389E-5,0.000517375902940868,2.58213708808034E-5,0.954652070999145,0.963712751865387,31.0333480834961,0,35,4,200,-1.91188610187965E-5,-0.252258777618408,0.000245354429353029,1,,,,,,,,,,,,,,,,
,3764751606.44846,197.251174926758,999.907531738281,,,6,,,,30.9454875232907,,,10,,,,,,,,,,,,,,,,,,,,,,197.092208862305,197.3974609375,999.907531738281,999.907531738281,,,7.31361198425293,,1,0,0,0,0.000457763671875,33.7243423461914,2,1,1,197.410140991211,0,2085105664,197.248182678223,,,0.000506363491145446,2.52808267997297E-5,0.000506546265286964,2.52809609227234E-5,0.95490425825119,0.963617920875549,31.0464286804199,0,35,4,200,-1.22580638617364E-6,-0.252615183591843,-0.00539774307981133,1,,,,,,,,,,,,,,,,
,3764751726.48991,201.24210357666,999.907531738281,,,6,,,,30.9613153831396,,,10,,,,,,,,,,,,,,,,,,,,,,201.084426879883,201.387268066406,999.907531738281,999.907531738281,,,7.31993722915649,,1,0,0,0,0.019378662109375,33.2355842590332,2,1,1,201.399780273438,0,2085105664,201.239099121094,,,0.0004963771300186,2.47818918892757E-5,0.000496549532935424,2.47821024681904E-5,0.955231010913849,0.963560163974762,31.0598468780518,0.000164110111654736,35,4,200,-2.27979635383235E-5,-0.253302574157715,-0.010948633775115,1,,,,,,,,,,,,,,,,
,3764751849.10551,205.300346374512,999.907531738281,,,6,,,,30.9813760250285,,,10,,,,,,,,,,,,,,,,,,,,,,205.154815673828,205.437454223633,999.907531738281,999.907531738281,,,7.32954597473145,,1,0,0,0,0.0159454345703125,33.2355842590332,2,1,1,205.445877075195,0,2085105664,205.295338439941,,,0.000487255360392754,2.43255737284483E-5,0.000487402686732752,2.43256990058601E-5,0.956063747406006,0.963434457778931,31.0736618041992,0.213567808270454,35,4,200,-4.01192919525783E-5,-0.147426128387451,0.090553030371666,1,,,,,,,,,,,,,,,,
,3764751968.03635,209.266960144043,999.907531738281,,,6,,,,30.9968642418578,,,10,,,,,,,,,,,,,,,,,,,,,,209.086700439453,209.42903137207,999.907531738281,999.907531738281,,,7.33614301681519,,1,0,0,0,0.01708984375,33.2355842590332,2,1,1,209.447219848633,0,2085105664,209.255554199219,,,0.000477216128946234,2.38240843129784E-5,0.00047735341798474,2.38241891247312E-5,0.95635050535202,0.963397979736328,31.0869655609131,0,35,4,200,1.63712138601113E-6,-0.149585634469986,0.0833794102072716,1,,,,,,,,,,,,,,,,
,3764752086.31141,213.170234680176,999.907531738281,,,6,,,,31.0120021925676,,,10,,,,,,,,,,,,,,,,,,,,,,213.006195068359,213.330673217773,999.907531738281,999.907531738281,,,7.34272146224976,,1,0,0,0,0,32.7468223571777,2,1,1,213.334274291992,0,2085105664,213.16710357666,,,0.00046933975134963,2.34307121406119E-5,0.000469470981673871,2.34308425030794E-5,0.956509292125702,0.963334977626801,31.1006107330322,,35,4,200,-1.97734498215141E-5,-0.15153543651104,0.0776638463139534,1,,,,,,,,,,,,,,,,
,3764752209.04002,217.245803833008,999.907531738281,,,6,,,,31.0328380360902,,,10,,,,,,,,,,,,,,,,,,,,,,217.086441040039,217.392333984375,999.907531738281,999.907531738281,,,7.35238456726074,,1,0,0,0,0.0147247314453125,33.2355842590332,2,1,1,217.405166625977,0,2085105664,217.243086242676,,,0.000459639051505563,2.29455415441213E-5,0.000459747735392139,2.29456564446969E-5,0.957397222518921,0.963218331336975,31.1142711639404,0,35,4,200,-6.79740469422541E-6,-0.154243528842926,0.0701953619718552,1,,,,,,,,,,,,,,,,
,3764752332.20318,221.317413330078,999.907531738281,,,6,,,,31.0529340851268,,,10,,,,,,,,,,,,,,,,,,,,,,221.164993286133,221.456832885742,999.907531738281,999.907531738281,,,7.35808753967285,,1,0,0,0,0.013885498046875,33.2355842590332,2,1,1,221.469833374023,0,2085105664,221.314503479004,,,0.00045184804248712,2.25559279935682E-5,0.000451938699950208,2.25559930238263E-5,0.958112299442291,0.96312552690506,31.1282062530518,5.57926559448242,35,4,200,-9.47582338994835E-6,-0.156325370073318,0.0643110498785973,1,,,,,,,,,,,,,,,,
,3764752449.20558,225.234535217285,999.907531738281,,,6,,,,31.0692464703279,,,10,,,,,,,,,,,,,,,,,,,,,,225.081970214844,225.371368408203,999.907531738281,999.907531738281,,,7.36866092681885,,1,0,0,0,0.013885498046875,33.2355842590332,2,1,1,225.387100219727,0,2085105664,225.22904510498,,,0.00044314969074964,2.21214029145913E-5,0.00044323096543323,2.21214648334277E-5,0.958445727825165,0.963038623332977,31.141170501709,0,35,4,200,-1.45673730003182E-5,-0.157307356595993,0.0590578615665436,1,,,,,,,,,,,,,,,,
,3764752570.84779,229.247863769531,999.907531738281,,,6,,,,31.0892831131187,,,10,,,,,,,,,,,,,,,,,,,,,,229.085815429687,229.383346557617,999.907531738281,999.907531738281,,,7.37746286392212,,1,0,0,0,0.013885498046875,33.2355842590332,2,1,1,229.409912109375,0,2085105664,229.238652038574,,,0.000435547760147411,2.1741359957455E-5,0.000435613591133413,2.1741384515301E-5,0.959076225757599,0.962916254997253,31.1548328399658,0,35,4,200,-2.29819379455876E-5,-0.159080266952515,0.0535879023373127,1,,,,,,,,,,,,,,,,
,3764752691.12354,233.235809326172,999.907531738281,,,6,,,,31.1094178153239,,,10,,,,,,,,,,,,,,,,,,,,,,233.078918457031,233.363098144531,999.907531738281,999.907531738281,,,7.38789939880371,,1,0,0,0,0.013885498046875,33.2355842590332,2,1,1,233.392700195313,0,2085105664,233.220652770996,,,0.000428447756486422,2.13864473130069E-5,0.000428501007480433,2.1386481174248E-5,0.959656774997711,0.962817370891571,31.1687088012695,0,35,4,200,-2.21198260987876E-5,-0.161529734730721,0.0476701185107231,1,,,,,,,,,,,,,,,,
,3764752812.50782,237.267532348633,999.907531738281,,,6,,,,31.1295100927529,,,10,,,,,,,,,,,,,,,,,,,,,,237.119369506836,237.409545898438,999.907531738281,999.907531738281,,,7.4054069519043,,1,0,0,0,0,33.2355842590332,2,1,1,237.421951293945,0,2085105664,237.262677001953,,,0.000421264977851204,2.10275107328615E-5,0.000421306771349296,2.10274962740418E-5,0.960126280784607,0.962711572647095,31.1829986572266,,35,4,200,-1.64530483743874E-5,-0.164349928498268,0.0413585118949413,1,,,,,,,,,,,,,,,,
,3764752933.05646,241.27214050293,999.907531738281,,,6,,,,31.1496061952384,,,10,,,,,,,,,,,,,,,,,,,,,,241.127960205078,241.399536132813,999.907531738281,999.907531738281,,,7.42790174484253,,1,0,0,0,0,33.2355842590332,2,1,1,241.416320800781,0,2085105664,241.264849853516,,,0.000414220842533906,2.06755746353718E-5,0.000414253838469053,2.06755915379381E-5,0.960523366928101,0.962570548057556,31.1971206665039,,35,4,200,-4.05905302613974E-5,-0.168190717697144,0.0341963432729244,1,,,,,,,,,,,,,,,,
,3764753052.38803,245.227546691895,999.907531738281,,,6,,,,31.1696843336066,,,10,,,,,,,,,,,,,,,,,,,,,,245.08332824707,245.362121582031,999.907531738281,999.907531738281,,,7.45433473587036,,1,0,0,0,0.013885498046875,33.7243423461914,2,1,1,245.371765136719,0,2085105664,245.224621582031,,,0.00040741060081393,2.03353396970485E-5,0.000407434931487085,2.03353332459789E-5,0.960906684398651,0.962471425533295,31.2111473083496,0,35,4,200,-4.47408674517646E-5,-0.172344267368317,0.0267263986170292,1,,,,,,,,,,,,,,,,
,3764753173.43479,249.238510131836,999.907531738281,,,6,,,,31.1897031959874,,,10,,,,,,,,,,,,,,,,,,,,,,249.069793701172,249.374206542969,999.907531738281,999.907531738281,,,7.48780822753906,,1,0,0,0,0.013885498046875,33.7243423461914,2,1,1,249.4072265625,0,2085105664,249.229090881348,,,0.000400450128475845,1.99876826186513E-5,0.000400468782674252,1.99877118438666E-5,0.961207330226898,0.962386608123779,31.2256450653076,,35,4,200,-4.51304622401949E-5,-0.177178293466568,0.0185190197080374,1,,,,,,,,,,,,,,,,
,3764753293.46974,253.240768432617,999.907531738281,,,6,,,,31.2098113062821,,,10,,,,,,,,,,,,,,,,,,,,,,253.080795288086,253.381332397461,999.907531738281,999.907531738281,,,7.50044202804565,,1,0,0,0,0,33.7243423461914,2,1,1,253.400741577148,0,2085105664,253.235232543945,,,0.000393802815628765,1.96557028366916E-5,0.000393815372779766,1.96557002407454E-5,0.961451709270477,0.962290227413177,31.2400875091553,0,35,4,200,-3.78237564291339E-5,-0.18218432366848,0.0101866694167256,1,,,,,,,,,,,,,,,,
,3764753414.67746,257.235687255859,999.907531738281,,,6,,,,31.2300647135257,,,10,,,,,,,,,,,,,,,,,,,,,,257.083984375,257.377807617187,999.907531738281,999.907531738281,,,7.51076459884644,,1,0,0,0,0,33.7243423461914,2,1,1,257.387390136719,0,2085105664,257.235247802734,,,0.000387446363779405,1.9338334267665E-5,0.000387454681971286,1.93383384558689E-5,0.96159952878952,0.962156236171722,31.2547283172607,5.59059286117554,35,4,200,-3.35539371008053E-5,-0.186138808727264,0.00315613835118711,1,,,,,,,,,,,,,,,,
,3764753535.04641,261.241561889648,999.907531738281,,,6,,,,31.2519255934168,,,10,,,,,,,,,,,,,,,,,,,,,,261.087585449219,261.387878417969,999.907531738281,999.907531738281,,,7.5308403968811,,1,0,0,0,0.0002288818359375,33.7243423461914,2,1,1,261.395538330078,0,2085105664,261.237622070313,,,0.000381444228588231,1.90386180902782E-5,0.000381448452089835,1.90386092685187E-5,0.961794435977936,0.962097108364105,31.2700977325439,0,35,4,200,-3.03419619740453E-5,-0.190149784088135,-0.00377400405704975,1,,,,,,,,,,,,,,,,
,3764753655.83456,265.239181518555,999.907531738281,,,6,,,,31.2739136189081,,,10,,,,,,,,,,,,,,,,,,,,,,265.082122802734,265.380981445313,999.907531738281,999.907531738281,,,7.56843280792236,,1,0,0,0,0,35.190616607666,2,1,1,265.396240234375,0,2085105664,265.235772705078,,,0.000375609425232892,1.87473594378888E-5,0.000375611229752234,1.87473560936338E-5,0.961826920509338,0.961957514286041,31.2858562469482,1.18049874799908E-5,35,4,200,-2.45458941208199E-5,-0.195144057273865,-0.0116306189447641,1,,,,,,,,,,,,,,,,
,3764753775.84168,269.237686157227,999.907531738281,,,6,,,,31.2963584679401,,,10,,,,,,,,,,,,,,,,,,,,,,269.080963134766,269.376861572266,999.907531738281,999.907531738281,,,7.62989139556885,,1,0,0,0,0.000152587890625,33.2355842590332,2,1,1,269.394409179687,0,2085105664,269.232562255859,,,0.000369997943115494,1.84672898960606E-5,0.000369998232533283,1.84672830272695E-5,0.96181583404541,0.961845993995667,31.3021068572998,5.59482860565186,35,4,200,-2.39044511545217E-5,-0.200780287384987,-0.0199945252388716,1,,,,,,,,,,,,,,,,
,3764753896.30781,273.232711791992,999.907531738281,,,6,,,,31.3188434467472,,,10,,,,,,,,,,,,,,,,,,,,,,273.080108642578,273.369812011719,999.907531738281,999.907531738281,,,7.71887683868408,,1,0,0,0,0.013885498046875,33.2355842590332,2,1,1,273.385314941406,0,2085105664,273.228610229492,,,0.000364532915741847,1.81945532259657E-5,0.000364532908013927,1.81945524796323E-5,0.961766123771667,0.96176666021347,31.3195972442627,9.70640758168884E-5,35,4,200,-3.03733668260975E-5,-0.20592112839222,-0.0278090909123421,1,,,,,,,,,,,,,,,,
,3764754017.06608,277.242095947266,999.907531738281,,,6,,,,31.3436604805066,,,10,,,,,,,,,,,,,,,,,,,,,,277.08349609375,277.381042480469,999.907531738281,999.907531738281,,,7.8458251953125,,1,0,0,0,0,32.7468223571777,2,1,1,277.400695800781,0,2085105664,277.232934570313,,,0.000359231573369986,1.79300992769089E-5,0.000359232144028194,1.79301044260811E-5,0.961548388004303,0.961582183837891,31.3375568389893,8.6516802184633E-6,35,4,200,-2.41422767430777E-5,-0.101058587431908,0.0744907483458519,1,,,,,,,,,,,,,,,,
,3764754137.69423,281.243988037109,999.907531738281,,,6,,,,31.3652317734439,,,10,,,,,,,,,,,,,,,,,,,,,,281.089324951172,281.392059326172,999.907531738281,999.907531738281,,,8.0078182220459,,1,0,0,0,0.013885498046875,33.7243423461914,2,1,1,281.398651123047,0,2085105664,281.240396118164,,,0.000354090898206502,1.76735992868039E-5,0.000354091764375681,1.76736072629767E-5,0.96142441034317,0.96147608757019,31.3576755523682,,35,4,200,-5.63526418773108E-6,-0.104408472776413,0.0685809478163719,1,,,,,,,,,,,,,,,,
,3764754258.46065,285.247680664062,999.907531738281,,,6,,,,31.3889333548101,,,10,,,,,,,,,,,,,,,,,,,,,,285.083312988281,285.412048339844,999.907531738281,999.907531738281,,,8.13780498504639,,1,0,0,0,0.013885498046875,32.7468223571777,2,1,1,285.412048339844,0,2085105664,285.247445678711,,,0.000349074632453953,1.74234205700126E-5,0.000349076157617865,1.74234273587615E-5,0.96114045381546,0.961242854595184,31.3782615661621,0,35,4,200,2.53124223803525E-8,-0.106522738933563,0.0639359951019287,1,,,,,,,,,,,,,,,,
,3764754378.81111,289.246017456055,999.907531738281,,,6,,,,31.412917009131,,,10,,,,,,,,,,,,,,,,,,,,,,289.090911865234,289.368957519531,999.907531738281,999.907531738281,,,8.08512115478516,,1,0,0,0,0.013885498046875,33.7243423461914,2,1,1,289.401123046875,0,2085105664,289.243252563477,,,0.000344006952235377,1.71706081095655E-5,0.000344009359406447,1.71706279549652E-5,0.960957944393158,0.961107611656189,31.3999862670898,0,35,4,200,-1.09597203845624E-5,-0.108492851257324,0.0596342384815216,1,,,,,,,,,,,,,,,,
,3764754498.98629,293.235717773438,999.907531738281,,,6,,,,31.4371466217269,,,10,,,,,,,,,,,,,,,,,,,,,,293.081359863281,293.359069824219,999.907531738281,999.907531738281,,,8.04239654541016,,1,0,0,0,0.013885498046875,33.7243423461914,2,1,1,293.390075683594,0,2085105664,293.230123901367,,,0.000339224793357737,1.6932087811785E-5,0.000339228020394916,1.69321110640282E-5,0.960689663887024,0.960896968841553,31.4218826293945,0,35,4,200,2.92947504476615E-7,-0.110322155058384,0.0553691983222961,1,,,,,,,,,,,,,,,,
,3764754620.35082,297.235916137695,999.907531738281,,,6,,,,31.4621109799037,,,10,,,,,,,,,,,,,,,,,,,,,,297.082733154297,297.374389648438,999.907531738281,999.907531738281,,,8.01661396026611,,1,0,0,0,0.013885498046875,33.2355842590332,2,1,1,297.389099121094,0,2085105664,297.228701782227,,,0.000334561593742148,1.66994977515481E-5,0.000334564895170679,1.66995168824742E-5,0.960427939891815,0.960648596286774,31.4463119506836,0,35,4,200,-1.48729950524284E-5,-0.112801149487495,0.0506770648062229,1,,,,,,,,,,,,,,,,
,3764754763.94255,299.903289794922,999.907531738281,,,6,,,,31.4793608290106,,,10,,,,,,,,,,,,,,,,,,,,,,299.896545410156,299.912048339844,999.907531738281,999.907531738281,,,7.99412298202515,,1,0,0,0,0,33.2355842590332,1,1,1,299.910034179687,0,2085105664,299.906842041016,,,0.000331438095104524,1.65436625841108E-5,0.000331441512497626,1.65436725518788E-5,0.960315883159638,0.960560917854309,31.4626960754395,0,35,4,200,1.99161968339467E-6,-0.11659437417984,0.0453647188842297,1,,,,,,,,,,,,,,,,