File: examples/pb6051_dc_mag_v3.rso.dat
[Header]
TITLE,MPMS RSO Measurement
BYAPP,MPMS Measurement,1.1,Summary
FILEOPENTIME, 1500091929.501000 7/14/2017, 9:12:09 PM

INFO, APPNAME, MPMS MultiVu Application, Revision 1.60,  Build 081

INFO, NAME, pb6051
INFO, WEIGHT, 70.000
INFO, AREA,
INFO, LENGTH,
INFO, SHAPE,
INFO, COMMENT,
INFO, SEQUENCE FILE: pb6051_dc_mag_v3_ac1500Oe.seq


INFO, BACKGROUND DATA FILE:, None


STARTUPAXIS,X,4,LINEAR,AUTO,0.000000,0.000000
STARTUPAXIS,Y1,5,LINEAR,AUTO,0.000000,0.000000


STARTUPGROUP,Longitudinal
FIELDGROUP,Longitudinal,1,2,3,4,5,6,7,8,9,10,11,19,20,21,22,23,35
FIELDGROUP,Transverse,1,2,3,4,12,13,14,15,16,17,18,24,25,26,27,28,35

PLOT_APPEARANCE,ALL,HORZ_GRID_ON,VERT_GRID_ON,MARKERS_AND_LINES

[Data]
Time,Comment,Field (Oe),Temperature (K),Long Moment (emu),Long Scan Std Dev,Long Offset (cm),Long Offset Std Dev,Long Algorithm,Long Reg Fit,Long Reg Factor,Trans Moment (emu),Trans Scan Std Dev,Trans Offset (cm),Trans Offset Std Dev,Trans Algorithm,Trans Reg Fit,Trans Reg Factor,Long Moment [w/o ABS] (emu),Long Scan Std Dev [w/o ABS],Long Offset [w/o ABS] (cm),Long Offset Std Dev [w/o ABS],Long Reg Fit [w/o ABS],Trans Moment [w/o ABS] (emu),Trans Scan Std Dev [w/o ABS],Trans Offset [w/o ABS] (cm),Trans Offset Std Dev [w/o ABS],Trans Reg Fit [w/o ABS],RSO Position (deg),Amplitude (cm),Frequency,Cycles to Average,Scans per Measurement,Delta Temp (K),Error,EC Comp. Running,Using ABS,
1500091929.501,,7.244097e-002,1.799809e+000,-7.899054e-004,0.000000e+000,0.000000e+000,0.000000e+000,2,9.907821e-001,1.825000e+000,,,,,,,,,,,,,,,,,,1,7.000000e-001,4.000000e+000,1,1,2.049208e-004,0,1,0,
1500092193.057,,2.509501e+002,1.800498e+000,1.520787e-002,0.000000e+000,0.000000e+000,0.000000e+000,2,9.909872e-001,1.825000e+000,,,,,,,,,,,,,,,,,,1,7.000000e-001,4.000000e+000,1,1,8.029938e-004,0,0,0,
1500092429.505,,2.509501e+002,1.800776e+000,1.517774e-002,0.000000e+000,0.000000e+000,0.000000e+000,2,9.907600e-001,1.825000e+000,,,,,,,,,,,,,,,,,,1,7.000000e-001,4.000000e+000,1,1,2.880096e-004,0,0,0,
1500092661.015,,2.509501e+002,1.799861e+000,1.523248e-002,0.000000e+000,0.000000e+000,0.000000e+000,2,9.905189e-001,1.825000e+000,,,,,,,,,,,,,,,,,,1,7.000000e-001,4.000000e+000,1,1,6.779432e-004,0,1,0,
1500092903.213,,5.017262e+002,1.798301e+000,2.929440e-002,0.000000e+000,0.000000e+000,0.000000e+000,2,9.910253e-001,1.825000e+000,,,,,,,,,,,,,,,,,,1,7.000000e-001,4.000000e+000,1,1,5.530119e-004,0,1,0,
1500093136.402,,5.017262e+002,1.800931e+000,3.114205e-002,0.000000e+000,0.000000e+000,0.000000e+000,2,9.909192e-001,1.825000e+000,,,,,,,,,,,,,,,,,,1,7.000000e-001,4.000000e+000,1,1,1.008987e-003,0,0,0,
1500093371.102,,5.017262e+002,1.801167e+000,3.115297e-002,0.000000e+000,0.000000e+000,0.000000e+000,2,9.908362e-001,1.825000e+000,,,,,,,,,,,,,,,,,,1,7.000000e-001,4.000000e+000,1,1,8.296967e-005,0,0,0,
1500093602.912,,5.017262e+002,1.800148e+000,3.115272e-002,0.000000e+000,0.000000e+000,0.000000e+000,2,9.909669e-001,1.825000e+000,,,,,,,,,,,,,,,,,,1,7.000000e-001,4.000000e+000,1,1,5.550385e-004,0,1,0,
1500093845.679,,7.529224e+002,1.799430e+000,4.526230e-002,0.000000e+000,0.000000e+000,0.000000e+000,2,9.911848e-001,1.825000e+000,,,,,,,,,,,,,,,,,,1,7.000000e-001,4.000000e+000,1,1,2.098083e-005,0,0,0,
1500094072.031,,7.529224e+002,1.800848e+000,4.672521e-002,0.000000e+000,0.000000e+000,0.000000e+000,2,9.910643e-001,1.825000e+000,,,,,,,,,,,,,,,,,,1,7.000000e-001,4.000000e+000,1,1,1.296997e-003,0,0,0,
1500094306.767,,7.529224e+002,1.801631e+000,4.694789e-002,0.000000e+000,0.000000e+000,0.000000e+000,2,9.906896e-001,1.825000e+000,,,,,,,,,,,,,,,,,,1,7.000000e-001,4.000000e+000,1,1,8.050203e-004,0,0,0,
1500094539.668,,7.529224e+002,1.799388e+000,4.696918e-002,0.000000e+000,0.000000e+000,0.000000e+000,2,9.909121e-001,1.825000e+000,,,,,,,,,,,,,,,,,,1,7.000000e-001,4.000000e+000,1,1,1.129031e-003,0,1,0,
1500094776.897,,1.003481e+003,1.798773e+000,6.060742e-002,0.000000e+000,0.000000e+000,0.000000e+000,2,9.908843e-001,1.825000e+000,,,,,,,,,,,,,,,,,,1,7.000000e-001,4.000000e+000,1,1,3.479719e-004,0,1,0,
1500095009.482,,1.003481e+003,1.800766e+000,6.247377e-002,0.000000e+000,0.000000e+000,0.000000e+000,2,9.906496e-001,1.825000e+000,,,,,,,,,,,,,,,,,,1,7.000000e-001,4.000000e+000,1,1,1.585007e-003,0,0,0,
1500095246.193,,1.003481e+003,1.801024e+000,6.241486e-002,0.000000e+000,0.000000e+000,0.000000e+000,2,9.905702e-001,1.825000e+000,,,,,,,,,,,,,,,,,,1,7.000000e-001,4.000000e+000,1,1,1.813054e-003,0,0,0,
1500095475.326,,1.003481e+003,1.800354e+000,6.254613e-002,0.000000e+000,0.000000e+000,0.000000e+000,2,9.908935e-001,1.825000e+000,,,,,,,,,,,,,,,,,,1,7.000000e-001,4.000000e+000,1,1,1.379013e-003,0,1,0,
1500095762.571,,1.254533e+003,1.799040e+000,7.443132e-002,0.000000e+000,0.000000e+000,0.000000e+000,2,9.906090e-001,1.825000e+000,,,,,,,,,,,,,,,,,,1,7.000000e-001,4.000000e+000,1,1,4.709959e-004,0,0,0,
1500095998.177,,1.254533e+003,1.801157e+000,7.625102e-002,0.000000e+000,0.000000e+000,0.000000e+000,2,9.908165e-001,1.825000e+000,,,,,,,,,,,,,,,,,,1,7.000000e-001,4.000000e+000,1,1,8.029938e-004,0,0,0,
1500096227.362,,1.254533e+003,1.801445e+000,7.690347e-002,0.000000e+000,0.000000e+000,0.000000e+000,2,9.909392e-001,1.825000e+000,,,,,,,,,,,,,,,,,,1,7.000000e-001,4.000000e+000,1,1,2.269745e-004,0,0,0,
1500096460.402,,1.254533e+003,1.798999e+000,7.703202e-002,0.000000e+000,0.000000e+000,0.000000e+000,2,9.908314e-001,1.825000e+000,,,,,,,,,,,,,,,,,,1,7.000000e-001,4.000000e+000,1,1,7.189512e-004,0,1,0,
1500096689.923,,1.254533e+003,1.799296e+000,7.739297e-002,0.000000e+000,0.000000e+000,0.000000e+000,2,9.907332e-001,1.825000e+000,,,,,,,,,,,,,,,,,,1,7.000000e-001,4.000000e+000,1,1,1.436949e-003,0,1,0,
1500096918.418,,1.254533e+003,1.801116e+000,7.743458e-002,0.000000e+000,0.000000e+000,0.000000e+000,2,9.907222e-001,1.825000e+000,,,,,,,,,,,,,,,,,,1,7.000000e-001,4.000000e+000,1,1,3.919601e-004,0,0,0,
1500097152.688,,1.254533e+003,1.801745e+000,7.752346e-002,0.000000e+000,0.000000e+000,0.000000e+000,2,9.907638e-001,1.825000e+000,,,,,,,,,,,,,,,,,,1,7.000000e-001,4.000000e+000,1,1,1.240969e-004,0,0,0,
1500097383.122,,1.254533e+003,1.800107e+000,7.758528e-002,0.000000e+000,0.000000e+000,0.000000e+000,2,9.907331e-001,1.825000e+000,,,,,,,,,,,,,,,,,,1,7.000000e-001,4.000000e+000,1,1,1.006961e-003,0,1,0,
1500097618.477,,1.254533e+003,1.799409e+000,7.756329e-002,0.000000e+000,0.000000e+000,0.000000e+000,2,9.907021e-001,1.825000e+000,,,,,,,,,,,,,,,,,,1,7.000000e-001,4.000000e+000,1,1,2.002716e-005,0,1,0,
1500097850.492,,1.254533e+003,1.800076e+000,7.766724e-002,0.000000e+000,0.000000e+000,0.000000e+000,2,9.908291e-001,1.825000e+000,,,,,,,,,,,,,,,,,,1,7.000000e-001,4.000000e+000,1,1,5.750656e-004,0,0,0,
1500098081.285,,1.254533e+003,1.801353e+000,7.772645e-002,0.000000e+000,0.000000e+000,0.000000e+000,2,9.906450e-001,1.825000e+000,,,,,,,,,,,,,,,,,,1,7.000000e-001,4.000000e+000,1,1,4.196167e-005,0,0,0,
1500098314.417,,1.254533e+003,1.799511e+000,7.779410e-002,0.000000e+000,0.000000e+000,0.000000e+000,2,9.907987e-001,1.825000e+000,,,,,,,,,,,,,,,,,,1,7.000000e-001,4.000000e+000,1,1,3.489256e-004,0,1,0,
1500098551.297,,1.254533e+003,1.797964e+000,7.788014e-002,0.000000e+000,0.000000e+000,0.000000e+000,2,9.907346e-001,1.825000e+000,,,,,,,,,,,,,,,,,,1,7.000000e-001,4.000000e+000,1,1,4.100800e-005,0,1,0,
1500098782.373,,1.254533e+003,1.800992e+000,7.758642e-002,0.000000e+000,0.000000e+000,0.000000e+000,2,9.908652e-001,1.825000e+000,,,,,,,,,,,,,,,,,,1,7.000000e-001,4.000000e+000,1,1,7.629395e-004,0,0,0,
1500099018.704,,1.254533e+003,1.801631e+000,7.775398e-002,0.000000e+000,0.000000e+000,0.000000e+000,2,9.907122e-001,1.825000e+000,,,,,,,,,,,,,,,,,,1,7.000000e-001,4.000000e+000,1,1,3.510714e-004,0,0,0,
1500099250.134,,1.254533e+003,1.799881e+000,7.781727e-002,0.000000e+000,0.000000e+000,0.000000e+000,2,9.909012e-001,1.825000e+000,,,,,,,,,,,,,,,,,,1,7.000000e-001,4.000000e+000,1,1,2.260208e-004,0,1,0,
1500099484.710,,1.254533e+003,1.799399e+000,7.793168e-002,0.000000e+000,0.000000e+000,0.000000e+000,2,9.907336e-001,1.825000e+000,,,,,,,,,,,,,,,,,,1,7.000000e-001,4.000000e+000,1,1,4.520416e-004,0,1,0,
1500099716.025,,1.254533e+003,1.800344e+000,7.763936e-002,0.000000e+000,0.000000e+000,0.000000e+000,2,9.907326e-001,1.825000e+000,,,,,,,,,,,,,,,,,,1,7.000000e-001,4.000000e+000,1,1,4.940033e-004,0,0,0,
1500099952.505,,1.254533e+003,1.801147e+000,7.781165e-002,0.000000e+000,0.000000e+000,0.000000e+000,2,9.906080e-001,1.825000e+000,,,,,,,,,,,,,,,,,,1,7.000000e-001,4.000000e+000,1,1,1.319051e-003,0,0,0,
1500100182.676,,1.254533e+003,1.799614e+000,7.789949e-002,0.000000e+000,0.000000e+000,0.000000e+000,2,9.906953e-001,1.825000e+000,,,,,,,,,,,,,,,,,,1,7.000000e-001,4.000000e+000,1,1,6.198883e-005,0,1,0,
1500100412.727,,1.254533e+003,1.798445e+000,7.778482e-002,0.000000e+000,0.000000e+000,0.000000e+000,2,9.905481e-001,1.825000e+000,,,,,,,,,,,,,,,,,,1,7.000000e-001,4.000000e+000,1,1,2.660751e-004,0,1,0,
1500100645.666,,1.254533e+003,1.800118e+000,7.788227e-002,0.000000e+000,0.000000e+000,0.000000e+000,2,9.908515e-001,1.825000e+000,,,,,,,,,,,,,,,,,,1,7.000000e-001,4.000000e+000,1,1,6.580353e-004,0,0,0,
1500100878.297,,1.254533e+003,1.801641e+000,7.765704e-002,0.000000e+000,0.000000e+000,0.000000e+000,2,9.906275e-001,1.825000e+000,,,,,,,,,,,,,,,,,,1,7.000000e-001,4.000000e+000,1,1,2.889633e-004,0,0,0,
1500101109.412,,1.254533e+003,1.799296e+000,7.791036e-002,0.000000e+000,0.000000e+000,0.000000e+000,2,9.907548e-001,1.825000e+000,,,,,,,,,,,,,,,,,,1,7.000000e-001,4.000000e+000,1,1,2.460480e-004,0,1,0,
1500101354.088,,1.505208e+003,1.798455e+000,8.944399e-002,0.000000e+000,0.000000e+000,0.000000e+000,2,9.908221e-001,1.825000e+000,,,,,,,,,,,,,,,,,,1,7.000000e-001,4.000000e+000,1,1,5.741119e-004,0,1,0,
1500101586.086,,1.505208e+003,1.800786e+000,9.064596e-002,0.000000e+000,0.000000e+000,0.000000e+000,2,9.905368e-001,1.825000e+000,,,,,,,,,,,,,,,,,,1,7.000000e-001,4.000000e+000,1,1,8.029938e-004,0,0,0,
1500101818.336,,1.505208e+003,1.801003e+000,9.140054e-002,0.000000e+000,0.000000e+000,0.000000e+000,2,9.908201e-001,1.825000e+000,,,,,,,,,,,,,,,,,,1,7.000000e-001,4.000000e+000,1,1,4.940033e-004,0,0,0,
1500102045.841,,1.505208e+003,1.800488e+000,9.159883e-002,0.000000e+000,0.000000e+000,0.000000e+000,2,9.905429e-001,1.825000e+000,,,,,,,,,,,,,,,,,,1,7.000000e-001,4.000000e+000,1,1,4.520416e-004,0,1,0,
1500102278.812,,1.505208e+003,1.798527e+000,9.209607e-002,0.000000e+000,0.000000e+000,0.000000e+000,2,9.907576e-001,1.825000e+000,,,,,,,,,,,,,,,,,,1,7.000000e-001,4.000000e+000,1,1,7.579327e-004,0,1,0,
1500102512.902,,1.505208e+003,1.800211e+000,9.220627e-002,0.000000e+000,0.000000e+000,0.000000e+000,2,9.906542e-001,1.825000e+000,,,,,,,,,,,,,,,,,,1,7.000000e-001,4.000000e+000,1,1,1.295924e-003,0,0,0,
1500102749.617,,1.505208e+003,1.801765e+000,9.238626e-002,0.000000e+000,0.000000e+000,0.000000e+000,2,9.905550e-001,1.825000e+000,,,,,,,,,,,,,,,,,,1,7.000000e-001,4.000000e+000,1,1,4.130602e-004,0,0,0,
1500102981.801,,1.505208e+003,1.800684e+000,9.241255e-002,0.000000e+000,0.000000e+000,0.000000e+000,2,9.907566e-001,1.825000e+000,,,,,,,,,,,,,,,,,,1,7.000000e-001,4.000000e+000,1,1,8.440018e-004,0,1,0,
1500103213.276,,1.505208e+003,1.798096e+000,9.242675e-002,0.000000e+000,0.000000e+000,0.000000e+000,2,9.907326e-001,1.825000e+000,,,,,,,,,,,,,,,,,,1,7.000000e-001,4.000000e+000,1,1,3.889799e-004,0,1,0,
1500103444.166,,1.505208e+003,1.800498e+000,9.259060e-002,0.000000e+000,0.000000e+000,0.000000e+000,2,9.908195e-001,1.825000e+000,,,,,,,,,,,,,,,,,,1,7.000000e-001,4.000000e+000,1,1,1.049042e-003,0,0,0,
1500103674.491,,1.505208e+003,1.801147e+000,9.264882e-002,0.000000e+000,0.000000e+000,0.000000e+000,2,9.907078e-001,1.825000e+000,,,,,,,,,,,,,,,,,,1,7.000000e-001,4.000000e+000,1,1,1.237035e-003,0,0,0,
1500103906.653,,1.505208e+003,1.801023e+000,9.286409e-002,0.000000e+000,0.000000e+000,0.000000e+000,2,9.907597e-001,1.825000e+000,,,,,,,,,,,,,,,,,,1,7.000000e-001,4.000000e+000,1,1,6.179810e-004,0,1,0,
1500104139.613,,1.505208e+003,1.798794e+000,9.283740e-002,0.000000e+000,0.000000e+000,0.000000e+000,2,9.907601e-001,1.825000e+000,,,,,,,,,,,,,,,,,,1,7.000000e-001,4.000000e+000,1,1,6.091595e-005,0,1,0,
1500104369.519,,1.505208e+003,1.799871e+000,9.273801e-002,0.000000e+000,0.000000e+000,0.000000e+000,2,9.907313e-001,1.825000e+000,,,,,,,,,,,,,,,,,,1,7.000000e-001,4.000000e+000,1,1,7.809401e-004,0,0,0,
1500104603.207,,1.505208e+003,1.801405e+000,9.275951e-002,0.000000e+000,0.000000e+000,0.000000e+000,2,9.907470e-001,1.825000e+000,,,,,,,,,,,,,,,,,,1,7.000000e-001,4.000000e+000,1,1,5.980730e-004,0,0,0,
1500104837.082,,1.505208e+003,1.799408e+000,9.276086e-002,0.000000e+000,0.000000e+000,0.000000e+000,2,9.908926e-001,1.825000e+000,,,,,,,,,,,,,,,,,,1,7.000000e-001,4.000000e+000,1,1,5.129576e-004,0,1,0,
1500105068.568,,1.505208e+003,1.799121e+000,9.278829e-002,0.000000e+000,0.000000e+000,0.000000e+000,2,9.906628e-001,1.825000e+000,,,,,,,,,,,,,,,,,,1,7.000000e-001,4.000000e+000,1,1,2.250671e-004,0,1,0,
1500105302.550,,1.505208e+003,1.800395e+000,9.290501e-002,0.000000e+000,0.000000e+000,0.000000e+000,2,9.907147e-001,1.825000e+000,,,,,,,,,,,,,,,,,,1,7.000000e-001,4.000000e+000,1,1,1.850128e-004,0,0,0,
1500105534.160,,1.505208e+003,1.800838e+000,9.263343e-002,0.000000e+000,0.000000e+000,0.000000e+000,2,9.905885e-001,1.825000e+000,,,,,,,,,,,,,,,,,,1,7.000000e-001,4.000000e+000,1,1,3.299713e-004,0,0,0,
1500105768.196,,1.505208e+003,1.799964e+000,9.293748e-002,0.000000e+000,0.000000e+000,0.000000e+000,2,9.906662e-001,1.825000e+000,,,,,,,,,,,,,,,,,,1,7.000000e-001,4.000000e+000,1,1,6.779432e-004,0,1,0,
1500106000.366,,1.505208e+003,1.798373e+000,9.293316e-002,0.000000e+000,0.000000e+000,0.000000e+000,2,9.908252e-001,1.825000e+000,,,,,,,,,,,,,,,,,,1,7.000000e-001,4.000000e+000,1,1,4.100800e-005,0,1,0,
1500106234.627,,1.505208e+003,1.799757e+000,9.285286e-002,0.000000e+000,0.000000e+000,0.000000e+000,2,9.907008e-001,1.825000e+000,,,,,,,,,,,,,,,,,,1,7.000000e-001,4.000000e+000,1,1,1.850128e-004,0,0,0,
1500106465.183,,1.505208e+003,1.800663e+000,9.284182e-002,0.000000e+000,0.000000e+000,0.000000e+000,2,9.907333e-001,1.825000e+000,,,,,,,,,,,,,,,,,,1,7.000000e-001,4.000000e+000,1,1,3.919601e-004,0,0,0,
1500106705.728,,1.756041e+003,1.800704e+000,1.008926e-001,0.000000e+000,0.000000e+000,0.000000e+000,2,9.906794e-001,1.825000e+000,,,,,,,,,,,,,,,,,,1,7.000000e-001,4.000000e+000,1,1,2.679825e-004,0,1,0,
1500106939.937,,1.756041e+003,1.798650e+000,1.047077e-001,0.000000e+000,0.000000e+000,0.000000e+000,2,9.909204e-001,1.825000e+000,,,,,,,,,,,,,,,,,,1,7.000000e-001,4.000000e+000,1,1,2.098083e-005,0,1,0,
1500107170.490,,1.756041e+003,1.800488e+000,1.057739e-001,0.000000e+000,0.000000e+000,0.000000e+000,2,9.907109e-001,1.825000e+000,,,,,,,,,,,,,,,,,,1,7.000000e-001,4.000000e+000,1,1,3.299713e-004,0,0,0,
1500107402.631,,1.756041e+003,1.801693e+000,1.063285e-001,0.000000e+000,0.000000e+000,0.000000e+000,2,9.908192e-001,1.825000e+000,,,,,,,,,,,,,,,,,,1,7.000000e-001,4.000000e+000,1,1,9.690523e-004,0,0,0,
1500107637.951,,1.756041e+003,1.800663e+000,1.066899e-001,0.000000e+000,0.000000e+000,0.000000e+000,2,9.905962e-001,1.825000e+000,,,,,,,,,,,,,,,,,,1,7.000000e-001,4.000000e+000,1,1,1.440048e-004,0,1,0,
1500107869.469,,1.756041e+003,1.798158e+000,1.070755e-001,0.000000e+000,0.000000e+000,0.000000e+000,2,9.906794e-001,1.825000e+000,,,,,,,,,,,,,,,,,,1,7.000000e-001,4.000000e+000,1,1,1.412988e-003,0,1,0,
1500108103.470,,1.756041e+003,1.799840e+000,1.071948e-001,0.000000e+000,0.000000e+000,0.000000e+000,2,9.908812e-001,1.825000e+000,,,,,,,,,,,,,,,,,,1,7.000000e-001,4.000000e+000,1,1,9.249449e-004,0,0,0,
1500108336.810,,1.756041e+003,1.801291e+000,1.072379e-001,0.000000e+000,0.000000e+000,0.000000e+000,2,9.908006e-001,1.825000e+000,,,,,,,,,,,,,,,,,,1,7.000000e-001,4.000000e+000,1,1,1.070976e-003,0,0,0,
1500108569.580,,1.756041e+003,1.800961e+000,1.073055e-001,0.000000e+000,0.000000e+000,0.000000e+000,2,9.907744e-001,1.825000e+000,,,,,,,,,,,,,,,,,,1,7.000000e-001,4.000000e+000,1,1,9.469986e-004,0,1,0,
1500108804.107,,1.756041e+003,1.798844e+000,1.074754e-001,0.000000e+000,0.000000e+000,0.000000e+000,2,9.909648e-001,1.825000e+000,,,,,,,,,,,,,,,,,,1,7.000000e-001,4.000000e+000,1,1,4.100800e-005,0,1,0,
1500109043.672,,1.756041e+003,1.799521e+000,1.075121e-001,0.000000e+000,0.000000e+000,0.000000e+000,2,9.907925e-001,1.825000e+000,,,,,,,,,,,,,,,,,,1,7.000000e-001,4.000000e+000,1,1,1.229048e-004,0,0,0,
1500109275.192,,1.756041e+003,1.800159e+000,1.074465e-001,0.000000e+000,0.000000e+000,0.000000e+000,2,9.907900e-001,1.825000e+000,,,,,,,,,,,,,,,,,,1,7.000000e-001,4.000000e+000,1,1,7.820129e-004,0,0,0,
1500109509.713,,1.756041e+003,1.801590e+000,1.075380e-001,0.000000e+000,0.000000e+000,0.000000e+000,2,9.905406e-001,1.825000e+000,,,,,,,,,,,,,,,,,,1,7.000000e-001,4.000000e+000,1,1,9.690523e-004,0,1,0,
1500109744.868,,1.756041e+003,1.799122e+000,1.075191e-001,0.000000e+000,0.000000e+000,0.000000e+000,2,9.906122e-001,1.825000e+000,,,,,,,,,,,,,,,,,,1,7.000000e-001,4.000000e+000,1,1,4.720688e-004,0,1,0,
1500109981.993,,1.756041e+003,1.799368e+000,1.076320e-001,0.000000e+000,0.000000e+000,0.000000e+000,2,9.906878e-001,1.825000e+000,,,,,,,,,,,,,,,,,,1,7.000000e-001,4.000000e+000,1,1,6.359816e-004,0,0,0,
1500110217.859,,1.756041e+003,1.801095e+000,1.075234e-001,0.000000e+000,0.000000e+000,0.000000e+000,2,9.908170e-001,1.825000e+000,,,,,,,,,,,,,,,,,,1,7.000000e-001,4.000000e+000,1,1,7.629395e-004,0,0,0,
1500110449.944,,1.756041e+003,1.800426e+000,1.076574e-001,0.000000e+000,0.000000e+000,0.000000e+000,2,9.906394e-001,1.825000e+000,,,,,,,,,,,,,,,,,,1,7.000000e-001,4.000000e+000,1,1,4.119873e-004,0,1,0,
1500110683.316,,1.756041e+003,1.799194e+000,1.076152e-001,0.000000e+000,0.000000e+000,0.000000e+000,2,9.907799e-001,1.825000e+000,,,,,,,,,,,,,,,,,,1,7.000000e-001,4.000000e+000,1,1,4.510880e-004,0,1,0,
1500110916.827,,1.756041e+003,1.799357e+000,1.074437e-001,0.000000e+000,0.000000e+000,0.000000e+000,2,9.906710e-001,1.825000e+000,,,,,,,,,,,,,,,,,,1,7.000000e-001,4.000000e+000,1,1,3.689528e-004,0,0,0,
1500111149.132,,1.756041e+003,1.801281e+000,1.075693e-001,0.000000e+000,0.000000e+000,0.000000e+000,2,9.907612e-001,1.825000e+000,,,,,,,,,,,,,,,,,,1,7.000000e-001,4.000000e+000,1,1,1.134038e-003,0,0,0,
1500111383.037,,1.756041e+003,1.800766e+000,1.076308e-001,0.000000e+000,0.000000e+000,0.000000e+000,2,9.906224e-001,1.825000e+000,,,,,,,,,,,,,,,,,,1,7.000000e-001,4.000000e+000,1,1,8.440018e-004,0,1,0,
1500111614.603,,1.756041e+003,1.798722e+000,1.077577e-001,0.000000e+000,0.000000e+000,0.000000e+000,2,9.907641e-001,1.825000e+000,,,,,,,,,,,,,,,,,,1,7.000000e-001,4.000000e+000,1,1,2.460480e-004,0,1,0,
1500111851.497,,1.756041e+003,1.799152e+000,1.077175e-001,0.000000e+000,0.000000e+000,0.000000e+000,2,9.907531e-001,1.825000e+000,,,,,,,,,,,,,,,,,,1,7.000000e-001,4.000000e+000,1,1,4.510880e-004,0,0,0,
1500112087.117,,1.756041e+003,1.801333e+000,1.073686e-001,0.000000e+000,0.000000e+000,0.000000e+000,2,9.906798e-001,1.825000e+000,,,,,,,,,,,,,,,,,,1,7.000000e-001,4.000000e+000,1,1,1.525998e-003,0,0,0,
1500112330.693,,2.007050e+003,1.801260e+000,1.179822e-001,0.000000e+000,0.000000e+000,0.000000e+000,2,9.906906e-001,1.825000e+000,,,,,,,,,,,,,,,,,,1,7.000000e-001,4.000000e+000,1,1,5.569458e-004,0,1,0,
1500112567.675,,2.007050e+003,1.799060e+000,1.199825e-001,0.000000e+000,0.000000e+000,0.000000e+000,2,9.907625e-001,1.825000e+000,,,,,,,,,,,,,,,,,,1,7.000000e-001,4.000000e+000,1,1,5.540848e-004,0,1,0,
1500112801.387,,2.007050e+003,1.799625e+000,1.208595e-001,0.000000e+000,0.000000e+000,0.000000e+000,2,9.907051e-001,1.825000e+000,,,,,,,,,,,,,,,,,,1,7.000000e-001,4.000000e+000,1,1,1.232028e-003,0,0,0,
1500113037.698,,2.007050e+003,1.801044e+000,1.212062e-001,0.000000e+000,0.000000e+000,0.000000e+000,2,9.906806e-001,1.825000e+000,,,,,,,,,,,,,,,,,,1,7.000000e-001,4.000000e+000,1,1,1.029968e-003,0,0,0,
1500113274.488,,2.007050e+003,1.801477e+000,1.212193e-001,0.000000e+000,0.000000e+000,0.000000e+000,2,9.906689e-001,1.825000e+000,,,,,,,,,,,,,,,,,,1,7.000000e-001,4.000000e+000,1,1,7.840395e-004,0,1,0,
1500113509.303,,2.007050e+003,1.798087e+000,1.217182e-001,0.000000e+000,0.000000e+000,0.000000e+000,2,9.906973e-001,1.825000e+000,,,,,,,,,,,,,,,,,,1,7.000000e-001,4.000000e+000,1,1,1.105070e-003,0,1,0,
1500113744.529,,2.007050e+003,1.799112e+000,1.217319e-001,0.000000e+000,0.000000e+000,0.000000e+000,2,9.906768e-001,1.825000e+000,,,,,,,,,,,,,,,,,,1,7.000000e-001,4.000000e+000,1,1,8.209944e-004,0,0,0,
1500113977.334,,2.007050e+003,1.801281e+000,1.218354e-001,0.000000e+000,0.000000e+000,0.000000e+000,2,9.907838e-001,1.825000e+000,,,,,,,,,,,,,,,,,,1,7.000000e-001,4.000000e+000,1,1,1.051068e-003,0,0,0,
1500114209.828,,2.007050e+003,1.801301e+000,1.218982e-001,0.000000e+000,0.000000e+000,0.000000e+000,2,9.908028e-001,1.825000e+000,,,,,,,,,,,,,,,,,,1,7.000000e-001,4.000000e+000,1,1,1.050949e-003,0,1,0,
1500114441.173,,2.007050e+003,1.798465e+000,1.216434e-001,0.000000e+000,0.000000e+000,0.000000e+000,2,9.907112e-001,1.825000e+000,,,,,,,,,,,,,,,,,,1,7.000000e-001,4.000000e+000,1,1,3.070831e-004,0,1,0,
1500114672.253,,2.007050e+003,1.799111e+000,1.218923e-001,0.000000e+000,0.000000e+000,0.000000e+000,2,9.908680e-001,1.825000e+000,,,,,,,,,,,,,,,,,,1,7.000000e-001,4.000000e+000,1,1,1.066923e-003,0,0,0,
1500114907.418,,2.007050e+003,1.800869e+000,1.219260e-001,0.000000e+000,0.000000e+000,0.000000e+000,2,9.908241e-001,1.825000e+000,,,,,,,,,,,,,,,,,,1,7.000000e-001,4.000000e+000,1,1,7.200241e-004,0,0,0,
1500115138.975,,2.007050e+003,1.800745e+000,1.219583e-001,0.000000e+000,0.000000e+000,0.000000e+000,2,9.908178e-001,1.825000e+000,,,,,,,,,,,,,,,,,,1,7.000000e-001,4.000000e+000,1,1,5.970001e-004,0,1,0,
1500115369.645,,2.007050e+003,1.798619e+000,1.220506e-001,0.000000e+000,0.000000e+000,0.000000e+000,2,9.908088e-001,1.825000e+000,,,,,,,,,,,,,,,,,,1,7.000000e-001,4.000000e+000,1,1,0.000000e+000,0,1,0,
1500115601.780,,2.007050e+003,1.798722e+000,1.220175e-001,0.000000e+000,0.000000e+000,0.000000e+000,2,9.907764e-001,1.825000e+000,,,,,,,,,,,,,,,,,,1,7.000000e-001,4.000000e+000,1,1,1.107097e-003,0,0,0,
1500115835.808,,2.007050e+003,1.800550e+000,1.219837e-001,0.000000e+000,0.000000e+000,0.000000e+000,2,9.908139e-001,1.825000e+000,,,,,,,,,,,,,,,,,,1,7.000000e-001,4.000000e+000,1,1,4.529953e-004,0,0,0,
1500116068.620,,2.007050e+003,1.801466e+000,1.220572e-001,0.000000e+000,0.000000e+000,0.000000e+000,2,9.907624e-001,1.825000e+000,,,,,,,,,,,,,,,,,,1,7.000000e-001,4.000000e+000,1,1,4.329681e-004,0,1,0,
1500116304.780,,2.007050e+003,1.798558e+000,1.217710e-001,0.000000e+000,0.000000e+000,0.000000e+000,2,9.906803e-001,1.825000e+000,,,,,,,,,,,,,,,,,,1,7.000000e-001,4.000000e+000,1,1,8.201599e-005,0,1,0,
1500116537.556,,2.007050e+003,1.799625e+000,1.219982e-001,0.000000e+000,0.000000e+000,0.000000e+000,2,9.907815e-001,1.825000e+000,,,,,,,,,,,,,,,,,,1,7.000000e-001,4.000000e+000,1,1,1.232028e-003,0,0,0,
1500116774.897,,2.007050e+003,1.800725e+000,1.217613e-001,0.000000e+000,0.000000e+000,0.000000e+000,2,9.906388e-001,1.825000e+000,,,,,,,,,,,,,,,,,,1,7.000000e-001,4.000000e+000,1,1,2.269745e-004,0,0,0,
1500117006.097,,2.007050e+003,1.801414e+000,1.219808e-001,0.000000e+000,0.000000e+000,0.000000e+000,2,9.908028e-001,1.825000e+000,,,,,,,,,,,,,,,,,,1,7.000000e-001,4.000000e+000,1,1,1.649857e-004,0,1,0,
1500117242.183,,2.007050e+003,1.798937e+000,1.220853e-001,0.000000e+000,0.000000e+000,0.000000e+000,2,9.906743e-001,1.825000e+000,,,,,,,,,,,,,,,,,,1,7.000000e-001,4.000000e+000,1,1,7.179976e-004,0,1,0,
1500117475.393,,2.007050e+003,1.798937e+000,1.218376e-001,0.000000e+000,0.000000e+000,0.000000e+000,2,9.907501e-001,1.825000e+000,,,,,,,,,,,,,,,,,,1,7.000000e-001,4.000000e+000,1,1,3.899336e-004,0,0,0,
1500117720.131,,2.257913e+003,1.801476e+000,1.292161e-001,0.000000e+000,0.000000e+000,0.000000e+000,2,9.907188e-001,1.825000e+000,,,,,,,,,,,,,,,,,,1,7.000000e-001,4.000000e+000,1,1,1.649857e-004,0,0,0,
1500117958.641,,2.257913e+003,1.801333e+000,1.338073e-001,0.000000e+000,0.000000e+000,0.000000e+000,2,9.905519e-001,1.825000e+000,,,,,,,,,,,,,,,,,,1,7.000000e-001,4.000000e+000,1,1,1.072049e-003,0,1,0,
1500118193.066,,2.257913e+003,1.798599e+000,1.349781e-001,0.000000e+000,0.000000e+000,0.000000e+000,2,9.906421e-001,1.825000e+000,,,,,,,,,,,,,,,,,,1,7.000000e-001,4.000000e+000,1,1,1.640320e-004,0,1,0,
1500118427.233,,2.257913e+003,1.799470e+000,1.354187e-001,0.000000e+000,0.000000e+000,0.000000e+000,2,9.907091e-001,1.825000e+000,,,,,,,,,,,,,,,,,,1,7.000000e-001,4.000000e+000,1,1,1.429319e-004,0,0,0,
1500118660.014,,2.257913e+003,1.800931e+000,1.356219e-001,0.000000e+000,0.000000e+000,0.000000e+000,2,9.907533e-001,1.825000e+000,,,,,,,,,,,,,,,,,,1,7.000000e-001,4.000000e+000,1,1,3.910065e-004,0,0,0,
1500118895.759,,2.257913e+003,1.801147e+000,1.357256e-001,0.000000e+000,0.000000e+000,0.000000e+000,2,9.907591e-001,1.825000e+000,,,,,,,,,,,,,,,,,,1,7.000000e-001,4.000000e+000,1,1,1.401067e-003,0,1,0,
1500119127.742,,2.257913e+003,1.798804e+000,1.359412e-001,0.000000e+000,0.000000e+000,0.000000e+000,2,9.907264e-001,1.825000e+000,,,,,,,,,,,,,,,,,,1,7.000000e-001,4.000000e+000,1,1,8.610487e-004,0,1,0,
1500119357.964,,2.257913e+003,1.798722e+000,1.359090e-001,0.000000e+000,0.000000e+000,0.000000e+000,2,9.907328e-001,1.825000e+000,,,,,,,,,,,,,,,,,,1,7.000000e-001,4.000000e+000,1,1,8.200407e-004,0,0,0,
1500119592.859,,2.257913e+003,1.801044e+000,1.358710e-001,0.000000e+000,0.000000e+000,0.000000e+000,2,9.907345e-001,1.825000e+000,,,,,,,,,,,,,,,,,,1,7.000000e-001,4.000000e+000,1,1,7.820129e-004,0,0,0,
1500119830.880,,2.257913e+003,1.801786e+000,1.359211e-001,0.000000e+000,0.000000e+000,0.000000e+000,2,9.904811e-001,1.825000e+000,,,,,,,,,,,,,,,,,,1,7.000000e-001,4.000000e+000,1,1,2.059937e-004,0,1,0,
1500120066.421,,2.257913e+003,1.799122e+000,1.359824e-001,0.000000e+000,0.000000e+000,0.000000e+000,2,9.906917e-001,1.825000e+000,,,,,,,,,,,,,,,,,,1,7.000000e-001,4.000000e+000,1,1,9.649992e-004,0,1,0,
1500120298.426,,2.257913e+003,1.799080e+000,1.359373e-001,0.000000e+000,0.000000e+000,0.000000e+000,2,9.907960e-001,1.825000e+000,,,,,,,,,,,,,,,,,,1,7.000000e-001,4.000000e+000,1,1,1.850128e-004,0,0,0,
1500120532.276,,2.257913e+003,1.800838e+000,1.356414e-001,0.000000e+000,0.000000e+000,0.000000e+000,2,9.906560e-001,1.825000e+000,,,,,,,,,,,,,,,,,,1,7.000000e-001,4.000000e+000,1,1,1.029968e-003,0,0,0,
1500120762.442,,2.257913e+003,1.801281e+000,1.359129e-001,0.000000e+000,0.000000e+000,0.000000e+000,2,9.907861e-001,1.825000e+000,,,,,,,,,,,,,,,,,,1,7.000000e-001,4.000000e+000,1,1,5.159378e-004,0,1,0,
1500120993.468,,2.257913e+003,1.798599e+000,1.360323e-001,0.000000e+000,0.000000e+000,0.000000e+000,2,9.906219e-001,1.825000e+000,,,,,,,,,,,,,,,,,,1,7.000000e-001,4.000000e+000,1,1,1.106024e-003,0,1,0,
1500121227.783,,2.257913e+003,1.799655e+000,1.360073e-001,0.000000e+000,0.000000e+000,0.000000e+000,2,9.906916e-001,1.825000e+000,,,,,,,,,,,,,,,,,,1,7.000000e-001,4.000000e+000,1,1,4.719496e-004,0,0,0,
1500121463.574,,2.257913e+003,1.801549e+000,1.359678e-001,0.000000e+000,0.000000e+000,0.000000e+000,2,9.908072e-001,1.825000e+000,,,,,,,,,,,,,,,,,,1,7.000000e-001,4.000000e+000,1,1,5.559921e-004,0,0,0,
1500121694.799,,2.257913e+003,1.800786e+000,1.360209e-001,0.000000e+000,0.000000e+000,0.000000e+000,2,9.907807e-001,1.825000e+000,,,,,,,,,,,,,,,,,,1,7.000000e-001,4.000000e+000,1,1,5.149841e-004,0,1,0,
1500121930.979,,2.257913e+003,1.799111e+000,1.361268e-001,0.000000e+000,0.000000e+000,0.000000e+000,2,9.906958e-001,1.825000e+000,,,,,,,,,,,,,,,,,,1,7.000000e-001,4.000000e+000,1,1,1.640320e-004,0,1,0,
1500122165.395,,2.257913e+003,1.799214e+000,1.360374e-001,0.000000e+000,0.000000e+000,0.000000e+000,2,9.906925e-001,1.825000e+000,,,,,,,,,,,,,,,,,,1,7.000000e-001,4.000000e+000,1,1,1.107931e-003,0,0,0,
1500122399.540,,2.257913e+003,1.801250e+000,1.359347e-001,0.000000e+000,0.000000e+000,0.000000e+000,2,9.907286e-001,1.825000e+000,,,,,,,,,,,,,,,,,,1,7.000000e-001,4.000000e+000,1,1,2.880096e-004,0,0,0,
1500122631.445,,2.257913e+003,1.800797e+000,1.359024e-001,0.000000e+000,0.000000e+000,0.000000e+000,2,9.908655e-001,1.825000e+000,,,,,,,,,,,,,,,,,,1,7.000000e-001,4.000000e+000,1,1,4.119873e-004,0,1,0,
1500122869.466,,2.257913e+003,1.799255e+000,1.358457e-001,0.000000e+000,0.000000e+000,0.000000e+000,2,9.904181e-001,1.825000e+000,,,,,,,,,,,,,,,,,,1,7.000000e-001,4.000000e+000,1,1,8.620024e-004,0,1,0,
1500123105.722,,2.257913e+003,1.799543e+000,1.360038e-001,0.000000e+000,0.000000e+000,0.000000e+000,2,9.906975e-001,1.825000e+000,,,,,,,,,,,,,,,,,,1,7.000000e-001,4.000000e+000,1,1,1.520038e-003,0,0,0,
1500123347.846,,2.508776e+003,1.800467e+000,1.463878e-001,0.000000e+000,0.000000e+000,0.000000e+000,2,9.907589e-001,1.825000e+000,,,,,,,,,,,,,,,,,,1,7.000000e-001,4.000000e+000,1,1,8.230209e-004,0,0,0,
1500123577.107,,2.508776e+003,1.801538e+000,1.484828e-001,0.000000e+000,0.000000e+000,0.000000e+000,2,9.907050e-001,1.825000e+000,,,,,,,,,,,,,,,,,,1,7.000000e-001,4.000000e+000,1,1,8.250475e-004,0,1,0,
1500123804.337,,2.508776e+003,1.798220e+000,1.490004e-001,0.000000e+000,0.000000e+000,0.000000e+000,2,9.907672e-001,1.825000e+000,,,,,,,,,,,,,,,,,,1,7.000000e-001,4.000000e+000,1,1,1.003981e-003,0,1,0,
1500124037.829,,2.508776e+003,1.799317e+000,1.489214e-001,0.000000e+000,0.000000e+000,0.000000e+000,2,9.906671e-001,1.825000e+000,,,,,,,,,,,,,,,,,,1,7.000000e-001,4.000000e+000,1,1,1.025915e-003,0,0,0,
1500124269.854,,2.508776e+003,1.801487e+000,1.492310e-001,0.000000e+000,0.000000e+000,0.000000e+000,2,9.906827e-001,1.825000e+000,,,,,,,,,,,,,,,,,,1,7.000000e-001,4.000000e+000,1,1,5.160570e-004,0,0,0,
1500124506.175,,2.508776e+003,1.801271e+000,1.494207e-001,0.000000e+000,0.000000e+000,0.000000e+000,2,9.906225e-001,1.825000e+000,,,,,,,,,,,,,,,,,,1,7.000000e-001,4.000000e+000,1,1,8.660555e-004,0,1,0,
1500124738.340,,2.508776e+003,1.798763e+000,1.493231e-001,0.000000e+000,0.000000e+000,0.000000e+000,2,9.905735e-001,1.825000e+000,,,,,,,,,,,,,,,,,,1,7.000000e-001,4.000000e+000,1,1,7.380247e-004,0,1,0,
1500124970.525,,2.508776e+003,1.799255e+000,1.495094e-001,0.000000e+000,0.000000e+000,0.000000e+000,2,9.907637e-001,1.825000e+000,,,,,,,,,,,,,,,,,,1,7.000000e-001,4.000000e+000,1,1,7.799864e-004,0,0,0,
1500125206.425,,2.508776e+003,1.801219e+000,1.494138e-001,0.000000e+000,0.000000e+000,0.000000e+000,2,9.907589e-001,1.825000e+000,,,,,,,,,,,,,,,,,,1,7.000000e-001,4.000000e+000,1,1,8.449554e-004,0,0,0,
1500125442.160,,2.508776e+003,1.801858e+000,1.493752e-001,0.000000e+000,0.000000e+000,0.000000e+000,2,9.906458e-001,1.825000e+000,,,,,,,,,,,,,,,,,,1,7.000000e-001,4.000000e+000,1,1,2.690554e-004,0,1,0,
1500125675.110,,2.508776e+003,1.799604e+000,1.494588e-001,0.000000e+000,0.000000e+000,0.000000e+000,2,9.907960e-001,1.825000e+000,,,,,,,,,,,,,,,,,,1,7.000000e-001,4.000000e+000,1,1,2.878904e-004,0,1,0,
1500125905.922,,2.508776e+003,1.799625e+000,1.492333e-001,0.000000e+000,0.000000e+000,0.000000e+000,2,9.906543e-001,1.825000e+000,,,,,,,,,,,,,,,,,,1,7.000000e-001,4.000000e+000,1,1,1.067996e-003,0,0,0,
1500126135.397,,2.508776e+003,1.800220e+000,1.493937e-001,0.000000e+000,0.000000e+000,0.000000e+000,2,9.907614e-001,1.825000e+000,,,,,,,,,,,,,,,,,,1,7.000000e-001,4.000000e+000,1,1,3.290176e-004,0,0,0,
1500126366.127,,2.508776e+003,1.800900e+000,1.494469e-001,0.000000e+000,0.000000e+000,0.000000e+000,2,9.908358e-001,1.825000e+000,,,,,,,,,,,,,,,,,,1,7.000000e-001,4.000000e+000,1,1,9.059906e-004,0,1,0,
1500126601.066,,2.508776e+003,1.798393e+000,1.496612e-001,0.000000e+000,0.000000e+000,0.000000e+000,2,9.905943e-001,1.825000e+000,,,,,,,,,,,,,,,,,,1,7.000000e-001,4.000000e+000,1,1,6.150007e-004,0,1,0,
1500126831.768,,2.508776e+003,1.798845e+000,1.495187e-001,0.000000e+000,0.000000e+000,0.000000e+000,2,9.906862e-001,1.825000e+000,,,,,,,,,,,,,,,,,,1,7.000000e-001,4.000000e+000,1,1,2.869368e-004,0,0,0,
1500127064.802,,2.508776e+003,1.800663e+000,1.491421e-001,0.000000e+000,0.000000e+000,0.000000e+000,2,9.906654e-001,1.825000e+000,,,,,,,,,,,,,,,,,,1,7.000000e-001,4.000000e+000,1,1,1.029968e-004,0,0,0,
1500127297.683,,2.508776e+003,1.801085e+000,1.495430e-001,0.000000e+000,0.000000e+000,0.000000e+000,2,9.908295e-001,1.825000e+000,,,,,,,,,,,,,,,,,,1,7.000000e-001,4.000000e+000,1,1,2.470016e-004,0,1,0,
1500127528.534,,2.508776e+003,1.799183e+000,1.495302e-001,0.000000e+000,0.000000e+000,0.000000e+000,2,9.906781e-001,1.825000e+000,,,,,,,,,,,,,,,,,,1,7.000000e-001,4.000000e+000,1,1,3.900528e-004,0,1,0,
1500127759.449,,2.508776e+003,1.799060e+000,1.491884e-001,0.000000e+000,0.000000e+000,0.000000e+000,2,9.905747e-001,1.825000e+000,,,,,,,,,,,,,,,,,,1,7.000000e-001,4.000000e+000,1,1,1.538992e-003,0,0,0,
1500127994.565,,2.508776e+003,1.801281e+000,1.495136e-001,0.000000e+000,0.000000e+000,0.000000e+000,2,9.908015e-001,1.825000e+000,,,,,,,,,,,,,,,,,,1,7.000000e-001,4.000000e+000,1,1,1.134038e-003,0,0,0,
1500128224.741,,2.508776e+003,1.801425e+000,1.491264e-001,0.000000e+000,0.000000e+000,0.000000e+000,2,9.906268e-001,1.825000e+000,,,,,,,,,,,,,,,,,,1,7.000000e-001,4.000000e+000,1,1,2.679825e-004,0,1,0,
1500128456.076,,2.508776e+003,1.799009e+000,1.494911e-001,0.000000e+000,0.000000e+000,0.000000e+000,2,9.907575e-001,1.825000e+000,,,,,,,,,,,,,,,,,,1,7.000000e-001,4.000000e+000,1,1,1.271963e-003,0,1,0,
1500128702.417,,2.760146e+003,1.799143e+000,1.559372e-001,0.000000e+000,0.000000e+000,0.000000e+000,2,9.909124e-001,1.825000e+000,,,,,,,,,,,,,,,,,,1,7.000000e-001,4.000000e+000,1,1,6.769896e-004,0,0,0,
1500128940.143,,2.760146e+003,1.801189e+000,1.612986e-001,0.000000e+000,0.000000e+000,0.000000e+000,2,9.907144e-001,1.825000e+000,,,,,,,,,,,,,,,,,,1,7.000000e-001,4.000000e+000,1,1,1.484036e-003,0,0,0,
1500129176.622,,2.760146e+003,1.800447e+000,1.620684e-001,0.000000e+000,0.000000e+000,0.000000e+000,2,9.905557e-001,1.825000e+000,,,,,,,,,,,,,,,,,,1,7.000000e-001,4.000000e+000,1,1,9.880066e-004,0,1,0,
1500129413.013,,2.760146e+003,1.798342e+000,1.624346e-001,0.000000e+000,0.000000e+000,0.000000e+000,2,9.906591e-001,1.825000e+000,,,,,,,,,,,,,,,,,,1,7.000000e-001,4.000000e+000,1,1,1.044989e-003,0,1,0,
1500129643.458,,2.760146e+003,1.799522e+000,1.620254e-001,0.000000e+000,0.000000e+000,0.000000e+000,2,9.906243e-001,1.825000e+000,,,,,,,,,,,,,,,,,,1,7.000000e-001,4.000000e+000,1,1,8.219481e-004,0,0,0,
1500129872.197,,2.760146e+003,1.801044e+000,1.624501e-001,0.000000e+000,0.000000e+000,0.000000e+000,2,9.908248e-001,1.825000e+000,,,,,,,,,,,,,,,,,,1,7.000000e-001,4.000000e+000,1,1,4.119873e-004,0,0,0,
1500130097.208,,2.760146e+003,1.800673e+000,1.621486e-001,0.000000e+000,0.000000e+000,0.000000e+000,2,9.905324e-001,1.825000e+000,,,,,,,,,,,,,,,,,,1,7.000000e-001,4.000000e+000,1,1,7.820129e-004,0,1,0,
1500130329.626,,2.760146e+003,1.798825e+000,1.625299e-001,0.000000e+000,0.000000e+000,0.000000e+000,2,9.907507e-001,1.825000e+000,,,,,,,,,,,,,,,,,,1,7.000000e-001,4.000000e+000,1,1,7.790327e-004,0,1,0,
1500130564.172,,2.760146e+003,1.799984e+000,1.625165e-001,0.000000e+000,0.000000e+000,0.000000e+000,2,9.908339e-001,1.825000e+000,,,,,,,,,,,,,,,,,,1,7.000000e-001,4.000000e+000,1,1,4.320145e-004,0,0,0,
1500130795.642,,2.760146e+003,1.800735e+000,1.620785e-001,0.000000e+000,0.000000e+000,0.000000e+000,2,9.905959e-001,1.825000e+000,,,,,,,,,,,,,,,,,,1,7.000000e-001,4.000000e+000,1,1,1.564980e-003,0,0,0,
1500131026.532,,2.760146e+003,1.801198e+000,1.623631e-001,0.000000e+000,0.000000e+000,0.000000e+000,2,9.907648e-001,1.825000e+000,,,,,,,,,,,,,,,,,,1,7.000000e-001,4.000000e+000,1,1,1.449585e-004,0,1,0,
1500131260.942,,2.760146e+003,1.798967e+000,1.625647e-001,0.000000e+000,0.000000e+000,0.000000e+000,2,9.908005e-001,1.825000e+000,,,,,,,,,,,,,,,,,,1,7.000000e-001,4.000000e+000,1,1,2.050400e-004,0,1,0,
1500131490.894,,2.760146e+003,1.799861e+000,1.625698e-001,0.000000e+000,0.000000e+000,0.000000e+000,2,9.907622e-001,1.825000e+000,,,,,,,,,,,,,,,,,,1,7.000000e-001,4.000000e+000,1,1,2.260208e-004,0,0,0,
1500131723.019,,2.760146e+003,1.801507e+000,1.624273e-001,0.000000e+000,0.000000e+000,0.000000e+000,2,9.907336e-001,1.825000e+000,,,,,,,,,,,,,,,,,,1,7.000000e-001,4.000000e+000,1,1,1.449585e-004,0,0,0,
1500131957.299,,2.760146e+003,1.800694e+000,1.622630e-001,0.000000e+000,0.000000e+000,0.000000e+000,2,9.905847e-001,1.825000e+000,,,,,,,,,,,,,,,,,,1,7.000000e-001,4.000000e+000,1,1,4.529953e-004,0,1,0,
1500132190.689,,2.760146e+003,1.799214e+000,1.626480e-001,0.000000e+000,0.000000e+000,0.000000e+000,2,9.908784e-001,1.825000e+000,,,,,,,,,,,,,,,,,,1,7.000000e-001,4.000000e+000,1,1,6.560087e-004,0,1,0,
1500132421.547,,2.760146e+003,1.799706e+000,1.625247e-001,0.000000e+000,0.000000e+000,0.000000e+000,2,9.908778e-001,1.825000e+000,,,,,,,,,,,,,,,,,,1,7.000000e-001,4.000000e+000,1,1,2.869368e-004,0,0,0,
1500132650.727,,2.760146e+003,1.800498e+000,1.625576e-001,0.000000e+000,0.000000e+000,0.000000e+000,2,9.907369e-001,1.825000e+000,,,,,,,,,,,,,,,,,,1,7.000000e-001,4.000000e+000,1,1,9.670258e-004,0,0,0,
1500132882.713,,2.760146e+003,1.800889e+000,1.624317e-001,0.000000e+000,0.000000e+000,0.000000e+000,2,9.907334e-001,1.825000e+000,,,,,,,,,,,,,,,,,,1,7.000000e-001,4.000000e+000,1,1,6.389618e-004,0,1,0,
1500133114.292,,2.760146e+003,1.799009e+000,1.627866e-001,0.000000e+000,0.000000e+000,0.000000e+000,2,9.907591e-001,1.825000e+000,,,,,,,,,,,,,,,,,,1,7.000000e-001,4.000000e+000,1,1,5.329847e-004,0,1,0,
1500133344.622,,2.760146e+003,1.799758e+000,1.626095e-001,0.000000e+000,0.000000e+000,0.000000e+000,2,9.908243e-001,1.825000e+000,,,,,,,,,,,,,,,,,,1,7.000000e-001,4.000000e+000,1,1,1.006961e-003,0,0,0,
1500133575.303,,2.760146e+003,1.800941e+000,1.623800e-001,0.000000e+000,0.000000e+000,0.000000e+000,2,9.907324e-001,1.825000e+000,,,,,,,,,,,,,,,,,,1,7.000000e-001,4.000000e+000,1,1,4.196167e-005,0,0,0,
1500133811.068,,2.760146e+003,1.800210e+000,1.627439e-001,0.000000e+000,0.000000e+000,0.000000e+000,2,9.906396e-001,1.825000e+000,,,,,,,,,,,,,,,,,,1,7.000000e-001,4.000000e+000,1,1,1.091003e-003,0,1,0,
1500134042.597,,2.760146e+003,1.798465e+000,1.627781e-001,0.000000e+000,0.000000e+000,0.000000e+000,2,9.909879e-001,1.825000e+000,,,,,,,,,,,,,,,,,,1,7.000000e-001,4.000000e+000,1,1,2.670288e-004,0,1,0,
1500134283.038,,3.011081e+003,1.799378e+000,1.727133e-001,0.000000e+000,0.000000e+000,0.000000e+000,2,9.907179e-001,1.825000e+000,,,,,,,,,,,,,,,,,,1,7.000000e-001,4.000000e+000,1,1,2.880096e-004,0,0,0,
1500134516.052,,3.011081e+003,1.801446e+000,1.745546e-001,0.000000e+000,0.000000e+000,0.000000e+000,2,9.907517e-001,1.825000e+000,,,,,,,,,,,,,,,,,,1,7.000000e-001,4.000000e+000,1,1,6.400347e-004,0,0,0,
1500134749.364,,3.011081e+003,1.800323e+000,1.748212e-001,0.000000e+000,0.000000e+000,0.000000e+000,2,9.908744e-001,1.825000e+000,,,,,,,,,,,,,,,,,,1,7.000000e-001,4.000000e+000,1,1,2.880096e-004,0,1,0,
1500134984.475,,3.011081e+003,1.798445e+000,1.752183e-001,0.000000e+000,0.000000e+000,0.000000e+000,2,9.907736e-001,1.825000e+000,,,,,,,,,,,,,,,,,,1,7.000000e-001,4.000000e+000,1,1,6.759167e-004,0,1,0,
1500135218.470,,3.011081e+003,1.799789e+000,1.749778e-001,0.000000e+000,0.000000e+000,0.000000e+000,2,9.908244e-001,1.825000e+000,,,,,,,,,,,,,,,,,,1,7.000000e-001,4.000000e+000,1,1,7.799864e-004,0,0,0,
1500135452.785,,3.011081e+003,1.800550e+000,1.745892e-001,0.000000e+000,0.000000e+000,0.000000e+000,2,9.906226e-001,1.825000e+000,,,,,,,,,,,,,,,,,,1,7.000000e-001,4.000000e+000,1,1,3.290176e-004,0,0,0,
1500135683.976,,3.011081e+003,1.800467e+000,1.751921e-001,0.000000e+000,0.000000e+000,0.000000e+000,2,9.907039e-001,1.825000e+000,,,,,,,,,,,,,,,,,,1,7.000000e-001,4.000000e+000,1,1,7.410049e-004,0,1,0,
1500135919.797,,3.011081e+003,1.798169e+000,1.753214e-001,0.000000e+000,0.000000e+000,0.000000e+000,2,9.904963e-001,1.825000e+000,,,,,,,,,,,,,,,,,,1,7.000000e-001,4.000000e+000,1,1,1.230240e-004,0,1,0,
1500136149.952,,3.011081e+003,1.799614e+000,1.751551e-001,0.000000e+000,0.000000e+000,0.000000e+000,2,9.908397e-001,1.825000e+000,,,,,,,,,,,,,,,,,,1,7.000000e-001,4.000000e+000,1,1,1.211047e-003,0,0,0,
1500136379.405,,3.011081e+003,1.800838e+000,1.750847e-001,0.000000e+000,0.000000e+000,0.000000e+000,2,9.906700e-001,1.825000e+000,,,,,,,,,,,,,,,,,,1,7.000000e-001,4.000000e+000,1,1,1.029968e-003,0,0,0,
1500136609.726,,3.011081e+003,1.800529e+000,1.751882e-001,0.000000e+000,0.000000e+000,0.000000e+000,2,9.907500e-001,1.825000e+000,,,,,,,,,,,,,,,,,,1,7.000000e-001,4.000000e+000,1,1,6.999969e-004,0,1,0,
1500136847.701,,3.011081e+003,1.797871e+000,1.751699e-001,0.000000e+000,0.000000e+000,0.000000e+000,2,9.908153e-001,1.825000e+000,,,,,,,,,,,,,,,,,,1,7.000000e-001,4.000000e+000,1,1,1.003027e-003,0,1,0,
1500137079.847,,3.011081e+003,1.800056e+000,1.748360e-001,0.000000e+000,0.000000e+000,0.000000e+000,2,9.906109e-001,1.825000e+000,,,,,,,,,,,,,,,,,,1,7.000000e-001,4.000000e+000,1,1,6.580353e-004,0,0,0,
1500137314.003,,3.011081e+003,1.801323e+000,1.750467e-001,0.000000e+000,0.000000e+000,0.000000e+000,2,9.907330e-001,1.825000e+000,,,,,,,,,,,,,,,,,,1,7.000000e-001,4.000000e+000,1,1,1.587987e-003,0,0,0,
1500137545.456,,3.011081e+003,1.800396e+000,1.752621e-001,0.000000e+000,0.000000e+000,0.000000e+000,2,9.906399e-001,1.825000e+000,,,,,,,,,,,,,,,,,,1,7.000000e-001,4.000000e+000,1,1,1.214027e-003,0,1,0,
1500137778.691,,3.011081e+003,1.798373e+000,1.753182e-001,0.000000e+000,0.000000e+000,0.000000e+000,2,9.905648e-001,1.825000e+000,,,,,,,,,,,,,,,,,,1,7.000000e-001,4.000000e+000,1,1,1.640320e-004,0,1,0,
1500138010.565,,3.011081e+003,1.799778e+000,1.751344e-001,0.000000e+000,0.000000e+000,0.000000e+000,2,9.908026e-001,1.825000e+000,,,,,,,,,,,,,,,,,,1,7.000000e-001,4.000000e+000,1,1,7.189512e-004,0,0,0,
1500138239.463,,3.011081e+003,1.801652e+000,1.750572e-001,0.000000e+000,0.000000e+000,0.000000e+000,2,9.906480e-001,1.825000e+000,,,,,,,,,,,,,,,,,,1,7.000000e-001,4.000000e+000,1,1,3.100634e-004,0,0,0,
1500138472.828,,3.011081e+003,1.800025e+000,1.751535e-001,0.000000e+000,0.000000e+000,0.000000e+000,2,9.907752e-001,1.825000e+000,,,,,,,,,,,,,,,,,,1,7.000000e-001,4.000000e+000,1,1,3.080368e-004,0,1,0,
1500138707.509,,3.011081e+003,1.798805e+000,1.751247e-001,0.000000e+000,0.000000e+000,0.000000e+000,2,9.907676e-001,1.825000e+000,,,,,,,,,,,,,,,,,,1,7.000000e-001,4.000000e+000,1,1,1.680970e-003,0,1,0,
1500138941.654,,3.011081e+003,1.799861e+000,1.751467e-001,0.000000e+000,0.000000e+000,0.000000e+000,2,9.906373e-001,1.825000e+000,,,,,,,,,,,,,,,,,,1,7.000000e-001,4.000000e+000,1,1,1.047969e-003,0,0,0,
1500139176.409,,3.011081e+003,1.801807e+000,1.749562e-001,0.000000e+000,0.000000e+000,0.000000e+000,2,9.907060e-001,1.825000e+000,,,,,,,,,,,,,,,,,,1,7.000000e-001,4.000000e+000,1,1,1.155972e-003,0,0,0,
1500139410.180,,3.011081e+003,1.799543e+000,1.751417e-001,0.000000e+000,0.000000e+000,0.000000e+000,2,9.907200e-001,1.825000e+000,,,,,,,,,,,,,,,,,,1,7.000000e-001,4.000000e+000,1,1,1.150012e-003,0,1,0,
1500139693.201,,3.513532e+003,1.798732e+000,1.874022e-001,0.000000e+000,0.000000e+000,0.000000e+000,2,9.908439e-001,1.825000e+000,,,,,,,,,,,,,,,,,,1,7.000000e-001,4.000000e+000,1,1,1.128078e-003,0,0,0,
1500139926.606,,3.513532e+003,1.800117e+000,1.979085e-001,0.000000e+000,0.000000e+000,0.000000e+000,2,9.906589e-001,1.825000e+000,,,,,,,,,,,,,,,,,,1,7.000000e-001,4.000000e+000,1,1,1.230240e-004,0,0,0,
1500140159.302,,3.513532e+003,1.801890e+000,1.984491e-001,0.000000e+000,0.000000e+000,0.000000e+000,2,9.906674e-001,1.825000e+000,,,,,,,,,,,,,,,,,,1,7.000000e-001,4.000000e+000,1,1,1.362085e-003,0,0,0,
1500140392.892,,3.513532e+003,1.799409e+000,1.988986e-001,0.000000e+000,0.000000e+000,0.000000e+000,2,9.907410e-001,1.825000e+000,,,,,,,,,,,,,,,,,,1,7.000000e-001,4.000000e+000,1,1,3.080368e-004,0,1,0,
1500140638.866,,4.015620e+003,1.798773e+000,2.154519e-001,0.000000e+000,0.000000e+000,0.000000e+000,2,9.907827e-001,1.825000e+000,,,,,,,,,,,,,,,,,,1,7.000000e-001,4.000000e+000,1,1,9.220839e-004,0,0,0,
1500140872.877,,4.015620e+003,1.800210e+000,2.197502e-001,0.000000e+000,0.000000e+000,0.000000e+000,2,9.905859e-001,1.825000e+000,,,,,,,,,,,,,,,,,,1,7.000000e-001,4.000000e+000,1,1,5.970001e-004,0,0,0,
1500141104.647,,4.015620e+003,1.800992e+000,2.203472e-001,0.000000e+000,0.000000e+000,0.000000e+000,2,9.907381e-001,1.825000e+000,,,,,,,,,,,,,,,,,,1,7.000000e-001,4.000000e+000,1,1,4.329681e-004,0,0,0,
1500141339.897,,4.015620e+003,1.800015e+000,2.207396e-001,0.000000e+000,0.000000e+000,0.000000e+000,2,9.906799e-001,1.825000e+000,,,,,,,,,,,,,,,,,,1,7.000000e-001,4.000000e+000,1,1,2.880096e-004,0,1,0,
1500141580.915,,4.517274e+003,1.799143e+000,2.387999e-001,0.000000e+000,0.000000e+000,0.000000e+000,2,9.907717e-001,1.825000e+000,,,,,,,,,,,,,,,,,,1,7.000000e-001,4.000000e+000,1,1,8.410215e-004,0,1,0,
1500141814.094,,4.517274e+003,1.799779e+000,2.399059e-001,0.000000e+000,0.000000e+000,0.000000e+000,2,9.905470e-001,1.825000e+000,,,,,,,,,,,,,,,,,,1,7.000000e-001,4.000000e+000,1,1,1.129985e-003,0,0,0,
1500142079.041,,4.517274e+003,1.800467e+000,2.402418e-001,0.000000e+000,0.000000e+000,0.000000e+000,2,9.906541e-001,1.825000e+000,,,,,,,,,,,,,,,,,,1,7.000000e-001,4.000000e+000,1,1,1.152992e-003,0,0,0,
1500142351.512,,4.517274e+003,1.798968e+000,2.403982e-001,0.000000e+000,0.000000e+000,0.000000e+000,2,9.905313e-001,1.825000e+000,,,,,,,,,,,,,,,,,,1,7.000000e-001,4.000000e+000,1,1,9.840727e-004,0,1,0,
1500142610.992,,5.020014e+003,1.799070e+000,2.580143e-001,0.000000e+000,0.000000e+000,0.000000e+000,2,9.906263e-001,1.825000e+000,,,,,,,,,,,,,,,,,,1,7.000000e-001,4.000000e+000,1,1,8.201599e-005,0,0,0,
1500142859.056,,5.020014e+003,1.800653e+000,2.582228e-001,0.000000e+000,0.000000e+000,0.000000e+000,2,9.906885e-001,1.825000e+000,,,,,,,,,,,,,,,,,,1,7.000000e-001,4.000000e+000,1,1,7.410049e-004,0,0,0,
1500143107.841,,5.020014e+003,1.801457e+000,2.577583e-001,0.000000e+000,0.000000e+000,0.000000e+000,2,9.905120e-001,1.825000e+000,,,,,,,,,,,,,,,,,,1,7.000000e-001,4.000000e+000,1,1,1.937985e-003,0,1,0,
1500143540.965,,5.020014e+003,1.798947e+000,2.578835e-001,0.000000e+000,0.000000e+000,0.000000e+000,2,9.904589e-001,1.825000e+000,,,,,,,,,,,,,,,,,,1,7.000000e-001,4.000000e+000,1,1,1.640320e-004,0,1,0,
1500143835.302,,5.522899e+003,1.800745e+000,2.742198e-001,0.000000e+000,0.000000e+000,0.000000e+000,2,9.908117e-001,1.825000e+000,,,,,,,,,,,,,,,,,,1,7.000000e-001,4.000000e+000,1,1,5.970001e-004,0,0,0,
1500144073.857,,5.522899e+003,1.801404e+000,2.743199e-001,0.000000e+000,0.000000e+000,0.000000e+000,2,9.906739e-001,1.825000e+000,,,,,,,,,,,,,,,,,,1,7.000000e-001,4.000000e+000,1,1,4.329681e-004,0,0,0,
1500144318.708,,6.024771e+003,1.799276e+000,2.890871e-001,0.000000e+000,0.000000e+000,0.000000e+000,2,9.907483e-001,1.825000e+000,,,,,,,,,,,,,,,,,,1,7.000000e-001,4.000000e+000,1,1,8.620024e-004,0,1,0,
1500144558.553,,6.024771e+003,1.798845e+000,2.889016e-001,0.000000e+000,0.000000e+000,0.000000e+000,2,9.906372e-001,1.825000e+000,,,,,,,,,,,,,,,,,,1,7.000000e-001,4.000000e+000,1,1,9.430647e-004,0,0,0,
1500144805.504,,6.527076e+003,1.800570e+000,3.018449e-001,0.000000e+000,0.000000e+000,0.000000e+000,2,9.907469e-001,1.825000e+000,,,,,,,,,,,,,,,,,,1,7.000000e-001,4.000000e+000,1,1,4.100800e-005,0,0,0,
1500145040.942,,6.527076e+003,1.801456e+000,3.017332e-001,0.000000e+000,0.000000e+000,0.000000e+000,2,9.905182e-001,1.825000e+000,,,,,,,,,,,,,,,,,,1,7.000000e-001,4.000000e+000,1,1,2.880096e-004,0,1,0,
1500145328.516,,7.026050e+003,1.798732e+000,3.129678e-001,0.000000e+000,0.000000e+000,0.000000e+000,2,9.905955e-001,1.825000e+000,,,,,,,,,,,,,,,,,,1,7.000000e-001,4.000000e+000,1,1,5.120039e-004,0,1,0,
1500145566.822,,7.026050e+003,1.799922e+000,3.136897e-001,0.000000e+000,0.000000e+000,0.000000e+000,2,9.906945e-001,1.825000e+000,,,,,,,,,,,,,,,,,,1,7.000000e-001,4.000000e+000,1,1,8.430481e-004,0,0,0,
1500145805.773,,7.531543e+003,1.801188e+000,3.232738e-001,0.000000e+000,0.000000e+000,0.000000e+000,2,9.904246e-001,1.825000e+000,,,,,,,,,,,,,,,,,,1,7.000000e-001,4.000000e+000,1,1,6.589890e-004,0,0,0,
1500146040.436,,7.531543e+003,1.800941e+000,3.239110e-001,0.000000e+000,0.000000e+000,0.000000e+000,2,9.907532e-001,1.825000e+000,,,,,,,,,,,,,,,,,,1,7.000000e-001,4.000000e+000,1,1,7.419586e-004,0,1,0,
1500146288.665,,8.029938e+003,1.797810e+000,3.327405e-001,0.000000e+000,0.000000e+000,0.000000e+000,2,9.904212e-001,1.825000e+000,,,,,,,,,,,,,,,,,,1,7.000000e-001,4.000000e+000,1,1,6.760359e-004,0,1,0,
1500146520.341,,8.029938e+003,1.800004e+000,3.332180e-001,0.000000e+000,0.000000e+000,0.000000e+000,2,9.905931e-001,1.825000e+000,,,,,,,,,,,,,,,,,,1,7.000000e-001,4.000000e+000,1,1,2.670288e-004,0,0,0,
1500146762.026,,8.531519e+003,1.800848e+000,3.414402e-001,0.000000e+000,0.000000e+000,0.000000e+000,2,9.905402e-001,1.825000e+000,,,,,,,,,,,,,,,,,,1,7.000000e-001,4.000000e+000,1,1,1.008987e-003,0,0,0,
1500146994.767,,8.531519e+003,1.800889e+000,3.413147e-001,0.000000e+000,0.000000e+000,0.000000e+000,2,9.906970e-001,1.825000e+000,,,,,,,,,,,,,,,,,,1,7.000000e-001,4.000000e+000,1,1,4.730225e-004,0,1,0,
1500147239.988,,9.034549e+003,1.797933e+000,3.489681e-001,0.000000e+000,0.000000e+000,0.000000e+000,2,9.905612e-001,1.825000e+000,,,,,,,,,,,,,,,,,,1,7.000000e-001,4.000000e+000,1,1,5.120039e-004,0,1,0,
1500147477.978,,9.034549e+003,1.800457e+000,3.488143e-001,0.000000e+000,0.000000e+000,0.000000e+000,2,9.905343e-001,1.825000e+000,,,,,,,,,,,,,,,,,,1,7.000000e-001,4.000000e+000,1,1,1.214027e-003,0,0,0,
1500147719.938,,9.537284e+003,1.801703e+000,3.553949e-001,0.000000e+000,0.000000e+000,0.000000e+000,2,9.907043e-001,1.825000e+000,,,,,,,,,,,,,,,,,,1,7.000000e-001,4.000000e+000,1,1,8.308887e-005,0,0,0,
1500147954.257,,9.537284e+003,1.800200e+000,3.554840e-001,0.000000e+000,0.000000e+000,0.000000e+000,2,9.906179e-001,1.825000e+000,,,,,,,,,,,,,,,,,,1,7.000000e-001,4.000000e+000,1,1,3.290176e-004,0,1,0,
1500148203.567,,1.003800e+004,1.798722e+000,3.614908e-001,0.000000e+000,0.000000e+000,0.000000e+000,2,9.905998e-001,1.825000e+000,,,,,,,,,,,,,,,,,,1,7.000000e-001,4.000000e+000,1,1,7.790327e-004,0,1,0,
1500148442.307,,1.003800e+004,1.799542e+000,3.613095e-001,0.000000e+000,0.000000e+000,0.000000e+000,2,9.906897e-001,1.825000e+000,,,,,,,,,,,,,,,,,,1,7.000000e-001,4.000000e+000,1,1,9.850264e-004,0,0,0,
1500148749.977,,1.204201e+004,1.800982e+000,3.796832e-001,0.000000e+000,0.000000e+000,0.000000e+000,2,9.905270e-001,1.825000e+000,,,,,,,,,,,,,,,,,,1,7.000000e-001,4.000000e+000,1,1,6.589890e-004,0,1,0,
1500149038.827,,1.505237e+004,1.798159e+000,3.971431e-001,0.000000e+000,0.000000e+000,0.000000e+000,2,9.912916e-001,1.825000e+000,,,,,,,,,,,,,,,,,,1,7.000000e-001,4.000000e+000,1,1,7.989407e-004,0,1,0,
1500149321.918,,1.756259e+004,1.799625e+000,4.043037e-001,0.000000e+000,0.000000e+000,0.000000e+000,2,9.905763e-001,1.825000e+000,,,,,,,,,,,,,,,,,,1,7.000000e-001,4.000000e+000,1,1,1.273990e-003,0,0,0,
1500149604.723,,2.007122e+004,1.802209e+000,4.103051e-001,0.000000e+000,0.000000e+000,0.000000e+000,2,9.906148e-001,1.825000e+000,,,,,,,,,,,,,,,,,,1,7.000000e-001,4.000000e+000,1,1,8.471012e-004,0,0,0,
1500150024.889,,4.517564e+004,1.798548e+000,4.280968e-001,0.000000e+000,0.000000e+000,0.000000e+000,2,9.902246e-001,1.825000e+000,,,,,,,,,,,,,,,,,,1,7.000000e-001,4.000000e+000,1,1,9.229183e-004,0,1,0,
1500150402.960,,7.029238e+004,1.800694e+000,4.327439e-001,0.000000e+000,0.000000e+000,0.000000e+000,2,9.900294e-001,1.825000e+000,,,,,,,,,,,,,,,,,,1,7.000000e-001,4.000000e+000,1,1,4.940033e-004,0,0,0,
1500150425.430,,7.029238e+004,1.800900e+000,4.328316e-001,0.000000e+000,0.000000e+000,0.000000e+000,2,9.900326e-001,1.825000e+000,,,,,,,,,,,,,,,,,,1,7.000000e-001,4.000000e+000,1,1,1.441956e-003,0,0,0,