File: examples/pb6051_ZFC_0p1T.dc.dat
[Header]
TITLE,MPMS DC Measurement
BYAPP,MPMS Measurement,2.1,Summary
FILEOPENTIME, 1480485262.746000 11/29/2016, 9:54:22 PM

INFO, APPNAME, MPMS MultiVu Application, Revision 1.60,  Build 081

INFO, NAME, pb6051
INFO, WEIGHT, 48.400
INFO, AREA, 0.000
INFO, LENGTH, 0.000
INFO, SHAPE, 0
INFO, COMMENT,
INFO, SEQUENCE FILE: pb6051.seq


INFO, BACKGROUND DATA FILE:, None


STARTUPAXIS,X,4,LINEAR,AUTO,0.000000,0.000000
STARTUPAXIS,Y1,5,LINEAR,AUTO,0.000000,0.000000


STARTUPGROUP,Longitudinal
FIELDGROUP,Longitudinal,1,2,3,4,5,6,7,8,9,15,16,17,18,27,28
FIELDGROUP,Transverse,1,2,3,4,10,11,12,13,14,19,20,21,22,27,28

PLOT_APPEARANCE,ALL,HORZ_GRID_ON,VERT_GRID_ON,MARKERS_AND_LINES

[Data]
Time,Comment,Field (Oe),Temperature (K),Long Moment (emu),Long Scan Std Dev,Long Algorithm,Long Reg Fit,Long Percent Error (%),Trans Moment (emu),Trans Scan Std Dev,Trans Algorithm,Trans Reg Fit,Trans Percent Error (%),Long Moment [w/o ABS] (emu),Long Scan Std Dev [w/o ABS],Long Reg Fit [w/o ABS],Long Percent Error [w/o ABS] (%),Trans Moment [w/o ABS] (emu),Trans Scan Std Dev [w/o ABS],Trans Reg Fit [w/o ABS],Trans Percent Error [w/o ABS] (%),Points per Scan,Scans per Measurement,Scan Length (cm),Delta Temp (K),Rot Position (deg),Error,EC Comp. Running,Using ABS,
1480485262.746,,1.000000e+003,1.999682e+000,5.397742e-002,0.000000e+000,3,9.885179e-001,0.000000e+000,,,,,,,,,,,,,,18,1,4.000000e+000,1.541972e-003,0.000000e+000,0,0,0,
1480485275.036,,1.000000e+003,2.000037e+000,5.414311e-002,0.000000e+000,3,9.886047e-001,0.000000e+000,,,,,,,,,,,,,,18,1,4.000000e+000,8.319616e-004,0.000000e+000,0,0,0,
1480485287.846,,1.000000e+003,1.999591e+000,5.430539e-002,0.000000e+000,3,9.886636e-001,0.000000e+000,,,,,,,,,,,,,,18,1,4.000000e+000,6.103516e-005,0.000000e+000,0,0,0,
1480485455.558,,1.000000e+003,3.000428e+000,3.678189e-002,0.000000e+000,3,9.888917e-001,0.000000e+000,,,,,,,,,,,,,,18,1,4.000000e+000,1.313925e-003,0.000000e+000,0,1,0,
1480485467.498,,1.000000e+003,3.003922e+000,3.673093e-002,0.000000e+000,3,9.888050e-001,0.000000e+000,,,,,,,,,,,,,,18,1,4.000000e+000,6.463051e-003,0.000000e+000,0,1,0,
1480485480.668,,1.000000e+003,3.004840e+000,3.673030e-002,0.000000e+000,3,9.888840e-001,0.000000e+000,,,,,,,,,,,,,,18,1,4.000000e+000,2.507925e-003,0.000000e+000,0,1,0,
1480485661.813,,1.000000e+003,3.978930e+000,2.764092e-002,0.000000e+000,3,9.893394e-001,0.000000e+000,,,,,,,,,,,,,,18,1,4.000000e+000,2.537012e-003,0.000000e+000,0,0,0,
1480485674.153,,1.000000e+003,3.966665e+000,2.765535e-002,0.000000e+000,3,9.892832e-001,0.000000e+000,,,,,,,,,,,,,,18,1,4.000000e+000,2.199507e-002,0.000000e+000,0,0,0,
1480485699.263,,1.000000e+003,3.979673e+000,2.764366e-002,0.000000e+000,3,9.891676e-001,0.000000e+000,,,,,,,,,,,,,,18,1,4.000000e+000,1.776814e-002,0.000000e+000,0,0,0,
1480485818.743,,1.000000e+003,5.002007e+000,2.222069e-002,0.000000e+000,3,9.895623e-001,0.000000e+000,,,,,,,,,,,,,,18,1,4.000000e+000,3.047943e-003,0.000000e+000,0,0,0,
1480485831.133,,1.000000e+003,4.999496e+000,2.218702e-002,0.000000e+000,3,9.895788e-001,0.000000e+000,,,,,,,,,,,,,,18,1,4.000000e+000,5.325317e-003,0.000000e+000,0,0,0,
1480485844.923,,1.000000e+003,4.998962e+000,2.218000e-002,0.000000e+000,3,9.895192e-001,0.000000e+000,,,,,,,,,,,,,,18,1,4.000000e+000,3.955841e-003,0.000000e+000,0,0,0,
1480485939.232,,1.000000e+003,6.002471e+000,1.857367e-002,0.000000e+000,3,9.897526e-001,0.000000e+000,,,,,,,,,,,,,,18,1,4.000000e+000,1.910210e-003,0.000000e+000,0,0,0,
1480485953.062,,1.000000e+003,6.005950e+000,1.854566e-002,0.000000e+000,3,9.897119e-001,0.000000e+000,,,,,,,,,,,,,,18,1,4.000000e+000,1.248360e-002,0.000000e+000,0,0,0,
1480485965.602,,1.000000e+003,5.998103e+000,1.853621e-002,0.000000e+000,3,9.897561e-001,0.000000e+000,,,,,,,,,,,,,,18,1,4.000000e+000,2.810001e-003,0.000000e+000,0,0,0,
1480486062.582,,1.000000e+003,7.001181e+000,1.600301e-002,0.000000e+000,3,9.900520e-001,0.000000e+000,,,,,,,,,,,,,,18,1,4.000000e+000,4.039288e-003,0.000000e+000,0,0,0,
1480486074.902,,1.000000e+003,6.997070e+000,1.597313e-002,0.000000e+000,3,9.902436e-001,0.000000e+000,,,,,,,,,,,,,,18,1,4.000000e+000,4.181862e-003,0.000000e+000,0,0,0,
1480486088.403,,1.000000e+003,6.994756e+000,1.596958e-002,0.000000e+000,3,9.900138e-001,0.000000e+000,,,,,,,,,,,,,,18,1,4.000000e+000,5.223751e-003,0.000000e+000,0,0,0,
1480486189.154,,1.000000e+003,7.960569e+000,1.400741e-002,0.000000e+000,3,9.903713e-001,0.000000e+000,,,,,,,,,,,,,,18,1,4.000000e+000,3.511906e-002,0.000000e+000,0,1,0,
1480486201.464,,1.000000e+003,8.004461e+000,1.395642e-002,0.000000e+000,3,9.900491e-001,0.000000e+000,,,,,,,,,,,,,,18,1,4.000000e+000,5.266523e-002,0.000000e+000,0,1,0,
1480486214.524,,1.000000e+003,8.013781e+000,1.392287e-002,0.000000e+000,3,9.902623e-001,0.000000e+000,,,,,,,,,,,,,,18,1,4.000000e+000,3.402805e-002,0.000000e+000,0,1,0,
1480486310.501,,1.000000e+003,8.997528e+000,1.243472e-002,0.000000e+000,3,9.904736e-001,0.000000e+000,,,,,,,,,,,,,,18,1,4.000000e+000,2.479553e-003,0.000000e+000,0,1,0,
1480486323.351,,1.000000e+003,8.969650e+000,1.242932e-002,0.000000e+000,3,9.904438e-001,0.000000e+000,,,,,,,,,,,,,,18,1,4.000000e+000,5.823612e-002,0.000000e+000,0,1,0,
1480486335.191,,1.000000e+003,8.954825e+000,1.244383e-002,0.000000e+000,3,9.902231e-001,0.000000e+000,,,,,,,,,,,,,,18,1,4.000000e+000,2.641869e-002,0.000000e+000,0,1,0,
1480486428.948,,1.000000e+003,9.994172e+000,1.117766e-002,0.000000e+000,3,9.906392e-001,0.000000e+000,,,,,,,,,,,,,,18,1,4.000000e+000,1.657486e-002,0.000000e+000,0,0,0,
1480486440.133,,1.000000e+003,9.988531e+000,1.117835e-002,0.000000e+000,3,9.904881e-001,0.000000e+000,,,,,,,,,,,,,,18,1,4.000000e+000,5.292892e-003,0.000000e+000,0,0,0,
1480486453.248,,1.000000e+003,9.988181e+000,1.117290e-002,0.000000e+000,3,9.904196e-001,0.000000e+000,,,,,,,,,,,,,,18,1,4.000000e+000,1.023293e-002,0.000000e+000,0,0,0,
1480486545.459,,1.000000e+003,1.098688e+001,1.016274e-002,0.000000e+000,3,9.908623e-001,0.000000e+000,,,,,,,,,,,,,,18,1,4.000000e+000,5.102158e-004,0.000000e+000,0,0,0,
1480486560.174,,1.000000e+003,1.098380e+001,1.015781e-002,0.000000e+000,3,9.909411e-001,0.000000e+000,,,,,,,,,,,,,,18,1,4.000000e+000,3.499985e-004,0.000000e+000,0,0,0,
1480486574.454,,1.000000e+003,1.098293e+001,1.015513e-002,0.000000e+000,3,9.906736e-001,0.000000e+000,,,,,,,,,,,,,,18,1,4.000000e+000,3.499985e-004,0.000000e+000,0,0,0,
1480486668.631,,1.000000e+003,1.199337e+001,9.275945e-003,0.000000e+000,3,9.909726e-001,0.000000e+000,,,,,,,,,,,,,,18,1,4.000000e+000,1.600266e-003,0.000000e+000,0,0,0,
1480486683.796,,1.000000e+003,1.199245e+001,9.268762e-003,0.000000e+000,3,9.909766e-001,0.000000e+000,,,,,,,,,,,,,,18,1,4.000000e+000,1.910210e-003,0.000000e+000,0,0,0,
1480486699.241,,1.000000e+003,1.199487e+001,9.266196e-003,0.000000e+000,3,9.910284e-001,0.000000e+000,,,,,,,,,,,,,,18,1,4.000000e+000,1.119614e-003,0.000000e+000,0,0,0,
1480486803.363,,1.000000e+003,1.299681e+001,8.573243e-003,0.000000e+000,3,9.912649e-001,0.000000e+000,,,,,,,,,,,,,,18,1,4.000000e+000,3.499985e-004,0.000000e+000,0,0,0,
1480486815.383,,1.000000e+003,1.299469e+001,8.570014e-003,0.000000e+000,3,9.910662e-001,0.000000e+000,,,,,,,,,,,,,,18,1,4.000000e+000,2.098083e-004,0.000000e+000,0,0,0,
1480486827.553,,1.000000e+003,1.299552e+001,8.568561e-003,0.000000e+000,3,9.911475e-001,0.000000e+000,,,,,,,,,,,,,,18,1,4.000000e+000,1.870155e-003,0.000000e+000,0,0,0,
1480486920.985,,1.000000e+003,1.400233e+001,7.966926e-003,0.000000e+000,3,9.915639e-001,0.000000e+000,,,,,,,,,,,,,,18,1,4.000000e+000,2.830505e-003,0.000000e+000,0,0,0,
1480486934.135,,1.000000e+003,1.400237e+001,7.966561e-003,0.000000e+000,3,9.912127e-001,0.000000e+000,,,,,,,,,,,,,,18,1,4.000000e+000,2.920151e-003,0.000000e+000,0,0,0,
1480486947.465,,1.000000e+003,1.400178e+001,7.966751e-003,0.000000e+000,3,9.913470e-001,0.000000e+000,,,,,,,,,,,,,,18,1,4.000000e+000,9.298325e-004,0.000000e+000,0,0,0,
1480487051.816,,1.000000e+003,1.499977e+001,7.441364e-003,0.000000e+000,3,9.916051e-001,0.000000e+000,,,,,,,,,,,,,,18,1,4.000000e+000,5.000114e-003,0.000000e+000,0,1,0,
1480487064.056,,1.000000e+003,1.500091e+001,7.440622e-003,0.000000e+000,3,9.915065e-001,0.000000e+000,,,,,,,,,,,,,,18,1,4.000000e+000,1.810074e-003,0.000000e+000,0,1,0,
1480487077.876,,1.000000e+003,1.500272e+001,7.442140e-003,0.000000e+000,3,9.914136e-001,0.000000e+000,,,,,,,,,,,,,,18,1,4.000000e+000,9.098053e-004,0.000000e+000,0,1,0,